I1030 05:01:30.384517       1 flags.go:64] FLAG: --allow-metric-labels="[]"
I1030 05:01:30.384645       1 flags.go:64] FLAG: --authentication-kubeconfig="/etc/kubernetes/scheduler.conf"
I1030 05:01:30.384657       1 flags.go:64] FLAG: --authentication-skip-lookup="false"
I1030 05:01:30.384665       1 flags.go:64] FLAG: --authentication-token-webhook-cache-ttl="10s"
I1030 05:01:30.384675       1 flags.go:64] FLAG: --authentication-tolerate-lookup-failure="true"
I1030 05:01:30.384681       1 flags.go:64] FLAG: --authorization-always-allow-paths="[/healthz,/readyz,/livez]"
I1030 05:01:30.384696       1 flags.go:64] FLAG: --authorization-kubeconfig="/etc/kubernetes/scheduler.conf"
I1030 05:01:30.384704       1 flags.go:64] FLAG: --authorization-webhook-cache-authorized-ttl="10s"
I1030 05:01:30.384711       1 flags.go:64] FLAG: --authorization-webhook-cache-unauthorized-ttl="10s"
I1030 05:01:30.384719       1 flags.go:64] FLAG: --bind-address="127.0.0.1"
I1030 05:01:30.384728       1 flags.go:64] FLAG: --cert-dir=""
I1030 05:01:30.384734       1 flags.go:64] FLAG: --client-ca-file=""
I1030 05:01:30.384741       1 flags.go:64] FLAG: --config="/etc/kubernetes/scheduler-policy-config.yaml"
I1030 05:01:30.384752       1 flags.go:64] FLAG: --contention-profiling="true"
I1030 05:01:30.384759       1 flags.go:64] FLAG: --disabled-metrics="[]"
I1030 05:01:30.384778       1 flags.go:64] FLAG: --feature-gates=""
I1030 05:01:30.384788       1 flags.go:64] FLAG: --help="false"
I1030 05:01:30.384794       1 flags.go:64] FLAG: --http2-max-streams-per-connection="0"
I1030 05:01:30.384802       1 flags.go:64] FLAG: --kube-api-burst="100"
I1030 05:01:30.384811       1 flags.go:64] FLAG: --kube-api-content-type="application/vnd.kubernetes.protobuf"
I1030 05:01:30.384818       1 flags.go:64] FLAG: --kube-api-qps="50"
I1030 05:01:30.384831       1 flags.go:64] FLAG: --kubeconfig="/etc/kubernetes/scheduler.conf"
I1030 05:01:30.384839       1 flags.go:64] FLAG: --leader-elect="true"
I1030 05:01:30.384845       1 flags.go:64] FLAG: --leader-elect-lease-duration="15s"
I1030 05:01:30.384853       1 flags.go:64] FLAG: --leader-elect-renew-deadline="10s"
I1030 05:01:30.384859       1 flags.go:64] FLAG: --leader-elect-resource-lock="leases"
I1030 05:01:30.384866       1 flags.go:64] FLAG: --leader-elect-resource-name="kube-scheduler"
I1030 05:01:30.384877       1 flags.go:64] FLAG: --leader-elect-resource-namespace="kube-system"
I1030 05:01:30.384883       1 flags.go:64] FLAG: --leader-elect-retry-period="2s"
I1030 05:01:30.384889       1 flags.go:64] FLAG: --lock-object-name="kube-scheduler"
I1030 05:01:30.384896       1 flags.go:64] FLAG: --lock-object-namespace="kube-system"
I1030 05:01:30.384904       1 flags.go:64] FLAG: --log-flush-frequency="5s"
I1030 05:01:30.384915       1 flags.go:64] FLAG: --log-json-info-buffer-size="0"
I1030 05:01:30.384938       1 flags.go:64] FLAG: --log-json-split-stream="false"
I1030 05:01:30.384945       1 flags.go:64] FLAG: --logging-format="text"
I1030 05:01:30.384951       1 flags.go:64] FLAG: --master=""
I1030 05:01:30.384958       1 flags.go:64] FLAG: --permit-address-sharing="false"
I1030 05:01:30.384969       1 flags.go:64] FLAG: --permit-port-sharing="false"
I1030 05:01:30.384975       1 flags.go:64] FLAG: --pod-max-in-unschedulable-pods-duration="5m0s"
I1030 05:01:30.384982       1 flags.go:64] FLAG: --profiling="true"
I1030 05:01:30.384988       1 flags.go:64] FLAG: --requestheader-allowed-names="[]"
I1030 05:01:30.385002       1 flags.go:64] FLAG: --requestheader-client-ca-file=""
I1030 05:01:30.385008       1 flags.go:64] FLAG: --requestheader-extra-headers-prefix="[x-remote-extra-]"
I1030 05:01:30.385024       1 flags.go:64] FLAG: --requestheader-group-headers="[x-remote-group]"
I1030 05:01:30.385035       1 flags.go:64] FLAG: --requestheader-username-headers="[x-remote-user]"
I1030 05:01:30.385050       1 flags.go:64] FLAG: --secure-port="10259"
I1030 05:01:30.385060       1 flags.go:64] FLAG: --show-hidden-metrics-for-version=""
I1030 05:01:30.385066       1 flags.go:64] FLAG: --tls-cert-file=""
I1030 05:01:30.385072       1 flags.go:64] FLAG: --tls-cipher-suites="[]"
I1030 05:01:30.385089       1 flags.go:64] FLAG: --tls-min-version=""
I1030 05:01:30.385095       1 flags.go:64] FLAG: --tls-private-key-file=""
I1030 05:01:30.385101       1 flags.go:64] FLAG: --tls-sni-cert-key="[]"
I1030 05:01:30.385114       1 flags.go:64] FLAG: --v="4"
I1030 05:01:30.385125       1 flags.go:64] FLAG: --version="false"
I1030 05:01:30.385141       1 flags.go:64] FLAG: --vmodule=""
I1030 05:01:30.385149       1 flags.go:64] FLAG: --write-config-to=""
I1030 05:01:30.761334       1 serving.go:348] Generated self-signed cert in-memory
I1030 05:01:31.109882       1 requestheader_controller.go:244] Loaded a new request header values for RequestHeaderAuthRequestController
I1030 05:01:31.129572       1 scheduler.go:387] "Creating extender" extender={URLPrefix:http://127.0.0.1:32766/gpushare-scheduler FilterVerb:filter PreemptVerb: PrioritizeVerb: Weight:0 BindVerb:bind EnableHTTPS:false TLSConfig:<nil> HTTPTimeout:{Duration:0s} NodeCacheCapable:true ManagedResources:[{Name:aliyun.com/gpu-mem IgnoredByScheduler:false}] Ignorable:false}
I1030 05:01:31.134637       1 configfile.go:105] "Using component config" config=<
	apiVersion: kubescheduler.config.k8s.io/v1
	clientConnection:
	  acceptContentTypes: ""
	  burst: 100
	  contentType: application/vnd.kubernetes.protobuf
	  kubeconfig: /etc/kubernetes/scheduler.conf
	  qps: 50
	enableContentionProfiling: true
	enableProfiling: true
	extenders:
	- bindVerb: bind
	  filterVerb: filter
	  httpTimeout: 5s
	  managedResources:
	  - name: aliyun.com/gpu-mem
	  nodeCacheCapable: true
	  urlPrefix: http://127.0.0.1:32766/gpushare-scheduler
	kind: KubeSchedulerConfiguration
	leaderElection:
	  leaderElect: true
	  leaseDuration: 15s
	  renewDeadline: 10s
	  resourceLock: leases
	  resourceName: kube-scheduler
	  resourceNamespace: kube-system
	  retryPeriod: 2s
	parallelism: 16
	percentageOfNodesToScore: 0
	podInitialBackoffSeconds: 1
	podMaxBackoffSeconds: 10
	profiles:
	- pluginConfig:
	  - args:
	      apiVersion: kubescheduler.config.k8s.io/v1
	      kind: DefaultPreemptionArgs
	      minCandidateNodesAbsolute: 100
	      minCandidateNodesPercentage: 10
	    name: DefaultPreemption
	  - args:
	      apiVersion: kubescheduler.config.k8s.io/v1
	      hardPodAffinityWeight: 1
	      ignorePreferredTermsOfExistingPods: false
	      kind: InterPodAffinityArgs
	    name: InterPodAffinity
	  - args:
	      apiVersion: kubescheduler.config.k8s.io/v1
	      kind: NodeAffinityArgs
	    name: NodeAffinity
	  - args:
	      apiVersion: kubescheduler.config.k8s.io/v1
	      kind: NodeResourcesBalancedAllocationArgs
	      resources:
	      - name: cpu
	        weight: 1
	      - name: memory
	        weight: 1
	    name: NodeResourcesBalancedAllocation
	  - args:
	      apiVersion: kubescheduler.config.k8s.io/v1
	      kind: NodeResourcesFitArgs
	      scoringStrategy:
	        resources:
	        - name: cpu
	          weight: 1
	        - name: memory
	          weight: 1
	        type: LeastAllocated
	    name: NodeResourcesFit
	  - args:
	      apiVersion: kubescheduler.config.k8s.io/v1
	      defaultingType: System
	      kind: PodTopologySpreadArgs
	    name: PodTopologySpread
	  - args:
	      apiVersion: kubescheduler.config.k8s.io/v1
	      bindTimeoutSeconds: 600
	      kind: VolumeBindingArgs
	    name: VolumeBinding
	  plugins:
	    bind: {}
	    filter: {}
	    multiPoint:
	      enabled:
	      - name: PrioritySort
	        weight: 0
	      - name: NodeUnschedulable
	        weight: 0
	      - name: NodeName
	        weight: 0
	      - name: TaintToleration
	        weight: 3
	      - name: NodeAffinity
	        weight: 2
	      - name: NodePorts
	        weight: 0
	      - name: NodeResourcesFit
	        weight: 1
	      - name: VolumeRestrictions
	        weight: 0
	      - name: EBSLimits
	        weight: 0
	      - name: GCEPDLimits
	        weight: 0
	      - name: NodeVolumeLimits
	        weight: 0
	      - name: AzureDiskLimits
	        weight: 0
	      - name: VolumeBinding
	        weight: 0
	      - name: VolumeZone
	        weight: 0
	      - name: PodTopologySpread
	        weight: 2
	      - name: InterPodAffinity
	        weight: 2
	      - name: DefaultPreemption
	        weight: 0
	      - name: NodeResourcesBalancedAllocation
	        weight: 1
	      - name: ImageLocality
	        weight: 1
	      - name: DefaultBinder
	        weight: 0
	      - name: SchedulingGates
	        weight: 0
	    permit: {}
	    postBind: {}
	    postFilter: {}
	    preBind: {}
	    preEnqueue: {}
	    preFilter: {}
	    preScore: {}
	    queueSort: {}
	    reserve: {}
	    score: {}
	  schedulerName: default-scheduler
 >
I1030 05:01:31.135198       1 server.go:154] "Starting Kubernetes Scheduler" version="v1.27.2-3+666c280030de93-dirty"
I1030 05:01:31.135223       1 server.go:156] "Golang settings" GOGC="" GOMAXPROCS="" GOTRACEBACK=""
I1030 05:01:31.141180       1 configmap_cafile_content.go:202] "Starting controller" name="client-ca::kube-system::extension-apiserver-authentication::client-ca-file"
I1030 05:01:31.141209       1 shared_informer.go:311] Waiting for caches to sync for client-ca::kube-system::extension-apiserver-authentication::client-ca-file
I1030 05:01:31.141183       1 requestheader_controller.go:169] Starting RequestHeaderAuthRequestController
I1030 05:01:31.141264       1 configmap_cafile_content.go:202] "Starting controller" name="client-ca::kube-system::extension-apiserver-authentication::requestheader-client-ca-file"
I1030 05:01:31.141313       1 shared_informer.go:311] Waiting for caches to sync for client-ca::kube-system::extension-apiserver-authentication::requestheader-client-ca-file
I1030 05:01:31.141282       1 shared_informer.go:311] Waiting for caches to sync for RequestHeaderAuthRequestController
I1030 05:01:31.141551       1 reflector.go:287] Starting reflector *v1.ConfigMap (12h0m0s) from pkg/authentication/request/headerrequest/requestheader_controller.go:172
I1030 05:01:31.141566       1 reflector.go:323] Listing and watching *v1.ConfigMap from pkg/authentication/request/headerrequest/requestheader_controller.go:172
I1030 05:01:31.141686       1 reflector.go:287] Starting reflector *v1.ConfigMap (12h0m0s) from pkg/server/dynamiccertificates/configmap_cafile_content.go:206
I1030 05:01:31.141701       1 reflector.go:323] Listing and watching *v1.ConfigMap from pkg/server/dynamiccertificates/configmap_cafile_content.go:206
I1030 05:01:31.141697       1 reflector.go:287] Starting reflector *v1.ConfigMap (12h0m0s) from pkg/server/dynamiccertificates/configmap_cafile_content.go:206
I1030 05:01:31.141718       1 reflector.go:323] Listing and watching *v1.ConfigMap from pkg/server/dynamiccertificates/configmap_cafile_content.go:206
I1030 05:01:31.142029       1 tlsconfig.go:200] "Loaded serving cert" certName="Generated self signed cert" certDetail="\"localhost@1698642090\" [serving] validServingFor=[127.0.0.1,127.0.0.1,localhost] issuer=\"localhost-ca@1698642090\" (2023-10-30 04:01:30 +0000 UTC to 2024-10-29 04:01:30 +0000 UTC (now=2023-10-30 05:01:31.141974917 +0000 UTC))"
I1030 05:01:31.142961       1 named_certificates.go:53] "Loaded SNI cert" index=0 certName="self-signed loopback" certDetail="\"apiserver-loopback-client@1698642091\" [serving] validServingFor=[apiserver-loopback-client] issuer=\"apiserver-loopback-client-ca@1698642091\" (2023-10-30 04:01:30 +0000 UTC to 2024-10-29 04:01:30 +0000 UTC (now=2023-10-30 05:01:31.14291467 +0000 UTC))"
I1030 05:01:31.143003       1 secure_serving.go:210] Serving securely on 127.0.0.1:10259
I1030 05:01:31.143132       1 reflector.go:287] Starting reflector *v1.CSIDriver (0s) from vendor/k8s.io/client-go/informers/factory.go:150
I1030 05:01:31.143139       1 reflector.go:287] Starting reflector *v1.PersistentVolumeClaim (0s) from vendor/k8s.io/client-go/informers/factory.go:150
I1030 05:01:31.143146       1 reflector.go:323] Listing and watching *v1.CSIDriver from vendor/k8s.io/client-go/informers/factory.go:150
I1030 05:01:31.143149       1 reflector.go:323] Listing and watching *v1.PersistentVolumeClaim from vendor/k8s.io/client-go/informers/factory.go:150
I1030 05:01:31.143188       1 tlsconfig.go:240] "Starting DynamicServingCertificateController"
I1030 05:01:31.143246       1 reflector.go:287] Starting reflector *v1.Service (0s) from vendor/k8s.io/client-go/informers/factory.go:150
I1030 05:01:31.143268       1 reflector.go:323] Listing and watching *v1.Service from vendor/k8s.io/client-go/informers/factory.go:150
I1030 05:01:31.143302       1 reflector.go:287] Starting reflector *v1.PodDisruptionBudget (0s) from vendor/k8s.io/client-go/informers/factory.go:150
I1030 05:01:31.143322       1 reflector.go:323] Listing and watching *v1.PodDisruptionBudget from vendor/k8s.io/client-go/informers/factory.go:150
I1030 05:01:31.143336       1 reflector.go:287] Starting reflector *v1.ReplicationController (0s) from vendor/k8s.io/client-go/informers/factory.go:150
I1030 05:01:31.143369       1 reflector.go:323] Listing and watching *v1.ReplicationController from vendor/k8s.io/client-go/informers/factory.go:150
I1030 05:01:31.143384       1 reflector.go:287] Starting reflector *v1.CSINode (0s) from vendor/k8s.io/client-go/informers/factory.go:150
I1030 05:01:31.143394       1 reflector.go:323] Listing and watching *v1.CSINode from vendor/k8s.io/client-go/informers/factory.go:150
I1030 05:01:31.143416       1 reflector.go:287] Starting reflector *v1.Namespace (0s) from vendor/k8s.io/client-go/informers/factory.go:150
I1030 05:01:31.143424       1 reflector.go:287] Starting reflector *v1.PersistentVolume (0s) from vendor/k8s.io/client-go/informers/factory.go:150
I1030 05:01:31.143454       1 reflector.go:323] Listing and watching *v1.PersistentVolume from vendor/k8s.io/client-go/informers/factory.go:150
I1030 05:01:31.143480       1 reflector.go:287] Starting reflector *v1.ReplicaSet (0s) from vendor/k8s.io/client-go/informers/factory.go:150
I1030 05:01:31.143436       1 reflector.go:323] Listing and watching *v1.Namespace from vendor/k8s.io/client-go/informers/factory.go:150
I1030 05:01:31.143490       1 reflector.go:323] Listing and watching *v1.ReplicaSet from vendor/k8s.io/client-go/informers/factory.go:150
I1030 05:01:31.143349       1 reflector.go:287] Starting reflector *v1.Node (0s) from vendor/k8s.io/client-go/informers/factory.go:150
I1030 05:01:31.143446       1 reflector.go:287] Starting reflector *v1.Pod (0s) from vendor/k8s.io/client-go/informers/factory.go:150
I1030 05:01:31.144183       1 reflector.go:287] Starting reflector *v1.CSIStorageCapacity (0s) from vendor/k8s.io/client-go/informers/factory.go:150
I1030 05:01:31.143562       1 reflector.go:287] Starting reflector *v1.StorageClass (0s) from vendor/k8s.io/client-go/informers/factory.go:150
I1030 05:01:31.144329       1 reflector.go:323] Listing and watching *v1.StorageClass from vendor/k8s.io/client-go/informers/factory.go:150
I1030 05:01:31.144413       1 reflector.go:287] Starting reflector *v1.StatefulSet (0s) from vendor/k8s.io/client-go/informers/factory.go:150
I1030 05:01:31.144429       1 reflector.go:323] Listing and watching *v1.StatefulSet from vendor/k8s.io/client-go/informers/factory.go:150
I1030 05:01:31.144256       1 reflector.go:323] Listing and watching *v1.CSIStorageCapacity from vendor/k8s.io/client-go/informers/factory.go:150
I1030 05:01:31.144729       1 reflector.go:323] Listing and watching *v1.Node from vendor/k8s.io/client-go/informers/factory.go:150
I1030 05:01:31.144573       1 reflector.go:323] Listing and watching *v1.Pod from vendor/k8s.io/client-go/informers/factory.go:150
I1030 05:01:31.149777       1 node_tree.go:65] "Added node in listed group to NodeTree" node="node2" zone=""
I1030 05:01:31.150094       1 eventhandlers.go:71] "Add event for node" node="node2"
I1030 05:01:31.150357       1 eventhandlers.go:186] "Add event for scheduled pod" pod="default/job-train-imgclassfication-cuda-epoch-20"
I1030 05:01:31.150466       1 eventhandlers.go:186] "Add event for scheduled pod" pod="kube-system/coredns-5d78c9869d-4sl97"
I1030 05:01:31.150586       1 eventhandlers.go:186] "Add event for scheduled pod" pod="kube-system/coredns-5d78c9869d-vwgfg"
I1030 05:01:31.150629       1 eventhandlers.go:186] "Add event for scheduled pod" pod="kube-system/etcd-node2"
I1030 05:01:31.150672       1 eventhandlers.go:186] "Add event for scheduled pod" pod="kube-system/gpushare-device-plugin-ds-hh2jx"
I1030 05:01:31.150710       1 eventhandlers.go:186] "Add event for scheduled pod" pod="kube-system/gpushare-schd-extender-c57cff5b6-z78jd"
I1030 05:01:31.150758       1 eventhandlers.go:186] "Add event for scheduled pod" pod="kube-system/kube-apiserver-node2"
I1030 05:01:31.150796       1 eventhandlers.go:186] "Add event for scheduled pod" pod="kube-system/kube-controller-manager-node2"
I1030 05:01:31.150843       1 eventhandlers.go:186] "Add event for scheduled pod" pod="kube-system/kube-proxy-z9wdr"
I1030 05:01:31.150875       1 eventhandlers.go:186] "Add event for scheduled pod" pod="kube-system/kube-scheduler-node2"
I1030 05:01:31.150918       1 eventhandlers.go:186] "Add event for scheduled pod" pod="kube-system/weave-net-jrf8d"
I1030 05:01:31.242231       1 shared_informer.go:341] caches populated
I1030 05:01:31.242256       1 shared_informer.go:318] Caches are synced for client-ca::kube-system::extension-apiserver-authentication::requestheader-client-ca-file
I1030 05:01:31.242338       1 shared_informer.go:341] caches populated
I1030 05:01:31.242360       1 shared_informer.go:318] Caches are synced for client-ca::kube-system::extension-apiserver-authentication::client-ca-file
I1030 05:01:31.242490       1 shared_informer.go:341] caches populated
I1030 05:01:31.242512       1 shared_informer.go:318] Caches are synced for RequestHeaderAuthRequestController
I1030 05:01:31.242614       1 tlsconfig.go:178] "Loaded client CA" index=0 certName="client-ca::kube-system::extension-apiserver-authentication::client-ca-file,client-ca::kube-system::extension-apiserver-authentication::requestheader-client-ca-file" certDetail="\"front-proxy-ca\" [] validServingFor=[front-proxy-ca] issuer=\"<self>\" (2023-10-15 21:47:43 +0000 UTC to 2033-10-12 21:47:43 +0000 UTC (now=2023-10-30 05:01:31.242564585 +0000 UTC))"
I1030 05:01:31.243695       1 shared_informer.go:341] caches populated
I1030 05:01:31.243713       1 shared_informer.go:341] caches populated
I1030 05:01:31.243722       1 shared_informer.go:341] caches populated
I1030 05:01:31.243728       1 shared_informer.go:341] caches populated
I1030 05:01:31.243736       1 shared_informer.go:341] caches populated
I1030 05:01:31.243745       1 shared_informer.go:341] caches populated
I1030 05:01:31.243747       1 tlsconfig.go:200] "Loaded serving cert" certName="Generated self signed cert" certDetail="\"localhost@1698642090\" [serving] validServingFor=[127.0.0.1,127.0.0.1,localhost] issuer=\"localhost-ca@1698642090\" (2023-10-30 04:01:30 +0000 UTC to 2024-10-29 04:01:30 +0000 UTC (now=2023-10-30 05:01:31.243692343 +0000 UTC))"
I1030 05:01:31.243752       1 shared_informer.go:341] caches populated
I1030 05:01:31.243867       1 shared_informer.go:341] caches populated
I1030 05:01:31.243877       1 shared_informer.go:341] caches populated
I1030 05:01:31.243892       1 shared_informer.go:341] caches populated
I1030 05:01:31.243907       1 shared_informer.go:341] caches populated
I1030 05:01:31.243924       1 shared_informer.go:341] caches populated
I1030 05:01:31.243942       1 shared_informer.go:341] caches populated
I1030 05:01:31.243959       1 shared_informer.go:341] caches populated
I1030 05:01:31.244020       1 leaderelection.go:245] attempting to acquire leader lease kube-system/kube-scheduler...
I1030 05:01:31.244734       1 named_certificates.go:53] "Loaded SNI cert" index=0 certName="self-signed loopback" certDetail="\"apiserver-loopback-client@1698642091\" [serving] validServingFor=[apiserver-loopback-client] issuer=\"apiserver-loopback-client-ca@1698642091\" (2023-10-30 04:01:30 +0000 UTC to 2024-10-29 04:01:30 +0000 UTC (now=2023-10-30 05:01:31.2446985 +0000 UTC))"
I1030 05:01:31.244867       1 tlsconfig.go:178] "Loaded client CA" index=0 certName="client-ca::kube-system::extension-apiserver-authentication::client-ca-file,client-ca::kube-system::extension-apiserver-authentication::requestheader-client-ca-file" certDetail="\"kubernetes\" [] validServingFor=[kubernetes] issuer=\"<self>\" (2023-10-15 21:47:42 +0000 UTC to 2033-10-12 21:47:42 +0000 UTC (now=2023-10-30 05:01:31.24483277 +0000 UTC))"
I1030 05:01:31.244914       1 tlsconfig.go:178] "Loaded client CA" index=1 certName="client-ca::kube-system::extension-apiserver-authentication::client-ca-file,client-ca::kube-system::extension-apiserver-authentication::requestheader-client-ca-file" certDetail="\"front-proxy-ca\" [] validServingFor=[front-proxy-ca] issuer=\"<self>\" (2023-10-15 21:47:43 +0000 UTC to 2033-10-12 21:47:43 +0000 UTC (now=2023-10-30 05:01:31.244887576 +0000 UTC))"
I1030 05:01:31.245839       1 tlsconfig.go:200] "Loaded serving cert" certName="Generated self signed cert" certDetail="\"localhost@1698642090\" [serving] validServingFor=[127.0.0.1,127.0.0.1,localhost] issuer=\"localhost-ca@1698642090\" (2023-10-30 04:01:30 +0000 UTC to 2024-10-29 04:01:30 +0000 UTC (now=2023-10-30 05:01:31.245792677 +0000 UTC))"
I1030 05:01:31.246757       1 named_certificates.go:53] "Loaded SNI cert" index=0 certName="self-signed loopback" certDetail="\"apiserver-loopback-client@1698642091\" [serving] validServingFor=[apiserver-loopback-client] issuer=\"apiserver-loopback-client-ca@1698642091\" (2023-10-30 04:01:30 +0000 UTC to 2024-10-29 04:01:30 +0000 UTC (now=2023-10-30 05:01:31.246726812 +0000 UTC))"
I1030 05:01:31.255925       1 leaderelection.go:255] successfully acquired lease kube-system/kube-scheduler
I1030 05:01:31.256105       1 schedule_one.go:63] "starting scheduling for next pod..."
I1030 05:01:31.456371       1 scheduling_queue.go:661] "[Bing]Pop called on the scheduling queue. current queue includes pods: " []="queue len:" %!s(int=0)="(MISSING)"
I1030 05:01:32.017700       1 eventhandlers.go:206] "Update event for scheduled pod" pod="default/job-train-imgclassfication-cuda-epoch-20"
I1030 05:01:46.531507       1 httplog.go:132] "HTTP" verb="GET" URI="/healthz" latency="143.959µs" userAgent="kube-probe/1.27" audit-ID="" srcIP="127.0.0.1:33048" resp=200
I1030 05:01:46.551284       1 eventhandlers.go:206] "Update event for scheduled pod" pod="kube-system/kube-scheduler-node2"
I1030 05:01:46.571011       1 eventhandlers.go:206] "Update event for scheduled pod" pod="kube-system/kube-scheduler-node2"
I1030 05:01:56.531222       1 httplog.go:132] "HTTP" verb="GET" URI="/healthz" latency="106.026µs" userAgent="kube-probe/1.27" audit-ID="" srcIP="127.0.0.1:37674" resp=200
I1030 05:02:02.605371       1 eventhandlers.go:231] "Delete event for scheduled pod" pod="default/job-train-imgclassfication-cuda-epoch-20"
I1030 05:02:06.532048       1 httplog.go:132] "HTTP" verb="GET" URI="/healthz" latency="131.462µs" userAgent="kube-probe/1.27" audit-ID="" srcIP="127.0.0.1:41348" resp=200
I1030 05:02:11.519308       1 eventhandlers.go:206] "Update event for scheduled pod" pod="kube-system/etcd-node2"
I1030 05:02:11.540905       1 eventhandlers.go:206] "Update event for scheduled pod" pod="kube-system/kube-apiserver-node2"
I1030 05:02:11.573526       1 eventhandlers.go:206] "Update event for scheduled pod" pod="kube-system/kube-controller-manager-node2"
I1030 05:02:11.603794       1 eventhandlers.go:206] "Update event for scheduled pod" pod="kube-system/etcd-node2"
I1030 05:02:11.624362       1 eventhandlers.go:206] "Update event for scheduled pod" pod="kube-system/kube-apiserver-node2"
I1030 05:02:11.644227       1 eventhandlers.go:206] "Update event for scheduled pod" pod="kube-system/kube-controller-manager-node2"
I1030 05:02:11.662672       1 eventhandlers.go:206] "Update event for scheduled pod" pod="kube-system/kube-scheduler-node2"
I1030 05:02:12.323728       1 eventhandlers.go:206] "Update event for scheduled pod" pod="kube-system/coredns-5d78c9869d-vwgfg"
I1030 05:02:12.346184       1 eventhandlers.go:206] "Update event for scheduled pod" pod="kube-system/kube-apiserver-node2"
I1030 05:02:12.369303       1 eventhandlers.go:206] "Update event for scheduled pod" pod="kube-system/coredns-5d78c9869d-vwgfg"
I1030 05:02:12.570034       1 eventhandlers.go:206] "Update event for scheduled pod" pod="kube-system/kube-apiserver-node2"
I1030 05:02:12.644681       1 eventhandlers.go:206] "Update event for scheduled pod" pod="kube-system/etcd-node2"
I1030 05:02:13.204294       1 httplog.go:132] "HTTP" verb="GET" URI="/healthz" latency="134.295µs" userAgent="kube-probe/1.27" audit-ID="" srcIP="127.0.0.1:41354" resp=200
I1030 05:02:13.227743       1 eventhandlers.go:206] "Update event for scheduled pod" pod="kube-system/kube-scheduler-node2"
I1030 05:02:13.561387       1 eventhandlers.go:206] "Update event for scheduled pod" pod="kube-system/kube-scheduler-node2"
I1030 05:02:13.581273       1 eventhandlers.go:206] "Update event for scheduled pod" pod="kube-system/etcd-node2"
I1030 05:02:16.346310       1 eventhandlers.go:206] "Update event for scheduled pod" pod="kube-system/kube-controller-manager-node2"
I1030 05:02:16.566956       1 eventhandlers.go:206] "Update event for scheduled pod" pod="kube-system/kube-controller-manager-node2"
I1030 05:02:17.360237       1 eventhandlers.go:206] "Update event for scheduled pod" pod="kube-system/coredns-5d78c9869d-4sl97"
I1030 05:02:17.386498       1 eventhandlers.go:206] "Update event for scheduled pod" pod="kube-system/coredns-5d78c9869d-4sl97"
I1030 05:02:18.672863       1 eventhandlers.go:206] "Update event for scheduled pod" pod="kube-system/weave-net-jrf8d"
I1030 05:02:18.696746       1 eventhandlers.go:206] "Update event for scheduled pod" pod="kube-system/weave-net-jrf8d"
I1030 05:02:21.632315       1 httplog.go:132] "HTTP" verb="GET" URI="/healthz" latency="110.42µs" userAgent="kube-probe/1.27" audit-ID="" srcIP="127.0.0.1:35370" resp=200
I1030 05:02:27.781800       1 eventhandlers.go:118] "Add event for unscheduled pod" pod="default/dummy-highest"
I1030 05:02:27.781930       1 scheduling_queue.go:1203] "[Bing]About to try and schedule pod" pod="default/dummy-highest"
I1030 05:02:27.781945       1 schedule_one.go:81] "Attempting to schedule pod" pod="default/dummy-highest"
I1030 05:02:27.828280       1 eventhandlers.go:118] "Add event for unscheduled pod" pod="default/job-train-imgclassfication-cuda-epoch-20"
I1030 05:02:27.909150       1 eventhandlers.go:118] "Add event for unscheduled pod" pod="default/job-train-imgclassfication-cuda-epoch-10"
I1030 05:02:27.982618       1 schedule_one.go:83] "sleep when attempting to schedule pod to increase job intervals..."
I1030 05:02:27.987135       1 eventhandlers.go:118] "Add event for unscheduled pod" pod="default/job-train-imgclassfication-cuda-epoch-5"
I1030 05:02:27.989347       1 schedule_one.go:63] "starting scheduling for next pod..."
I1030 05:02:28.111549       1 eventhandlers.go:161] "Delete event for unscheduled pod" pod="default/dummy-highest"
I1030 05:02:28.111601       1 eventhandlers.go:186] "Add event for scheduled pod" pod="default/dummy-highest"
I1030 05:02:28.112252       1 schedule_one.go:260] "Successfully bound pod to node" pod="default/dummy-highest" node="node2" evaluatedNodes=1 feasibleNodes=1
I1030 05:02:28.155301       1 eventhandlers.go:206] "Update event for scheduled pod" pod="default/dummy-highest"
I1030 05:02:28.190506       1 scheduling_queue.go:661] "[Bing]Pop called on the scheduling queue. current queue includes pods: " [%!s(*framework.QueuedPodInfo=&{0xc00035ca10 {13927359964620320615 57576598206 0x38092e0} 0 {13927359964620320615 57576598206 0x38092e0} map[] false}) %!s(*framework.QueuedPodInfo=&{0xc000218f50 {13927359964698302623 57654580219 0x38092e0} 0 {13927359964698302623 57654580219 0x38092e0} map[] false}) %!s(*framework.QueuedPodInfo=&{0xc00035c930 {13927359964539462823 57495740410 0x38092e0} 0 {13927359964539462823 57495740410 0x38092e0} map[] false})]="queue len:" %!s(int=3)="(MISSING)"
I1030 05:02:28.190577       1 scheduling_queue.go:1203] "[Bing]About to try and schedule pod" pod="default/job-train-imgclassfication-cuda-epoch-5"
I1030 05:02:28.190606       1 schedule_one.go:81] "Attempting to schedule pod" pod="default/job-train-imgclassfication-cuda-epoch-5"
I1030 05:02:28.219892       1 eventhandlers.go:206] "Update event for scheduled pod" pod="default/dummy-highest"
I1030 05:02:28.391672       1 schedule_one.go:83] "sleep when attempting to schedule pod to increase job intervals..."
I1030 05:02:28.394372       1 schedule_one.go:63] "starting scheduling for next pod..."
I1030 05:02:28.516921       1 eventhandlers.go:161] "Delete event for unscheduled pod" pod="default/job-train-imgclassfication-cuda-epoch-5"
I1030 05:02:28.517015       1 eventhandlers.go:186] "Add event for scheduled pod" pod="default/job-train-imgclassfication-cuda-epoch-5"
I1030 05:02:28.518044       1 schedule_one.go:260] "Successfully bound pod to node" pod="default/job-train-imgclassfication-cuda-epoch-5" node="node2" evaluatedNodes=1 feasibleNodes=1
I1030 05:02:28.563839       1 eventhandlers.go:206] "Update event for scheduled pod" pod="default/job-train-imgclassfication-cuda-epoch-5"
I1030 05:02:28.595472       1 scheduling_queue.go:661] "[Bing]Pop called on the scheduling queue. current queue includes pods: " [%!s(*framework.QueuedPodInfo=&{0xc00035c930 {13927359964539462823 57495740410 0x38092e0} 0 {13927359964539462823 57495740410 0x38092e0} map[] false}) %!s(*framework.QueuedPodInfo=&{0xc00035ca10 {13927359964620320615 57576598206 0x38092e0} 0 {13927359964620320615 57576598206 0x38092e0} map[] false})]="queue len:" %!s(int=2)="(MISSING)"
I1030 05:02:28.595520       1 scheduling_queue.go:1203] "[Bing]About to try and schedule pod" pod="default/job-train-imgclassfication-cuda-epoch-10"
I1030 05:02:28.595537       1 schedule_one.go:81] "Attempting to schedule pod" pod="default/job-train-imgclassfication-cuda-epoch-10"
I1030 05:02:28.608913       1 eventhandlers.go:206] "Update event for scheduled pod" pod="default/job-train-imgclassfication-cuda-epoch-5"
I1030 05:02:28.796592       1 schedule_one.go:83] "sleep when attempting to schedule pod to increase job intervals..."
I1030 05:02:28.799457       1 schedule_one.go:63] "starting scheduling for next pod..."
I1030 05:02:28.917925       1 eventhandlers.go:161] "Delete event for unscheduled pod" pod="default/job-train-imgclassfication-cuda-epoch-10"
I1030 05:02:28.917967       1 eventhandlers.go:186] "Add event for scheduled pod" pod="default/job-train-imgclassfication-cuda-epoch-10"
I1030 05:02:28.918787       1 schedule_one.go:260] "Successfully bound pod to node" pod="default/job-train-imgclassfication-cuda-epoch-10" node="node2" evaluatedNodes=1 feasibleNodes=1
I1030 05:02:28.955492       1 eventhandlers.go:206] "Update event for scheduled pod" pod="default/job-train-imgclassfication-cuda-epoch-10"
I1030 05:02:28.999843       1 scheduling_queue.go:661] "[Bing]Pop called on the scheduling queue. current queue includes pods: " [%!s(*framework.QueuedPodInfo=&{0xc00035c930 {13927359964539462823 57495740410 0x38092e0} 0 {13927359964539462823 57495740410 0x38092e0} map[] false})]="queue len:" %!s(int=1)="(MISSING)"
I1030 05:02:28.999889       1 scheduling_queue.go:1203] "[Bing]About to try and schedule pod" pod="default/job-train-imgclassfication-cuda-epoch-20"
I1030 05:02:28.999905       1 schedule_one.go:81] "Attempting to schedule pod" pod="default/job-train-imgclassfication-cuda-epoch-20"
I1030 05:02:29.007489       1 eventhandlers.go:206] "Update event for scheduled pod" pod="default/job-train-imgclassfication-cuda-epoch-10"
I1030 05:02:29.200376       1 schedule_one.go:83] "sleep when attempting to schedule pod to increase job intervals..."
I1030 05:02:29.203710       1 schedule_one.go:63] "starting scheduling for next pod..."
I1030 05:02:29.327273       1 eventhandlers.go:161] "Delete event for unscheduled pod" pod="default/job-train-imgclassfication-cuda-epoch-20"
I1030 05:02:29.327299       1 eventhandlers.go:186] "Add event for scheduled pod" pod="default/job-train-imgclassfication-cuda-epoch-20"
I1030 05:02:29.328464       1 schedule_one.go:260] "Successfully bound pod to node" pod="default/job-train-imgclassfication-cuda-epoch-20" node="node2" evaluatedNodes=1 feasibleNodes=1
I1030 05:02:29.366853       1 eventhandlers.go:206] "Update event for scheduled pod" pod="default/job-train-imgclassfication-cuda-epoch-20"
I1030 05:02:29.404710       1 scheduling_queue.go:661] "[Bing]Pop called on the scheduling queue. current queue includes pods: " []="queue len:" %!s(int=0)="(MISSING)"
I1030 05:02:29.414733       1 eventhandlers.go:206] "Update event for scheduled pod" pod="default/job-train-imgclassfication-cuda-epoch-20"
I1030 05:02:29.598447       1 eventhandlers.go:206] "Update event for scheduled pod" pod="default/job-train-imgclassfication-cuda-epoch-5"
I1030 05:02:29.615434       1 eventhandlers.go:206] "Update event for scheduled pod" pod="default/dummy-highest"
I1030 05:02:30.600938       1 eventhandlers.go:206] "Update event for scheduled pod" pod="default/job-train-imgclassfication-cuda-epoch-10"
I1030 05:02:30.614186       1 eventhandlers.go:206] "Update event for scheduled pod" pod="default/job-train-imgclassfication-cuda-epoch-20"
I1030 05:02:31.631749       1 httplog.go:132] "HTTP" verb="GET" URI="/healthz" latency="113.172µs" userAgent="kube-probe/1.27" audit-ID="" srcIP="127.0.0.1:35032" resp=200
I1030 05:02:41.631900       1 httplog.go:132] "HTTP" verb="GET" URI="/healthz" latency="138.386µs" userAgent="kube-probe/1.27" audit-ID="" srcIP="127.0.0.1:40790" resp=200
I1030 05:02:51.632634       1 httplog.go:132] "HTTP" verb="GET" URI="/healthz" latency="96.955µs" userAgent="kube-probe/1.27" audit-ID="" srcIP="127.0.0.1:54890" resp=200
I1030 05:03:01.632232       1 httplog.go:132] "HTTP" verb="GET" URI="/healthz" latency="77.455µs" userAgent="kube-probe/1.27" audit-ID="" srcIP="127.0.0.1:46808" resp=200
I1030 05:03:11.631026       1 httplog.go:132] "HTTP" verb="GET" URI="/healthz" latency="116.772µs" userAgent="kube-probe/1.27" audit-ID="" srcIP="127.0.0.1:33072" resp=200
I1030 05:03:15.732568       1 eventhandlers.go:206] "Update event for scheduled pod" pod="default/dummy-highest"
I1030 05:03:16.976454       1 eventhandlers.go:231] "Delete event for scheduled pod" pod="default/dummy-highest"
I1030 05:03:21.632540       1 httplog.go:132] "HTTP" verb="GET" URI="/healthz" latency="116.17µs" userAgent="kube-probe/1.27" audit-ID="" srcIP="127.0.0.1:41850" resp=200
I1030 05:03:31.632426       1 httplog.go:132] "HTTP" verb="GET" URI="/healthz" latency="117.966µs" userAgent="kube-probe/1.27" audit-ID="" srcIP="127.0.0.1:36902" resp=200
I1030 05:03:32.202446       1 eventhandlers.go:206] "Update event for scheduled pod" pod="default/job-train-imgclassfication-cuda-epoch-20"
I1030 05:03:32.216204       1 eventhandlers.go:206] "Update event for scheduled pod" pod="default/job-train-imgclassfication-cuda-epoch-10"
I1030 05:03:32.229854       1 eventhandlers.go:206] "Update event for scheduled pod" pod="default/job-train-imgclassfication-cuda-epoch-5"
I1030 05:03:41.629755       1 httplog.go:132] "HTTP" verb="GET" URI="/healthz" latency="81.816µs" userAgent="kube-probe/1.27" audit-ID="" srcIP="127.0.0.1:34842" resp=200
I1030 05:03:51.632818       1 httplog.go:132] "HTTP" verb="GET" URI="/healthz" latency="123.948µs" userAgent="kube-probe/1.27" audit-ID="" srcIP="127.0.0.1:46152" resp=200
I1030 05:04:00.878455       1 eventhandlers.go:231] "Delete event for scheduled pod" pod="default/job-train-imgclassfication-cuda-epoch-5"
I1030 05:04:01.632232       1 httplog.go:132] "HTTP" verb="GET" URI="/healthz" latency="105.925µs" userAgent="kube-probe/1.27" audit-ID="" srcIP="127.0.0.1:41410" resp=200
I1030 05:04:02.869305       1 eventhandlers.go:231] "Delete event for scheduled pod" pod="default/job-train-imgclassfication-cuda-epoch-10"
I1030 05:04:02.887393       1 eventhandlers.go:231] "Delete event for scheduled pod" pod="default/job-train-imgclassfication-cuda-epoch-20"
I1030 05:04:11.632983       1 httplog.go:132] "HTTP" verb="GET" URI="/healthz" latency="139.174µs" userAgent="kube-probe/1.27" audit-ID="" srcIP="127.0.0.1:33702" resp=200
I1030 05:04:21.632942       1 httplog.go:132] "HTTP" verb="GET" URI="/healthz" latency="155.872µs" userAgent="kube-probe/1.27" audit-ID="" srcIP="127.0.0.1:49076" resp=200
I1030 05:04:31.632851       1 httplog.go:132] "HTTP" verb="GET" URI="/healthz" latency="133.658µs" userAgent="kube-probe/1.27" audit-ID="" srcIP="127.0.0.1:45672" resp=200
I1030 05:04:41.632011       1 httplog.go:132] "HTTP" verb="GET" URI="/healthz" latency="121.743µs" userAgent="kube-probe/1.27" audit-ID="" srcIP="127.0.0.1:39222" resp=200
I1030 05:04:51.632382       1 httplog.go:132] "HTTP" verb="GET" URI="/healthz" latency="176.297µs" userAgent="kube-probe/1.27" audit-ID="" srcIP="127.0.0.1:52680" resp=200
I1030 05:05:01.633093       1 httplog.go:132] "HTTP" verb="GET" URI="/healthz" latency="129.683µs" userAgent="kube-probe/1.27" audit-ID="" srcIP="127.0.0.1:46476" resp=200
I1030 05:05:11.632660       1 httplog.go:132] "HTTP" verb="GET" URI="/healthz" latency="140.702µs" userAgent="kube-probe/1.27" audit-ID="" srcIP="127.0.0.1:44608" resp=200
I1030 05:05:21.633113       1 httplog.go:132] "HTTP" verb="GET" URI="/healthz" latency="155.961µs" userAgent="kube-probe/1.27" audit-ID="" srcIP="127.0.0.1:53306" resp=200
I1030 05:05:31.633167       1 httplog.go:132] "HTTP" verb="GET" URI="/healthz" latency="117.411µs" userAgent="kube-probe/1.27" audit-ID="" srcIP="127.0.0.1:48752" resp=200
I1030 05:05:41.631669       1 httplog.go:132] "HTTP" verb="GET" URI="/healthz" latency="125.468µs" userAgent="kube-probe/1.27" audit-ID="" srcIP="127.0.0.1:39650" resp=200
I1030 05:05:51.632010       1 httplog.go:132] "HTTP" verb="GET" URI="/healthz" latency="122.706µs" userAgent="kube-probe/1.27" audit-ID="" srcIP="127.0.0.1:49106" resp=200
I1030 05:06:01.633520       1 httplog.go:132] "HTTP" verb="GET" URI="/healthz" latency="127.235µs" userAgent="kube-probe/1.27" audit-ID="" srcIP="127.0.0.1:53292" resp=200
I1030 05:06:11.118520       1 eventhandlers.go:118] "Add event for unscheduled pod" pod="default/job-train-imgclassfication1-cuda-epoch10"
I1030 05:06:11.118635       1 scheduling_queue.go:1203] "[Bing]About to try and schedule pod" pod="default/job-train-imgclassfication1-cuda-epoch10"
I1030 05:06:11.118654       1 schedule_one.go:81] "Attempting to schedule pod" pod="default/job-train-imgclassfication1-cuda-epoch10"
I1030 05:06:11.186069       1 eventhandlers.go:118] "Add event for unscheduled pod" pod="default/job-train-imgclassfication2-cuda-epoch20"
I1030 05:06:11.243732       1 eventhandlers.go:118] "Add event for unscheduled pod" pod="default/job-train-imgclassfication3-cuda-epoch30"
I1030 05:06:11.318912       1 schedule_one.go:83] "sleep when attempting to schedule pod to increase job intervals..."
I1030 05:06:11.320053       1 eventhandlers.go:118] "Add event for unscheduled pod" pod="default/job-train-imgclassfication4-cuda-epoch40"
I1030 05:06:11.321654       1 schedule_one.go:63] "starting scheduling for next pod..."
I1030 05:06:11.386235       1 eventhandlers.go:118] "Add event for unscheduled pod" pod="default/job-train-imgclassfication5-cuda-epoch50"
I1030 05:06:11.441150       1 eventhandlers.go:186] "Add event for scheduled pod" pod="default/job-train-imgclassfication1-cuda-epoch10"
I1030 05:06:11.441327       1 eventhandlers.go:161] "Delete event for unscheduled pod" pod="default/job-train-imgclassfication1-cuda-epoch10"
I1030 05:06:11.442972       1 schedule_one.go:260] "Successfully bound pod to node" pod="default/job-train-imgclassfication1-cuda-epoch10" node="node2" evaluatedNodes=1 feasibleNodes=1
I1030 05:06:11.459016       1 eventhandlers.go:118] "Add event for unscheduled pod" pod="default/job-train-imgclassfication6-cuda-epoch60"
I1030 05:06:11.488857       1 eventhandlers.go:206] "Update event for scheduled pod" pod="default/job-train-imgclassfication1-cuda-epoch10"
I1030 05:06:11.512534       1 eventhandlers.go:118] "Add event for unscheduled pod" pod="default/job-train-imgclassfication7-cuda-epoch70"
I1030 05:06:11.522508       1 scheduling_queue.go:661] "[Bing]Pop called on the scheduling queue. current queue includes pods: " [%!s(*framework.QueuedPodInfo=&{0xc000221490 {13927360204415407862 280853516897 0x38092e0} 0 {13927360204415407862 280853516897 0x38092e0} map[] false}) %!s(*framework.QueuedPodInfo=&{0xc000221570 {13927360204473069734 280911178768 0x38092e0} 0 {13927360204473069734 280911178768 0x38092e0} map[] false}) %!s(*framework.QueuedPodInfo=&{0xc0002218f0 {13927360204549391068 280987500100 0x38092e0} 0 {13927360204549391068 280987500100 0x38092e0} map[] false}) %!s(*framework.QueuedPodInfo=&{0xc0002f7490 {13927360204615576585 281053685603 0x38092e0} 0 {13927360204615576585 281053685603 0x38092e0} map[] false}) %!s(*framework.QueuedPodInfo=&{0xc0002f77a0 {13927360204688357518 281126466544 0x38092e0} 0 {13927360204688357518 281126466544 0x38092e0} map[] false}) %!s(*framework.QueuedPodInfo=&{0xc00022f5e0 {13927360204741874373 281179983391 0x38092e0} 0 {13927360204741874373 281179983391 0x38092e0} map[] false})]="queue len:" %!s(int=6)="(MISSING)"
I1030 05:06:11.522560       1 scheduling_queue.go:1203] "[Bing]About to try and schedule pod" pod="default/job-train-imgclassfication2-cuda-epoch20"
I1030 05:06:11.522579       1 schedule_one.go:81] "Attempting to schedule pod" pod="default/job-train-imgclassfication2-cuda-epoch20"
I1030 05:06:11.543869       1 eventhandlers.go:206] "Update event for scheduled pod" pod="default/job-train-imgclassfication1-cuda-epoch10"
I1030 05:06:11.592060       1 eventhandlers.go:118] "Add event for unscheduled pod" pod="default/job-train-imgclassfication8-cuda-epoch80"
I1030 05:06:11.633771       1 httplog.go:132] "HTTP" verb="GET" URI="/healthz" latency="106.3µs" userAgent="kube-probe/1.27" audit-ID="" srcIP="127.0.0.1:50918" resp=200
I1030 05:06:11.668924       1 eventhandlers.go:118] "Add event for unscheduled pod" pod="default/job-train-imgclassfication9-cuda-epoch90"
I1030 05:06:11.723250       1 schedule_one.go:83] "sleep when attempting to schedule pod to increase job intervals..."
I1030 05:06:11.725759       1 schedule_one.go:63] "starting scheduling for next pod..."
I1030 05:06:11.747960       1 eventhandlers.go:118] "Add event for unscheduled pod" pod="default/job-train-imgclassfication10-cuda-epoch100"
I1030 05:06:11.811240       1 eventhandlers.go:118] "Add event for unscheduled pod" pod="default/job-train-imgclassfication11-cuda-epoch110"
I1030 05:06:11.849029       1 eventhandlers.go:161] "Delete event for unscheduled pod" pod="default/job-train-imgclassfication2-cuda-epoch20"
I1030 05:06:11.849046       1 eventhandlers.go:186] "Add event for scheduled pod" pod="default/job-train-imgclassfication2-cuda-epoch20"
I1030 05:06:11.849505       1 schedule_one.go:260] "Successfully bound pod to node" pod="default/job-train-imgclassfication2-cuda-epoch20" node="node2" evaluatedNodes=1 feasibleNodes=1
I1030 05:06:11.853474       1 eventhandlers.go:118] "Add event for unscheduled pod" pod="default/job-train-imgclassfication12-cuda-epoch120"
I1030 05:06:11.890438       1 eventhandlers.go:206] "Update event for scheduled pod" pod="default/job-train-imgclassfication2-cuda-epoch20"
I1030 05:06:11.900239       1 eventhandlers.go:118] "Add event for unscheduled pod" pod="default/job-train-imgclassfication13-cuda-epoch130"
I1030 05:06:11.926246       1 scheduling_queue.go:661] "[Bing]Pop called on the scheduling queue. current queue includes pods: " [%!s(*framework.QueuedPodInfo=&{0xc0002f77a0 {13927360204688357518 281126466544 0x38092e0} 0 {13927360204688357518 281126466544 0x38092e0} map[] false}) %!s(*framework.QueuedPodInfo=&{0xc00032e700 {13927360205040581987 281478691021 0x38092e0} 0 {13927360205040581987 281478691021 0x38092e0} map[] false}) %!s(*framework.QueuedPodInfo=&{0xc00032e620 {13927360204977293464 281415402494 0x38092e0} 0 {13927360204977293464 281415402494 0x38092e0} map[] false}) %!s(*framework.QueuedPodInfo=&{0xc00032eb60 {13927360205082804413 281520913432 0x38092e0} 0 {13927360205082804413 281520913432 0x38092e0} map[] false}) %!s(*framework.QueuedPodInfo=&{0xc00022fc70 {13927360204821395897 281259504916 0x38092e0} 0 {13927360204821395897 281259504916 0x38092e0} map[] false}) %!s(*framework.QueuedPodInfo=&{0xc000221570 {13927360204473069734 280911178768 0x38092e0} 0 {13927360204473069734 280911178768 0x38092e0} map[] false}) %!s(*framework.QueuedPodInfo=&{0xc0002218f0 {13927360204549391068 280987500100 0x38092e0} 0 {13927360204549391068 280987500100 0x38092e0} map[] false}) %!s(*framework.QueuedPodInfo=&{0xc0002f7490 {13927360204615576585 281053685603 0x38092e0} 0 {13927360204615576585 281053685603 0x38092e0} map[] false}) %!s(*framework.QueuedPodInfo=&{0xc00022f5e0 {13927360204741874373 281179983391 0x38092e0} 0 {13927360204741874373 281179983391 0x38092e0} map[] false}) %!s(*framework.QueuedPodInfo=&{0xc000273730 {13927360204898257973 281336366992 0x38092e0} 0 {13927360204898257973 281336366992 0x38092e0} map[] false}) %!s(*framework.QueuedPodInfo=&{0xc00032ed20 {13927360205129572425 281567681457 0x38092e0} 0 {13927360205129572425 281567681457 0x38092e0} map[] false})]="queue len:" %!s(int=11)="(MISSING)"
I1030 05:06:11.926300       1 scheduling_queue.go:1203] "[Bing]About to try and schedule pod" pod="default/job-train-imgclassfication3-cuda-epoch30"
I1030 05:06:11.926323       1 schedule_one.go:81] "Attempting to schedule pod" pod="default/job-train-imgclassfication3-cuda-epoch30"
I1030 05:06:11.943506       1 eventhandlers.go:206] "Update event for scheduled pod" pod="default/job-train-imgclassfication2-cuda-epoch20"
I1030 05:06:11.976962       1 eventhandlers.go:118] "Add event for unscheduled pod" pod="default/job-train-imgclassfication14-cuda-epoch140"
I1030 05:06:12.060273       1 eventhandlers.go:118] "Add event for unscheduled pod" pod="default/job-train-imgclassfication15-cuda-epoch150"
I1030 05:06:12.126820       1 schedule_one.go:83] "sleep when attempting to schedule pod to increase job intervals..."
I1030 05:06:12.128660       1 eventhandlers.go:118] "Add event for unscheduled pod" pod="default/job-train-imgclassfication16-cuda-epoch160"
I1030 05:06:12.129412       1 schedule_one.go:63] "starting scheduling for next pod..."
I1030 05:06:12.182020       1 eventhandlers.go:118] "Add event for unscheduled pod" pod="default/job-train-imgclassfication17-cuda-epoch170"
I1030 05:06:12.246005       1 eventhandlers.go:118] "Add event for unscheduled pod" pod="default/job-train-imgclassfication18-cuda-epoch180"
I1030 05:06:12.251617       1 eventhandlers.go:161] "Delete event for unscheduled pod" pod="default/job-train-imgclassfication3-cuda-epoch30"
I1030 05:06:12.251645       1 eventhandlers.go:186] "Add event for scheduled pod" pod="default/job-train-imgclassfication3-cuda-epoch30"
I1030 05:06:12.252199       1 schedule_one.go:260] "Successfully bound pod to node" pod="default/job-train-imgclassfication3-cuda-epoch30" node="node2" evaluatedNodes=1 feasibleNodes=1
I1030 05:06:12.286111       1 eventhandlers.go:206] "Update event for scheduled pod" pod="default/job-train-imgclassfication3-cuda-epoch30"
I1030 05:06:12.309662       1 eventhandlers.go:118] "Add event for unscheduled pod" pod="default/job-train-imgclassfication19-cuda-epoch190"
I1030 05:06:12.330090       1 scheduling_queue.go:661] "[Bing]Pop called on the scheduling queue. current queue includes pods: " [%!s(*framework.QueuedPodInfo=&{0xc00022fc70 {13927360204821395897 281259504916 0x38092e0} 0 {13927360204821395897 281259504916 0x38092e0} map[] false}) %!s(*framework.QueuedPodInfo=&{0xc000273c00 {13927360205206297686 281644406701 0x38092e0} 0 {13927360205206297686 281644406701 0x38092e0} map[] false}) %!s(*framework.QueuedPodInfo=&{0xc00022f5e0 {13927360204741874373 281179983391 0x38092e0} 0 {13927360204741874373 281179983391 0x38092e0} map[] false}) %!s(*framework.QueuedPodInfo=&{0xc00032eb60 {13927360205082804413 281520913432 0x38092e0} 0 {13927360205082804413 281520913432 0x38092e0} map[] false}) %!s(*framework.QueuedPodInfo=&{0xc00024e3f0 {13927360205612739548 281977106744 0x38092e0} 0 {13927360205612739548 281977106744 0x38092e0} map[] false}) %!s(*framework.QueuedPodInfo=&{0xc000273ce0 {13927360205363368956 281727736145 0x38092e0} 0 {13927360205363368956 281727736145 0x38092e0} map[] false}) %!s(*framework.QueuedPodInfo=&{0xc000273dc0 {13927360205431737232 281796104442 0x38092e0} 0 {13927360205431737232 281796104442 0x38092e0} map[] false}) %!s(*framework.QueuedPodInfo=&{0xc00024e0e0 {13927360205549087692 281913454909 0x38092e0} 0 {13927360205549087692 281913454909 0x38092e0} map[] false}) %!s(*framework.QueuedPodInfo=&{0xc0002218f0 {13927360204549391068 280987500100 0x38092e0} 0 {13927360204549391068 280987500100 0x38092e0} map[] false}) %!s(*framework.QueuedPodInfo=&{0xc0002f7490 {13927360204615576585 281053685603 0x38092e0} 0 {13927360204615576585 281053685603 0x38092e0} map[] false}) %!s(*framework.QueuedPodInfo=&{0xc000273730 {13927360204898257973 281336366992 0x38092e0} 0 {13927360204898257973 281336366992 0x38092e0} map[] false}) %!s(*framework.QueuedPodInfo=&{0xc00032e620 {13927360204977293464 281415402494 0x38092e0} 0 {13927360204977293464 281415402494 0x38092e0} map[] false}) %!s(*framework.QueuedPodInfo=&{0xc00032ed20 {13927360205129572425 281567681457 0x38092e0} 0 {13927360205129572425 281567681457 0x38092e0} map[] false}) %!s(*framework.QueuedPodInfo=&{0xc0002f77a0 {13927360204688357518 281126466544 0x38092e0} 0 {13927360204688357518 281126466544 0x38092e0} map[] false}) %!s(*framework.QueuedPodInfo=&{0xc00032e700 {13927360205040581987 281478691021 0x38092e0} 0 {13927360205040581987 281478691021 0x38092e0} map[] false}) %!s(*framework.QueuedPodInfo=&{0xc00032f260 {13927360205485099519 281849466714 0x38092e0} 0 {13927360205485099519 281849466714 0x38092e0} map[] false})]="queue len:" %!s(int=16)="(MISSING)"
I1030 05:06:12.330148       1 scheduling_queue.go:1203] "[Bing]About to try and schedule pod" pod="default/job-train-imgclassfication4-cuda-epoch40"
I1030 05:06:12.330167       1 schedule_one.go:81] "Attempting to schedule pod" pod="default/job-train-imgclassfication4-cuda-epoch40"
I1030 05:06:12.347215       1 eventhandlers.go:206] "Update event for scheduled pod" pod="default/job-train-imgclassfication3-cuda-epoch30"
I1030 05:06:12.368543       1 eventhandlers.go:118] "Add event for unscheduled pod" pod="default/job-train-imgclassfication20-cuda-epoch200"
I1030 05:06:12.530979       1 schedule_one.go:83] "sleep when attempting to schedule pod to increase job intervals..."
I1030 05:06:12.536103       1 schedule_one.go:63] "starting scheduling for next pod..."
I1030 05:06:12.655551       1 eventhandlers.go:161] "Delete event for unscheduled pod" pod="default/job-train-imgclassfication4-cuda-epoch40"
I1030 05:06:12.655572       1 eventhandlers.go:186] "Add event for scheduled pod" pod="default/job-train-imgclassfication4-cuda-epoch40"
I1030 05:06:12.656494       1 schedule_one.go:260] "Successfully bound pod to node" pod="default/job-train-imgclassfication4-cuda-epoch40" node="node2" evaluatedNodes=1 feasibleNodes=1
I1030 05:06:12.697291       1 eventhandlers.go:206] "Update event for scheduled pod" pod="default/job-train-imgclassfication4-cuda-epoch40"
I1030 05:06:12.737292       1 scheduling_queue.go:661] "[Bing]Pop called on the scheduling queue. current queue includes pods: " [%!s(*framework.QueuedPodInfo=&{0xc000273730 {13927360204898257973 281336366992 0x38092e0} 0 {13927360204898257973 281336366992 0x38092e0} map[] false}) %!s(*framework.QueuedPodInfo=&{0xc00032e620 {13927360204977293464 281415402494 0x38092e0} 0 {13927360204977293464 281415402494 0x38092e0} map[] false}) %!s(*framework.QueuedPodInfo=&{0xc00032ed20 {13927360205129572425 281567681457 0x38092e0} 0 {13927360205129572425 281567681457 0x38092e0} map[] false}) %!s(*framework.QueuedPodInfo=&{0xc0002f7490 {13927360204615576585 281053685603 0x38092e0} 0 {13927360204615576585 281053685603 0x38092e0} map[] false}) %!s(*framework.QueuedPodInfo=&{0xc00032f260 {13927360205485099519 281849466714 0x38092e0} 0 {13927360205485099519 281849466714 0x38092e0} map[] false}) %!s(*framework.QueuedPodInfo=&{0xc0002f77a0 {13927360204688357518 281126466544 0x38092e0} 0 {13927360204688357518 281126466544 0x38092e0} map[] false}) %!s(*framework.QueuedPodInfo=&{0xc00032e700 {13927360205040581987 281478691021 0x38092e0} 0 {13927360205040581987 281478691021 0x38092e0} map[] false}) %!s(*framework.QueuedPodInfo=&{0xc00022f5e0 {13927360204741874373 281179983391 0x38092e0} 0 {13927360204741874373 281179983391 0x38092e0} map[] false}) %!s(*framework.QueuedPodInfo=&{0xc00032eb60 {13927360205082804413 281520913432 0x38092e0} 0 {13927360205082804413 281520913432 0x38092e0} map[] false}) %!s(*framework.QueuedPodInfo=&{0xc00024e3f0 {13927360205612739548 281977106744 0x38092e0} 0 {13927360205612739548 281977106744 0x38092e0} map[] false}) %!s(*framework.QueuedPodInfo=&{0xc00024e540 {13927360205671620050 282035987245 0x38092e0} 0 {13927360205671620050 282035987245 0x38092e0} map[] false}) %!s(*framework.QueuedPodInfo=&{0xc00022fc70 {13927360204821395897 281259504916 0x38092e0} 0 {13927360204821395897 281259504916 0x38092e0} map[] false}) %!s(*framework.QueuedPodInfo=&{0xc000273c00 {13927360205206297686 281644406701 0x38092e0} 0 {13927360205206297686 281644406701 0x38092e0} map[] false}) %!s(*framework.QueuedPodInfo=&{0xc00024e0e0 {13927360205549087692 281913454909 0x38092e0} 0 {13927360205549087692 281913454909 0x38092e0} map[] false}) %!s(*framework.QueuedPodInfo=&{0xc000273ce0 {13927360205363368956 281727736145 0x38092e0} 0 {13927360205363368956 281727736145 0x38092e0} map[] false}) %!s(*framework.QueuedPodInfo=&{0xc000273dc0 {13927360205431737232 281796104442 0x38092e0} 0 {13927360205431737232 281796104442 0x38092e0} map[] false})]="queue len:" %!s(int=16)="(MISSING)"
I1030 05:06:12.737344       1 scheduling_queue.go:1203] "[Bing]About to try and schedule pod" pod="default/job-train-imgclassfication5-cuda-epoch50"
I1030 05:06:12.737360       1 schedule_one.go:81] "Attempting to schedule pod" pod="default/job-train-imgclassfication5-cuda-epoch50"
I1030 05:06:12.748850       1 eventhandlers.go:206] "Update event for scheduled pod" pod="default/job-train-imgclassfication4-cuda-epoch40"
I1030 05:06:12.938177       1 schedule_one.go:83] "sleep when attempting to schedule pod to increase job intervals..."
I1030 05:06:12.941051       1 schedule_one.go:63] "starting scheduling for next pod..."
I1030 05:06:13.060292       1 eventhandlers.go:161] "Delete event for unscheduled pod" pod="default/job-train-imgclassfication5-cuda-epoch50"
I1030 05:06:13.060391       1 eventhandlers.go:186] "Add event for scheduled pod" pod="default/job-train-imgclassfication5-cuda-epoch50"
I1030 05:06:13.061245       1 schedule_one.go:260] "Successfully bound pod to node" pod="default/job-train-imgclassfication5-cuda-epoch50" node="node2" evaluatedNodes=1 feasibleNodes=1
I1030 05:06:13.091461       1 eventhandlers.go:206] "Update event for scheduled pod" pod="default/job-train-imgclassfication5-cuda-epoch50"
I1030 05:06:13.138688       1 eventhandlers.go:206] "Update event for scheduled pod" pod="default/job-train-imgclassfication5-cuda-epoch50"
I1030 05:06:13.141655       1 scheduling_queue.go:661] "[Bing]Pop called on the scheduling queue. current queue includes pods: " [%!s(*framework.QueuedPodInfo=&{0xc000273ce0 {13927360205363368956 281727736145 0x38092e0} 0 {13927360205363368956 281727736145 0x38092e0} map[] false}) %!s(*framework.QueuedPodInfo=&{0xc000273dc0 {13927360205431737232 281796104442 0x38092e0} 0 {13927360205431737232 281796104442 0x38092e0} map[] false}) %!s(*framework.QueuedPodInfo=&{0xc00024e0e0 {13927360205549087692 281913454909 0x38092e0} 0 {13927360205549087692 281913454909 0x38092e0} map[] false}) %!s(*framework.QueuedPodInfo=&{0xc000273730 {13927360204898257973 281336366992 0x38092e0} 0 {13927360204898257973 281336366992 0x38092e0} map[] false}) %!s(*framework.QueuedPodInfo=&{0xc00032e620 {13927360204977293464 281415402494 0x38092e0} 0 {13927360204977293464 281415402494 0x38092e0} map[] false}) %!s(*framework.QueuedPodInfo=&{0xc00032ed20 {13927360205129572425 281567681457 0x38092e0} 0 {13927360205129572425 281567681457 0x38092e0} map[] false}) %!s(*framework.QueuedPodInfo=&{0xc0002f77a0 {13927360204688357518 281126466544 0x38092e0} 0 {13927360204688357518 281126466544 0x38092e0} map[] false}) %!s(*framework.QueuedPodInfo=&{0xc00032e700 {13927360205040581987 281478691021 0x38092e0} 0 {13927360205040581987 281478691021 0x38092e0} map[] false}) %!s(*framework.QueuedPodInfo=&{0xc00032f260 {13927360205485099519 281849466714 0x38092e0} 0 {13927360205485099519 281849466714 0x38092e0} map[] false}) %!s(*framework.QueuedPodInfo=&{0xc00022fc70 {13927360204821395897 281259504916 0x38092e0} 0 {13927360204821395897 281259504916 0x38092e0} map[] false}) %!s(*framework.QueuedPodInfo=&{0xc000273c00 {13927360205206297686 281644406701 0x38092e0} 0 {13927360205206297686 281644406701 0x38092e0} map[] false}) %!s(*framework.QueuedPodInfo=&{0xc00022f5e0 {13927360204741874373 281179983391 0x38092e0} 0 {13927360204741874373 281179983391 0x38092e0} map[] false}) %!s(*framework.QueuedPodInfo=&{0xc00032eb60 {13927360205082804413 281520913432 0x38092e0} 0 {13927360205082804413 281520913432 0x38092e0} map[] false}) %!s(*framework.QueuedPodInfo=&{0xc00024e3f0 {13927360205612739548 281977106744 0x38092e0} 0 {13927360205612739548 281977106744 0x38092e0} map[] false}) %!s(*framework.QueuedPodInfo=&{0xc00024e540 {13927360205671620050 282035987245 0x38092e0} 0 {13927360205671620050 282035987245 0x38092e0} map[] false})]="queue len:" %!s(int=15)="(MISSING)"
I1030 05:06:13.141715       1 scheduling_queue.go:1203] "[Bing]About to try and schedule pod" pod="default/job-train-imgclassfication6-cuda-epoch60"
I1030 05:06:13.141739       1 schedule_one.go:81] "Attempting to schedule pod" pod="default/job-train-imgclassfication6-cuda-epoch60"
I1030 05:06:13.211129       1 eventhandlers.go:206] "Update event for scheduled pod" pod="default/job-train-imgclassfication2-cuda-epoch20"
I1030 05:06:13.229352       1 eventhandlers.go:206] "Update event for scheduled pod" pod="default/job-train-imgclassfication1-cuda-epoch10"
I1030 05:06:13.342510       1 schedule_one.go:83] "sleep when attempting to schedule pod to increase job intervals..."
I1030 05:06:13.346096       1 schedule_one.go:63] "starting scheduling for next pod..."
I1030 05:06:13.507788       1 eventhandlers.go:161] "Delete event for unscheduled pod" pod="default/job-train-imgclassfication6-cuda-epoch60"
I1030 05:06:13.507806       1 eventhandlers.go:186] "Add event for scheduled pod" pod="default/job-train-imgclassfication6-cuda-epoch60"
I1030 05:06:13.509305       1 schedule_one.go:260] "Successfully bound pod to node" pod="default/job-train-imgclassfication6-cuda-epoch60" node="node2" evaluatedNodes=1 feasibleNodes=1
I1030 05:06:13.546821       1 scheduling_queue.go:661] "[Bing]Pop called on the scheduling queue. current queue includes pods: " [%!s(*framework.QueuedPodInfo=&{0xc00032e700 {13927360205040581987 281478691021 0x38092e0} 0 {13927360205040581987 281478691021 0x38092e0} map[] false}) %!s(*framework.QueuedPodInfo=&{0xc00032f260 {13927360205485099519 281849466714 0x38092e0} 0 {13927360205485099519 281849466714 0x38092e0} map[] false}) %!s(*framework.QueuedPodInfo=&{0xc00022fc70 {13927360204821395897 281259504916 0x38092e0} 0 {13927360204821395897 281259504916 0x38092e0} map[] false}) %!s(*framework.QueuedPodInfo=&{0xc000273c00 {13927360205206297686 281644406701 0x38092e0} 0 {13927360205206297686 281644406701 0x38092e0} map[] false}) %!s(*framework.QueuedPodInfo=&{0xc00022f5e0 {13927360204741874373 281179983391 0x38092e0} 0 {13927360204741874373 281179983391 0x38092e0} map[] false}) %!s(*framework.QueuedPodInfo=&{0xc00032eb60 {13927360205082804413 281520913432 0x38092e0} 0 {13927360205082804413 281520913432 0x38092e0} map[] false}) %!s(*framework.QueuedPodInfo=&{0xc00024e3f0 {13927360205612739548 281977106744 0x38092e0} 0 {13927360205612739548 281977106744 0x38092e0} map[] false}) %!s(*framework.QueuedPodInfo=&{0xc00024e540 {13927360205671620050 282035987245 0x38092e0} 0 {13927360205671620050 282035987245 0x38092e0} map[] false}) %!s(*framework.QueuedPodInfo=&{0xc000273ce0 {13927360205363368956 281727736145 0x38092e0} 0 {13927360205363368956 281727736145 0x38092e0} map[] false}) %!s(*framework.QueuedPodInfo=&{0xc000273dc0 {13927360205431737232 281796104442 0x38092e0} 0 {13927360205431737232 281796104442 0x38092e0} map[] false}) %!s(*framework.QueuedPodInfo=&{0xc00024e0e0 {13927360205549087692 281913454909 0x38092e0} 0 {13927360205549087692 281913454909 0x38092e0} map[] false}) %!s(*framework.QueuedPodInfo=&{0xc000273730 {13927360204898257973 281336366992 0x38092e0} 0 {13927360204898257973 281336366992 0x38092e0} map[] false}) %!s(*framework.QueuedPodInfo=&{0xc00032e620 {13927360204977293464 281415402494 0x38092e0} 0 {13927360204977293464 281415402494 0x38092e0} map[] false}) %!s(*framework.QueuedPodInfo=&{0xc00032ed20 {13927360205129572425 281567681457 0x38092e0} 0 {13927360205129572425 281567681457 0x38092e0} map[] false})]="queue len:" %!s(int=14)="(MISSING)"
I1030 05:06:13.546869       1 scheduling_queue.go:1203] "[Bing]About to try and schedule pod" pod="default/job-train-imgclassfication7-cuda-epoch70"
I1030 05:06:13.546883       1 schedule_one.go:81] "Attempting to schedule pod" pod="default/job-train-imgclassfication7-cuda-epoch70"
I1030 05:06:13.563717       1 eventhandlers.go:206] "Update event for scheduled pod" pod="default/job-train-imgclassfication6-cuda-epoch60"
I1030 05:06:13.612851       1 eventhandlers.go:206] "Update event for scheduled pod" pod="default/job-train-imgclassfication6-cuda-epoch60"
I1030 05:06:13.747205       1 schedule_one.go:83] "sleep when attempting to schedule pod to increase job intervals..."
I1030 05:06:13.749789       1 schedule_one.go:63] "starting scheduling for next pod..."
I1030 05:06:13.872552       1 eventhandlers.go:161] "Delete event for unscheduled pod" pod="default/job-train-imgclassfication7-cuda-epoch70"
I1030 05:06:13.872573       1 eventhandlers.go:186] "Add event for scheduled pod" pod="default/job-train-imgclassfication7-cuda-epoch70"
I1030 05:06:13.872927       1 schedule_one.go:260] "Successfully bound pod to node" pod="default/job-train-imgclassfication7-cuda-epoch70" node="node2" evaluatedNodes=1 feasibleNodes=1
I1030 05:06:13.905679       1 eventhandlers.go:206] "Update event for scheduled pod" pod="default/job-train-imgclassfication7-cuda-epoch70"
I1030 05:06:13.950638       1 scheduling_queue.go:661] "[Bing]Pop called on the scheduling queue. current queue includes pods: " [%!s(*framework.QueuedPodInfo=&{0xc000273ce0 {13927360205363368956 281727736145 0x38092e0} 0 {13927360205363368956 281727736145 0x38092e0} map[] false}) %!s(*framework.QueuedPodInfo=&{0xc000273dc0 {13927360205431737232 281796104442 0x38092e0} 0 {13927360205431737232 281796104442 0x38092e0} map[] false}) %!s(*framework.QueuedPodInfo=&{0xc00024e0e0 {13927360205549087692 281913454909 0x38092e0} 0 {13927360205549087692 281913454909 0x38092e0} map[] false}) %!s(*framework.QueuedPodInfo=&{0xc000273730 {13927360204898257973 281336366992 0x38092e0} 0 {13927360204898257973 281336366992 0x38092e0} map[] false}) %!s(*framework.QueuedPodInfo=&{0xc00032e620 {13927360204977293464 281415402494 0x38092e0} 0 {13927360204977293464 281415402494 0x38092e0} map[] false}) %!s(*framework.QueuedPodInfo=&{0xc00032ed20 {13927360205129572425 281567681457 0x38092e0} 0 {13927360205129572425 281567681457 0x38092e0} map[] false}) %!s(*framework.QueuedPodInfo=&{0xc00032e700 {13927360205040581987 281478691021 0x38092e0} 0 {13927360205040581987 281478691021 0x38092e0} map[] false}) %!s(*framework.QueuedPodInfo=&{0xc00032f260 {13927360205485099519 281849466714 0x38092e0} 0 {13927360205485099519 281849466714 0x38092e0} map[] false}) %!s(*framework.QueuedPodInfo=&{0xc00022fc70 {13927360204821395897 281259504916 0x38092e0} 0 {13927360204821395897 281259504916 0x38092e0} map[] false}) %!s(*framework.QueuedPodInfo=&{0xc000273c00 {13927360205206297686 281644406701 0x38092e0} 0 {13927360205206297686 281644406701 0x38092e0} map[] false}) %!s(*framework.QueuedPodInfo=&{0xc00032eb60 {13927360205082804413 281520913432 0x38092e0} 0 {13927360205082804413 281520913432 0x38092e0} map[] false}) %!s(*framework.QueuedPodInfo=&{0xc00024e3f0 {13927360205612739548 281977106744 0x38092e0} 0 {13927360205612739548 281977106744 0x38092e0} map[] false}) %!s(*framework.QueuedPodInfo=&{0xc00024e540 {13927360205671620050 282035987245 0x38092e0} 0 {13927360205671620050 282035987245 0x38092e0} map[] false})]="queue len:" %!s(int=13)="(MISSING)"
I1030 05:06:13.950685       1 scheduling_queue.go:1203] "[Bing]About to try and schedule pod" pod="default/job-train-imgclassfication8-cuda-epoch80"
I1030 05:06:13.950707       1 schedule_one.go:81] "Attempting to schedule pod" pod="default/job-train-imgclassfication8-cuda-epoch80"
I1030 05:06:13.964357       1 eventhandlers.go:206] "Update event for scheduled pod" pod="default/job-train-imgclassfication7-cuda-epoch70"
I1030 05:06:14.151816       1 schedule_one.go:83] "sleep when attempting to schedule pod to increase job intervals..."
I1030 05:06:14.155481       1 schedule_one.go:63] "starting scheduling for next pod..."
I1030 05:06:14.211082       1 eventhandlers.go:206] "Update event for scheduled pod" pod="default/job-train-imgclassfication3-cuda-epoch30"
I1030 05:06:14.230065       1 eventhandlers.go:206] "Update event for scheduled pod" pod="default/job-train-imgclassfication5-cuda-epoch50"
I1030 05:06:14.250076       1 eventhandlers.go:206] "Update event for scheduled pod" pod="default/job-train-imgclassfication4-cuda-epoch40"
I1030 05:06:14.280914       1 eventhandlers.go:161] "Delete event for unscheduled pod" pod="default/job-train-imgclassfication8-cuda-epoch80"
I1030 05:06:14.280946       1 eventhandlers.go:186] "Add event for scheduled pod" pod="default/job-train-imgclassfication8-cuda-epoch80"
I1030 05:06:14.281982       1 schedule_one.go:260] "Successfully bound pod to node" pod="default/job-train-imgclassfication8-cuda-epoch80" node="node2" evaluatedNodes=1 feasibleNodes=1
I1030 05:06:14.312279       1 eventhandlers.go:206] "Update event for scheduled pod" pod="default/job-train-imgclassfication8-cuda-epoch80"
I1030 05:06:14.355925       1 scheduling_queue.go:661] "[Bing]Pop called on the scheduling queue. current queue includes pods: " [%!s(*framework.QueuedPodInfo=&{0xc00032e700 {13927360205040581987 281478691021 0x38092e0} 0 {13927360205040581987 281478691021 0x38092e0} map[] false}) %!s(*framework.QueuedPodInfo=&{0xc00032f260 {13927360205485099519 281849466714 0x38092e0} 0 {13927360205485099519 281849466714 0x38092e0} map[] false}) %!s(*framework.QueuedPodInfo=&{0xc00024e3f0 {13927360205612739548 281977106744 0x38092e0} 0 {13927360205612739548 281977106744 0x38092e0} map[] false}) %!s(*framework.QueuedPodInfo=&{0xc00024e540 {13927360205671620050 282035987245 0x38092e0} 0 {13927360205671620050 282035987245 0x38092e0} map[] false}) %!s(*framework.QueuedPodInfo=&{0xc000273c00 {13927360205206297686 281644406701 0x38092e0} 0 {13927360205206297686 281644406701 0x38092e0} map[] false}) %!s(*framework.QueuedPodInfo=&{0xc00032eb60 {13927360205082804413 281520913432 0x38092e0} 0 {13927360205082804413 281520913432 0x38092e0} map[] false}) %!s(*framework.QueuedPodInfo=&{0xc000273ce0 {13927360205363368956 281727736145 0x38092e0} 0 {13927360205363368956 281727736145 0x38092e0} map[] false}) %!s(*framework.QueuedPodInfo=&{0xc000273dc0 {13927360205431737232 281796104442 0x38092e0} 0 {13927360205431737232 281796104442 0x38092e0} map[] false}) %!s(*framework.QueuedPodInfo=&{0xc00024e0e0 {13927360205549087692 281913454909 0x38092e0} 0 {13927360205549087692 281913454909 0x38092e0} map[] false}) %!s(*framework.QueuedPodInfo=&{0xc00032ed20 {13927360205129572425 281567681457 0x38092e0} 0 {13927360205129572425 281567681457 0x38092e0} map[] false}) %!s(*framework.QueuedPodInfo=&{0xc000273730 {13927360204898257973 281336366992 0x38092e0} 0 {13927360204898257973 281336366992 0x38092e0} map[] false}) %!s(*framework.QueuedPodInfo=&{0xc00032e620 {13927360204977293464 281415402494 0x38092e0} 0 {13927360204977293464 281415402494 0x38092e0} map[] false})]="queue len:" %!s(int=12)="(MISSING)"
I1030 05:06:14.356003       1 scheduling_queue.go:1203] "[Bing]About to try and schedule pod" pod="default/job-train-imgclassfication9-cuda-epoch90"
I1030 05:06:14.356030       1 schedule_one.go:81] "Attempting to schedule pod" pod="default/job-train-imgclassfication9-cuda-epoch90"
I1030 05:06:14.359419       1 eventhandlers.go:206] "Update event for scheduled pod" pod="default/job-train-imgclassfication8-cuda-epoch80"
I1030 05:06:14.556599       1 schedule_one.go:83] "sleep when attempting to schedule pod to increase job intervals..."
I1030 05:06:14.559899       1 schedule_one.go:63] "starting scheduling for next pod..."
I1030 05:06:14.685100       1 eventhandlers.go:161] "Delete event for unscheduled pod" pod="default/job-train-imgclassfication9-cuda-epoch90"
I1030 05:06:14.685121       1 eventhandlers.go:186] "Add event for scheduled pod" pod="default/job-train-imgclassfication9-cuda-epoch90"
I1030 05:06:14.689617       1 schedule_one.go:260] "Successfully bound pod to node" pod="default/job-train-imgclassfication9-cuda-epoch90" node="node2" evaluatedNodes=1 feasibleNodes=1
I1030 05:06:14.718673       1 eventhandlers.go:206] "Update event for scheduled pod" pod="default/job-train-imgclassfication9-cuda-epoch90"
I1030 05:06:14.760684       1 scheduling_queue.go:661] "[Bing]Pop called on the scheduling queue. current queue includes pods: " [%!s(*framework.QueuedPodInfo=&{0xc00032e620 {13927360204977293464 281415402494 0x38092e0} 0 {13927360204977293464 281415402494 0x38092e0} map[] false}) %!s(*framework.QueuedPodInfo=&{0xc00032ed20 {13927360205129572425 281567681457 0x38092e0} 0 {13927360205129572425 281567681457 0x38092e0} map[] false}) %!s(*framework.QueuedPodInfo=&{0xc00032e700 {13927360205040581987 281478691021 0x38092e0} 0 {13927360205040581987 281478691021 0x38092e0} map[] false}) %!s(*framework.QueuedPodInfo=&{0xc00032f260 {13927360205485099519 281849466714 0x38092e0} 0 {13927360205485099519 281849466714 0x38092e0} map[] false}) %!s(*framework.QueuedPodInfo=&{0xc000273c00 {13927360205206297686 281644406701 0x38092e0} 0 {13927360205206297686 281644406701 0x38092e0} map[] false}) %!s(*framework.QueuedPodInfo=&{0xc00032eb60 {13927360205082804413 281520913432 0x38092e0} 0 {13927360205082804413 281520913432 0x38092e0} map[] false}) %!s(*framework.QueuedPodInfo=&{0xc00024e3f0 {13927360205612739548 281977106744 0x38092e0} 0 {13927360205612739548 281977106744 0x38092e0} map[] false}) %!s(*framework.QueuedPodInfo=&{0xc00024e540 {13927360205671620050 282035987245 0x38092e0} 0 {13927360205671620050 282035987245 0x38092e0} map[] false}) %!s(*framework.QueuedPodInfo=&{0xc000273dc0 {13927360205431737232 281796104442 0x38092e0} 0 {13927360205431737232 281796104442 0x38092e0} map[] false}) %!s(*framework.QueuedPodInfo=&{0xc00024e0e0 {13927360205549087692 281913454909 0x38092e0} 0 {13927360205549087692 281913454909 0x38092e0} map[] false}) %!s(*framework.QueuedPodInfo=&{0xc000273ce0 {13927360205363368956 281727736145 0x38092e0} 0 {13927360205363368956 281727736145 0x38092e0} map[] false})]="queue len:" %!s(int=11)="(MISSING)"
I1030 05:06:14.760753       1 scheduling_queue.go:1203] "[Bing]About to try and schedule pod" pod="default/job-train-imgclassfication10-cuda-epoch100"
I1030 05:06:14.760771       1 schedule_one.go:81] "Attempting to schedule pod" pod="default/job-train-imgclassfication10-cuda-epoch100"
I1030 05:06:14.771019       1 eventhandlers.go:206] "Update event for scheduled pod" pod="default/job-train-imgclassfication9-cuda-epoch90"
I1030 05:06:14.960851       1 schedule_one.go:83] "sleep when attempting to schedule pod to increase job intervals..."
I1030 05:06:14.964774       1 schedule_one.go:63] "starting scheduling for next pod..."
I1030 05:06:15.087185       1 eventhandlers.go:161] "Delete event for unscheduled pod" pod="default/job-train-imgclassfication10-cuda-epoch100"
I1030 05:06:15.087191       1 eventhandlers.go:186] "Add event for scheduled pod" pod="default/job-train-imgclassfication10-cuda-epoch100"
I1030 05:06:15.088519       1 schedule_one.go:260] "Successfully bound pod to node" pod="default/job-train-imgclassfication10-cuda-epoch100" node="node2" evaluatedNodes=1 feasibleNodes=1
I1030 05:06:15.128102       1 eventhandlers.go:206] "Update event for scheduled pod" pod="default/job-train-imgclassfication10-cuda-epoch100"
I1030 05:06:15.165282       1 scheduling_queue.go:661] "[Bing]Pop called on the scheduling queue. current queue includes pods: " [%!s(*framework.QueuedPodInfo=&{0xc00032e700 {13927360205040581987 281478691021 0x38092e0} 0 {13927360205040581987 281478691021 0x38092e0} map[] false}) %!s(*framework.QueuedPodInfo=&{0xc00032f260 {13927360205485099519 281849466714 0x38092e0} 0 {13927360205485099519 281849466714 0x38092e0} map[] false}) %!s(*framework.QueuedPodInfo=&{0xc000273c00 {13927360205206297686 281644406701 0x38092e0} 0 {13927360205206297686 281644406701 0x38092e0} map[] false}) %!s(*framework.QueuedPodInfo=&{0xc00032eb60 {13927360205082804413 281520913432 0x38092e0} 0 {13927360205082804413 281520913432 0x38092e0} map[] false}) %!s(*framework.QueuedPodInfo=&{0xc00024e3f0 {13927360205612739548 281977106744 0x38092e0} 0 {13927360205612739548 281977106744 0x38092e0} map[] false}) %!s(*framework.QueuedPodInfo=&{0xc00024e540 {13927360205671620050 282035987245 0x38092e0} 0 {13927360205671620050 282035987245 0x38092e0} map[] false}) %!s(*framework.QueuedPodInfo=&{0xc000273ce0 {13927360205363368956 281727736145 0x38092e0} 0 {13927360205363368956 281727736145 0x38092e0} map[] false}) %!s(*framework.QueuedPodInfo=&{0xc000273dc0 {13927360205431737232 281796104442 0x38092e0} 0 {13927360205431737232 281796104442 0x38092e0} map[] false}) %!s(*framework.QueuedPodInfo=&{0xc00024e0e0 {13927360205549087692 281913454909 0x38092e0} 0 {13927360205549087692 281913454909 0x38092e0} map[] false}) %!s(*framework.QueuedPodInfo=&{0xc00032ed20 {13927360205129572425 281567681457 0x38092e0} 0 {13927360205129572425 281567681457 0x38092e0} map[] false})]="queue len:" %!s(int=10)="(MISSING)"
I1030 05:06:15.165344       1 scheduling_queue.go:1203] "[Bing]About to try and schedule pod" pod="default/job-train-imgclassfication11-cuda-epoch110"
I1030 05:06:15.165364       1 schedule_one.go:81] "Attempting to schedule pod" pod="default/job-train-imgclassfication11-cuda-epoch110"
I1030 05:06:15.193094       1 eventhandlers.go:206] "Update event for scheduled pod" pod="default/job-train-imgclassfication10-cuda-epoch100"
I1030 05:06:15.220725       1 eventhandlers.go:206] "Update event for scheduled pod" pod="default/job-train-imgclassfication6-cuda-epoch60"
I1030 05:06:15.238667       1 eventhandlers.go:206] "Update event for scheduled pod" pod="default/job-train-imgclassfication7-cuda-epoch70"
I1030 05:06:15.365983       1 schedule_one.go:83] "sleep when attempting to schedule pod to increase job intervals..."
I1030 05:06:15.369565       1 schedule_one.go:63] "starting scheduling for next pod..."
I1030 05:06:15.494809       1 eventhandlers.go:186] "Add event for scheduled pod" pod="default/job-train-imgclassfication11-cuda-epoch110"
I1030 05:06:15.494849       1 eventhandlers.go:161] "Delete event for unscheduled pod" pod="default/job-train-imgclassfication11-cuda-epoch110"
I1030 05:06:15.497078       1 schedule_one.go:260] "Successfully bound pod to node" pod="default/job-train-imgclassfication11-cuda-epoch110" node="node2" evaluatedNodes=1 feasibleNodes=1
I1030 05:06:15.530388       1 eventhandlers.go:206] "Update event for scheduled pod" pod="default/job-train-imgclassfication11-cuda-epoch110"
I1030 05:06:15.570202       1 scheduling_queue.go:661] "[Bing]Pop called on the scheduling queue. current queue includes pods: " [%!s(*framework.QueuedPodInfo=&{0xc00032f260 {13927360205485099519 281849466714 0x38092e0} 0 {13927360205485099519 281849466714 0x38092e0} map[] false}) %!s(*framework.QueuedPodInfo=&{0xc000273c00 {13927360205206297686 281644406701 0x38092e0} 0 {13927360205206297686 281644406701 0x38092e0} map[] false}) %!s(*framework.QueuedPodInfo=&{0xc00032eb60 {13927360205082804413 281520913432 0x38092e0} 0 {13927360205082804413 281520913432 0x38092e0} map[] false}) %!s(*framework.QueuedPodInfo=&{0xc00024e3f0 {13927360205612739548 281977106744 0x38092e0} 0 {13927360205612739548 281977106744 0x38092e0} map[] false}) %!s(*framework.QueuedPodInfo=&{0xc00024e540 {13927360205671620050 282035987245 0x38092e0} 0 {13927360205671620050 282035987245 0x38092e0} map[] false}) %!s(*framework.QueuedPodInfo=&{0xc000273ce0 {13927360205363368956 281727736145 0x38092e0} 0 {13927360205363368956 281727736145 0x38092e0} map[] false}) %!s(*framework.QueuedPodInfo=&{0xc000273dc0 {13927360205431737232 281796104442 0x38092e0} 0 {13927360205431737232 281796104442 0x38092e0} map[] false}) %!s(*framework.QueuedPodInfo=&{0xc00024e0e0 {13927360205549087692 281913454909 0x38092e0} 0 {13927360205549087692 281913454909 0x38092e0} map[] false}) %!s(*framework.QueuedPodInfo=&{0xc00032ed20 {13927360205129572425 281567681457 0x38092e0} 0 {13927360205129572425 281567681457 0x38092e0} map[] false})]="queue len:" %!s(int=9)="(MISSING)"
I1030 05:06:15.570248       1 scheduling_queue.go:1203] "[Bing]About to try and schedule pod" pod="default/job-train-imgclassfication12-cuda-epoch120"
I1030 05:06:15.570263       1 schedule_one.go:81] "Attempting to schedule pod" pod="default/job-train-imgclassfication12-cuda-epoch120"
I1030 05:06:15.591760       1 eventhandlers.go:206] "Update event for scheduled pod" pod="default/job-train-imgclassfication11-cuda-epoch110"
I1030 05:06:15.770348       1 schedule_one.go:83] "sleep when attempting to schedule pod to increase job intervals..."
I1030 05:06:15.772975       1 schedule_one.go:63] "starting scheduling for next pod..."
I1030 05:06:15.894424       1 eventhandlers.go:161] "Delete event for unscheduled pod" pod="default/job-train-imgclassfication12-cuda-epoch120"
I1030 05:06:15.894465       1 eventhandlers.go:186] "Add event for scheduled pod" pod="default/job-train-imgclassfication12-cuda-epoch120"
I1030 05:06:15.896147       1 schedule_one.go:260] "Successfully bound pod to node" pod="default/job-train-imgclassfication12-cuda-epoch120" node="node2" evaluatedNodes=1 feasibleNodes=1
I1030 05:06:15.925611       1 eventhandlers.go:206] "Update event for scheduled pod" pod="default/job-train-imgclassfication12-cuda-epoch120"
I1030 05:06:15.973529       1 scheduling_queue.go:661] "[Bing]Pop called on the scheduling queue. current queue includes pods: " [%!s(*framework.QueuedPodInfo=&{0xc00024e3f0 {13927360205612739548 281977106744 0x38092e0} 0 {13927360205612739548 281977106744 0x38092e0} map[] false}) %!s(*framework.QueuedPodInfo=&{0xc00024e540 {13927360205671620050 282035987245 0x38092e0} 0 {13927360205671620050 282035987245 0x38092e0} map[] false}) %!s(*framework.QueuedPodInfo=&{0xc000273c00 {13927360205206297686 281644406701 0x38092e0} 0 {13927360205206297686 281644406701 0x38092e0} map[] false}) %!s(*framework.QueuedPodInfo=&{0xc00024e0e0 {13927360205549087692 281913454909 0x38092e0} 0 {13927360205549087692 281913454909 0x38092e0} map[] false}) %!s(*framework.QueuedPodInfo=&{0xc000273ce0 {13927360205363368956 281727736145 0x38092e0} 0 {13927360205363368956 281727736145 0x38092e0} map[] false}) %!s(*framework.QueuedPodInfo=&{0xc000273dc0 {13927360205431737232 281796104442 0x38092e0} 0 {13927360205431737232 281796104442 0x38092e0} map[] false}) %!s(*framework.QueuedPodInfo=&{0xc00032ed20 {13927360205129572425 281567681457 0x38092e0} 0 {13927360205129572425 281567681457 0x38092e0} map[] false}) %!s(*framework.QueuedPodInfo=&{0xc00032f260 {13927360205485099519 281849466714 0x38092e0} 0 {13927360205485099519 281849466714 0x38092e0} map[] false})]="queue len:" %!s(int=8)="(MISSING)"
I1030 05:06:15.973596       1 scheduling_queue.go:1203] "[Bing]About to try and schedule pod" pod="default/job-train-imgclassfication13-cuda-epoch130"
I1030 05:06:15.973617       1 schedule_one.go:81] "Attempting to schedule pod" pod="default/job-train-imgclassfication13-cuda-epoch130"
I1030 05:06:15.989112       1 eventhandlers.go:206] "Update event for scheduled pod" pod="default/job-train-imgclassfication12-cuda-epoch120"
I1030 05:06:16.174423       1 schedule_one.go:83] "sleep when attempting to schedule pod to increase job intervals..."
I1030 05:06:16.174794       1 schedule_one.go:875] "Unable to schedule pod; no fit; waiting" pod="default/job-train-imgclassfication13-cuda-epoch130" err="0/1 nodes are available: 1 Insufficient aliyun.com/gpu-mem. preemption: 0/1 nodes are available: 1 Insufficient aliyun.com/gpu-mem.."
I1030 05:06:16.174891       1 schedule_one.go:951] "Updating pod condition" pod="default/job-train-imgclassfication13-cuda-epoch130" conditionType=PodScheduled conditionStatus=False conditionReason="Unschedulable"
I1030 05:06:16.184347       1 schedule_one.go:63] "starting scheduling for next pod..."
I1030 05:06:16.227080       1 eventhandlers.go:206] "Update event for scheduled pod" pod="default/job-train-imgclassfication8-cuda-epoch80"
I1030 05:06:16.246590       1 eventhandlers.go:206] "Update event for scheduled pod" pod="default/job-train-imgclassfication9-cuda-epoch90"
I1030 05:06:16.267658       1 eventhandlers.go:206] "Update event for scheduled pod" pod="default/job-train-imgclassfication10-cuda-epoch100"
I1030 05:06:16.385347       1 scheduling_queue.go:661] "[Bing]Pop called on the scheduling queue. current queue includes pods: " [%!s(*framework.QueuedPodInfo=&{0xc00032f260 {13927360205485099519 281849466714 0x38092e0} 0 {13927360205485099519 281849466714 0x38092e0} map[] false}) %!s(*framework.QueuedPodInfo=&{0xc000273c00 {13927360205206297686 281644406701 0x38092e0} 0 {13927360205206297686 281644406701 0x38092e0} map[] false}) %!s(*framework.QueuedPodInfo=&{0xc00024e3f0 {13927360205612739548 281977106744 0x38092e0} 0 {13927360205612739548 281977106744 0x38092e0} map[] false}) %!s(*framework.QueuedPodInfo=&{0xc00024e540 {13927360205671620050 282035987245 0x38092e0} 0 {13927360205671620050 282035987245 0x38092e0} map[] false}) %!s(*framework.QueuedPodInfo=&{0xc000273ce0 {13927360205363368956 281727736145 0x38092e0} 0 {13927360205363368956 281727736145 0x38092e0} map[] false}) %!s(*framework.QueuedPodInfo=&{0xc000273dc0 {13927360205431737232 281796104442 0x38092e0} 0 {13927360205431737232 281796104442 0x38092e0} map[] false}) %!s(*framework.QueuedPodInfo=&{0xc00024e0e0 {13927360205549087692 281913454909 0x38092e0} 0 {13927360205549087692 281913454909 0x38092e0} map[] false})]="queue len:" %!s(int=7)="(MISSING)"
I1030 05:06:16.385425       1 scheduling_queue.go:1203] "[Bing]About to try and schedule pod" pod="default/job-train-imgclassfication14-cuda-epoch140"
I1030 05:06:16.385453       1 schedule_one.go:81] "Attempting to schedule pod" pod="default/job-train-imgclassfication14-cuda-epoch140"
I1030 05:06:16.585617       1 schedule_one.go:83] "sleep when attempting to schedule pod to increase job intervals..."
I1030 05:06:16.586018       1 schedule_one.go:875] "Unable to schedule pod; no fit; waiting" pod="default/job-train-imgclassfication14-cuda-epoch140" err="0/1 nodes are available: 1 Insufficient aliyun.com/gpu-mem. preemption: 0/1 nodes are available: 1 Insufficient aliyun.com/gpu-mem.."
I1030 05:06:16.586123       1 schedule_one.go:951] "Updating pod condition" pod="default/job-train-imgclassfication14-cuda-epoch140" conditionType=PodScheduled conditionStatus=False conditionReason="Unschedulable"
I1030 05:06:16.599799       1 schedule_one.go:63] "starting scheduling for next pod..."
I1030 05:06:16.800667       1 scheduling_queue.go:661] "[Bing]Pop called on the scheduling queue. current queue includes pods: " [%!s(*framework.QueuedPodInfo=&{0xc00032f260 {13927360205485099519 281849466714 0x38092e0} 0 {13927360205485099519 281849466714 0x38092e0} map[] false}) %!s(*framework.QueuedPodInfo=&{0xc00024e3f0 {13927360205612739548 281977106744 0x38092e0} 0 {13927360205612739548 281977106744 0x38092e0} map[] false}) %!s(*framework.QueuedPodInfo=&{0xc00024e540 {13927360205671620050 282035987245 0x38092e0} 0 {13927360205671620050 282035987245 0x38092e0} map[] false}) %!s(*framework.QueuedPodInfo=&{0xc000273ce0 {13927360205363368956 281727736145 0x38092e0} 0 {13927360205363368956 281727736145 0x38092e0} map[] false}) %!s(*framework.QueuedPodInfo=&{0xc000273dc0 {13927360205431737232 281796104442 0x38092e0} 0 {13927360205431737232 281796104442 0x38092e0} map[] false}) %!s(*framework.QueuedPodInfo=&{0xc00024e0e0 {13927360205549087692 281913454909 0x38092e0} 0 {13927360205549087692 281913454909 0x38092e0} map[] false})]="queue len:" %!s(int=6)="(MISSING)"
I1030 05:06:16.800719       1 scheduling_queue.go:1203] "[Bing]About to try and schedule pod" pod="default/job-train-imgclassfication15-cuda-epoch150"
I1030 05:06:16.800732       1 schedule_one.go:81] "Attempting to schedule pod" pod="default/job-train-imgclassfication15-cuda-epoch150"
I1030 05:06:17.001081       1 schedule_one.go:83] "sleep when attempting to schedule pod to increase job intervals..."
I1030 05:06:17.001433       1 schedule_one.go:875] "Unable to schedule pod; no fit; waiting" pod="default/job-train-imgclassfication15-cuda-epoch150" err="0/1 nodes are available: 1 Insufficient aliyun.com/gpu-mem. preemption: 0/1 nodes are available: 1 Insufficient aliyun.com/gpu-mem.."
I1030 05:06:17.001517       1 schedule_one.go:951] "Updating pod condition" pod="default/job-train-imgclassfication15-cuda-epoch150" conditionType=PodScheduled conditionStatus=False conditionReason="Unschedulable"
I1030 05:06:17.009998       1 schedule_one.go:63] "starting scheduling for next pod..."
I1030 05:06:17.211097       1 scheduling_queue.go:661] "[Bing]Pop called on the scheduling queue. current queue includes pods: " [%!s(*framework.QueuedPodInfo=&{0xc00024e540 {13927360205671620050 282035987245 0x38092e0} 0 {13927360205671620050 282035987245 0x38092e0} map[] false}) %!s(*framework.QueuedPodInfo=&{0xc00024e3f0 {13927360205612739548 281977106744 0x38092e0} 0 {13927360205612739548 281977106744 0x38092e0} map[] false}) %!s(*framework.QueuedPodInfo=&{0xc000273dc0 {13927360205431737232 281796104442 0x38092e0} 0 {13927360205431737232 281796104442 0x38092e0} map[] false}) %!s(*framework.QueuedPodInfo=&{0xc00024e0e0 {13927360205549087692 281913454909 0x38092e0} 0 {13927360205549087692 281913454909 0x38092e0} map[] false}) %!s(*framework.QueuedPodInfo=&{0xc00032f260 {13927360205485099519 281849466714 0x38092e0} 0 {13927360205485099519 281849466714 0x38092e0} map[] false})]="queue len:" %!s(int=5)="(MISSING)"
I1030 05:06:17.211147       1 scheduling_queue.go:1203] "[Bing]About to try and schedule pod" pod="default/job-train-imgclassfication16-cuda-epoch160"
I1030 05:06:17.211165       1 schedule_one.go:81] "Attempting to schedule pod" pod="default/job-train-imgclassfication16-cuda-epoch160"
I1030 05:06:17.233801       1 eventhandlers.go:206] "Update event for scheduled pod" pod="default/job-train-imgclassfication11-cuda-epoch110"
I1030 05:06:17.252384       1 eventhandlers.go:206] "Update event for scheduled pod" pod="default/job-train-imgclassfication12-cuda-epoch120"
I1030 05:06:17.411959       1 schedule_one.go:83] "sleep when attempting to schedule pod to increase job intervals..."
I1030 05:06:17.412419       1 schedule_one.go:875] "Unable to schedule pod; no fit; waiting" pod="default/job-train-imgclassfication16-cuda-epoch160" err="0/1 nodes are available: 1 Insufficient aliyun.com/gpu-mem. preemption: 0/1 nodes are available: 1 Insufficient aliyun.com/gpu-mem.."
I1030 05:06:17.412558       1 schedule_one.go:951] "Updating pod condition" pod="default/job-train-imgclassfication16-cuda-epoch160" conditionType=PodScheduled conditionStatus=False conditionReason="Unschedulable"
I1030 05:06:17.425985       1 schedule_one.go:63] "starting scheduling for next pod..."
I1030 05:06:17.626738       1 scheduling_queue.go:661] "[Bing]Pop called on the scheduling queue. current queue includes pods: " [%!s(*framework.QueuedPodInfo=&{0xc00024e0e0 {13927360205549087692 281913454909 0x38092e0} 0 {13927360205549087692 281913454909 0x38092e0} map[] false}) %!s(*framework.QueuedPodInfo=&{0xc00024f2d0 {13927360209772868325 285842268204 0x38092e0} 1 {13927360205129572425 281567681457 0x38092e0} map[NodeResourcesFit:{}] false}) %!s(*framework.QueuedPodInfo=&{0xc00032f260 {13927360205485099519 281849466714 0x38092e0} 0 {13927360205485099519 281849466714 0x38092e0} map[] false}) %!s(*framework.QueuedPodInfo=&{0xc00024e3f0 {13927360205612739548 281977106744 0x38092e0} 0 {13927360205612739548 281977106744 0x38092e0} map[] false}) %!s(*framework.QueuedPodInfo=&{0xc00024e540 {13927360205671620050 282035987245 0x38092e0} 0 {13927360205671620050 282035987245 0x38092e0} map[] false})]="queue len:" %!s(int=5)="(MISSING)"
I1030 05:06:17.626795       1 scheduling_queue.go:1203] "[Bing]About to try and schedule pod" pod="default/job-train-imgclassfication13-cuda-epoch130"
I1030 05:06:17.626824       1 schedule_one.go:81] "Attempting to schedule pod" pod="default/job-train-imgclassfication13-cuda-epoch130"
I1030 05:06:17.827546       1 schedule_one.go:83] "sleep when attempting to schedule pod to increase job intervals..."
I1030 05:06:17.827976       1 schedule_one.go:875] "Unable to schedule pod; no fit; waiting" pod="default/job-train-imgclassfication13-cuda-epoch130" err="0/1 nodes are available: 1 Insufficient aliyun.com/gpu-mem. preemption: 0/1 nodes are available: 1 Insufficient aliyun.com/gpu-mem.."
I1030 05:06:17.828088       1 schedule_one.go:951] "Updating pod condition" pod="default/job-train-imgclassfication13-cuda-epoch130" conditionType=PodScheduled conditionStatus=False conditionReason="Unschedulable"
I1030 05:06:17.828131       1 schedule_one.go:63] "starting scheduling for next pod..."
I1030 05:06:18.029238       1 scheduling_queue.go:661] "[Bing]Pop called on the scheduling queue. current queue includes pods: " [%!s(*framework.QueuedPodInfo=&{0xc00032f260 {13927360205485099519 281849466714 0x38092e0} 0 {13927360205485099519 281849466714 0x38092e0} map[] false}) %!s(*framework.QueuedPodInfo=&{0xc00024e3f0 {13927360205612739548 281977106744 0x38092e0} 0 {13927360205612739548 281977106744 0x38092e0} map[] false}) %!s(*framework.QueuedPodInfo=&{0xc00024e540 {13927360205671620050 282035987245 0x38092e0} 0 {13927360205671620050 282035987245 0x38092e0} map[] false}) %!s(*framework.QueuedPodInfo=&{0xc00024e0e0 {13927360205549087692 281913454909 0x38092e0} 0 {13927360205549087692 281913454909 0x38092e0} map[] false})]="queue len:" %!s(int=4)="(MISSING)"
I1030 05:06:18.029296       1 scheduling_queue.go:1203] "[Bing]About to try and schedule pod" pod="default/job-train-imgclassfication17-cuda-epoch170"
I1030 05:06:18.029313       1 schedule_one.go:81] "Attempting to schedule pod" pod="default/job-train-imgclassfication17-cuda-epoch170"
I1030 05:06:18.230067       1 schedule_one.go:83] "sleep when attempting to schedule pod to increase job intervals..."
I1030 05:06:18.230570       1 schedule_one.go:875] "Unable to schedule pod; no fit; waiting" pod="default/job-train-imgclassfication17-cuda-epoch170" err="0/1 nodes are available: 1 Insufficient aliyun.com/gpu-mem. preemption: 0/1 nodes are available: 1 Insufficient aliyun.com/gpu-mem.."
I1030 05:06:18.230697       1 schedule_one.go:951] "Updating pod condition" pod="default/job-train-imgclassfication17-cuda-epoch170" conditionType=PodScheduled conditionStatus=False conditionReason="Unschedulable"
I1030 05:06:18.242247       1 schedule_one.go:63] "starting scheduling for next pod..."
I1030 05:06:18.442383       1 scheduling_queue.go:661] "[Bing]Pop called on the scheduling queue. current queue includes pods: " [%!s(*framework.QueuedPodInfo=&{0xc00024e0e0 {13927360205549087692 281913454909 0x38092e0} 0 {13927360205549087692 281913454909 0x38092e0} map[] false}) %!s(*framework.QueuedPodInfo=&{0xc00024e3f0 {13927360205612739548 281977106744 0x38092e0} 0 {13927360205612739548 281977106744 0x38092e0} map[] false}) %!s(*framework.QueuedPodInfo=&{0xc00024e540 {13927360205671620050 282035987245 0x38092e0} 0 {13927360205671620050 282035987245 0x38092e0} map[] false})]="queue len:" %!s(int=3)="(MISSING)"
I1030 05:06:18.442451       1 scheduling_queue.go:1203] "[Bing]About to try and schedule pod" pod="default/job-train-imgclassfication18-cuda-epoch180"
I1030 05:06:18.442472       1 schedule_one.go:81] "Attempting to schedule pod" pod="default/job-train-imgclassfication18-cuda-epoch180"
I1030 05:06:18.643785       1 schedule_one.go:83] "sleep when attempting to schedule pod to increase job intervals..."
I1030 05:06:18.644369       1 schedule_one.go:875] "Unable to schedule pod; no fit; waiting" pod="default/job-train-imgclassfication18-cuda-epoch180" err="0/1 nodes are available: 1 Insufficient aliyun.com/gpu-mem. preemption: 0/1 nodes are available: 1 Insufficient aliyun.com/gpu-mem.."
I1030 05:06:18.644536       1 schedule_one.go:951] "Updating pod condition" pod="default/job-train-imgclassfication18-cuda-epoch180" conditionType=PodScheduled conditionStatus=False conditionReason="Unschedulable"
I1030 05:06:18.661405       1 schedule_one.go:63] "starting scheduling for next pod..."
I1030 05:06:18.862418       1 scheduling_queue.go:661] "[Bing]Pop called on the scheduling queue. current queue includes pods: " [%!s(*framework.QueuedPodInfo=&{0xc00085c460 {13927360211084261602 287079919680 0x38092e0} 1 {13927360205431737232 281796104442 0x38092e0} map[NodeResourcesFit:{}] false}) %!s(*framework.QueuedPodInfo=&{0xc00024e3f0 {13927360205612739548 281977106744 0x38092e0} 0 {13927360205612739548 281977106744 0x38092e0} map[] false}) %!s(*framework.QueuedPodInfo=&{0xc00024e540 {13927360205671620050 282035987245 0x38092e0} 0 {13927360205671620050 282035987245 0x38092e0} map[] false})]="queue len:" %!s(int=3)="(MISSING)"
I1030 05:06:18.862483       1 scheduling_queue.go:1203] "[Bing]About to try and schedule pod" pod="default/job-train-imgclassfication16-cuda-epoch160"
I1030 05:06:18.862514       1 schedule_one.go:81] "Attempting to schedule pod" pod="default/job-train-imgclassfication16-cuda-epoch160"
I1030 05:06:19.062921       1 schedule_one.go:83] "sleep when attempting to schedule pod to increase job intervals..."
I1030 05:06:19.063455       1 schedule_one.go:875] "Unable to schedule pod; no fit; waiting" pod="default/job-train-imgclassfication16-cuda-epoch160" err="0/1 nodes are available: 1 Insufficient aliyun.com/gpu-mem. preemption: 0/1 nodes are available: 1 Insufficient aliyun.com/gpu-mem.."
I1030 05:06:19.063597       1 schedule_one.go:951] "Updating pod condition" pod="default/job-train-imgclassfication16-cuda-epoch160" conditionType=PodScheduled conditionStatus=False conditionReason="Unschedulable"
I1030 05:06:19.063647       1 schedule_one.go:63] "starting scheduling for next pod..."
I1030 05:06:19.263815       1 scheduling_queue.go:661] "[Bing]Pop called on the scheduling queue. current queue includes pods: " [%!s(*framework.QueuedPodInfo=&{0xc00024e3f0 {13927360205612739548 281977106744 0x38092e0} 0 {13927360205612739548 281977106744 0x38092e0} map[] false}) %!s(*framework.QueuedPodInfo=&{0xc00024e540 {13927360205671620050 282035987245 0x38092e0} 0 {13927360205671620050 282035987245 0x38092e0} map[] false})]="queue len:" %!s(int=2)="(MISSING)"
I1030 05:06:19.263879       1 scheduling_queue.go:1203] "[Bing]About to try and schedule pod" pod="default/job-train-imgclassfication19-cuda-epoch190"
I1030 05:06:19.263903       1 schedule_one.go:81] "Attempting to schedule pod" pod="default/job-train-imgclassfication19-cuda-epoch190"
I1030 05:06:19.464343       1 schedule_one.go:83] "sleep when attempting to schedule pod to increase job intervals..."
I1030 05:06:19.465062       1 schedule_one.go:875] "Unable to schedule pod; no fit; waiting" pod="default/job-train-imgclassfication19-cuda-epoch190" err="0/1 nodes are available: 1 Insufficient aliyun.com/gpu-mem. preemption: 0/1 nodes are available: 1 Insufficient aliyun.com/gpu-mem.."
I1030 05:06:19.465226       1 schedule_one.go:951] "Updating pod condition" pod="default/job-train-imgclassfication19-cuda-epoch190" conditionType=PodScheduled conditionStatus=False conditionReason="Unschedulable"
I1030 05:06:19.482053       1 schedule_one.go:63] "starting scheduling for next pod..."
I1030 05:06:19.682554       1 scheduling_queue.go:661] "[Bing]Pop called on the scheduling queue. current queue includes pods: " [%!s(*framework.QueuedPodInfo=&{0xc00024e540 {13927360205671620050 282035987245 0x38092e0} 0 {13927360205671620050 282035987245 0x38092e0} map[] false})]="queue len:" %!s(int=1)="(MISSING)"
I1030 05:06:19.682619       1 scheduling_queue.go:1203] "[Bing]About to try and schedule pod" pod="default/job-train-imgclassfication20-cuda-epoch200"
I1030 05:06:19.682642       1 schedule_one.go:81] "Attempting to schedule pod" pod="default/job-train-imgclassfication20-cuda-epoch200"
I1030 05:06:19.883233       1 schedule_one.go:83] "sleep when attempting to schedule pod to increase job intervals..."
I1030 05:06:19.883731       1 schedule_one.go:875] "Unable to schedule pod; no fit; waiting" pod="default/job-train-imgclassfication20-cuda-epoch200" err="0/1 nodes are available: 1 Insufficient aliyun.com/gpu-mem. preemption: 0/1 nodes are available: 1 Insufficient aliyun.com/gpu-mem.."
I1030 05:06:19.883862       1 schedule_one.go:951] "Updating pod condition" pod="default/job-train-imgclassfication20-cuda-epoch200" conditionType=PodScheduled conditionStatus=False conditionReason="Unschedulable"
I1030 05:06:19.897689       1 schedule_one.go:63] "starting scheduling for next pod..."
I1030 05:06:20.098020       1 scheduling_queue.go:661] "[Bing]Pop called on the scheduling queue. current queue includes pods: " []="queue len:" %!s(int=0)="(MISSING)"
I1030 05:06:21.632660       1 httplog.go:132] "HTTP" verb="GET" URI="/healthz" latency="144.996µs" userAgent="kube-probe/1.27" audit-ID="" srcIP="127.0.0.1:53658" resp=200
I1030 05:06:31.632877       1 httplog.go:132] "HTTP" verb="GET" URI="/healthz" latency="98.843µs" userAgent="kube-probe/1.27" audit-ID="" srcIP="127.0.0.1:59998" resp=200
I1030 05:06:41.628400       1 httplog.go:132] "HTTP" verb="GET" URI="/healthz" latency="116.671µs" userAgent="kube-probe/1.27" audit-ID="" srcIP="127.0.0.1:58452" resp=200
I1030 05:06:51.629276       1 httplog.go:132] "HTTP" verb="GET" URI="/healthz" latency="84.599µs" userAgent="kube-probe/1.27" audit-ID="" srcIP="127.0.0.1:42208" resp=200
I1030 05:06:56.150826       1 reflector.go:788] vendor/k8s.io/client-go/informers/factory.go:150: Watch close - *v1.ReplicaSet total 10 items received
I1030 05:07:00.150079       1 reflector.go:788] vendor/k8s.io/client-go/informers/factory.go:150: Watch close - *v1.PersistentVolumeClaim total 6 items received
I1030 05:07:01.627648       1 httplog.go:132] "HTTP" verb="GET" URI="/healthz" latency="106.666µs" userAgent="kube-probe/1.27" audit-ID="" srcIP="127.0.0.1:55478" resp=200
I1030 05:07:06.149496       1 reflector.go:788] pkg/server/dynamiccertificates/configmap_cafile_content.go:206: Watch close - *v1.ConfigMap total 6 items received
I1030 05:07:11.628572       1 httplog.go:132] "HTTP" verb="GET" URI="/healthz" latency="125.158µs" userAgent="kube-probe/1.27" audit-ID="" srcIP="127.0.0.1:50066" resp=200
I1030 05:07:12.148625       1 reflector.go:788] vendor/k8s.io/client-go/informers/factory.go:150: Watch close - *v1.CSIDriver total 7 items received
I1030 05:07:16.149350       1 reflector.go:788] vendor/k8s.io/client-go/informers/factory.go:150: Watch close - *v1.Service total 6 items received
I1030 05:07:21.630769       1 httplog.go:132] "HTTP" verb="GET" URI="/healthz" latency="87.308µs" userAgent="kube-probe/1.27" audit-ID="" srcIP="127.0.0.1:47820" resp=200
I1030 05:07:31.628863       1 httplog.go:132] "HTTP" verb="GET" URI="/healthz" latency="85.365µs" userAgent="kube-probe/1.27" audit-ID="" srcIP="127.0.0.1:54668" resp=200
I1030 05:07:41.630398       1 httplog.go:132] "HTTP" verb="GET" URI="/healthz" latency="89.294µs" userAgent="kube-probe/1.27" audit-ID="" srcIP="127.0.0.1:52744" resp=200
I1030 05:07:51.629625       1 httplog.go:132] "HTTP" verb="GET" URI="/healthz" latency="88.55µs" userAgent="kube-probe/1.27" audit-ID="" srcIP="127.0.0.1:38866" resp=200
I1030 05:08:01.628437       1 httplog.go:132] "HTTP" verb="GET" URI="/healthz" latency="160.958µs" userAgent="kube-probe/1.27" audit-ID="" srcIP="127.0.0.1:50272" resp=200
I1030 05:08:11.630300       1 httplog.go:132] "HTTP" verb="GET" URI="/healthz" latency="103.414µs" userAgent="kube-probe/1.27" audit-ID="" srcIP="127.0.0.1:46860" resp=200
I1030 05:08:19.149146       1 reflector.go:788] pkg/server/dynamiccertificates/configmap_cafile_content.go:206: Watch close - *v1.ConfigMap total 7 items received
I1030 05:08:21.627182       1 httplog.go:132] "HTTP" verb="GET" URI="/healthz" latency="64.844µs" userAgent="kube-probe/1.27" audit-ID="" srcIP="127.0.0.1:59460" resp=200
I1030 05:08:31.631607       1 httplog.go:132] "HTTP" verb="GET" URI="/healthz" latency="98.769µs" userAgent="kube-probe/1.27" audit-ID="" srcIP="127.0.0.1:40454" resp=200
I1030 05:08:41.628858       1 httplog.go:132] "HTTP" verb="GET" URI="/healthz" latency="140.424µs" userAgent="kube-probe/1.27" audit-ID="" srcIP="127.0.0.1:53836" resp=200
I1030 05:08:51.629135       1 httplog.go:132] "HTTP" verb="GET" URI="/healthz" latency="88.783µs" userAgent="kube-probe/1.27" audit-ID="" srcIP="127.0.0.1:49126" resp=200
I1030 05:09:01.149677       1 reflector.go:788] pkg/authentication/request/headerrequest/requestheader_controller.go:172: Watch close - *v1.ConfigMap total 8 items received
I1030 05:09:01.629291       1 httplog.go:132] "HTTP" verb="GET" URI="/healthz" latency="102.138µs" userAgent="kube-probe/1.27" audit-ID="" srcIP="127.0.0.1:33452" resp=200
I1030 05:09:04.150227       1 reflector.go:788] vendor/k8s.io/client-go/informers/factory.go:150: Watch close - *v1.CSINode total 9 items received
I1030 05:09:11.629109       1 httplog.go:132] "HTTP" verb="GET" URI="/healthz" latency="72.397µs" userAgent="kube-probe/1.27" audit-ID="" srcIP="127.0.0.1:59366" resp=200
I1030 05:09:16.152445       1 reflector.go:788] vendor/k8s.io/client-go/informers/factory.go:150: Watch close - *v1.Pod total 153 items received
I1030 05:09:18.149665       1 reflector.go:788] vendor/k8s.io/client-go/informers/factory.go:150: Watch close - *v1.StatefulSet total 8 items received
I1030 05:09:21.631418       1 httplog.go:132] "HTTP" verb="GET" URI="/healthz" latency="104.059µs" userAgent="kube-probe/1.27" audit-ID="" srcIP="127.0.0.1:36916" resp=200
I1030 05:09:31.629190       1 httplog.go:132] "HTTP" verb="GET" URI="/healthz" latency="99.643µs" userAgent="kube-probe/1.27" audit-ID="" srcIP="127.0.0.1:40662" resp=200
I1030 05:09:41.632081       1 httplog.go:132] "HTTP" verb="GET" URI="/healthz" latency="80.524µs" userAgent="kube-probe/1.27" audit-ID="" srcIP="127.0.0.1:36104" resp=200
I1030 05:09:43.779999       1 eventhandlers.go:206] "Update event for scheduled pod" pod="default/job-train-imgclassfication1-cuda-epoch10"
I1030 05:09:45.026706       1 eventhandlers.go:231] "Delete event for scheduled pod" pod="default/job-train-imgclassfication1-cuda-epoch10"
I1030 05:09:45.026911       1 scheduling_queue.go:1203] "[Bing]About to try and schedule pod" pod="default/job-train-imgclassfication13-cuda-epoch130"
I1030 05:09:45.026929       1 schedule_one.go:81] "Attempting to schedule pod" pod="default/job-train-imgclassfication13-cuda-epoch130"
I1030 05:09:45.150956       1 reflector.go:788] vendor/k8s.io/client-go/informers/factory.go:150: Watch close - *v1.CSIStorageCapacity total 9 items received
I1030 05:09:45.227013       1 schedule_one.go:83] "sleep when attempting to schedule pod to increase job intervals..."
I1030 05:09:45.231597       1 schedule_one.go:63] "starting scheduling for next pod..."
I1030 05:09:45.359238       1 eventhandlers.go:186] "Add event for scheduled pod" pod="default/job-train-imgclassfication13-cuda-epoch130"
I1030 05:09:45.359242       1 eventhandlers.go:161] "Delete event for unscheduled pod" pod="default/job-train-imgclassfication13-cuda-epoch130"
I1030 05:09:45.363049       1 schedule_one.go:260] "Successfully bound pod to node" pod="default/job-train-imgclassfication13-cuda-epoch130" node="node2" evaluatedNodes=1 feasibleNodes=1
I1030 05:09:45.403800       1 eventhandlers.go:206] "Update event for scheduled pod" pod="default/job-train-imgclassfication13-cuda-epoch130"
I1030 05:09:45.432676       1 scheduling_queue.go:661] "[Bing]Pop called on the scheduling queue. current queue includes pods: " [%!s(*framework.QueuedPodInfo=&{0xc0001592d0 {13927360211976141497 287898057751 0x38092e0} 1 {13927360205485099519 281849466714 0x38092e0} map[NodeResourcesFit:{}] false}) %!s(*framework.QueuedPodInfo=&{0xc0003a2230 {13927360212882777822 288730952249 0x38092e0} 2 {13927360205431737232 281796104442 0x38092e0} map[NodeResourcesFit:{}] false}) %!s(*framework.QueuedPodInfo=&{0xc0008b6150 {13927360213284386581 289132561024 0x38092e0} 1 {13927360205612739548 281977106744 0x38092e0} map[NodeResourcesFit:{}] false}) %!s(*framework.QueuedPodInfo=&{0xc000261960 {13927360210184094747 286253494638 0x38092e0} 1 {13927360205206297686 281644406701 0x38092e0} map[NodeResourcesFit:{}] false}) %!s(*framework.QueuedPodInfo=&{0xc000159a40 {13927360212389963134 288311879386 0x38092e0} 1 {13927360205549087692 281913454909 0x38092e0} map[NodeResourcesFit:{}] false}) %!s(*framework.QueuedPodInfo=&{0xc000acee00 {13927360213703050932 289551225357 0x38092e0} 1 {13927360205671620050 282035987245 0x38092e0} map[NodeResourcesFit:{}] false}) %!s(*framework.QueuedPodInfo=&{0xc000ace230 {13927360210673243097 286668901164 0x38092e0} 1 {13927360205363368956 281727736145 0x38092e0} map[NodeResourcesFit:{}] false})]="queue len:" %!s(int=7)="(MISSING)"
I1030 05:09:45.432738       1 scheduling_queue.go:1203] "[Bing]About to try and schedule pod" pod="default/job-train-imgclassfication14-cuda-epoch140"
I1030 05:09:45.432764       1 schedule_one.go:81] "Attempting to schedule pod" pod="default/job-train-imgclassfication14-cuda-epoch140"
I1030 05:09:45.464983       1 eventhandlers.go:206] "Update event for scheduled pod" pod="default/job-train-imgclassfication13-cuda-epoch130"
I1030 05:09:45.633340       1 schedule_one.go:83] "sleep when attempting to schedule pod to increase job intervals..."
I1030 05:09:45.633709       1 schedule_one.go:875] "Unable to schedule pod; no fit; waiting" pod="default/job-train-imgclassfication14-cuda-epoch140" err="0/1 nodes are available: 1 Insufficient aliyun.com/gpu-mem. preemption: 0/1 nodes are available: 1 Insufficient aliyun.com/gpu-mem.."
I1030 05:09:45.633804       1 schedule_one.go:951] "Updating pod condition" pod="default/job-train-imgclassfication14-cuda-epoch140" conditionType=PodScheduled conditionStatus=False conditionReason="Unschedulable"
I1030 05:09:45.633836       1 schedule_one.go:63] "starting scheduling for next pod..."
I1030 05:09:45.834044       1 scheduling_queue.go:661] "[Bing]Pop called on the scheduling queue. current queue includes pods: " [%!s(*framework.QueuedPodInfo=&{0xc000ace230 {13927360210673243097 286668901164 0x38092e0} 1 {13927360205363368956 281727736145 0x38092e0} map[NodeResourcesFit:{}] false}) %!s(*framework.QueuedPodInfo=&{0xc000acee00 {13927360213703050932 289551225357 0x38092e0} 1 {13927360205671620050 282035987245 0x38092e0} map[NodeResourcesFit:{}] false}) %!s(*framework.QueuedPodInfo=&{0xc0003a2230 {13927360212882777822 288730952249 0x38092e0} 2 {13927360205431737232 281796104442 0x38092e0} map[NodeResourcesFit:{}] false}) %!s(*framework.QueuedPodInfo=&{0xc0001592d0 {13927360211976141497 287898057751 0x38092e0} 1 {13927360205485099519 281849466714 0x38092e0} map[NodeResourcesFit:{}] false}) %!s(*framework.QueuedPodInfo=&{0xc0008b6150 {13927360213284386581 289132561024 0x38092e0} 1 {13927360205612739548 281977106744 0x38092e0} map[NodeResourcesFit:{}] false}) %!s(*framework.QueuedPodInfo=&{0xc000159a40 {13927360212389963134 288311879386 0x38092e0} 1 {13927360205549087692 281913454909 0x38092e0} map[NodeResourcesFit:{}] false})]="queue len:" %!s(int=6)="(MISSING)"
I1030 05:09:45.834076       1 scheduling_queue.go:1203] "[Bing]About to try and schedule pod" pod="default/job-train-imgclassfication15-cuda-epoch150"
I1030 05:09:45.834093       1 schedule_one.go:81] "Attempting to schedule pod" pod="default/job-train-imgclassfication15-cuda-epoch150"
I1030 05:09:46.034204       1 schedule_one.go:83] "sleep when attempting to schedule pod to increase job intervals..."
I1030 05:09:46.034528       1 schedule_one.go:875] "Unable to schedule pod; no fit; waiting" pod="default/job-train-imgclassfication15-cuda-epoch150" err="0/1 nodes are available: 1 Insufficient aliyun.com/gpu-mem. preemption: 0/1 nodes are available: 1 Insufficient aliyun.com/gpu-mem.."
I1030 05:09:46.034613       1 schedule_one.go:951] "Updating pod condition" pod="default/job-train-imgclassfication15-cuda-epoch150" conditionType=PodScheduled conditionStatus=False conditionReason="Unschedulable"
I1030 05:09:46.034654       1 schedule_one.go:63] "starting scheduling for next pod..."
I1030 05:09:46.235851       1 scheduling_queue.go:661] "[Bing]Pop called on the scheduling queue. current queue includes pods: " [%!s(*framework.QueuedPodInfo=&{0xc000acee00 {13927360213703050932 289551225357 0x38092e0} 1 {13927360205671620050 282035987245 0x38092e0} map[NodeResourcesFit:{}] false}) %!s(*framework.QueuedPodInfo=&{0xc0001592d0 {13927360211976141497 287898057751 0x38092e0} 1 {13927360205485099519 281849466714 0x38092e0} map[NodeResourcesFit:{}] false}) %!s(*framework.QueuedPodInfo=&{0xc0003a2230 {13927360212882777822 288730952249 0x38092e0} 2 {13927360205431737232 281796104442 0x38092e0} map[NodeResourcesFit:{}] false}) %!s(*framework.QueuedPodInfo=&{0xc0008b6150 {13927360213284386581 289132561024 0x38092e0} 1 {13927360205612739548 281977106744 0x38092e0} map[NodeResourcesFit:{}] false}) %!s(*framework.QueuedPodInfo=&{0xc000159a40 {13927360212389963134 288311879386 0x38092e0} 1 {13927360205549087692 281913454909 0x38092e0} map[NodeResourcesFit:{}] false})]="queue len:" %!s(int=5)="(MISSING)"
I1030 05:09:46.235919       1 scheduling_queue.go:1203] "[Bing]About to try and schedule pod" pod="default/job-train-imgclassfication16-cuda-epoch160"
I1030 05:09:46.235958       1 schedule_one.go:81] "Attempting to schedule pod" pod="default/job-train-imgclassfication16-cuda-epoch160"
I1030 05:09:46.436386       1 schedule_one.go:83] "sleep when attempting to schedule pod to increase job intervals..."
I1030 05:09:46.436668       1 schedule_one.go:875] "Unable to schedule pod; no fit; waiting" pod="default/job-train-imgclassfication16-cuda-epoch160" err="0/1 nodes are available: 1 Insufficient aliyun.com/gpu-mem. preemption: 0/1 nodes are available: 1 Insufficient aliyun.com/gpu-mem.."
I1030 05:09:46.436739       1 schedule_one.go:951] "Updating pod condition" pod="default/job-train-imgclassfication16-cuda-epoch160" conditionType=PodScheduled conditionStatus=False conditionReason="Unschedulable"
I1030 05:09:46.436772       1 schedule_one.go:63] "starting scheduling for next pod..."
I1030 05:09:46.637907       1 scheduling_queue.go:661] "[Bing]Pop called on the scheduling queue. current queue includes pods: " [%!s(*framework.QueuedPodInfo=&{0xc000159a40 {13927360212389963134 288311879386 0x38092e0} 1 {13927360205549087692 281913454909 0x38092e0} map[NodeResourcesFit:{}] false}) %!s(*framework.QueuedPodInfo=&{0xc000acee00 {13927360213703050932 289551225357 0x38092e0} 1 {13927360205671620050 282035987245 0x38092e0} map[NodeResourcesFit:{}] false}) %!s(*framework.QueuedPodInfo=&{0xc0001592d0 {13927360211976141497 287898057751 0x38092e0} 1 {13927360205485099519 281849466714 0x38092e0} map[NodeResourcesFit:{}] false}) %!s(*framework.QueuedPodInfo=&{0xc0008b6150 {13927360213284386581 289132561024 0x38092e0} 1 {13927360205612739548 281977106744 0x38092e0} map[NodeResourcesFit:{}] false})]="queue len:" %!s(int=4)="(MISSING)"
I1030 05:09:46.637963       1 scheduling_queue.go:1203] "[Bing]About to try and schedule pod" pod="default/job-train-imgclassfication17-cuda-epoch170"
I1030 05:09:46.637994       1 schedule_one.go:81] "Attempting to schedule pod" pod="default/job-train-imgclassfication17-cuda-epoch170"
I1030 05:09:46.788285       1 eventhandlers.go:206] "Update event for scheduled pod" pod="default/job-train-imgclassfication13-cuda-epoch130"
I1030 05:09:46.838499       1 schedule_one.go:83] "sleep when attempting to schedule pod to increase job intervals..."
I1030 05:09:46.838949       1 schedule_one.go:875] "Unable to schedule pod; no fit; waiting" pod="default/job-train-imgclassfication17-cuda-epoch170" err="0/1 nodes are available: 1 Insufficient aliyun.com/gpu-mem. preemption: 0/1 nodes are available: 1 Insufficient aliyun.com/gpu-mem.."
I1030 05:09:46.839063       1 schedule_one.go:951] "Updating pod condition" pod="default/job-train-imgclassfication17-cuda-epoch170" conditionType=PodScheduled conditionStatus=False conditionReason="Unschedulable"
I1030 05:09:46.839102       1 schedule_one.go:63] "starting scheduling for next pod..."
I1030 05:09:47.039301       1 scheduling_queue.go:661] "[Bing]Pop called on the scheduling queue. current queue includes pods: " [%!s(*framework.QueuedPodInfo=&{0xc0008b6150 {13927360213284386581 289132561024 0x38092e0} 1 {13927360205612739548 281977106744 0x38092e0} map[NodeResourcesFit:{}] false}) %!s(*framework.QueuedPodInfo=&{0xc000159a40 {13927360212389963134 288311879386 0x38092e0} 1 {13927360205549087692 281913454909 0x38092e0} map[NodeResourcesFit:{}] false}) %!s(*framework.QueuedPodInfo=&{0xc000acee00 {13927360213703050932 289551225357 0x38092e0} 1 {13927360205671620050 282035987245 0x38092e0} map[NodeResourcesFit:{}] false})]="queue len:" %!s(int=3)="(MISSING)"
I1030 05:09:47.039338       1 scheduling_queue.go:1203] "[Bing]About to try and schedule pod" pod="default/job-train-imgclassfication18-cuda-epoch180"
I1030 05:09:47.039361       1 schedule_one.go:81] "Attempting to schedule pod" pod="default/job-train-imgclassfication18-cuda-epoch180"
I1030 05:09:47.150655       1 reflector.go:788] vendor/k8s.io/client-go/informers/factory.go:150: Watch close - *v1.StorageClass total 10 items received
I1030 05:09:47.239744       1 schedule_one.go:83] "sleep when attempting to schedule pod to increase job intervals..."
I1030 05:09:47.240013       1 schedule_one.go:875] "Unable to schedule pod; no fit; waiting" pod="default/job-train-imgclassfication18-cuda-epoch180" err="0/1 nodes are available: 1 Insufficient aliyun.com/gpu-mem. preemption: 0/1 nodes are available: 1 Insufficient aliyun.com/gpu-mem.."
I1030 05:09:47.240079       1 schedule_one.go:951] "Updating pod condition" pod="default/job-train-imgclassfication18-cuda-epoch180" conditionType=PodScheduled conditionStatus=False conditionReason="Unschedulable"
I1030 05:09:47.240102       1 schedule_one.go:63] "starting scheduling for next pod..."
I1030 05:09:47.441085       1 scheduling_queue.go:661] "[Bing]Pop called on the scheduling queue. current queue includes pods: " [%!s(*framework.QueuedPodInfo=&{0xc000acee00 {13927360213703050932 289551225357 0x38092e0} 1 {13927360205671620050 282035987245 0x38092e0} map[NodeResourcesFit:{}] false}) %!s(*framework.QueuedPodInfo=&{0xc0008b6150 {13927360213284386581 289132561024 0x38092e0} 1 {13927360205612739548 281977106744 0x38092e0} map[NodeResourcesFit:{}] false})]="queue len:" %!s(int=2)="(MISSING)"
I1030 05:09:47.441136       1 scheduling_queue.go:1203] "[Bing]About to try and schedule pod" pod="default/job-train-imgclassfication19-cuda-epoch190"
I1030 05:09:47.441160       1 schedule_one.go:81] "Attempting to schedule pod" pod="default/job-train-imgclassfication19-cuda-epoch190"
I1030 05:09:47.641681       1 schedule_one.go:83] "sleep when attempting to schedule pod to increase job intervals..."
I1030 05:09:47.642030       1 schedule_one.go:875] "Unable to schedule pod; no fit; waiting" pod="default/job-train-imgclassfication19-cuda-epoch190" err="0/1 nodes are available: 1 Insufficient aliyun.com/gpu-mem. preemption: 0/1 nodes are available: 1 Insufficient aliyun.com/gpu-mem.."
I1030 05:09:47.642123       1 schedule_one.go:951] "Updating pod condition" pod="default/job-train-imgclassfication19-cuda-epoch190" conditionType=PodScheduled conditionStatus=False conditionReason="Unschedulable"
I1030 05:09:47.642162       1 schedule_one.go:63] "starting scheduling for next pod..."
I1030 05:09:47.843190       1 scheduling_queue.go:661] "[Bing]Pop called on the scheduling queue. current queue includes pods: " [%!s(*framework.QueuedPodInfo=&{0xc000acee00 {13927360213703050932 289551225357 0x38092e0} 1 {13927360205671620050 282035987245 0x38092e0} map[NodeResourcesFit:{}] false})]="queue len:" %!s(int=1)="(MISSING)"
I1030 05:09:47.843243       1 scheduling_queue.go:1203] "[Bing]About to try and schedule pod" pod="default/job-train-imgclassfication20-cuda-epoch200"
I1030 05:09:47.843271       1 schedule_one.go:81] "Attempting to schedule pod" pod="default/job-train-imgclassfication20-cuda-epoch200"
I1030 05:09:48.043646       1 schedule_one.go:83] "sleep when attempting to schedule pod to increase job intervals..."
I1030 05:09:48.044005       1 schedule_one.go:875] "Unable to schedule pod; no fit; waiting" pod="default/job-train-imgclassfication20-cuda-epoch200" err="0/1 nodes are available: 1 Insufficient aliyun.com/gpu-mem. preemption: 0/1 nodes are available: 1 Insufficient aliyun.com/gpu-mem.."
I1030 05:09:48.044120       1 schedule_one.go:951] "Updating pod condition" pod="default/job-train-imgclassfication20-cuda-epoch200" conditionType=PodScheduled conditionStatus=False conditionReason="Unschedulable"
I1030 05:09:48.044147       1 schedule_one.go:63] "starting scheduling for next pod..."
I1030 05:09:48.245098       1 scheduling_queue.go:661] "[Bing]Pop called on the scheduling queue. current queue includes pods: " []="queue len:" %!s(int=0)="(MISSING)"
I1030 05:09:48.572373       1 scheduling_queue.go:1203] "[Bing]About to try and schedule pod" pod="default/job-train-imgclassfication14-cuda-epoch140"
I1030 05:09:48.572409       1 schedule_one.go:81] "Attempting to schedule pod" pod="default/job-train-imgclassfication14-cuda-epoch140"
I1030 05:09:48.772843       1 schedule_one.go:83] "sleep when attempting to schedule pod to increase job intervals..."
I1030 05:09:48.773216       1 schedule_one.go:875] "Unable to schedule pod; no fit; waiting" pod="default/job-train-imgclassfication14-cuda-epoch140" err="0/1 nodes are available: 1 Insufficient aliyun.com/gpu-mem. preemption: 0/1 nodes are available: 1 Insufficient aliyun.com/gpu-mem.."
I1030 05:09:48.773323       1 schedule_one.go:951] "Updating pod condition" pod="default/job-train-imgclassfication14-cuda-epoch140" conditionType=PodScheduled conditionStatus=False conditionReason="Unschedulable"
I1030 05:09:48.773359       1 schedule_one.go:63] "starting scheduling for next pod..."
I1030 05:09:48.973490       1 scheduling_queue.go:661] "[Bing]Pop called on the scheduling queue. current queue includes pods: " []="queue len:" %!s(int=0)="(MISSING)"
I1030 05:09:49.572995       1 scheduling_queue.go:1203] "[Bing]About to try and schedule pod" pod="default/job-train-imgclassfication17-cuda-epoch170"
I1030 05:09:49.573025       1 schedule_one.go:81] "Attempting to schedule pod" pod="default/job-train-imgclassfication17-cuda-epoch170"
I1030 05:09:49.773874       1 schedule_one.go:83] "sleep when attempting to schedule pod to increase job intervals..."
I1030 05:09:49.774461       1 schedule_one.go:875] "Unable to schedule pod; no fit; waiting" pod="default/job-train-imgclassfication17-cuda-epoch170" err="0/1 nodes are available: 1 Insufficient aliyun.com/gpu-mem. preemption: 0/1 nodes are available: 1 Insufficient aliyun.com/gpu-mem.."
I1030 05:09:49.774612       1 schedule_one.go:951] "Updating pod condition" pod="default/job-train-imgclassfication17-cuda-epoch170" conditionType=PodScheduled conditionStatus=False conditionReason="Unschedulable"
I1030 05:09:49.774665       1 schedule_one.go:63] "starting scheduling for next pod..."
I1030 05:09:49.974745       1 scheduling_queue.go:661] "[Bing]Pop called on the scheduling queue. current queue includes pods: " []="queue len:" %!s(int=0)="(MISSING)"
I1030 05:09:51.633521       1 httplog.go:132] "HTTP" verb="GET" URI="/healthz" latency="93.885µs" userAgent="kube-probe/1.27" audit-ID="" srcIP="127.0.0.1:36574" resp=200
I1030 05:09:58.149792       1 reflector.go:788] vendor/k8s.io/client-go/informers/factory.go:150: Watch close - *v1.ReplicationController total 10 items received
I1030 05:10:01.630371       1 httplog.go:132] "HTTP" verb="GET" URI="/healthz" latency="89.232µs" userAgent="kube-probe/1.27" audit-ID="" srcIP="127.0.0.1:33902" resp=200
I1030 05:10:09.149319       1 reflector.go:788] vendor/k8s.io/client-go/informers/factory.go:150: Watch close - *v1.Namespace total 9 items received
I1030 05:10:09.779869       1 eventhandlers.go:118] "Add event for unscheduled pod" pod="default/job-train-online-cuda-epoch3"
I1030 05:10:09.779934       1 scheduling_queue.go:1203] "[Bing]About to try and schedule pod" pod="default/job-train-online-cuda-epoch3"
I1030 05:10:09.779941       1 schedule_one.go:81] "Attempting to schedule pod" pod="default/job-train-online-cuda-epoch3"
I1030 05:10:09.828356       1 eventhandlers.go:118] "Add event for unscheduled pod" pod="default/job-train-online5-cuda-epoch40"
I1030 05:10:09.872847       1 eventhandlers.go:118] "Add event for unscheduled pod" pod="default/job-train-online-cuda-epoch6"
I1030 05:10:09.980989       1 schedule_one.go:83] "sleep when attempting to schedule pod to increase job intervals..."
I1030 05:10:10.001065       1 eventhandlers.go:206] "Update event for scheduled pod" pod="default/job-train-imgclassfication13-cuda-epoch130"
I1030 05:10:10.012918       1 preemption.go:381] "Preemptor Pod preempted victim Pod" preemptor="default/job-train-online-cuda-epoch3" victim="default/job-train-imgclassfication13-cuda-epoch130" node="node2"
I1030 05:10:10.013008       1 schedule_one.go:875] "Unable to schedule pod; no fit; waiting" pod="default/job-train-online-cuda-epoch3" err="0/1 nodes are available: 1 Insufficient aliyun.com/gpu-mem."
I1030 05:10:10.013033       1 eventhandlers.go:206] "Update event for scheduled pod" pod="default/job-train-imgclassfication13-cuda-epoch130"
I1030 05:10:10.013067       1 schedule_one.go:951] "Updating pod condition" pod="default/job-train-online-cuda-epoch3" conditionType=PodScheduled conditionStatus=False conditionReason="Unschedulable"
I1030 05:10:10.024563       1 schedule_one.go:63] "starting scheduling for next pod..."
I1030 05:10:10.037249       1 eventhandlers.go:206] "Update event for scheduled pod" pod="default/job-train-imgclassfication13-cuda-epoch130"
I1030 05:10:10.224694       1 scheduling_queue.go:661] "[Bing]Pop called on the scheduling queue. current queue includes pods: " [%!s(*framework.QueuedPodInfo=&{0xc00025d9d0 {13927360460608244678 519495799570 0x38092e0} 0 {13927360460608244678 519495799570 0x38092e0} map[] false}) %!s(*framework.QueuedPodInfo=&{0xc00025dab0 {13927360460652733271 519540288151 0x38092e0} 0 {13927360460652733271 519540288151 0x38092e0} map[] false})]="queue len:" %!s(int=2)="(MISSING)"
I1030 05:10:10.224734       1 scheduling_queue.go:1203] "[Bing]About to try and schedule pod" pod="default/job-train-online-cuda-epoch6"
I1030 05:10:10.224750       1 schedule_one.go:81] "Attempting to schedule pod" pod="default/job-train-online-cuda-epoch6"
I1030 05:10:10.425832       1 schedule_one.go:83] "sleep when attempting to schedule pod to increase job intervals..."
I1030 05:10:10.441820       1 eventhandlers.go:206] "Update event for scheduled pod" pod="default/job-train-imgclassfication13-cuda-epoch130"
I1030 05:10:10.448226       1 preemption.go:381] "Preemptor Pod preempted victim Pod" preemptor="default/job-train-online-cuda-epoch6" victim="default/job-train-imgclassfication13-cuda-epoch130" node="node2"
I1030 05:10:10.448566       1 eventhandlers.go:206] "Update event for scheduled pod" pod="default/job-train-imgclassfication12-cuda-epoch120"
I1030 05:10:10.460842       1 eventhandlers.go:206] "Update event for scheduled pod" pod="default/job-train-imgclassfication12-cuda-epoch120"
I1030 05:10:10.460871       1 preemption.go:381] "Preemptor Pod preempted victim Pod" preemptor="default/job-train-online-cuda-epoch6" victim="default/job-train-imgclassfication12-cuda-epoch120" node="node2"
I1030 05:10:10.461069       1 schedule_one.go:875] "Unable to schedule pod; no fit; waiting" pod="default/job-train-online-cuda-epoch6" err="0/1 nodes are available: 1 Insufficient aliyun.com/gpu-mem."
I1030 05:10:10.461172       1 schedule_one.go:951] "Updating pod condition" pod="default/job-train-online-cuda-epoch6" conditionType=PodScheduled conditionStatus=False conditionReason="Unschedulable"
I1030 05:10:10.477130       1 schedule_one.go:63] "starting scheduling for next pod..."
I1030 05:10:10.485872       1 eventhandlers.go:206] "Update event for scheduled pod" pod="default/job-train-imgclassfication12-cuda-epoch120"
I1030 05:10:10.677244       1 scheduling_queue.go:661] "[Bing]Pop called on the scheduling queue. current queue includes pods: " [%!s(*framework.QueuedPodInfo=&{0xc00025d9d0 {13927360460608244678 519495799570 0x38092e0} 0 {13927360460608244678 519495799570 0x38092e0} map[] false})]="queue len:" %!s(int=1)="(MISSING)"
I1030 05:10:10.677283       1 scheduling_queue.go:1203] "[Bing]About to try and schedule pod" pod="default/job-train-online5-cuda-epoch40"
I1030 05:10:10.677294       1 schedule_one.go:81] "Attempting to schedule pod" pod="default/job-train-online5-cuda-epoch40"
I1030 05:10:10.877623       1 schedule_one.go:83] "sleep when attempting to schedule pod to increase job intervals..."
I1030 05:10:10.892574       1 eventhandlers.go:206] "Update event for scheduled pod" pod="default/job-train-imgclassfication11-cuda-epoch110"
I1030 05:10:10.895106       1 preemption.go:381] "Preemptor Pod preempted victim Pod" preemptor="default/job-train-online5-cuda-epoch40" victim="default/job-train-imgclassfication13-cuda-epoch130" node="node2"
I1030 05:10:10.895587       1 preemption.go:381] "Preemptor Pod preempted victim Pod" preemptor="default/job-train-online5-cuda-epoch40" victim="default/job-train-imgclassfication12-cuda-epoch120" node="node2"
I1030 05:10:10.903230       1 preemption.go:381] "Preemptor Pod preempted victim Pod" preemptor="default/job-train-online5-cuda-epoch40" victim="default/job-train-imgclassfication11-cuda-epoch110" node="node2"
I1030 05:10:10.903342       1 eventhandlers.go:206] "Update event for scheduled pod" pod="default/job-train-imgclassfication11-cuda-epoch110"
I1030 05:10:10.903461       1 schedule_one.go:875] "Unable to schedule pod; no fit; waiting" pod="default/job-train-online5-cuda-epoch40" err="0/1 nodes are available: 1 Insufficient aliyun.com/gpu-mem."
I1030 05:10:10.903566       1 schedule_one.go:951] "Updating pod condition" pod="default/job-train-online5-cuda-epoch40" conditionType=PodScheduled conditionStatus=False conditionReason="Unschedulable"
I1030 05:10:10.914724       1 schedule_one.go:63] "starting scheduling for next pod..."
I1030 05:10:10.930126       1 eventhandlers.go:206] "Update event for scheduled pod" pod="default/job-train-imgclassfication11-cuda-epoch110"
I1030 05:10:11.115430       1 scheduling_queue.go:661] "[Bing]Pop called on the scheduling queue. current queue includes pods: " []="queue len:" %!s(int=0)="(MISSING)"
I1030 05:10:11.585992       1 scheduling_queue.go:1203] "[Bing]About to try and schedule pod" pod="default/job-train-online-cuda-epoch3"
I1030 05:10:11.586049       1 schedule_one.go:81] "Attempting to schedule pod" pod="default/job-train-online-cuda-epoch3"
I1030 05:10:11.629773       1 httplog.go:132] "HTTP" verb="GET" URI="/healthz" latency="84.56µs" userAgent="kube-probe/1.27" audit-ID="" srcIP="127.0.0.1:42084" resp=200
I1030 05:10:11.786779       1 schedule_one.go:83] "sleep when attempting to schedule pod to increase job intervals..."
I1030 05:10:11.787177       1 schedule_one.go:875] "Unable to schedule pod; no fit; waiting" pod="default/job-train-online-cuda-epoch3" err="0/1 nodes are available: 1 Insufficient aliyun.com/gpu-mem. preemption: not eligible due to a terminating pod on the nominated node.."
I1030 05:10:11.787250       1 schedule_one.go:951] "Updating pod condition" pod="default/job-train-online-cuda-epoch3" conditionType=PodScheduled conditionStatus=False conditionReason="Unschedulable"
I1030 05:10:11.799909       1 schedule_one.go:63] "starting scheduling for next pod..."
I1030 05:10:12.000446       1 scheduling_queue.go:661] "[Bing]Pop called on the scheduling queue. current queue includes pods: " [%!s(*framework.QueuedPodInfo=&{0xc000170a10 {13927360461314723125 520128536221 0x38092e0} 1 {13927360460652733271 519540288151 0x38092e0} map[NodeResourcesFit:{}] false})]="queue len:" %!s(int=1)="(MISSING)"
I1030 05:10:12.000513       1 scheduling_queue.go:1203] "[Bing]About to try and schedule pod" pod="default/job-train-online-cuda-epoch6"
I1030 05:10:12.000559       1 schedule_one.go:81] "Attempting to schedule pod" pod="default/job-train-online-cuda-epoch6"
I1030 05:10:12.200755       1 schedule_one.go:83] "sleep when attempting to schedule pod to increase job intervals..."
I1030 05:10:12.201352       1 schedule_one.go:875] "Unable to schedule pod; no fit; waiting" pod="default/job-train-online-cuda-epoch6" err="0/1 nodes are available: 1 Insufficient aliyun.com/gpu-mem. preemption: not eligible due to a terminating pod on the nominated node.."
I1030 05:10:12.201454       1 schedule_one.go:951] "Updating pod condition" pod="default/job-train-online-cuda-epoch6" conditionType=PodScheduled conditionStatus=False conditionReason="Unschedulable"
I1030 05:10:12.213570       1 schedule_one.go:63] "starting scheduling for next pod..."
I1030 05:10:12.413999       1 scheduling_queue.go:661] "[Bing]Pop called on the scheduling queue. current queue includes pods: " []="queue len:" %!s(int=0)="(MISSING)"
I1030 05:10:12.586270       1 scheduling_queue.go:1203] "[Bing]About to try and schedule pod" pod="default/job-train-online5-cuda-epoch40"
I1030 05:10:12.586336       1 schedule_one.go:81] "Attempting to schedule pod" pod="default/job-train-online5-cuda-epoch40"
I1030 05:10:12.786717       1 schedule_one.go:83] "sleep when attempting to schedule pod to increase job intervals..."
I1030 05:10:12.787205       1 schedule_one.go:875] "Unable to schedule pod; no fit; waiting" pod="default/job-train-online5-cuda-epoch40" err="0/1 nodes are available: 1 Insufficient aliyun.com/gpu-mem. preemption: not eligible due to a terminating pod on the nominated node.."
I1030 05:10:12.787288       1 schedule_one.go:951] "Updating pod condition" pod="default/job-train-online5-cuda-epoch40" conditionType=PodScheduled conditionStatus=False conditionReason="Unschedulable"
I1030 05:10:12.799514       1 schedule_one.go:63] "starting scheduling for next pod..."
I1030 05:10:12.999909       1 scheduling_queue.go:661] "[Bing]Pop called on the scheduling queue. current queue includes pods: " []="queue len:" %!s(int=0)="(MISSING)"
I1030 05:10:21.632359       1 httplog.go:132] "HTTP" verb="GET" URI="/healthz" latency="129.795µs" userAgent="kube-probe/1.27" audit-ID="" srcIP="127.0.0.1:42358" resp=200
I1030 05:10:31.632093       1 httplog.go:132] "HTTP" verb="GET" URI="/healthz" latency="91.736µs" userAgent="kube-probe/1.27" audit-ID="" srcIP="127.0.0.1:50672" resp=200
I1030 05:10:40.573104       1 eventhandlers.go:231] "Delete event for scheduled pod" pod="default/job-train-imgclassfication13-cuda-epoch130"
I1030 05:10:40.573273       1 scheduling_queue.go:1203] "[Bing]About to try and schedule pod" pod="default/job-train-online-cuda-epoch3"
I1030 05:10:40.573292       1 schedule_one.go:81] "Attempting to schedule pod" pod="default/job-train-online-cuda-epoch3"
I1030 05:10:40.773866       1 schedule_one.go:83] "sleep when attempting to schedule pod to increase job intervals..."
I1030 05:10:40.776450       1 schedule_one.go:63] "starting scheduling for next pod..."
I1030 05:10:40.898796       1 eventhandlers.go:161] "Delete event for unscheduled pod" pod="default/job-train-online-cuda-epoch3"
I1030 05:10:40.898821       1 eventhandlers.go:186] "Add event for scheduled pod" pod="default/job-train-online-cuda-epoch3"
I1030 05:10:40.900099       1 schedule_one.go:260] "Successfully bound pod to node" pod="default/job-train-online-cuda-epoch3" node="node2" evaluatedNodes=1 feasibleNodes=1
I1030 05:10:40.951161       1 eventhandlers.go:206] "Update event for scheduled pod" pod="default/job-train-online-cuda-epoch3"
I1030 05:10:40.976917       1 scheduling_queue.go:661] "[Bing]Pop called on the scheduling queue. current queue includes pods: " [%!s(*framework.QueuedPodInfo=&{0xc00025d0a0 {13927360438004566026 498440699209 0x38092e0} 3 {13927360205206297686 281644406701 0x38092e0} map[NodeResourcesFit:{}] false}) %!s(*framework.QueuedPodInfo=&{0xc000260ee0 {13927360463202488304 521868817755 0x38092e0} 2 {13927360460652733271 519540288151 0x38092e0} map[NodeResourcesFit:{}] false}) %!s(*framework.QueuedPodInfo=&{0xc0002213b0 {13927360439079571147 499441962568 0x38092e0} 3 {13927360205485099519 281849466714 0x38092e0} map[NodeResourcesFit:{}] false}) %!s(*framework.QueuedPodInfo=&{0xc00025c230 {13927360435118377797 495701994641 0x38092e0} 2 {13927360205363368956 281727736145 0x38092e0} map[NodeResourcesFit:{}] false}) %!s(*framework.QueuedPodInfo=&{0xc00021f7a0 {13927360436799625037 497309500047 0x38092e0} 2 {13927360205612739548 281977106744 0x38092e0} map[NodeResourcesFit:{}] false}) %!s(*framework.QueuedPodInfo=&{0xc00085c460 {13927360463788334793 522454664205 0x38092e0} 2 {13927360460608244678 519495799570 0x38092e0} map[NodeResourcesFit:{}] false}) %!s(*framework.QueuedPodInfo=&{0xc000220700 {13927360437275369036 497711502219 0x38092e0} 2 {13927360205671620050 282035987245 0x38092e0} map[NodeResourcesFit:{}] false}) %!s(*framework.QueuedPodInfo=&{0xc0002f3260 {13927360436397597002 496907472008 0x38092e0} 2 {13927360205549087692 281913454909 0x38092e0} map[NodeResourcesFit:{}] false}) %!s(*framework.QueuedPodInfo=&{0xc00025c930 {13927360435520511689 496104128520 0x38092e0} 3 {13927360205431737232 281796104442 0x38092e0} map[NodeResourcesFit:{}] false})]="queue len:" %!s(int=9)="(MISSING)"
I1030 05:10:40.976953       1 scheduling_queue.go:1203] "[Bing]About to try and schedule pod" pod="default/job-train-online-cuda-epoch6"
I1030 05:10:40.976972       1 schedule_one.go:81] "Attempting to schedule pod" pod="default/job-train-online-cuda-epoch6"
I1030 05:10:41.005526       1 eventhandlers.go:231] "Delete event for scheduled pod" pod="default/job-train-imgclassfication12-cuda-epoch120"
I1030 05:10:41.021508       1 eventhandlers.go:206] "Update event for scheduled pod" pod="default/job-train-online-cuda-epoch3"
I1030 05:10:41.177978       1 schedule_one.go:83] "sleep when attempting to schedule pod to increase job intervals..."
I1030 05:10:41.183067       1 schedule_one.go:63] "starting scheduling for next pod..."
I1030 05:10:41.302687       1 eventhandlers.go:161] "Delete event for unscheduled pod" pod="default/job-train-online-cuda-epoch6"
I1030 05:10:41.302745       1 eventhandlers.go:186] "Add event for scheduled pod" pod="default/job-train-online-cuda-epoch6"
I1030 05:10:41.304921       1 schedule_one.go:260] "Successfully bound pod to node" pod="default/job-train-online-cuda-epoch6" node="node2" evaluatedNodes=1 feasibleNodes=1
I1030 05:10:41.362324       1 eventhandlers.go:206] "Update event for scheduled pod" pod="default/job-train-online-cuda-epoch6"
I1030 05:10:41.384276       1 scheduling_queue.go:661] "[Bing]Pop called on the scheduling queue. current queue includes pods: " [%!s(*framework.QueuedPodInfo=&{0xc00021f7a0 {13927360436799625037 497309500047 0x38092e0} 2 {13927360205612739548 281977106744 0x38092e0} map[NodeResourcesFit:{}] false}) %!s(*framework.QueuedPodInfo=&{0xc00085c460 {13927360463788334793 522454664205 0x38092e0} 2 {13927360460608244678 519495799570 0x38092e0} map[NodeResourcesFit:{}] false}) %!s(*framework.QueuedPodInfo=&{0xc00025c230 {13927360435118377797 495701994641 0x38092e0} 2 {13927360205363368956 281727736145 0x38092e0} map[NodeResourcesFit:{}] false}) %!s(*framework.QueuedPodInfo=&{0xc000220700 {13927360437275369036 497711502219 0x38092e0} 2 {13927360205671620050 282035987245 0x38092e0} map[NodeResourcesFit:{}] false}) %!s(*framework.QueuedPodInfo=&{0xc00025c930 {13927360435520511689 496104128520 0x38092e0} 3 {13927360205431737232 281796104442 0x38092e0} map[NodeResourcesFit:{}] false}) %!s(*framework.QueuedPodInfo=&{0xc0002f3260 {13927360436397597002 496907472008 0x38092e0} 2 {13927360205549087692 281913454909 0x38092e0} map[NodeResourcesFit:{}] false}) %!s(*framework.QueuedPodInfo=&{0xc0002213b0 {13927360439079571147 499441962568 0x38092e0} 3 {13927360205485099519 281849466714 0x38092e0} map[NodeResourcesFit:{}] false}) %!s(*framework.QueuedPodInfo=&{0xc00025d0a0 {13927360438004566026 498440699209 0x38092e0} 3 {13927360205206297686 281644406701 0x38092e0} map[NodeResourcesFit:{}] false})]="queue len:" %!s(int=8)="(MISSING)"
I1030 05:10:41.384352       1 scheduling_queue.go:1203] "[Bing]About to try and schedule pod" pod="default/job-train-online5-cuda-epoch40"
I1030 05:10:41.384379       1 schedule_one.go:81] "Attempting to schedule pod" pod="default/job-train-online5-cuda-epoch40"
I1030 05:10:41.409910       1 eventhandlers.go:231] "Delete event for scheduled pod" pod="default/job-train-imgclassfication11-cuda-epoch110"
I1030 05:10:41.424480       1 eventhandlers.go:206] "Update event for scheduled pod" pod="default/job-train-online-cuda-epoch6"
I1030 05:10:41.584523       1 schedule_one.go:83] "sleep when attempting to schedule pod to increase job intervals..."
I1030 05:10:41.589877       1 schedule_one.go:63] "starting scheduling for next pod..."
I1030 05:10:41.627194       1 httplog.go:132] "HTTP" verb="GET" URI="/healthz" latency="64.452µs" userAgent="kube-probe/1.27" audit-ID="" srcIP="127.0.0.1:57868" resp=200
I1030 05:10:41.708822       1 eventhandlers.go:161] "Delete event for unscheduled pod" pod="default/job-train-online5-cuda-epoch40"
I1030 05:10:41.708828       1 eventhandlers.go:186] "Add event for scheduled pod" pod="default/job-train-online5-cuda-epoch40"
I1030 05:10:41.710623       1 schedule_one.go:260] "Successfully bound pod to node" pod="default/job-train-online5-cuda-epoch40" node="node2" evaluatedNodes=1 feasibleNodes=1
I1030 05:10:41.755159       1 eventhandlers.go:206] "Update event for scheduled pod" pod="default/job-train-online5-cuda-epoch40"
I1030 05:10:41.790161       1 scheduling_queue.go:661] "[Bing]Pop called on the scheduling queue. current queue includes pods: " [%!s(*framework.QueuedPodInfo=&{0xc00025c230 {13927360435118377797 495701994641 0x38092e0} 2 {13927360205363368956 281727736145 0x38092e0} map[NodeResourcesFit:{}] false}) %!s(*framework.QueuedPodInfo=&{0xc00021f7a0 {13927360436799625037 497309500047 0x38092e0} 2 {13927360205612739548 281977106744 0x38092e0} map[NodeResourcesFit:{}] false}) %!s(*framework.QueuedPodInfo=&{0xc000220700 {13927360437275369036 497711502219 0x38092e0} 2 {13927360205671620050 282035987245 0x38092e0} map[NodeResourcesFit:{}] false}) %!s(*framework.QueuedPodInfo=&{0xc00025c930 {13927360435520511689 496104128520 0x38092e0} 3 {13927360205431737232 281796104442 0x38092e0} map[NodeResourcesFit:{}] false}) %!s(*framework.QueuedPodInfo=&{0xc0002f3260 {13927360436397597002 496907472008 0x38092e0} 2 {13927360205549087692 281913454909 0x38092e0} map[NodeResourcesFit:{}] false}) %!s(*framework.QueuedPodInfo=&{0xc0002213b0 {13927360439079571147 499441962568 0x38092e0} 3 {13927360205485099519 281849466714 0x38092e0} map[NodeResourcesFit:{}] false}) %!s(*framework.QueuedPodInfo=&{0xc00025d0a0 {13927360438004566026 498440699209 0x38092e0} 3 {13927360205206297686 281644406701 0x38092e0} map[NodeResourcesFit:{}] false})]="queue len:" %!s(int=7)="(MISSING)"
I1030 05:10:41.790200       1 scheduling_queue.go:1203] "[Bing]About to try and schedule pod" pod="default/job-train-imgclassfication14-cuda-epoch140"
I1030 05:10:41.790223       1 schedule_one.go:81] "Attempting to schedule pod" pod="default/job-train-imgclassfication14-cuda-epoch140"
I1030 05:10:41.816430       1 eventhandlers.go:206] "Update event for scheduled pod" pod="default/job-train-online5-cuda-epoch40"
I1030 05:10:41.990442       1 schedule_one.go:83] "sleep when attempting to schedule pod to increase job intervals..."
I1030 05:10:41.990753       1 schedule_one.go:875] "Unable to schedule pod; no fit; waiting" pod="default/job-train-imgclassfication14-cuda-epoch140" err="0/1 nodes are available: 1 Insufficient aliyun.com/gpu-mem. preemption: 0/1 nodes are available: 1 Insufficient aliyun.com/gpu-mem.."
I1030 05:10:41.990833       1 schedule_one.go:951] "Updating pod condition" pod="default/job-train-imgclassfication14-cuda-epoch140" conditionType=PodScheduled conditionStatus=False conditionReason="Unschedulable"
I1030 05:10:41.990858       1 schedule_one.go:63] "starting scheduling for next pod..."
I1030 05:10:42.191636       1 scheduling_queue.go:661] "[Bing]Pop called on the scheduling queue. current queue includes pods: " [%!s(*framework.QueuedPodInfo=&{0xc000220700 {13927360437275369036 497711502219 0x38092e0} 2 {13927360205671620050 282035987245 0x38092e0} map[NodeResourcesFit:{}] false}) %!s(*framework.QueuedPodInfo=&{0xc00025c930 {13927360435520511689 496104128520 0x38092e0} 3 {13927360205431737232 281796104442 0x38092e0} map[NodeResourcesFit:{}] false}) %!s(*framework.QueuedPodInfo=&{0xc0002f3260 {13927360436397597002 496907472008 0x38092e0} 2 {13927360205549087692 281913454909 0x38092e0} map[NodeResourcesFit:{}] false}) %!s(*framework.QueuedPodInfo=&{0xc0002213b0 {13927360439079571147 499441962568 0x38092e0} 3 {13927360205485099519 281849466714 0x38092e0} map[NodeResourcesFit:{}] false}) %!s(*framework.QueuedPodInfo=&{0xc00025c230 {13927360435118377797 495701994641 0x38092e0} 2 {13927360205363368956 281727736145 0x38092e0} map[NodeResourcesFit:{}] false}) %!s(*framework.QueuedPodInfo=&{0xc00021f7a0 {13927360436799625037 497309500047 0x38092e0} 2 {13927360205612739548 281977106744 0x38092e0} map[NodeResourcesFit:{}] false})]="queue len:" %!s(int=6)="(MISSING)"
I1030 05:10:42.191705       1 scheduling_queue.go:1203] "[Bing]About to try and schedule pod" pod="default/job-train-imgclassfication15-cuda-epoch150"
I1030 05:10:42.191740       1 schedule_one.go:81] "Attempting to schedule pod" pod="default/job-train-imgclassfication15-cuda-epoch150"
I1030 05:10:42.392222       1 schedule_one.go:83] "sleep when attempting to schedule pod to increase job intervals..."
I1030 05:10:42.392616       1 schedule_one.go:875] "Unable to schedule pod; no fit; waiting" pod="default/job-train-imgclassfication15-cuda-epoch150" err="0/1 nodes are available: 1 Insufficient aliyun.com/gpu-mem. preemption: 0/1 nodes are available: 1 Insufficient aliyun.com/gpu-mem.."
I1030 05:10:42.392709       1 schedule_one.go:951] "Updating pod condition" pod="default/job-train-imgclassfication15-cuda-epoch150" conditionType=PodScheduled conditionStatus=False conditionReason="Unschedulable"
I1030 05:10:42.392740       1 schedule_one.go:63] "starting scheduling for next pod..."
I1030 05:10:42.593316       1 scheduling_queue.go:661] "[Bing]Pop called on the scheduling queue. current queue includes pods: " [%!s(*framework.QueuedPodInfo=&{0xc000220700 {13927360437275369036 497711502219 0x38092e0} 2 {13927360205671620050 282035987245 0x38092e0} map[NodeResourcesFit:{}] false}) %!s(*framework.QueuedPodInfo=&{0xc00025c930 {13927360435520511689 496104128520 0x38092e0} 3 {13927360205431737232 281796104442 0x38092e0} map[NodeResourcesFit:{}] false}) %!s(*framework.QueuedPodInfo=&{0xc0002f3260 {13927360436397597002 496907472008 0x38092e0} 2 {13927360205549087692 281913454909 0x38092e0} map[NodeResourcesFit:{}] false}) %!s(*framework.QueuedPodInfo=&{0xc0002213b0 {13927360439079571147 499441962568 0x38092e0} 3 {13927360205485099519 281849466714 0x38092e0} map[NodeResourcesFit:{}] false}) %!s(*framework.QueuedPodInfo=&{0xc00021f7a0 {13927360436799625037 497309500047 0x38092e0} 2 {13927360205612739548 281977106744 0x38092e0} map[NodeResourcesFit:{}] false})]="queue len:" %!s(int=5)="(MISSING)"
I1030 05:10:42.593369       1 scheduling_queue.go:1203] "[Bing]About to try and schedule pod" pod="default/job-train-imgclassfication16-cuda-epoch160"
I1030 05:10:42.593403       1 schedule_one.go:81] "Attempting to schedule pod" pod="default/job-train-imgclassfication16-cuda-epoch160"
I1030 05:10:42.793835       1 schedule_one.go:83] "sleep when attempting to schedule pod to increase job intervals..."
I1030 05:10:42.794265       1 schedule_one.go:875] "Unable to schedule pod; no fit; waiting" pod="default/job-train-imgclassfication16-cuda-epoch160" err="0/1 nodes are available: 1 Insufficient aliyun.com/gpu-mem. preemption: 0/1 nodes are available: 1 Insufficient aliyun.com/gpu-mem.."
I1030 05:10:42.794381       1 schedule_one.go:951] "Updating pod condition" pod="default/job-train-imgclassfication16-cuda-epoch160" conditionType=PodScheduled conditionStatus=False conditionReason="Unschedulable"
I1030 05:10:42.794430       1 schedule_one.go:63] "starting scheduling for next pod..."
I1030 05:10:42.954795       1 eventhandlers.go:206] "Update event for scheduled pod" pod="default/job-train-online-cuda-epoch3"
I1030 05:10:42.974037       1 eventhandlers.go:206] "Update event for scheduled pod" pod="default/job-train-online-cuda-epoch6"
I1030 05:10:42.990259       1 eventhandlers.go:206] "Update event for scheduled pod" pod="default/job-train-online5-cuda-epoch40"
I1030 05:10:42.995274       1 scheduling_queue.go:661] "[Bing]Pop called on the scheduling queue. current queue includes pods: " [%!s(*framework.QueuedPodInfo=&{0xc0002213b0 {13927360439079571147 499441962568 0x38092e0} 3 {13927360205485099519 281849466714 0x38092e0} map[NodeResourcesFit:{}] false}) %!s(*framework.QueuedPodInfo=&{0xc00021f7a0 {13927360436799625037 497309500047 0x38092e0} 2 {13927360205612739548 281977106744 0x38092e0} map[NodeResourcesFit:{}] false}) %!s(*framework.QueuedPodInfo=&{0xc000220700 {13927360437275369036 497711502219 0x38092e0} 2 {13927360205671620050 282035987245 0x38092e0} map[NodeResourcesFit:{}] false}) %!s(*framework.QueuedPodInfo=&{0xc0002f3260 {13927360436397597002 496907472008 0x38092e0} 2 {13927360205549087692 281913454909 0x38092e0} map[NodeResourcesFit:{}] false})]="queue len:" %!s(int=4)="(MISSING)"
I1030 05:10:42.995314       1 scheduling_queue.go:1203] "[Bing]About to try and schedule pod" pod="default/job-train-imgclassfication17-cuda-epoch170"
I1030 05:10:42.995335       1 schedule_one.go:81] "Attempting to schedule pod" pod="default/job-train-imgclassfication17-cuda-epoch170"
I1030 05:10:43.196291       1 schedule_one.go:83] "sleep when attempting to schedule pod to increase job intervals..."
I1030 05:10:43.196659       1 schedule_one.go:875] "Unable to schedule pod; no fit; waiting" pod="default/job-train-imgclassfication17-cuda-epoch170" err="0/1 nodes are available: 1 Insufficient aliyun.com/gpu-mem. preemption: 0/1 nodes are available: 1 Insufficient aliyun.com/gpu-mem.."
I1030 05:10:43.196752       1 schedule_one.go:951] "Updating pod condition" pod="default/job-train-imgclassfication17-cuda-epoch170" conditionType=PodScheduled conditionStatus=False conditionReason="Unschedulable"
I1030 05:10:43.196788       1 schedule_one.go:63] "starting scheduling for next pod..."
I1030 05:10:43.397488       1 scheduling_queue.go:661] "[Bing]Pop called on the scheduling queue. current queue includes pods: " [%!s(*framework.QueuedPodInfo=&{0xc00021f7a0 {13927360436799625037 497309500047 0x38092e0} 2 {13927360205612739548 281977106744 0x38092e0} map[NodeResourcesFit:{}] false}) %!s(*framework.QueuedPodInfo=&{0xc000220700 {13927360437275369036 497711502219 0x38092e0} 2 {13927360205671620050 282035987245 0x38092e0} map[NodeResourcesFit:{}] false}) %!s(*framework.QueuedPodInfo=&{0xc0002f3260 {13927360436397597002 496907472008 0x38092e0} 2 {13927360205549087692 281913454909 0x38092e0} map[NodeResourcesFit:{}] false})]="queue len:" %!s(int=3)="(MISSING)"
I1030 05:10:43.397564       1 scheduling_queue.go:1203] "[Bing]About to try and schedule pod" pod="default/job-train-imgclassfication18-cuda-epoch180"
I1030 05:10:43.397605       1 schedule_one.go:81] "Attempting to schedule pod" pod="default/job-train-imgclassfication18-cuda-epoch180"
I1030 05:10:43.598520       1 schedule_one.go:83] "sleep when attempting to schedule pod to increase job intervals..."
I1030 05:10:43.598916       1 schedule_one.go:875] "Unable to schedule pod; no fit; waiting" pod="default/job-train-imgclassfication18-cuda-epoch180" err="0/1 nodes are available: 1 Insufficient aliyun.com/gpu-mem. preemption: 0/1 nodes are available: 1 Insufficient aliyun.com/gpu-mem.."
I1030 05:10:43.599058       1 schedule_one.go:951] "Updating pod condition" pod="default/job-train-imgclassfication18-cuda-epoch180" conditionType=PodScheduled conditionStatus=False conditionReason="Unschedulable"
I1030 05:10:43.599100       1 schedule_one.go:63] "starting scheduling for next pod..."
I1030 05:10:43.799188       1 scheduling_queue.go:661] "[Bing]Pop called on the scheduling queue. current queue includes pods: " [%!s(*framework.QueuedPodInfo=&{0xc000220700 {13927360437275369036 497711502219 0x38092e0} 2 {13927360205671620050 282035987245 0x38092e0} map[NodeResourcesFit:{}] false}) %!s(*framework.QueuedPodInfo=&{0xc00021f7a0 {13927360436799625037 497309500047 0x38092e0} 2 {13927360205612739548 281977106744 0x38092e0} map[NodeResourcesFit:{}] false})]="queue len:" %!s(int=2)="(MISSING)"
I1030 05:10:43.799228       1 scheduling_queue.go:1203] "[Bing]About to try and schedule pod" pod="default/job-train-imgclassfication19-cuda-epoch190"
I1030 05:10:43.799260       1 schedule_one.go:81] "Attempting to schedule pod" pod="default/job-train-imgclassfication19-cuda-epoch190"
I1030 05:10:44.000268       1 schedule_one.go:83] "sleep when attempting to schedule pod to increase job intervals..."
I1030 05:10:44.000730       1 schedule_one.go:875] "Unable to schedule pod; no fit; waiting" pod="default/job-train-imgclassfication19-cuda-epoch190" err="0/1 nodes are available: 1 Insufficient aliyun.com/gpu-mem. preemption: 0/1 nodes are available: 1 Insufficient aliyun.com/gpu-mem.."
I1030 05:10:44.000830       1 schedule_one.go:951] "Updating pod condition" pod="default/job-train-imgclassfication19-cuda-epoch190" conditionType=PodScheduled conditionStatus=False conditionReason="Unschedulable"
I1030 05:10:44.000867       1 schedule_one.go:63] "starting scheduling for next pod..."
I1030 05:10:44.201687       1 scheduling_queue.go:661] "[Bing]Pop called on the scheduling queue. current queue includes pods: " [%!s(*framework.QueuedPodInfo=&{0xc000220700 {13927360437275369036 497711502219 0x38092e0} 2 {13927360205671620050 282035987245 0x38092e0} map[NodeResourcesFit:{}] false})]="queue len:" %!s(int=1)="(MISSING)"
I1030 05:10:44.201738       1 scheduling_queue.go:1203] "[Bing]About to try and schedule pod" pod="default/job-train-imgclassfication20-cuda-epoch200"
I1030 05:10:44.201764       1 schedule_one.go:81] "Attempting to schedule pod" pod="default/job-train-imgclassfication20-cuda-epoch200"
I1030 05:10:44.402137       1 schedule_one.go:83] "sleep when attempting to schedule pod to increase job intervals..."
I1030 05:10:44.402574       1 schedule_one.go:875] "Unable to schedule pod; no fit; waiting" pod="default/job-train-imgclassfication20-cuda-epoch200" err="0/1 nodes are available: 1 Insufficient aliyun.com/gpu-mem. preemption: 0/1 nodes are available: 1 Insufficient aliyun.com/gpu-mem.."
I1030 05:10:44.402692       1 schedule_one.go:951] "Updating pod condition" pod="default/job-train-imgclassfication20-cuda-epoch200" conditionType=PodScheduled conditionStatus=False conditionReason="Unschedulable"
I1030 05:10:44.402737       1 schedule_one.go:63] "starting scheduling for next pod..."
I1030 05:10:44.603825       1 scheduling_queue.go:661] "[Bing]Pop called on the scheduling queue. current queue includes pods: " []="queue len:" %!s(int=0)="(MISSING)"
I1030 05:10:50.607788       1 scheduling_queue.go:1203] "[Bing]About to try and schedule pod" pod="default/job-train-imgclassfication14-cuda-epoch140"
I1030 05:10:50.607824       1 schedule_one.go:81] "Attempting to schedule pod" pod="default/job-train-imgclassfication14-cuda-epoch140"
I1030 05:10:50.808277       1 schedule_one.go:83] "sleep when attempting to schedule pod to increase job intervals..."
I1030 05:10:50.808756       1 schedule_one.go:875] "Unable to schedule pod; no fit; waiting" pod="default/job-train-imgclassfication14-cuda-epoch140" err="0/1 nodes are available: 1 Insufficient aliyun.com/gpu-mem. preemption: 0/1 nodes are available: 1 Insufficient aliyun.com/gpu-mem.."
I1030 05:10:50.808890       1 schedule_one.go:951] "Updating pod condition" pod="default/job-train-imgclassfication14-cuda-epoch140" conditionType=PodScheduled conditionStatus=False conditionReason="Unschedulable"
I1030 05:10:50.808954       1 schedule_one.go:63] "starting scheduling for next pod..."
I1030 05:10:51.009344       1 scheduling_queue.go:661] "[Bing]Pop called on the scheduling queue. current queue includes pods: " []="queue len:" %!s(int=0)="(MISSING)"
I1030 05:10:51.629016       1 httplog.go:132] "HTTP" verb="GET" URI="/healthz" latency="77.975µs" userAgent="kube-probe/1.27" audit-ID="" srcIP="127.0.0.1:56654" resp=200
I1030 05:11:01.149019       1 reflector.go:788] vendor/k8s.io/client-go/informers/factory.go:150: Watch close - *v1.PodDisruptionBudget total 11 items received
I1030 05:11:01.632150       1 httplog.go:132] "HTTP" verb="GET" URI="/healthz" latency="83.219µs" userAgent="kube-probe/1.27" audit-ID="" srcIP="127.0.0.1:46120" resp=200
I1030 05:11:09.150794       1 reflector.go:788] vendor/k8s.io/client-go/informers/factory.go:150: Watch close - *v1.PersistentVolume total 10 items received
I1030 05:11:11.633000       1 httplog.go:132] "HTTP" verb="GET" URI="/healthz" latency="78.413µs" userAgent="kube-probe/1.27" audit-ID="" srcIP="127.0.0.1:57338" resp=200
I1030 05:11:21.630980       1 httplog.go:132] "HTTP" verb="GET" URI="/healthz" latency="89.285µs" userAgent="kube-probe/1.27" audit-ID="" srcIP="127.0.0.1:60270" resp=200
I1030 05:11:30.152647       1 reflector.go:788] vendor/k8s.io/client-go/informers/factory.go:150: Watch close - *v1.Node total 16 items received
I1030 05:11:31.631941       1 httplog.go:132] "HTTP" verb="GET" URI="/healthz" latency="107.93µs" userAgent="kube-probe/1.27" audit-ID="" srcIP="127.0.0.1:36944" resp=200
I1030 05:11:41.630334       1 httplog.go:132] "HTTP" verb="GET" URI="/healthz" latency="83.315µs" userAgent="kube-probe/1.27" audit-ID="" srcIP="127.0.0.1:59026" resp=200
I1030 05:11:51.630500       1 httplog.go:132] "HTTP" verb="GET" URI="/healthz" latency="100.693µs" userAgent="kube-probe/1.27" audit-ID="" srcIP="127.0.0.1:50060" resp=200
I1030 05:12:01.632888       1 httplog.go:132] "HTTP" verb="GET" URI="/healthz" latency="82.533µs" userAgent="kube-probe/1.27" audit-ID="" srcIP="127.0.0.1:35674" resp=200
I1030 05:12:06.183915       1 eventhandlers.go:206] "Update event for scheduled pod" pod="default/job-train-online-cuda-epoch3"
I1030 05:12:07.426215       1 eventhandlers.go:231] "Delete event for scheduled pod" pod="default/job-train-online-cuda-epoch3"
I1030 05:12:07.426368       1 scheduling_queue.go:1203] "[Bing]About to try and schedule pod" pod="default/job-train-imgclassfication14-cuda-epoch140"
I1030 05:12:07.426390       1 schedule_one.go:81] "Attempting to schedule pod" pod="default/job-train-imgclassfication14-cuda-epoch140"
I1030 05:12:07.626987       1 schedule_one.go:83] "sleep when attempting to schedule pod to increase job intervals..."
I1030 05:12:07.629556       1 schedule_one.go:63] "starting scheduling for next pod..."
I1030 05:12:07.758095       1 eventhandlers.go:186] "Add event for scheduled pod" pod="default/job-train-imgclassfication14-cuda-epoch140"
I1030 05:12:07.758101       1 eventhandlers.go:161] "Delete event for unscheduled pod" pod="default/job-train-imgclassfication14-cuda-epoch140"
I1030 05:12:07.760002       1 schedule_one.go:260] "Successfully bound pod to node" pod="default/job-train-imgclassfication14-cuda-epoch140" node="node2" evaluatedNodes=1 feasibleNodes=1
I1030 05:12:07.796135       1 eventhandlers.go:206] "Update event for scheduled pod" pod="default/job-train-imgclassfication14-cuda-epoch140"
I1030 05:12:07.830130       1 scheduling_queue.go:661] "[Bing]Pop called on the scheduling queue. current queue includes pods: " [%!s(*framework.QueuedPodInfo=&{0xc0002199d0 {13927360495606014637 552060089328 0x38092e0} 3 {13927360205363368956 281727736145 0x38092e0} map[NodeResourcesFit:{}] false}) %!s(*framework.QueuedPodInfo=&{0xc00022e4d0 {13927360496007672339 552461747054 0x38092e0} 4 {13927360205431737232 281796104442 0x38092e0} map[NodeResourcesFit:{}] false}) %!s(*framework.QueuedPodInfo=&{0xc00022eb60 {13927360496483797637 552864130508 0x38092e0} 4 {13927360205485099519 281849466714 0x38092e0} map[NodeResourcesFit:{}] false}) %!s(*framework.QueuedPodInfo=&{0xc00022ee70 {13927360497361616446 553668207506 0x38092e0} 3 {13927360205612739548 281977106744 0x38092e0} map[NodeResourcesFit:{}] false}) %!s(*framework.QueuedPodInfo=&{0xc000221b20 {13927360497763465991 554070057059 0x38092e0} 3 {13927360205671620050 282035987245 0x38092e0} map[NodeResourcesFit:{}] false}) %!s(*framework.QueuedPodInfo=&{0xc000220930 {13927360496886097229 553266430117 0x38092e0} 3 {13927360205549087692 281913454909 0x38092e0} map[NodeResourcesFit:{}] false})]="queue len:" %!s(int=6)="(MISSING)"
I1030 05:12:07.830171       1 scheduling_queue.go:1203] "[Bing]About to try and schedule pod" pod="default/job-train-imgclassfication15-cuda-epoch150"
I1030 05:12:07.830194       1 schedule_one.go:81] "Attempting to schedule pod" pod="default/job-train-imgclassfication15-cuda-epoch150"
I1030 05:12:07.857650       1 eventhandlers.go:206] "Update event for scheduled pod" pod="default/job-train-imgclassfication14-cuda-epoch140"
I1030 05:12:08.030686       1 schedule_one.go:83] "sleep when attempting to schedule pod to increase job intervals..."
I1030 05:12:08.030988       1 schedule_one.go:875] "Unable to schedule pod; no fit; waiting" pod="default/job-train-imgclassfication15-cuda-epoch150" err="0/1 nodes are available: 1 Insufficient aliyun.com/gpu-mem. preemption: 0/1 nodes are available: 1 Insufficient aliyun.com/gpu-mem.."
I1030 05:12:08.031078       1 schedule_one.go:951] "Updating pod condition" pod="default/job-train-imgclassfication15-cuda-epoch150" conditionType=PodScheduled conditionStatus=False conditionReason="Unschedulable"
I1030 05:12:08.031129       1 schedule_one.go:63] "starting scheduling for next pod..."
I1030 05:12:08.231780       1 scheduling_queue.go:661] "[Bing]Pop called on the scheduling queue. current queue includes pods: " [%!s(*framework.QueuedPodInfo=&{0xc00022e4d0 {13927360496007672339 552461747054 0x38092e0} 4 {13927360205431737232 281796104442 0x38092e0} map[NodeResourcesFit:{}] false}) %!s(*framework.QueuedPodInfo=&{0xc00022eb60 {13927360496483797637 552864130508 0x38092e0} 4 {13927360205485099519 281849466714 0x38092e0} map[NodeResourcesFit:{}] false}) %!s(*framework.QueuedPodInfo=&{0xc00022ee70 {13927360497361616446 553668207506 0x38092e0} 3 {13927360205612739548 281977106744 0x38092e0} map[NodeResourcesFit:{}] false}) %!s(*framework.QueuedPodInfo=&{0xc000221b20 {13927360497763465991 554070057059 0x38092e0} 3 {13927360205671620050 282035987245 0x38092e0} map[NodeResourcesFit:{}] false}) %!s(*framework.QueuedPodInfo=&{0xc000220930 {13927360496886097229 553266430117 0x38092e0} 3 {13927360205549087692 281913454909 0x38092e0} map[NodeResourcesFit:{}] false})]="queue len:" %!s(int=5)="(MISSING)"
I1030 05:12:08.231822       1 scheduling_queue.go:1203] "[Bing]About to try and schedule pod" pod="default/job-train-imgclassfication16-cuda-epoch160"
I1030 05:12:08.231846       1 schedule_one.go:81] "Attempting to schedule pod" pod="default/job-train-imgclassfication16-cuda-epoch160"
I1030 05:12:08.432179       1 schedule_one.go:83] "sleep when attempting to schedule pod to increase job intervals..."
I1030 05:12:08.432518       1 schedule_one.go:875] "Unable to schedule pod; no fit; waiting" pod="default/job-train-imgclassfication16-cuda-epoch160" err="0/1 nodes are available: 1 Insufficient aliyun.com/gpu-mem. preemption: 0/1 nodes are available: 1 Insufficient aliyun.com/gpu-mem.."
I1030 05:12:08.432584       1 schedule_one.go:951] "Updating pod condition" pod="default/job-train-imgclassfication16-cuda-epoch160" conditionType=PodScheduled conditionStatus=False conditionReason="Unschedulable"
I1030 05:12:08.432608       1 schedule_one.go:63] "starting scheduling for next pod..."
I1030 05:12:08.633657       1 scheduling_queue.go:661] "[Bing]Pop called on the scheduling queue. current queue includes pods: " [%!s(*framework.QueuedPodInfo=&{0xc00022eb60 {13927360496483797637 552864130508 0x38092e0} 4 {13927360205485099519 281849466714 0x38092e0} map[NodeResourcesFit:{}] false}) %!s(*framework.QueuedPodInfo=&{0xc00022ee70 {13927360497361616446 553668207506 0x38092e0} 3 {13927360205612739548 281977106744 0x38092e0} map[NodeResourcesFit:{}] false}) %!s(*framework.QueuedPodInfo=&{0xc000221b20 {13927360497763465991 554070057059 0x38092e0} 3 {13927360205671620050 282035987245 0x38092e0} map[NodeResourcesFit:{}] false}) %!s(*framework.QueuedPodInfo=&{0xc000220930 {13927360496886097229 553266430117 0x38092e0} 3 {13927360205549087692 281913454909 0x38092e0} map[NodeResourcesFit:{}] false})]="queue len:" %!s(int=4)="(MISSING)"
I1030 05:12:08.633706       1 scheduling_queue.go:1203] "[Bing]About to try and schedule pod" pod="default/job-train-imgclassfication17-cuda-epoch170"
I1030 05:12:08.633737       1 schedule_one.go:81] "Attempting to schedule pod" pod="default/job-train-imgclassfication17-cuda-epoch170"
I1030 05:12:08.834435       1 schedule_one.go:83] "sleep when attempting to schedule pod to increase job intervals..."
I1030 05:12:08.834890       1 schedule_one.go:875] "Unable to schedule pod; no fit; waiting" pod="default/job-train-imgclassfication17-cuda-epoch170" err="0/1 nodes are available: 1 Insufficient aliyun.com/gpu-mem. preemption: 0/1 nodes are available: 1 Insufficient aliyun.com/gpu-mem.."
I1030 05:12:08.835009       1 schedule_one.go:951] "Updating pod condition" pod="default/job-train-imgclassfication17-cuda-epoch170" conditionType=PodScheduled conditionStatus=False conditionReason="Unschedulable"
I1030 05:12:08.835053       1 schedule_one.go:63] "starting scheduling for next pod..."
I1030 05:12:09.035495       1 scheduling_queue.go:661] "[Bing]Pop called on the scheduling queue. current queue includes pods: " [%!s(*framework.QueuedPodInfo=&{0xc00022ee70 {13927360497361616446 553668207506 0x38092e0} 3 {13927360205612739548 281977106744 0x38092e0} map[NodeResourcesFit:{}] false}) %!s(*framework.QueuedPodInfo=&{0xc000221b20 {13927360497763465991 554070057059 0x38092e0} 3 {13927360205671620050 282035987245 0x38092e0} map[NodeResourcesFit:{}] false}) %!s(*framework.QueuedPodInfo=&{0xc000220930 {13927360496886097229 553266430117 0x38092e0} 3 {13927360205549087692 281913454909 0x38092e0} map[NodeResourcesFit:{}] false})]="queue len:" %!s(int=3)="(MISSING)"
I1030 05:12:09.035541       1 scheduling_queue.go:1203] "[Bing]About to try and schedule pod" pod="default/job-train-imgclassfication18-cuda-epoch180"
I1030 05:12:09.035575       1 schedule_one.go:81] "Attempting to schedule pod" pod="default/job-train-imgclassfication18-cuda-epoch180"
I1030 05:12:09.197344       1 eventhandlers.go:206] "Update event for scheduled pod" pod="default/job-train-imgclassfication14-cuda-epoch140"
I1030 05:12:09.236644       1 schedule_one.go:83] "sleep when attempting to schedule pod to increase job intervals..."
I1030 05:12:09.236999       1 schedule_one.go:875] "Unable to schedule pod; no fit; waiting" pod="default/job-train-imgclassfication18-cuda-epoch180" err="0/1 nodes are available: 1 Insufficient aliyun.com/gpu-mem. preemption: 0/1 nodes are available: 1 Insufficient aliyun.com/gpu-mem.."
I1030 05:12:09.237081       1 schedule_one.go:951] "Updating pod condition" pod="default/job-train-imgclassfication18-cuda-epoch180" conditionType=PodScheduled conditionStatus=False conditionReason="Unschedulable"
I1030 05:12:09.237106       1 schedule_one.go:63] "starting scheduling for next pod..."
I1030 05:12:09.437963       1 scheduling_queue.go:661] "[Bing]Pop called on the scheduling queue. current queue includes pods: " [%!s(*framework.QueuedPodInfo=&{0xc000221b20 {13927360497763465991 554070057059 0x38092e0} 3 {13927360205671620050 282035987245 0x38092e0} map[NodeResourcesFit:{}] false}) %!s(*framework.QueuedPodInfo=&{0xc00022ee70 {13927360497361616446 553668207506 0x38092e0} 3 {13927360205612739548 281977106744 0x38092e0} map[NodeResourcesFit:{}] false})]="queue len:" %!s(int=2)="(MISSING)"
I1030 05:12:09.438023       1 scheduling_queue.go:1203] "[Bing]About to try and schedule pod" pod="default/job-train-imgclassfication19-cuda-epoch190"
I1030 05:12:09.438052       1 schedule_one.go:81] "Attempting to schedule pod" pod="default/job-train-imgclassfication19-cuda-epoch190"
I1030 05:12:09.638371       1 schedule_one.go:83] "sleep when attempting to schedule pod to increase job intervals..."
I1030 05:12:09.639008       1 schedule_one.go:875] "Unable to schedule pod; no fit; waiting" pod="default/job-train-imgclassfication19-cuda-epoch190" err="0/1 nodes are available: 1 Insufficient aliyun.com/gpu-mem. preemption: 0/1 nodes are available: 1 Insufficient aliyun.com/gpu-mem.."
I1030 05:12:09.639173       1 schedule_one.go:951] "Updating pod condition" pod="default/job-train-imgclassfication19-cuda-epoch190" conditionType=PodScheduled conditionStatus=False conditionReason="Unschedulable"
I1030 05:12:09.639238       1 schedule_one.go:63] "starting scheduling for next pod..."
I1030 05:12:09.840186       1 scheduling_queue.go:661] "[Bing]Pop called on the scheduling queue. current queue includes pods: " [%!s(*framework.QueuedPodInfo=&{0xc000221b20 {13927360497763465991 554070057059 0x38092e0} 3 {13927360205671620050 282035987245 0x38092e0} map[NodeResourcesFit:{}] false})]="queue len:" %!s(int=1)="(MISSING)"
I1030 05:12:09.840273       1 scheduling_queue.go:1203] "[Bing]About to try and schedule pod" pod="default/job-train-imgclassfication20-cuda-epoch200"
I1030 05:12:09.840350       1 schedule_one.go:81] "Attempting to schedule pod" pod="default/job-train-imgclassfication20-cuda-epoch200"
I1030 05:12:10.041110       1 schedule_one.go:83] "sleep when attempting to schedule pod to increase job intervals..."
I1030 05:12:10.041564       1 schedule_one.go:875] "Unable to schedule pod; no fit; waiting" pod="default/job-train-imgclassfication20-cuda-epoch200" err="0/1 nodes are available: 1 Insufficient aliyun.com/gpu-mem. preemption: 0/1 nodes are available: 1 Insufficient aliyun.com/gpu-mem.."
I1030 05:12:10.041679       1 schedule_one.go:951] "Updating pod condition" pod="default/job-train-imgclassfication20-cuda-epoch200" conditionType=PodScheduled conditionStatus=False conditionReason="Unschedulable"
I1030 05:12:10.041721       1 schedule_one.go:63] "starting scheduling for next pod..."
I1030 05:12:10.242395       1 scheduling_queue.go:661] "[Bing]Pop called on the scheduling queue. current queue includes pods: " []="queue len:" %!s(int=0)="(MISSING)"
I1030 05:12:11.627470       1 httplog.go:132] "HTTP" verb="GET" URI="/healthz" latency="101.939µs" userAgent="kube-probe/1.27" audit-ID="" srcIP="127.0.0.1:39312" resp=200
I1030 05:12:16.652908       1 scheduling_queue.go:1203] "[Bing]About to try and schedule pod" pod="default/job-train-imgclassfication15-cuda-epoch150"
I1030 05:12:16.652960       1 schedule_one.go:81] "Attempting to schedule pod" pod="default/job-train-imgclassfication15-cuda-epoch150"
I1030 05:12:16.853858       1 schedule_one.go:83] "sleep when attempting to schedule pod to increase job intervals..."
I1030 05:12:16.854312       1 schedule_one.go:875] "Unable to schedule pod; no fit; waiting" pod="default/job-train-imgclassfication15-cuda-epoch150" err="0/1 nodes are available: 1 Insufficient aliyun.com/gpu-mem. preemption: 0/1 nodes are available: 1 Insufficient aliyun.com/gpu-mem.."
I1030 05:12:16.854421       1 schedule_one.go:951] "Updating pod condition" pod="default/job-train-imgclassfication15-cuda-epoch150" conditionType=PodScheduled conditionStatus=False conditionReason="Unschedulable"
I1030 05:12:16.854465       1 schedule_one.go:63] "starting scheduling for next pod..."
I1030 05:12:17.054828       1 scheduling_queue.go:661] "[Bing]Pop called on the scheduling queue. current queue includes pods: " []="queue len:" %!s(int=0)="(MISSING)"
I1030 05:12:17.653851       1 scheduling_queue.go:1203] "[Bing]About to try and schedule pod" pod="default/job-train-imgclassfication18-cuda-epoch180"
I1030 05:12:17.653890       1 schedule_one.go:81] "Attempting to schedule pod" pod="default/job-train-imgclassfication18-cuda-epoch180"
I1030 05:12:17.854246       1 schedule_one.go:83] "sleep when attempting to schedule pod to increase job intervals..."
I1030 05:12:17.854513       1 schedule_one.go:875] "Unable to schedule pod; no fit; waiting" pod="default/job-train-imgclassfication18-cuda-epoch180" err="0/1 nodes are available: 1 Insufficient aliyun.com/gpu-mem. preemption: 0/1 nodes are available: 1 Insufficient aliyun.com/gpu-mem.."
I1030 05:12:17.854577       1 schedule_one.go:951] "Updating pod condition" pod="default/job-train-imgclassfication18-cuda-epoch180" conditionType=PodScheduled conditionStatus=False conditionReason="Unschedulable"
I1030 05:12:17.854598       1 schedule_one.go:63] "starting scheduling for next pod..."
I1030 05:12:18.054947       1 scheduling_queue.go:661] "[Bing]Pop called on the scheduling queue. current queue includes pods: " []="queue len:" %!s(int=0)="(MISSING)"
I1030 05:12:21.627927       1 httplog.go:132] "HTTP" verb="GET" URI="/healthz" latency="87.417µs" userAgent="kube-probe/1.27" audit-ID="" srcIP="127.0.0.1:52340" resp=200
I1030 05:12:31.633501       1 httplog.go:132] "HTTP" verb="GET" URI="/healthz" latency="94.916µs" userAgent="kube-probe/1.27" audit-ID="" srcIP="127.0.0.1:47398" resp=200
I1030 05:12:41.635341       1 httplog.go:132] "HTTP" verb="GET" URI="/healthz" latency="68.153µs" userAgent="kube-probe/1.27" audit-ID="" srcIP="127.0.0.1:40368" resp=200
I1030 05:12:51.628497       1 httplog.go:132] "HTTP" verb="GET" URI="/healthz" latency="166.477µs" userAgent="kube-probe/1.27" audit-ID="" srcIP="127.0.0.1:59420" resp=200
I1030 05:12:55.317210       1 eventhandlers.go:206] "Update event for scheduled pod" pod="default/job-train-imgclassfication2-cuda-epoch20"
I1030 05:12:56.543074       1 eventhandlers.go:231] "Delete event for scheduled pod" pod="default/job-train-imgclassfication2-cuda-epoch20"
I1030 05:12:56.543334       1 scheduling_queue.go:1203] "[Bing]About to try and schedule pod" pod="default/job-train-imgclassfication15-cuda-epoch150"
I1030 05:12:56.543380       1 schedule_one.go:81] "Attempting to schedule pod" pod="default/job-train-imgclassfication15-cuda-epoch150"
I1030 05:12:56.743919       1 schedule_one.go:83] "sleep when attempting to schedule pod to increase job intervals..."
I1030 05:12:56.746575       1 schedule_one.go:63] "starting scheduling for next pod..."
I1030 05:12:56.869472       1 eventhandlers.go:161] "Delete event for unscheduled pod" pod="default/job-train-imgclassfication15-cuda-epoch150"
I1030 05:12:56.869483       1 eventhandlers.go:186] "Add event for scheduled pod" pod="default/job-train-imgclassfication15-cuda-epoch150"
I1030 05:12:56.872125       1 schedule_one.go:260] "Successfully bound pod to node" pod="default/job-train-imgclassfication15-cuda-epoch150" node="node2" evaluatedNodes=1 feasibleNodes=1
I1030 05:12:56.911027       1 eventhandlers.go:206] "Update event for scheduled pod" pod="default/job-train-imgclassfication15-cuda-epoch150"
I1030 05:12:56.947362       1 scheduling_queue.go:661] "[Bing]Pop called on the scheduling queue. current queue includes pods: " [%!s(*framework.QueuedPodInfo=&{0xc0003a29a0 {13927360587987697293 638099975113 0x38092e0} 5 {13927360205431737232 281796104442 0x38092e0} map[NodeResourcesFit:{}] false}) %!s(*framework.QueuedPodInfo=&{0xc00024e2a0 {13927360588390090539 638502368393 0x38092e0} 5 {13927360205485099519 281849466714 0x38092e0} map[NodeResourcesFit:{}] false}) %!s(*framework.QueuedPodInfo=&{0xc00086a150 {13927360589267977343 639306513387 0x38092e0} 4 {13927360205612739548 281977106744 0x38092e0} map[NodeResourcesFit:{}] false}) %!s(*framework.QueuedPodInfo=&{0xc0003a2f50 {13927360589744245974 639709040179 0x38092e0} 4 {13927360205671620050 282035987245 0x38092e0} map[NodeResourcesFit:{}] false}) %!s(*framework.QueuedPodInfo=&{0xc000170a10 {13927360598073366290 647521967695 0x38092e0} 5 {13927360205549087692 281913454909 0x38092e0} map[NodeResourcesFit:{}] false})]="queue len:" %!s(int=5)="(MISSING)"
I1030 05:12:56.947407       1 scheduling_queue.go:1203] "[Bing]About to try and schedule pod" pod="default/job-train-imgclassfication16-cuda-epoch160"
I1030 05:12:56.947429       1 schedule_one.go:81] "Attempting to schedule pod" pod="default/job-train-imgclassfication16-cuda-epoch160"
I1030 05:12:56.986911       1 eventhandlers.go:206] "Update event for scheduled pod" pod="default/job-train-imgclassfication15-cuda-epoch150"
I1030 05:12:57.147915       1 schedule_one.go:83] "sleep when attempting to schedule pod to increase job intervals..."
I1030 05:12:57.148431       1 schedule_one.go:875] "Unable to schedule pod; no fit; waiting" pod="default/job-train-imgclassfication16-cuda-epoch160" err="0/1 nodes are available: 1 Insufficient aliyun.com/gpu-mem. preemption: 0/1 nodes are available: 1 Insufficient aliyun.com/gpu-mem.."
I1030 05:12:57.148551       1 schedule_one.go:951] "Updating pod condition" pod="default/job-train-imgclassfication16-cuda-epoch160" conditionType=PodScheduled conditionStatus=False conditionReason="Unschedulable"
I1030 05:12:57.148596       1 schedule_one.go:63] "starting scheduling for next pod..."
I1030 05:12:57.348977       1 scheduling_queue.go:661] "[Bing]Pop called on the scheduling queue. current queue includes pods: " [%!s(*framework.QueuedPodInfo=&{0xc000170a10 {13927360598073366290 647521967695 0x38092e0} 5 {13927360205549087692 281913454909 0x38092e0} map[NodeResourcesFit:{}] false}) %!s(*framework.QueuedPodInfo=&{0xc0003a2f50 {13927360589744245974 639709040179 0x38092e0} 4 {13927360205671620050 282035987245 0x38092e0} map[NodeResourcesFit:{}] false}) %!s(*framework.QueuedPodInfo=&{0xc00024e2a0 {13927360588390090539 638502368393 0x38092e0} 5 {13927360205485099519 281849466714 0x38092e0} map[NodeResourcesFit:{}] false}) %!s(*framework.QueuedPodInfo=&{0xc00086a150 {13927360589267977343 639306513387 0x38092e0} 4 {13927360205612739548 281977106744 0x38092e0} map[NodeResourcesFit:{}] false})]="queue len:" %!s(int=4)="(MISSING)"
I1030 05:12:57.349017       1 scheduling_queue.go:1203] "[Bing]About to try and schedule pod" pod="default/job-train-imgclassfication17-cuda-epoch170"
I1030 05:12:57.349037       1 schedule_one.go:81] "Attempting to schedule pod" pod="default/job-train-imgclassfication17-cuda-epoch170"
I1030 05:12:57.549605       1 schedule_one.go:83] "sleep when attempting to schedule pod to increase job intervals..."
I1030 05:12:57.549926       1 schedule_one.go:875] "Unable to schedule pod; no fit; waiting" pod="default/job-train-imgclassfication17-cuda-epoch170" err="0/1 nodes are available: 1 Insufficient aliyun.com/gpu-mem. preemption: 0/1 nodes are available: 1 Insufficient aliyun.com/gpu-mem.."
I1030 05:12:57.550003       1 schedule_one.go:951] "Updating pod condition" pod="default/job-train-imgclassfication17-cuda-epoch170" conditionType=PodScheduled conditionStatus=False conditionReason="Unschedulable"
I1030 05:12:57.550036       1 schedule_one.go:63] "starting scheduling for next pod..."
I1030 05:12:57.750208       1 scheduling_queue.go:661] "[Bing]Pop called on the scheduling queue. current queue includes pods: " [%!s(*framework.QueuedPodInfo=&{0xc0003a2f50 {13927360589744245974 639709040179 0x38092e0} 4 {13927360205671620050 282035987245 0x38092e0} map[NodeResourcesFit:{}] false}) %!s(*framework.QueuedPodInfo=&{0xc00086a150 {13927360589267977343 639306513387 0x38092e0} 4 {13927360205612739548 281977106744 0x38092e0} map[NodeResourcesFit:{}] false}) %!s(*framework.QueuedPodInfo=&{0xc000170a10 {13927360598073366290 647521967695 0x38092e0} 5 {13927360205549087692 281913454909 0x38092e0} map[NodeResourcesFit:{}] false})]="queue len:" %!s(int=3)="(MISSING)"
I1030 05:12:57.750247       1 scheduling_queue.go:1203] "[Bing]About to try and schedule pod" pod="default/job-train-imgclassfication18-cuda-epoch180"
I1030 05:12:57.750268       1 schedule_one.go:81] "Attempting to schedule pod" pod="default/job-train-imgclassfication18-cuda-epoch180"
I1030 05:12:57.950835       1 schedule_one.go:83] "sleep when attempting to schedule pod to increase job intervals..."
I1030 05:12:57.951247       1 schedule_one.go:875] "Unable to schedule pod; no fit; waiting" pod="default/job-train-imgclassfication18-cuda-epoch180" err="0/1 nodes are available: 1 Insufficient aliyun.com/gpu-mem. preemption: 0/1 nodes are available: 1 Insufficient aliyun.com/gpu-mem.."
I1030 05:12:57.951355       1 schedule_one.go:951] "Updating pod condition" pod="default/job-train-imgclassfication18-cuda-epoch180" conditionType=PodScheduled conditionStatus=False conditionReason="Unschedulable"
I1030 05:12:57.951396       1 schedule_one.go:63] "starting scheduling for next pod..."
I1030 05:12:58.152351       1 scheduling_queue.go:661] "[Bing]Pop called on the scheduling queue. current queue includes pods: " [%!s(*framework.QueuedPodInfo=&{0xc00086a150 {13927360589267977343 639306513387 0x38092e0} 4 {13927360205612739548 281977106744 0x38092e0} map[NodeResourcesFit:{}] false}) %!s(*framework.QueuedPodInfo=&{0xc0003a2f50 {13927360589744245974 639709040179 0x38092e0} 4 {13927360205671620050 282035987245 0x38092e0} map[NodeResourcesFit:{}] false})]="queue len:" %!s(int=2)="(MISSING)"
I1030 05:12:58.152425       1 scheduling_queue.go:1203] "[Bing]About to try and schedule pod" pod="default/job-train-imgclassfication19-cuda-epoch190"
I1030 05:12:58.152458       1 schedule_one.go:81] "Attempting to schedule pod" pod="default/job-train-imgclassfication19-cuda-epoch190"
I1030 05:12:58.329649       1 eventhandlers.go:206] "Update event for scheduled pod" pod="default/job-train-imgclassfication15-cuda-epoch150"
I1030 05:12:58.353494       1 schedule_one.go:83] "sleep when attempting to schedule pod to increase job intervals..."
I1030 05:12:58.353828       1 schedule_one.go:875] "Unable to schedule pod; no fit; waiting" pod="default/job-train-imgclassfication19-cuda-epoch190" err="0/1 nodes are available: 1 Insufficient aliyun.com/gpu-mem. preemption: 0/1 nodes are available: 1 Insufficient aliyun.com/gpu-mem.."
I1030 05:12:58.353928       1 schedule_one.go:951] "Updating pod condition" pod="default/job-train-imgclassfication19-cuda-epoch190" conditionType=PodScheduled conditionStatus=False conditionReason="Unschedulable"
I1030 05:12:58.353975       1 schedule_one.go:63] "starting scheduling for next pod..."
I1030 05:12:58.554281       1 scheduling_queue.go:661] "[Bing]Pop called on the scheduling queue. current queue includes pods: " [%!s(*framework.QueuedPodInfo=&{0xc0003a2f50 {13927360589744245974 639709040179 0x38092e0} 4 {13927360205671620050 282035987245 0x38092e0} map[NodeResourcesFit:{}] false})]="queue len:" %!s(int=1)="(MISSING)"
I1030 05:12:58.554332       1 scheduling_queue.go:1203] "[Bing]About to try and schedule pod" pod="default/job-train-imgclassfication20-cuda-epoch200"
I1030 05:12:58.554364       1 schedule_one.go:81] "Attempting to schedule pod" pod="default/job-train-imgclassfication20-cuda-epoch200"
I1030 05:12:58.755207       1 schedule_one.go:83] "sleep when attempting to schedule pod to increase job intervals..."
I1030 05:12:58.755510       1 schedule_one.go:875] "Unable to schedule pod; no fit; waiting" pod="default/job-train-imgclassfication20-cuda-epoch200" err="0/1 nodes are available: 1 Insufficient aliyun.com/gpu-mem. preemption: 0/1 nodes are available: 1 Insufficient aliyun.com/gpu-mem.."
I1030 05:12:58.755593       1 schedule_one.go:951] "Updating pod condition" pod="default/job-train-imgclassfication20-cuda-epoch200" conditionType=PodScheduled conditionStatus=False conditionReason="Unschedulable"
I1030 05:12:58.755619       1 schedule_one.go:63] "starting scheduling for next pod..."
I1030 05:12:58.956189       1 scheduling_queue.go:661] "[Bing]Pop called on the scheduling queue. current queue includes pods: " []="queue len:" %!s(int=0)="(MISSING)"
I1030 05:13:01.631709       1 httplog.go:132] "HTTP" verb="GET" URI="/healthz" latency="101.664µs" userAgent="kube-probe/1.27" audit-ID="" srcIP="127.0.0.1:57962" resp=200
I1030 05:13:07.685416       1 scheduling_queue.go:1203] "[Bing]About to try and schedule pod" pod="default/job-train-imgclassfication16-cuda-epoch160"
I1030 05:13:07.685458       1 schedule_one.go:81] "Attempting to schedule pod" pod="default/job-train-imgclassfication16-cuda-epoch160"
I1030 05:13:07.885813       1 schedule_one.go:83] "sleep when attempting to schedule pod to increase job intervals..."
I1030 05:13:07.886158       1 schedule_one.go:875] "Unable to schedule pod; no fit; waiting" pod="default/job-train-imgclassfication16-cuda-epoch160" err="0/1 nodes are available: 1 Insufficient aliyun.com/gpu-mem. preemption: 0/1 nodes are available: 1 Insufficient aliyun.com/gpu-mem.."
I1030 05:13:07.886250       1 schedule_one.go:951] "Updating pod condition" pod="default/job-train-imgclassfication16-cuda-epoch160" conditionType=PodScheduled conditionStatus=False conditionReason="Unschedulable"
I1030 05:13:07.886285       1 schedule_one.go:63] "starting scheduling for next pod..."
I1030 05:13:08.086651       1 scheduling_queue.go:661] "[Bing]Pop called on the scheduling queue. current queue includes pods: " []="queue len:" %!s(int=0)="(MISSING)"
I1030 05:13:08.686055       1 scheduling_queue.go:1203] "[Bing]About to try and schedule pod" pod="default/job-train-imgclassfication19-cuda-epoch190"
I1030 05:13:08.686098       1 schedule_one.go:81] "Attempting to schedule pod" pod="default/job-train-imgclassfication19-cuda-epoch190"
I1030 05:13:08.886441       1 schedule_one.go:83] "sleep when attempting to schedule pod to increase job intervals..."
I1030 05:13:08.886715       1 schedule_one.go:875] "Unable to schedule pod; no fit; waiting" pod="default/job-train-imgclassfication19-cuda-epoch190" err="0/1 nodes are available: 1 Insufficient aliyun.com/gpu-mem. preemption: 0/1 nodes are available: 1 Insufficient aliyun.com/gpu-mem.."
I1030 05:13:08.886797       1 schedule_one.go:951] "Updating pod condition" pod="default/job-train-imgclassfication19-cuda-epoch190" conditionType=PodScheduled conditionStatus=False conditionReason="Unschedulable"
I1030 05:13:08.886825       1 schedule_one.go:63] "starting scheduling for next pod..."
I1030 05:13:09.087354       1 scheduling_queue.go:661] "[Bing]Pop called on the scheduling queue. current queue includes pods: " []="queue len:" %!s(int=0)="(MISSING)"
I1030 05:13:11.629371       1 httplog.go:132] "HTTP" verb="GET" URI="/healthz" latency="95.309µs" userAgent="kube-probe/1.27" audit-ID="" srcIP="127.0.0.1:52804" resp=200
I1030 05:13:21.629033       1 httplog.go:132] "HTTP" verb="GET" URI="/healthz" latency="139.533µs" userAgent="kube-probe/1.27" audit-ID="" srcIP="127.0.0.1:38430" resp=200
I1030 05:13:31.629550       1 httplog.go:132] "HTTP" verb="GET" URI="/healthz" latency="133.695µs" userAgent="kube-probe/1.27" audit-ID="" srcIP="127.0.0.1:57768" resp=200
I1030 05:13:41.629485       1 httplog.go:132] "HTTP" verb="GET" URI="/healthz" latency="91.64µs" userAgent="kube-probe/1.27" audit-ID="" srcIP="127.0.0.1:43360" resp=200
I1030 05:13:51.629007       1 httplog.go:132] "HTTP" verb="GET" URI="/healthz" latency="79.879µs" userAgent="kube-probe/1.27" audit-ID="" srcIP="127.0.0.1:47370" resp=200
I1030 05:13:58.152622       1 reflector.go:788] vendor/k8s.io/client-go/informers/factory.go:150: Watch close - *v1.Service total 8 items received
I1030 05:14:01.629678       1 httplog.go:132] "HTTP" verb="GET" URI="/healthz" latency="62.628µs" userAgent="kube-probe/1.27" audit-ID="" srcIP="127.0.0.1:59308" resp=200
I1030 05:14:11.627618       1 httplog.go:132] "HTTP" verb="GET" URI="/healthz" latency="66.631µs" userAgent="kube-probe/1.27" audit-ID="" srcIP="127.0.0.1:49560" resp=200
I1030 05:14:21.627975       1 httplog.go:132] "HTTP" verb="GET" URI="/healthz" latency="64.283µs" userAgent="kube-probe/1.27" audit-ID="" srcIP="127.0.0.1:46774" resp=200
I1030 05:14:23.153265       1 reflector.go:788] vendor/k8s.io/client-go/informers/factory.go:150: Watch close - *v1.ReplicaSet total 9 items received
I1030 05:14:31.628127       1 httplog.go:132] "HTTP" verb="GET" URI="/healthz" latency="94.141µs" userAgent="kube-probe/1.27" audit-ID="" srcIP="127.0.0.1:58184" resp=200
I1030 05:14:41.632752       1 httplog.go:132] "HTTP" verb="GET" URI="/healthz" latency="115.209µs" userAgent="kube-probe/1.27" audit-ID="" srcIP="127.0.0.1:42356" resp=200
I1030 05:14:51.633245       1 httplog.go:132] "HTTP" verb="GET" URI="/healthz" latency="68.196µs" userAgent="kube-probe/1.27" audit-ID="" srcIP="127.0.0.1:46444" resp=200
I1030 05:14:55.153526       1 reflector.go:788] vendor/k8s.io/client-go/informers/factory.go:150: Watch close - *v1.CSIStorageCapacity total 7 items received
I1030 05:15:01.629236       1 httplog.go:132] "HTTP" verb="GET" URI="/healthz" latency="87.162µs" userAgent="kube-probe/1.27" audit-ID="" srcIP="127.0.0.1:52468" resp=200
I1030 05:15:05.152686       1 reflector.go:788] vendor/k8s.io/client-go/informers/factory.go:150: Watch close - *v1.CSINode total 7 items received
I1030 05:15:11.628669       1 httplog.go:132] "HTTP" verb="GET" URI="/healthz" latency="79.965µs" userAgent="kube-probe/1.27" audit-ID="" srcIP="127.0.0.1:33484" resp=200
I1030 05:15:21.630262       1 httplog.go:132] "HTTP" verb="GET" URI="/healthz" latency="91.903µs" userAgent="kube-probe/1.27" audit-ID="" srcIP="127.0.0.1:34708" resp=200
I1030 05:15:31.628864       1 httplog.go:132] "HTTP" verb="GET" URI="/healthz" latency="68.062µs" userAgent="kube-probe/1.27" audit-ID="" srcIP="127.0.0.1:46964" resp=200
I1030 05:15:38.151945       1 reflector.go:788] pkg/server/dynamiccertificates/configmap_cafile_content.go:206: Watch close - *v1.ConfigMap total 8 items received
I1030 05:15:41.155072       1 reflector.go:788] pkg/authentication/request/headerrequest/requestheader_controller.go:172: Watch close - *v1.ConfigMap total 7 items received
I1030 05:15:41.632888       1 httplog.go:132] "HTTP" verb="GET" URI="/healthz" latency="84.19µs" userAgent="kube-probe/1.27" audit-ID="" srcIP="127.0.0.1:42512" resp=200
I1030 05:15:46.151854       1 reflector.go:788] vendor/k8s.io/client-go/informers/factory.go:150: Watch close - *v1.StatefulSet total 7 items received
I1030 05:15:51.629147       1 httplog.go:132] "HTTP" verb="GET" URI="/healthz" latency="88.491µs" userAgent="kube-probe/1.27" audit-ID="" srcIP="127.0.0.1:49332" resp=200
I1030 05:15:52.943067       1 eventhandlers.go:118] "Add event for unscheduled pod" pod="default/dummy-highest"
I1030 05:15:52.943156       1 scheduling_queue.go:1203] "[Bing]About to try and schedule pod" pod="default/dummy-highest"
I1030 05:15:52.943169       1 schedule_one.go:81] "Attempting to schedule pod" pod="default/dummy-highest"
I1030 05:15:52.972666       1 eventhandlers.go:118] "Add event for unscheduled pod" pod="default/job-train-imgclassfication-cuda-epoch-20"
I1030 05:15:53.006638       1 eventhandlers.go:118] "Add event for unscheduled pod" pod="default/job-train-imgclassfication-cuda-epoch-10"
I1030 05:15:53.075114       1 eventhandlers.go:118] "Add event for unscheduled pod" pod="default/job-train-imgclassfication-cuda-epoch-5"
I1030 05:15:53.143376       1 schedule_one.go:83] "sleep when attempting to schedule pod to increase job intervals..."
I1030 05:15:53.158460       1 eventhandlers.go:206] "Update event for scheduled pod" pod="default/job-train-imgclassfication15-cuda-epoch150"
I1030 05:15:53.169630       1 eventhandlers.go:206] "Update event for scheduled pod" pod="default/job-train-imgclassfication15-cuda-epoch150"
I1030 05:15:53.169690       1 preemption.go:381] "Preemptor Pod preempted victim Pod" preemptor="default/dummy-highest" victim="default/job-train-imgclassfication15-cuda-epoch150" node="node2"
I1030 05:15:53.169782       1 schedule_one.go:875] "Unable to schedule pod; no fit; waiting" pod="default/dummy-highest" err="0/1 nodes are available: 1 Insufficient aliyun.com/gpu-mem."
I1030 05:15:53.169863       1 schedule_one.go:951] "Updating pod condition" pod="default/dummy-highest" conditionType=PodScheduled conditionStatus=False conditionReason="Unschedulable"
I1030 05:15:53.184272       1 schedule_one.go:63] "starting scheduling for next pod..."
I1030 05:15:53.190911       1 eventhandlers.go:206] "Update event for scheduled pod" pod="default/job-train-imgclassfication15-cuda-epoch150"
I1030 05:15:53.385107       1 scheduling_queue.go:661] "[Bing]Pop called on the scheduling queue. current queue includes pods: " [%!s(*framework.QueuedPodInfo=&{0xc00085d810 {13927360829046005056 862640114322 0x38092e0} 0 {13927360829046005056 862640114322 0x38092e0} map[] false}) %!s(*framework.QueuedPodInfo=&{0xc00085d960 {13927360829153709164 862674076588 0x38092e0} 0 {13927360829153709164 862674076588 0x38092e0} map[] false}) %!s(*framework.QueuedPodInfo=&{0xc00085db90 {13927360829222195017 862742562452 0x38092e0} 0 {13927360829222195017 862742562452 0x38092e0} map[] false})]="queue len:" %!s(int=3)="(MISSING)"
I1030 05:15:53.385166       1 scheduling_queue.go:1203] "[Bing]About to try and schedule pod" pod="default/job-train-imgclassfication-cuda-epoch-5"
I1030 05:15:53.385187       1 schedule_one.go:81] "Attempting to schedule pod" pod="default/job-train-imgclassfication-cuda-epoch-5"
I1030 05:15:53.585465       1 schedule_one.go:83] "sleep when attempting to schedule pod to increase job intervals..."
I1030 05:15:53.599925       1 preemption.go:381] "Preemptor Pod preempted victim Pod" preemptor="default/job-train-imgclassfication-cuda-epoch-5" victim="default/job-train-imgclassfication15-cuda-epoch150" node="node2"
I1030 05:15:53.600128       1 eventhandlers.go:206] "Update event for scheduled pod" pod="default/job-train-imgclassfication14-cuda-epoch140"
I1030 05:15:53.611665       1 preemption.go:381] "Preemptor Pod preempted victim Pod" preemptor="default/job-train-imgclassfication-cuda-epoch-5" victim="default/job-train-imgclassfication14-cuda-epoch140" node="node2"
I1030 05:15:53.611783       1 schedule_one.go:875] "Unable to schedule pod; no fit; waiting" pod="default/job-train-imgclassfication-cuda-epoch-5" err="0/1 nodes are available: 1 Insufficient aliyun.com/gpu-mem."
I1030 05:15:53.611850       1 schedule_one.go:951] "Updating pod condition" pod="default/job-train-imgclassfication-cuda-epoch-5" conditionType=PodScheduled conditionStatus=False conditionReason="Unschedulable"
I1030 05:15:53.611881       1 eventhandlers.go:206] "Update event for scheduled pod" pod="default/job-train-imgclassfication14-cuda-epoch140"
I1030 05:15:53.623362       1 schedule_one.go:63] "starting scheduling for next pod..."
I1030 05:15:53.629854       1 eventhandlers.go:206] "Update event for scheduled pod" pod="default/job-train-imgclassfication14-cuda-epoch140"
I1030 05:15:53.824421       1 scheduling_queue.go:661] "[Bing]Pop called on the scheduling queue. current queue includes pods: " [%!s(*framework.QueuedPodInfo=&{0xc00085d960 {13927360829153709164 862674076588 0x38092e0} 0 {13927360829153709164 862674076588 0x38092e0} map[] false}) %!s(*framework.QueuedPodInfo=&{0xc00085d810 {13927360829046005056 862640114322 0x38092e0} 0 {13927360829046005056 862640114322 0x38092e0} map[] false})]="queue len:" %!s(int=2)="(MISSING)"
I1030 05:15:53.824469       1 scheduling_queue.go:1203] "[Bing]About to try and schedule pod" pod="default/job-train-imgclassfication-cuda-epoch-10"
I1030 05:15:53.824483       1 schedule_one.go:81] "Attempting to schedule pod" pod="default/job-train-imgclassfication-cuda-epoch-10"
I1030 05:15:54.024829       1 schedule_one.go:83] "sleep when attempting to schedule pod to increase job intervals..."
I1030 05:15:54.040206       1 eventhandlers.go:206] "Update event for scheduled pod" pod="default/job-train-imgclassfication10-cuda-epoch100"
I1030 05:15:54.046684       1 eventhandlers.go:206] "Update event for scheduled pod" pod="default/job-train-imgclassfication14-cuda-epoch140"
I1030 05:15:54.046732       1 eventhandlers.go:206] "Update event for scheduled pod" pod="default/job-train-imgclassfication15-cuda-epoch150"
I1030 05:15:54.054339       1 eventhandlers.go:206] "Update event for scheduled pod" pod="default/job-train-imgclassfication10-cuda-epoch100"
I1030 05:15:54.054764       1 preemption.go:381] "Preemptor Pod preempted victim Pod" preemptor="default/job-train-imgclassfication-cuda-epoch-10" victim="default/job-train-imgclassfication15-cuda-epoch150" node="node2"
I1030 05:15:54.054841       1 preemption.go:381] "Preemptor Pod preempted victim Pod" preemptor="default/job-train-imgclassfication-cuda-epoch-10" victim="default/job-train-imgclassfication10-cuda-epoch100" node="node2"
I1030 05:15:54.054867       1 preemption.go:381] "Preemptor Pod preempted victim Pod" preemptor="default/job-train-imgclassfication-cuda-epoch-10" victim="default/job-train-imgclassfication14-cuda-epoch140" node="node2"
I1030 05:15:54.055023       1 schedule_one.go:875] "Unable to schedule pod; no fit; waiting" pod="default/job-train-imgclassfication-cuda-epoch-10" err="0/1 nodes are available: 1 Insufficient aliyun.com/gpu-mem."
I1030 05:15:54.055114       1 schedule_one.go:951] "Updating pod condition" pod="default/job-train-imgclassfication-cuda-epoch-10" conditionType=PodScheduled conditionStatus=False conditionReason="Unschedulable"
I1030 05:15:54.066588       1 schedule_one.go:63] "starting scheduling for next pod..."
I1030 05:15:54.074261       1 eventhandlers.go:206] "Update event for scheduled pod" pod="default/job-train-imgclassfication10-cuda-epoch100"
I1030 05:15:54.266763       1 scheduling_queue.go:661] "[Bing]Pop called on the scheduling queue. current queue includes pods: " [%!s(*framework.QueuedPodInfo=&{0xc00085d810 {13927360829046005056 862640114322 0x38092e0} 0 {13927360829046005056 862640114322 0x38092e0} map[] false})]="queue len:" %!s(int=1)="(MISSING)"
I1030 05:15:54.266803       1 scheduling_queue.go:1203] "[Bing]About to try and schedule pod" pod="default/job-train-imgclassfication-cuda-epoch-20"
I1030 05:15:54.266815       1 schedule_one.go:81] "Attempting to schedule pod" pod="default/job-train-imgclassfication-cuda-epoch-20"
I1030 05:15:54.467343       1 schedule_one.go:83] "sleep when attempting to schedule pod to increase job intervals..."
I1030 05:15:54.483967       1 preemption.go:381] "Preemptor Pod preempted victim Pod" preemptor="default/job-train-imgclassfication-cuda-epoch-20" victim="default/job-train-imgclassfication15-cuda-epoch150" node="node2"
I1030 05:15:54.483987       1 preemption.go:381] "Preemptor Pod preempted victim Pod" preemptor="default/job-train-imgclassfication-cuda-epoch-20" victim="default/job-train-imgclassfication10-cuda-epoch100" node="node2"
I1030 05:15:54.484039       1 eventhandlers.go:206] "Update event for scheduled pod" pod="default/job-train-imgclassfication9-cuda-epoch90"
I1030 05:15:54.489690       1 preemption.go:381] "Preemptor Pod preempted victim Pod" preemptor="default/job-train-imgclassfication-cuda-epoch-20" victim="default/job-train-imgclassfication14-cuda-epoch140" node="node2"
I1030 05:15:54.496448       1 preemption.go:381] "Preemptor Pod preempted victim Pod" preemptor="default/job-train-imgclassfication-cuda-epoch-20" victim="default/job-train-imgclassfication9-cuda-epoch90" node="node2"
I1030 05:15:54.496488       1 eventhandlers.go:206] "Update event for scheduled pod" pod="default/job-train-imgclassfication9-cuda-epoch90"
I1030 05:15:54.496582       1 schedule_one.go:875] "Unable to schedule pod; no fit; waiting" pod="default/job-train-imgclassfication-cuda-epoch-20" err="0/1 nodes are available: 1 Insufficient aliyun.com/gpu-mem."
I1030 05:15:54.496647       1 schedule_one.go:951] "Updating pod condition" pod="default/job-train-imgclassfication-cuda-epoch-20" conditionType=PodScheduled conditionStatus=False conditionReason="Unschedulable"
I1030 05:15:54.508543       1 schedule_one.go:63] "starting scheduling for next pod..."
I1030 05:15:54.525702       1 eventhandlers.go:206] "Update event for scheduled pod" pod="default/job-train-imgclassfication9-cuda-epoch90"
I1030 05:15:54.708631       1 scheduling_queue.go:661] "[Bing]Pop called on the scheduling queue. current queue includes pods: " []="queue len:" %!s(int=0)="(MISSING)"
I1030 05:15:54.809931       1 scheduling_queue.go:1203] "[Bing]About to try and schedule pod" pod="default/dummy-highest"
I1030 05:15:54.809985       1 schedule_one.go:81] "Attempting to schedule pod" pod="default/dummy-highest"
I1030 05:15:55.010766       1 schedule_one.go:83] "sleep when attempting to schedule pod to increase job intervals..."
I1030 05:15:55.011324       1 schedule_one.go:875] "Unable to schedule pod; no fit; waiting" pod="default/dummy-highest" err="0/1 nodes are available: 1 Insufficient aliyun.com/gpu-mem. preemption: not eligible due to a terminating pod on the nominated node.."
I1030 05:15:55.011438       1 schedule_one.go:951] "Updating pod condition" pod="default/dummy-highest" conditionType=PodScheduled conditionStatus=False conditionReason="Unschedulable"
I1030 05:15:55.026048       1 schedule_one.go:63] "starting scheduling for next pod..."
I1030 05:15:55.226798       1 scheduling_queue.go:661] "[Bing]Pop called on the scheduling queue. current queue includes pods: " [%!s(*framework.QueuedPodInfo=&{0xc000261260 {13927360829758873938 863279241376 0x38092e0} 1 {13927360829222195017 862742562452 0x38092e0} map[NodeResourcesFit:{}] false})]="queue len:" %!s(int=1)="(MISSING)"
I1030 05:15:55.226845       1 scheduling_queue.go:1203] "[Bing]About to try and schedule pod" pod="default/job-train-imgclassfication-cuda-epoch-5"
I1030 05:15:55.226873       1 schedule_one.go:81] "Attempting to schedule pod" pod="default/job-train-imgclassfication-cuda-epoch-5"
I1030 05:15:55.427736       1 schedule_one.go:83] "sleep when attempting to schedule pod to increase job intervals..."
I1030 05:15:55.428252       1 schedule_one.go:875] "Unable to schedule pod; no fit; waiting" pod="default/job-train-imgclassfication-cuda-epoch-5" err="0/1 nodes are available: 1 Insufficient aliyun.com/gpu-mem. preemption: not eligible due to a terminating pod on the nominated node.."
I1030 05:15:55.428347       1 schedule_one.go:951] "Updating pod condition" pod="default/job-train-imgclassfication-cuda-epoch-5" conditionType=PodScheduled conditionStatus=False conditionReason="Unschedulable"
I1030 05:15:55.440405       1 schedule_one.go:63] "starting scheduling for next pod..."
I1030 05:15:55.641428       1 scheduling_queue.go:661] "[Bing]Pop called on the scheduling queue. current queue includes pods: " []="queue len:" %!s(int=0)="(MISSING)"
I1030 05:15:55.810767       1 scheduling_queue.go:1203] "[Bing]About to try and schedule pod" pod="default/job-train-imgclassfication-cuda-epoch-10"
I1030 05:15:55.810815       1 schedule_one.go:81] "Attempting to schedule pod" pod="default/job-train-imgclassfication-cuda-epoch-10"
I1030 05:15:56.011184       1 schedule_one.go:83] "sleep when attempting to schedule pod to increase job intervals..."
I1030 05:15:56.011719       1 schedule_one.go:875] "Unable to schedule pod; no fit; waiting" pod="default/job-train-imgclassfication-cuda-epoch-10" err="0/1 nodes are available: 1 Insufficient aliyun.com/gpu-mem. preemption: not eligible due to a terminating pod on the nominated node.."
I1030 05:15:56.011798       1 schedule_one.go:951] "Updating pod condition" pod="default/job-train-imgclassfication-cuda-epoch-10" conditionType=PodScheduled conditionStatus=False conditionReason="Unschedulable"
I1030 05:15:56.025177       1 schedule_one.go:63] "starting scheduling for next pod..."
I1030 05:15:56.226254       1 scheduling_queue.go:661] "[Bing]Pop called on the scheduling queue. current queue includes pods: " [%!s(*framework.QueuedPodInfo=&{0xc0007e07e0 {13927360830717407040 864164032646 0x38092e0} 1 {13927360829046005056 862640114322 0x38092e0} map[NodeResourcesFit:{}] false})]="queue len:" %!s(int=1)="(MISSING)"
I1030 05:15:56.226332       1 scheduling_queue.go:1203] "[Bing]About to try and schedule pod" pod="default/job-train-imgclassfication-cuda-epoch-20"
I1030 05:15:56.226359       1 schedule_one.go:81] "Attempting to schedule pod" pod="default/job-train-imgclassfication-cuda-epoch-20"
I1030 05:15:56.426474       1 schedule_one.go:83] "sleep when attempting to schedule pod to increase job intervals..."
I1030 05:15:56.426941       1 schedule_one.go:875] "Unable to schedule pod; no fit; waiting" pod="default/job-train-imgclassfication-cuda-epoch-20" err="0/1 nodes are available: 1 Insufficient aliyun.com/gpu-mem. preemption: not eligible due to a terminating pod on the nominated node.."
I1030 05:15:56.427002       1 schedule_one.go:951] "Updating pod condition" pod="default/job-train-imgclassfication-cuda-epoch-20" conditionType=PodScheduled conditionStatus=False conditionReason="Unschedulable"
I1030 05:15:56.441726       1 schedule_one.go:63] "starting scheduling for next pod..."
I1030 05:15:56.642374       1 scheduling_queue.go:661] "[Bing]Pop called on the scheduling queue. current queue includes pods: " []="queue len:" %!s(int=0)="(MISSING)"
I1030 05:16:01.631480       1 httplog.go:132] "HTTP" verb="GET" URI="/healthz" latency="68.324µs" userAgent="kube-probe/1.27" audit-ID="" srcIP="127.0.0.1:48512" resp=200
I1030 05:16:11.632826       1 httplog.go:132] "HTTP" verb="GET" URI="/healthz" latency="76.44µs" userAgent="kube-probe/1.27" audit-ID="" srcIP="127.0.0.1:55326" resp=200
I1030 05:16:11.918765       1 eventhandlers.go:206] "Update event for scheduled pod" pod="default/job-train-imgclassfication3-cuda-epoch30"
I1030 05:16:13.169955       1 eventhandlers.go:231] "Delete event for scheduled pod" pod="default/job-train-imgclassfication3-cuda-epoch30"
I1030 05:16:13.170083       1 scheduling_queue.go:1203] "[Bing]About to try and schedule pod" pod="default/dummy-highest"
I1030 05:16:13.170097       1 schedule_one.go:81] "Attempting to schedule pod" pod="default/dummy-highest"
I1030 05:16:13.370457       1 schedule_one.go:83] "sleep when attempting to schedule pod to increase job intervals..."
I1030 05:16:13.373878       1 schedule_one.go:63] "starting scheduling for next pod..."
I1030 05:16:13.511321       1 eventhandlers.go:161] "Delete event for unscheduled pod" pod="default/dummy-highest"
I1030 05:16:13.511341       1 eventhandlers.go:186] "Add event for scheduled pod" pod="default/dummy-highest"
I1030 05:16:13.513699       1 schedule_one.go:260] "Successfully bound pod to node" pod="default/dummy-highest" node="node2" evaluatedNodes=1 feasibleNodes=1
I1030 05:16:13.558185       1 eventhandlers.go:206] "Update event for scheduled pod" pod="default/dummy-highest"
I1030 05:16:13.574179       1 scheduling_queue.go:661] "[Bing]Pop called on the scheduling queue. current queue includes pods: " [%!s(*framework.QueuedPodInfo=&{0xc000acff80 {13927360831722823953 865095707738 0x38092e0} 2 {13927360829222195017 862742562452 0x38092e0} map[NodeResourcesFit:{}] false}) %!s(*framework.QueuedPodInfo=&{0xc0008b71f0 {13927360641997789445 688422976067 0x38092e0} 5 {13927360205671620050 282035987245 0x38092e0} map[NodeResourcesFit:{}] false}) %!s(*framework.QueuedPodInfo=&{0xc0002605b0 {13927360652866407874 698554176254 0x38092e0} 6 {13927360205612739548 281977106744 0x38092e0} map[NodeResourcesFit:{}] false}) %!s(*framework.QueuedPodInfo=&{0xc00024f1f0 {13927360641119794988 687618723441 0x38092e0} 6 {13927360205549087692 281913454909 0x38092e0} map[NodeResourcesFit:{}] false}) %!s(*framework.QueuedPodInfo=&{0xc00025c7e0 {13927360832795248396 866094390350 0x38092e0} 2 {13927360829046005056 862640114322 0x38092e0} map[NodeResourcesFit:{}] false}) %!s(*framework.QueuedPodInfo=&{0xc000171c00 {13927360651792117913 697553628126 0x38092e0} 7 {13927360205431737232 281796104442 0x38092e0} map[NodeResourcesFit:{}] false}) %!s(*framework.QueuedPodInfo=&{0xc000261c70 {13927360832380033168 865679175127 0x38092e0} 2 {13927360829153709164 862674076588 0x38092e0} map[NodeResourcesFit:{}] false}) %!s(*framework.QueuedPodInfo=&{0xc00024ebd0 {13927360640718457663 687217386120 0x38092e0} 6 {13927360205485099519 281849466714 0x38092e0} map[NodeResourcesFit:{}] false})]="queue len:" %!s(int=8)="(MISSING)"
I1030 05:16:13.574252       1 scheduling_queue.go:1203] "[Bing]About to try and schedule pod" pod="default/job-train-imgclassfication-cuda-epoch-5"
I1030 05:16:13.574295       1 schedule_one.go:81] "Attempting to schedule pod" pod="default/job-train-imgclassfication-cuda-epoch-5"
I1030 05:16:13.625976       1 eventhandlers.go:206] "Update event for scheduled pod" pod="default/dummy-highest"
I1030 05:16:13.774584       1 schedule_one.go:83] "sleep when attempting to schedule pod to increase job intervals..."
I1030 05:16:13.774963       1 schedule_one.go:875] "Unable to schedule pod; no fit; waiting" pod="default/job-train-imgclassfication-cuda-epoch-5" err="0/1 nodes are available: 1 Insufficient aliyun.com/gpu-mem. preemption: not eligible due to a terminating pod on the nominated node.."
I1030 05:16:13.775026       1 schedule_one.go:951] "Updating pod condition" pod="default/job-train-imgclassfication-cuda-epoch-5" conditionType=PodScheduled conditionStatus=False conditionReason="Unschedulable"
I1030 05:16:13.775053       1 schedule_one.go:63] "starting scheduling for next pod..."
I1030 05:16:13.975620       1 scheduling_queue.go:661] "[Bing]Pop called on the scheduling queue. current queue includes pods: " [%!s(*framework.QueuedPodInfo=&{0xc0008b71f0 {13927360641997789445 688422976067 0x38092e0} 5 {13927360205671620050 282035987245 0x38092e0} map[NodeResourcesFit:{}] false}) %!s(*framework.QueuedPodInfo=&{0xc0002605b0 {13927360652866407874 698554176254 0x38092e0} 6 {13927360205612739548 281977106744 0x38092e0} map[NodeResourcesFit:{}] false}) %!s(*framework.QueuedPodInfo=&{0xc00024f1f0 {13927360641119794988 687618723441 0x38092e0} 6 {13927360205549087692 281913454909 0x38092e0} map[NodeResourcesFit:{}] false}) %!s(*framework.QueuedPodInfo=&{0xc00025c7e0 {13927360832795248396 866094390350 0x38092e0} 2 {13927360829046005056 862640114322 0x38092e0} map[NodeResourcesFit:{}] false}) %!s(*framework.QueuedPodInfo=&{0xc000171c00 {13927360651792117913 697553628126 0x38092e0} 7 {13927360205431737232 281796104442 0x38092e0} map[NodeResourcesFit:{}] false}) %!s(*framework.QueuedPodInfo=&{0xc000261c70 {13927360832380033168 865679175127 0x38092e0} 2 {13927360829153709164 862674076588 0x38092e0} map[NodeResourcesFit:{}] false}) %!s(*framework.QueuedPodInfo=&{0xc00024ebd0 {13927360640718457663 687217386120 0x38092e0} 6 {13927360205485099519 281849466714 0x38092e0} map[NodeResourcesFit:{}] false})]="queue len:" %!s(int=7)="(MISSING)"
I1030 05:16:13.975661       1 scheduling_queue.go:1203] "[Bing]About to try and schedule pod" pod="default/job-train-imgclassfication-cuda-epoch-10"
I1030 05:16:13.975684       1 schedule_one.go:81] "Attempting to schedule pod" pod="default/job-train-imgclassfication-cuda-epoch-10"
I1030 05:16:14.176359       1 schedule_one.go:83] "sleep when attempting to schedule pod to increase job intervals..."
I1030 05:16:14.176769       1 schedule_one.go:875] "Unable to schedule pod; no fit; waiting" pod="default/job-train-imgclassfication-cuda-epoch-10" err="0/1 nodes are available: 1 Insufficient aliyun.com/gpu-mem. preemption: not eligible due to a terminating pod on the nominated node.."
I1030 05:16:14.176834       1 schedule_one.go:951] "Updating pod condition" pod="default/job-train-imgclassfication-cuda-epoch-10" conditionType=PodScheduled conditionStatus=False conditionReason="Unschedulable"
I1030 05:16:14.176865       1 schedule_one.go:63] "starting scheduling for next pod..."
I1030 05:16:14.378002       1 scheduling_queue.go:661] "[Bing]Pop called on the scheduling queue. current queue includes pods: " [%!s(*framework.QueuedPodInfo=&{0xc0008b71f0 {13927360641997789445 688422976067 0x38092e0} 5 {13927360205671620050 282035987245 0x38092e0} map[NodeResourcesFit:{}] false}) %!s(*framework.QueuedPodInfo=&{0xc0002605b0 {13927360652866407874 698554176254 0x38092e0} 6 {13927360205612739548 281977106744 0x38092e0} map[NodeResourcesFit:{}] false}) %!s(*framework.QueuedPodInfo=&{0xc00024f1f0 {13927360641119794988 687618723441 0x38092e0} 6 {13927360205549087692 281913454909 0x38092e0} map[NodeResourcesFit:{}] false}) %!s(*framework.QueuedPodInfo=&{0xc00025c7e0 {13927360832795248396 866094390350 0x38092e0} 2 {13927360829046005056 862640114322 0x38092e0} map[NodeResourcesFit:{}] false}) %!s(*framework.QueuedPodInfo=&{0xc000171c00 {13927360651792117913 697553628126 0x38092e0} 7 {13927360205431737232 281796104442 0x38092e0} map[NodeResourcesFit:{}] false}) %!s(*framework.QueuedPodInfo=&{0xc00024ebd0 {13927360640718457663 687217386120 0x38092e0} 6 {13927360205485099519 281849466714 0x38092e0} map[NodeResourcesFit:{}] false})]="queue len:" %!s(int=6)="(MISSING)"
I1030 05:16:14.378076       1 scheduling_queue.go:1203] "[Bing]About to try and schedule pod" pod="default/job-train-imgclassfication-cuda-epoch-20"
I1030 05:16:14.378104       1 schedule_one.go:81] "Attempting to schedule pod" pod="default/job-train-imgclassfication-cuda-epoch-20"
I1030 05:16:14.578903       1 schedule_one.go:83] "sleep when attempting to schedule pod to increase job intervals..."
I1030 05:16:14.579669       1 schedule_one.go:875] "Unable to schedule pod; no fit; waiting" pod="default/job-train-imgclassfication-cuda-epoch-20" err="0/1 nodes are available: 1 Insufficient aliyun.com/gpu-mem. preemption: not eligible due to a terminating pod on the nominated node.."
I1030 05:16:14.579796       1 schedule_one.go:951] "Updating pod condition" pod="default/job-train-imgclassfication-cuda-epoch-20" conditionType=PodScheduled conditionStatus=False conditionReason="Unschedulable"
I1030 05:16:14.579860       1 schedule_one.go:63] "starting scheduling for next pod..."
I1030 05:16:14.780801       1 scheduling_queue.go:661] "[Bing]Pop called on the scheduling queue. current queue includes pods: " [%!s(*framework.QueuedPodInfo=&{0xc00024f1f0 {13927360641119794988 687618723441 0x38092e0} 6 {13927360205549087692 281913454909 0x38092e0} map[NodeResourcesFit:{}] false}) %!s(*framework.QueuedPodInfo=&{0xc0008b71f0 {13927360641997789445 688422976067 0x38092e0} 5 {13927360205671620050 282035987245 0x38092e0} map[NodeResourcesFit:{}] false}) %!s(*framework.QueuedPodInfo=&{0xc0002605b0 {13927360652866407874 698554176254 0x38092e0} 6 {13927360205612739548 281977106744 0x38092e0} map[NodeResourcesFit:{}] false}) %!s(*framework.QueuedPodInfo=&{0xc000171c00 {13927360651792117913 697553628126 0x38092e0} 7 {13927360205431737232 281796104442 0x38092e0} map[NodeResourcesFit:{}] false}) %!s(*framework.QueuedPodInfo=&{0xc00024ebd0 {13927360640718457663 687217386120 0x38092e0} 6 {13927360205485099519 281849466714 0x38092e0} map[NodeResourcesFit:{}] false})]="queue len:" %!s(int=5)="(MISSING)"
I1030 05:16:14.780871       1 scheduling_queue.go:1203] "[Bing]About to try and schedule pod" pod="default/job-train-imgclassfication16-cuda-epoch160"
I1030 05:16:14.780894       1 schedule_one.go:81] "Attempting to schedule pod" pod="default/job-train-imgclassfication16-cuda-epoch160"
I1030 05:16:14.917152       1 eventhandlers.go:206] "Update event for scheduled pod" pod="default/dummy-highest"
I1030 05:16:14.981032       1 schedule_one.go:83] "sleep when attempting to schedule pod to increase job intervals..."
I1030 05:16:14.981842       1 schedule_one.go:875] "Unable to schedule pod; no fit; waiting" pod="default/job-train-imgclassfication16-cuda-epoch160" err="0/1 nodes are available: 1 Insufficient aliyun.com/gpu-mem. preemption: 0/1 nodes are available: 1 Insufficient aliyun.com/gpu-mem.."
I1030 05:16:14.981964       1 schedule_one.go:951] "Updating pod condition" pod="default/job-train-imgclassfication16-cuda-epoch160" conditionType=PodScheduled conditionStatus=False conditionReason="Unschedulable"
I1030 05:16:14.982022       1 schedule_one.go:63] "starting scheduling for next pod..."
I1030 05:16:15.182788       1 scheduling_queue.go:661] "[Bing]Pop called on the scheduling queue. current queue includes pods: " [%!s(*framework.QueuedPodInfo=&{0xc0008b71f0 {13927360641997789445 688422976067 0x38092e0} 5 {13927360205671620050 282035987245 0x38092e0} map[NodeResourcesFit:{}] false}) %!s(*framework.QueuedPodInfo=&{0xc0002605b0 {13927360652866407874 698554176254 0x38092e0} 6 {13927360205612739548 281977106744 0x38092e0} map[NodeResourcesFit:{}] false}) %!s(*framework.QueuedPodInfo=&{0xc00024f1f0 {13927360641119794988 687618723441 0x38092e0} 6 {13927360205549087692 281913454909 0x38092e0} map[NodeResourcesFit:{}] false}) %!s(*framework.QueuedPodInfo=&{0xc00024ebd0 {13927360640718457663 687217386120 0x38092e0} 6 {13927360205485099519 281849466714 0x38092e0} map[NodeResourcesFit:{}] false})]="queue len:" %!s(int=4)="(MISSING)"
I1030 05:16:15.182835       1 scheduling_queue.go:1203] "[Bing]About to try and schedule pod" pod="default/job-train-imgclassfication17-cuda-epoch170"
I1030 05:16:15.182855       1 schedule_one.go:81] "Attempting to schedule pod" pod="default/job-train-imgclassfication17-cuda-epoch170"
I1030 05:16:15.383214       1 schedule_one.go:83] "sleep when attempting to schedule pod to increase job intervals..."
I1030 05:16:15.383718       1 schedule_one.go:875] "Unable to schedule pod; no fit; waiting" pod="default/job-train-imgclassfication17-cuda-epoch170" err="0/1 nodes are available: 1 Insufficient aliyun.com/gpu-mem. preemption: 0/1 nodes are available: 1 Insufficient aliyun.com/gpu-mem.."
I1030 05:16:15.383796       1 schedule_one.go:951] "Updating pod condition" pod="default/job-train-imgclassfication17-cuda-epoch170" conditionType=PodScheduled conditionStatus=False conditionReason="Unschedulable"
I1030 05:16:15.383828       1 schedule_one.go:63] "starting scheduling for next pod..."
I1030 05:16:15.584370       1 scheduling_queue.go:661] "[Bing]Pop called on the scheduling queue. current queue includes pods: " [%!s(*framework.QueuedPodInfo=&{0xc0008b71f0 {13927360641997789445 688422976067 0x38092e0} 5 {13927360205671620050 282035987245 0x38092e0} map[NodeResourcesFit:{}] false}) %!s(*framework.QueuedPodInfo=&{0xc0002605b0 {13927360652866407874 698554176254 0x38092e0} 6 {13927360205612739548 281977106744 0x38092e0} map[NodeResourcesFit:{}] false}) %!s(*framework.QueuedPodInfo=&{0xc00024f1f0 {13927360641119794988 687618723441 0x38092e0} 6 {13927360205549087692 281913454909 0x38092e0} map[NodeResourcesFit:{}] false})]="queue len:" %!s(int=3)="(MISSING)"
I1030 05:16:15.584410       1 scheduling_queue.go:1203] "[Bing]About to try and schedule pod" pod="default/job-train-imgclassfication18-cuda-epoch180"
I1030 05:16:15.584437       1 schedule_one.go:81] "Attempting to schedule pod" pod="default/job-train-imgclassfication18-cuda-epoch180"
I1030 05:16:15.784738       1 schedule_one.go:83] "sleep when attempting to schedule pod to increase job intervals..."
I1030 05:16:15.785165       1 schedule_one.go:875] "Unable to schedule pod; no fit; waiting" pod="default/job-train-imgclassfication18-cuda-epoch180" err="0/1 nodes are available: 1 Insufficient aliyun.com/gpu-mem. preemption: 0/1 nodes are available: 1 Insufficient aliyun.com/gpu-mem.."
I1030 05:16:15.785240       1 schedule_one.go:951] "Updating pod condition" pod="default/job-train-imgclassfication18-cuda-epoch180" conditionType=PodScheduled conditionStatus=False conditionReason="Unschedulable"
I1030 05:16:15.785267       1 schedule_one.go:63] "starting scheduling for next pod..."
I1030 05:16:15.987003       1 scheduling_queue.go:661] "[Bing]Pop called on the scheduling queue. current queue includes pods: " [%!s(*framework.QueuedPodInfo=&{0xc0008b71f0 {13927360641997789445 688422976067 0x38092e0} 5 {13927360205671620050 282035987245 0x38092e0} map[NodeResourcesFit:{}] false}) %!s(*framework.QueuedPodInfo=&{0xc0002605b0 {13927360652866407874 698554176254 0x38092e0} 6 {13927360205612739548 281977106744 0x38092e0} map[NodeResourcesFit:{}] false})]="queue len:" %!s(int=2)="(MISSING)"
I1030 05:16:15.987064       1 scheduling_queue.go:1203] "[Bing]About to try and schedule pod" pod="default/job-train-imgclassfication19-cuda-epoch190"
I1030 05:16:15.987097       1 schedule_one.go:81] "Attempting to schedule pod" pod="default/job-train-imgclassfication19-cuda-epoch190"
I1030 05:16:16.152655       1 reflector.go:788] vendor/k8s.io/client-go/informers/factory.go:150: Watch close - *v1.PersistentVolumeClaim total 10 items received
I1030 05:16:16.187770       1 schedule_one.go:83] "sleep when attempting to schedule pod to increase job intervals..."
I1030 05:16:16.188219       1 schedule_one.go:875] "Unable to schedule pod; no fit; waiting" pod="default/job-train-imgclassfication19-cuda-epoch190" err="0/1 nodes are available: 1 Insufficient aliyun.com/gpu-mem. preemption: 0/1 nodes are available: 1 Insufficient aliyun.com/gpu-mem.."
I1030 05:16:16.188295       1 schedule_one.go:951] "Updating pod condition" pod="default/job-train-imgclassfication19-cuda-epoch190" conditionType=PodScheduled conditionStatus=False conditionReason="Unschedulable"
I1030 05:16:16.188354       1 schedule_one.go:63] "starting scheduling for next pod..."
I1030 05:16:16.388756       1 scheduling_queue.go:661] "[Bing]Pop called on the scheduling queue. current queue includes pods: " [%!s(*framework.QueuedPodInfo=&{0xc0008b71f0 {13927360641997789445 688422976067 0x38092e0} 5 {13927360205671620050 282035987245 0x38092e0} map[NodeResourcesFit:{}] false})]="queue len:" %!s(int=1)="(MISSING)"
I1030 05:16:16.388798       1 scheduling_queue.go:1203] "[Bing]About to try and schedule pod" pod="default/job-train-imgclassfication20-cuda-epoch200"
I1030 05:16:16.388818       1 schedule_one.go:81] "Attempting to schedule pod" pod="default/job-train-imgclassfication20-cuda-epoch200"
I1030 05:16:16.589279       1 schedule_one.go:83] "sleep when attempting to schedule pod to increase job intervals..."
I1030 05:16:16.590203       1 schedule_one.go:875] "Unable to schedule pod; no fit; waiting" pod="default/job-train-imgclassfication20-cuda-epoch200" err="0/1 nodes are available: 1 Insufficient aliyun.com/gpu-mem. preemption: 0/1 nodes are available: 1 Insufficient aliyun.com/gpu-mem.."
I1030 05:16:16.590312       1 schedule_one.go:951] "Updating pod condition" pod="default/job-train-imgclassfication20-cuda-epoch200" conditionType=PodScheduled conditionStatus=False conditionReason="Unschedulable"
I1030 05:16:16.590371       1 schedule_one.go:63] "starting scheduling for next pod..."
I1030 05:16:16.791038       1 scheduling_queue.go:661] "[Bing]Pop called on the scheduling queue. current queue includes pods: " []="queue len:" %!s(int=0)="(MISSING)"
I1030 05:16:17.830708       1 scheduling_queue.go:1203] "[Bing]About to try and schedule pod" pod="default/job-train-imgclassfication-cuda-epoch-5"
I1030 05:16:17.830771       1 schedule_one.go:81] "Attempting to schedule pod" pod="default/job-train-imgclassfication-cuda-epoch-5"
I1030 05:16:18.031198       1 schedule_one.go:83] "sleep when attempting to schedule pod to increase job intervals..."
I1030 05:16:18.031893       1 schedule_one.go:875] "Unable to schedule pod; no fit; waiting" pod="default/job-train-imgclassfication-cuda-epoch-5" err="0/1 nodes are available: 1 Insufficient aliyun.com/gpu-mem. preemption: not eligible due to a terminating pod on the nominated node.."
I1030 05:16:18.032023       1 schedule_one.go:951] "Updating pod condition" pod="default/job-train-imgclassfication-cuda-epoch-5" conditionType=PodScheduled conditionStatus=False conditionReason="Unschedulable"
I1030 05:16:18.032086       1 schedule_one.go:63] "starting scheduling for next pod..."
I1030 05:16:18.232163       1 scheduling_queue.go:661] "[Bing]Pop called on the scheduling queue. current queue includes pods: " []="queue len:" %!s(int=0)="(MISSING)"
I1030 05:16:21.632545       1 httplog.go:132] "HTTP" verb="GET" URI="/healthz" latency="99.406µs" userAgent="kube-probe/1.27" audit-ID="" srcIP="127.0.0.1:55458" resp=200
I1030 05:16:23.969191       1 eventhandlers.go:231] "Delete event for scheduled pod" pod="default/job-train-imgclassfication15-cuda-epoch150"
I1030 05:16:23.969374       1 scheduling_queue.go:1203] "[Bing]About to try and schedule pod" pod="default/job-train-imgclassfication-cuda-epoch-10"
I1030 05:16:23.969395       1 schedule_one.go:81] "Attempting to schedule pod" pod="default/job-train-imgclassfication-cuda-epoch-10"
I1030 05:16:24.169723       1 schedule_one.go:83] "sleep when attempting to schedule pod to increase job intervals..."
I1030 05:16:24.170144       1 schedule_one.go:875] "Unable to schedule pod; no fit; waiting" pod="default/job-train-imgclassfication-cuda-epoch-10" err="0/1 nodes are available: 1 Insufficient aliyun.com/gpu-mem. preemption: not eligible due to a terminating pod on the nominated node.."
I1030 05:16:24.170220       1 schedule_one.go:951] "Updating pod condition" pod="default/job-train-imgclassfication-cuda-epoch-10" conditionType=PodScheduled conditionStatus=False conditionReason="Unschedulable"
I1030 05:16:24.170250       1 schedule_one.go:63] "starting scheduling for next pod..."
I1030 05:16:24.313358       1 eventhandlers.go:231] "Delete event for scheduled pod" pod="default/job-train-imgclassfication14-cuda-epoch140"
I1030 05:16:24.370610       1 scheduling_queue.go:661] "[Bing]Pop called on the scheduling queue. current queue includes pods: " [%!s(*framework.QueuedPodInfo=&{0xc0003a32d0 {13927360852275362391 884247151542 0x38092e0} 3 {13927360829046005056 862640114322 0x38092e0} map[NodeResourcesFit:{}] false})]="queue len:" %!s(int=1)="(MISSING)"
I1030 05:16:24.370689       1 scheduling_queue.go:1203] "[Bing]About to try and schedule pod" pod="default/job-train-imgclassfication-cuda-epoch-20"
I1030 05:16:24.370720       1 schedule_one.go:81] "Attempting to schedule pod" pod="default/job-train-imgclassfication-cuda-epoch-20"
I1030 05:16:24.570754       1 eventhandlers.go:231] "Delete event for scheduled pod" pod="default/job-train-imgclassfication10-cuda-epoch100"
I1030 05:16:24.570792       1 schedule_one.go:83] "sleep when attempting to schedule pod to increase job intervals..."
I1030 05:16:24.574508       1 schedule_one.go:63] "starting scheduling for next pod..."
I1030 05:16:24.698344       1 eventhandlers.go:186] "Add event for scheduled pod" pod="default/job-train-imgclassfication-cuda-epoch-20"
I1030 05:16:24.698350       1 eventhandlers.go:161] "Delete event for unscheduled pod" pod="default/job-train-imgclassfication-cuda-epoch-20"
I1030 05:16:24.700750       1 schedule_one.go:260] "Successfully bound pod to node" pod="default/job-train-imgclassfication-cuda-epoch-20" node="node2" evaluatedNodes=1 feasibleNodes=1
I1030 05:16:24.748399       1 eventhandlers.go:206] "Update event for scheduled pod" pod="default/job-train-imgclassfication-cuda-epoch-20"
I1030 05:16:24.775292       1 scheduling_queue.go:661] "[Bing]Pop called on the scheduling queue. current queue includes pods: " []="queue len:" %!s(int=0)="(MISSING)"
I1030 05:16:24.833079       1 eventhandlers.go:206] "Update event for scheduled pod" pod="default/job-train-imgclassfication-cuda-epoch-20"
I1030 05:16:25.080618       1 eventhandlers.go:231] "Delete event for scheduled pod" pod="default/job-train-imgclassfication9-cuda-epoch90"
I1030 05:16:25.834435       1 scheduling_queue.go:1203] "[Bing]About to try and schedule pod" pod="default/job-train-imgclassfication16-cuda-epoch160"
I1030 05:16:25.834497       1 schedule_one.go:81] "Attempting to schedule pod" pod="default/job-train-imgclassfication16-cuda-epoch160"
I1030 05:16:25.983978       1 eventhandlers.go:206] "Update event for scheduled pod" pod="default/job-train-imgclassfication-cuda-epoch-20"
I1030 05:16:26.034870       1 schedule_one.go:83] "sleep when attempting to schedule pod to increase job intervals..."
I1030 05:16:26.039630       1 schedule_one.go:63] "starting scheduling for next pod..."
I1030 05:16:26.164549       1 eventhandlers.go:186] "Add event for scheduled pod" pod="default/job-train-imgclassfication16-cuda-epoch160"
I1030 05:16:26.164564       1 eventhandlers.go:161] "Delete event for unscheduled pod" pod="default/job-train-imgclassfication16-cuda-epoch160"
I1030 05:16:26.166460       1 schedule_one.go:260] "Successfully bound pod to node" pod="default/job-train-imgclassfication16-cuda-epoch160" node="node2" evaluatedNodes=1 feasibleNodes=1
I1030 05:16:26.205660       1 eventhandlers.go:206] "Update event for scheduled pod" pod="default/job-train-imgclassfication16-cuda-epoch160"
I1030 05:16:26.240774       1 scheduling_queue.go:661] "[Bing]Pop called on the scheduling queue. current queue includes pods: " [%!s(*framework.QueuedPodInfo=&{0xc0008b7f80 {13927360853554567746 885452615050 0x38092e0} 7 {13927360205549087692 281913454909 0x38092e0} map[NodeResourcesFit:{}] false}) %!s(*framework.QueuedPodInfo=&{0xc0008b7420 {13927360853153126659 885051173953 0x38092e0} 7 {13927360205485099519 281849466714 0x38092e0} map[NodeResourcesFit:{}] false})]="queue len:" %!s(int=2)="(MISSING)"
I1030 05:16:26.240829       1 scheduling_queue.go:1203] "[Bing]About to try and schedule pod" pod="default/job-train-imgclassfication17-cuda-epoch170"
I1030 05:16:26.240856       1 schedule_one.go:81] "Attempting to schedule pod" pod="default/job-train-imgclassfication17-cuda-epoch170"
I1030 05:16:26.267457       1 eventhandlers.go:206] "Update event for scheduled pod" pod="default/job-train-imgclassfication16-cuda-epoch160"
I1030 05:16:26.441571       1 schedule_one.go:83] "sleep when attempting to schedule pod to increase job intervals..."
I1030 05:16:26.442307       1 schedule_one.go:875] "Unable to schedule pod; no fit; waiting" pod="default/job-train-imgclassfication17-cuda-epoch170" err="0/1 nodes are available: 1 Insufficient aliyun.com/gpu-mem. preemption: 0/1 nodes are available: 1 Insufficient aliyun.com/gpu-mem.."
I1030 05:16:26.442422       1 schedule_one.go:951] "Updating pod condition" pod="default/job-train-imgclassfication17-cuda-epoch170" conditionType=PodScheduled conditionStatus=False conditionReason="Unschedulable"
I1030 05:16:26.442480       1 schedule_one.go:63] "starting scheduling for next pod..."
I1030 05:16:26.643037       1 scheduling_queue.go:661] "[Bing]Pop called on the scheduling queue. current queue includes pods: " [%!s(*framework.QueuedPodInfo=&{0xc0008b7f80 {13927360853554567746 885452615050 0x38092e0} 7 {13927360205549087692 281913454909 0x38092e0} map[NodeResourcesFit:{}] false})]="queue len:" %!s(int=1)="(MISSING)"
I1030 05:16:26.643093       1 scheduling_queue.go:1203] "[Bing]About to try and schedule pod" pod="default/job-train-imgclassfication18-cuda-epoch180"
I1030 05:16:26.643129       1 schedule_one.go:81] "Attempting to schedule pod" pod="default/job-train-imgclassfication18-cuda-epoch180"
I1030 05:16:26.844118       1 schedule_one.go:83] "sleep when attempting to schedule pod to increase job intervals..."
I1030 05:16:26.844985       1 schedule_one.go:875] "Unable to schedule pod; no fit; waiting" pod="default/job-train-imgclassfication18-cuda-epoch180" err="0/1 nodes are available: 1 Insufficient aliyun.com/gpu-mem. preemption: 0/1 nodes are available: 1 Insufficient aliyun.com/gpu-mem.."
I1030 05:16:26.845119       1 schedule_one.go:951] "Updating pod condition" pod="default/job-train-imgclassfication18-cuda-epoch180" conditionType=PodScheduled conditionStatus=False conditionReason="Unschedulable"
I1030 05:16:26.845192       1 schedule_one.go:63] "starting scheduling for next pod..."
I1030 05:16:27.045568       1 scheduling_queue.go:661] "[Bing]Pop called on the scheduling queue. current queue includes pods: " [%!s(*framework.QueuedPodInfo=&{0xc00024f500 {13927360854031371018 885855676498 0x38092e0} 7 {13927360205612739548 281977106744 0x38092e0} map[NodeResourcesFit:{}] false}) %!s(*framework.QueuedPodInfo=&{0xc0003a3f10 {13927360854433359326 886257664803 0x38092e0} 6 {13927360205671620050 282035987245 0x38092e0} map[NodeResourcesFit:{}] false}) %!s(*framework.QueuedPodInfo=&{0xc0002e4540 {13927360856022552952 887699374819 0x38092e0} 4 {13927360829222195017 862742562452 0x38092e0} map[NodeResourcesFit:{}] false})]="queue len:" %!s(int=3)="(MISSING)"
I1030 05:16:27.045608       1 scheduling_queue.go:1203] "[Bing]About to try and schedule pod" pod="default/job-train-imgclassfication-cuda-epoch-5"
I1030 05:16:27.045625       1 schedule_one.go:81] "Attempting to schedule pod" pod="default/job-train-imgclassfication-cuda-epoch-5"
I1030 05:16:27.151172       1 reflector.go:788] pkg/server/dynamiccertificates/configmap_cafile_content.go:206: Watch close - *v1.ConfigMap total 10 items received
I1030 05:16:27.246531       1 schedule_one.go:83] "sleep when attempting to schedule pod to increase job intervals..."
I1030 05:16:27.252618       1 schedule_one.go:63] "starting scheduling for next pod..."
I1030 05:16:27.392670       1 eventhandlers.go:186] "Add event for scheduled pod" pod="default/job-train-imgclassfication-cuda-epoch-5"
I1030 05:16:27.392751       1 eventhandlers.go:161] "Delete event for unscheduled pod" pod="default/job-train-imgclassfication-cuda-epoch-5"
I1030 05:16:27.399104       1 schedule_one.go:260] "Successfully bound pod to node" pod="default/job-train-imgclassfication-cuda-epoch-5" node="node2" evaluatedNodes=1 feasibleNodes=1
I1030 05:16:27.415283       1 eventhandlers.go:206] "Update event for scheduled pod" pod="default/job-train-imgclassfication-cuda-epoch-5"
I1030 05:16:27.453328       1 scheduling_queue.go:661] "[Bing]Pop called on the scheduling queue. current queue includes pods: " [%!s(*framework.QueuedPodInfo=&{0xc00024f500 {13927360854031371018 885855676498 0x38092e0} 7 {13927360205612739548 281977106744 0x38092e0} map[NodeResourcesFit:{}] false}) %!s(*framework.QueuedPodInfo=&{0xc0003a3f10 {13927360854433359326 886257664803 0x38092e0} 6 {13927360205671620050 282035987245 0x38092e0} map[NodeResourcesFit:{}] false})]="queue len:" %!s(int=2)="(MISSING)"
I1030 05:16:27.453388       1 scheduling_queue.go:1203] "[Bing]About to try and schedule pod" pod="default/job-train-imgclassfication19-cuda-epoch190"
I1030 05:16:27.453424       1 schedule_one.go:81] "Attempting to schedule pod" pod="default/job-train-imgclassfication19-cuda-epoch190"
I1030 05:16:27.476535       1 eventhandlers.go:206] "Update event for scheduled pod" pod="default/job-train-imgclassfication-cuda-epoch-5"
I1030 05:16:27.653930       1 schedule_one.go:83] "sleep when attempting to schedule pod to increase job intervals..."
I1030 05:16:27.654265       1 schedule_one.go:875] "Unable to schedule pod; no fit; waiting" pod="default/job-train-imgclassfication19-cuda-epoch190" err="0/1 nodes are available: 1 Insufficient aliyun.com/gpu-mem. preemption: 0/1 nodes are available: 1 Insufficient aliyun.com/gpu-mem.."
I1030 05:16:27.654332       1 schedule_one.go:951] "Updating pod condition" pod="default/job-train-imgclassfication19-cuda-epoch190" conditionType=PodScheduled conditionStatus=False conditionReason="Unschedulable"
I1030 05:16:27.654357       1 schedule_one.go:63] "starting scheduling for next pod..."
I1030 05:16:27.855410       1 scheduling_queue.go:661] "[Bing]Pop called on the scheduling queue. current queue includes pods: " [%!s(*framework.QueuedPodInfo=&{0xc0003a3f10 {13927360854433359326 886257664803 0x38092e0} 6 {13927360205671620050 282035987245 0x38092e0} map[NodeResourcesFit:{}] false})]="queue len:" %!s(int=1)="(MISSING)"
I1030 05:16:27.855461       1 scheduling_queue.go:1203] "[Bing]About to try and schedule pod" pod="default/job-train-imgclassfication20-cuda-epoch200"
I1030 05:16:27.855484       1 schedule_one.go:81] "Attempting to schedule pod" pod="default/job-train-imgclassfication20-cuda-epoch200"
I1030 05:16:27.998316       1 eventhandlers.go:206] "Update event for scheduled pod" pod="default/job-train-imgclassfication16-cuda-epoch160"
I1030 05:16:28.056222       1 schedule_one.go:83] "sleep when attempting to schedule pod to increase job intervals..."
I1030 05:16:28.056567       1 schedule_one.go:875] "Unable to schedule pod; no fit; waiting" pod="default/job-train-imgclassfication20-cuda-epoch200" err="0/1 nodes are available: 1 Insufficient aliyun.com/gpu-mem. preemption: 0/1 nodes are available: 1 Insufficient aliyun.com/gpu-mem.."
I1030 05:16:28.056634       1 schedule_one.go:951] "Updating pod condition" pod="default/job-train-imgclassfication20-cuda-epoch200" conditionType=PodScheduled conditionStatus=False conditionReason="Unschedulable"
I1030 05:16:28.056655       1 schedule_one.go:63] "starting scheduling for next pod..."
I1030 05:16:28.257468       1 scheduling_queue.go:661] "[Bing]Pop called on the scheduling queue. current queue includes pods: " []="queue len:" %!s(int=0)="(MISSING)"
I1030 05:16:29.002690       1 eventhandlers.go:206] "Update event for scheduled pod" pod="default/job-train-imgclassfication-cuda-epoch-5"
I1030 05:16:31.628434       1 httplog.go:132] "HTTP" verb="GET" URI="/healthz" latency="80.441µs" userAgent="kube-probe/1.27" audit-ID="" srcIP="127.0.0.1:55634" resp=200
I1030 05:16:32.838361       1 scheduling_queue.go:1203] "[Bing]About to try and schedule pod" pod="default/job-train-imgclassfication-cuda-epoch-10"
I1030 05:16:32.838390       1 schedule_one.go:81] "Attempting to schedule pod" pod="default/job-train-imgclassfication-cuda-epoch-10"
I1030 05:16:33.038741       1 schedule_one.go:83] "sleep when attempting to schedule pod to increase job intervals..."
I1030 05:16:33.068722       1 schedule_one.go:63] "starting scheduling for next pod..."
I1030 05:16:33.198687       1 eventhandlers.go:161] "Delete event for unscheduled pod" pod="default/job-train-imgclassfication-cuda-epoch-10"
I1030 05:16:33.198753       1 eventhandlers.go:186] "Add event for scheduled pod" pod="default/job-train-imgclassfication-cuda-epoch-10"
I1030 05:16:33.200135       1 schedule_one.go:260] "Successfully bound pod to node" pod="default/job-train-imgclassfication-cuda-epoch-10" node="node2" evaluatedNodes=1 feasibleNodes=1
I1030 05:16:33.219546       1 eventhandlers.go:206] "Update event for scheduled pod" pod="default/job-train-imgclassfication-cuda-epoch-10"
I1030 05:16:33.269440       1 scheduling_queue.go:661] "[Bing]Pop called on the scheduling queue. current queue includes pods: " []="queue len:" %!s(int=0)="(MISSING)"
I1030 05:16:33.277369       1 eventhandlers.go:206] "Update event for scheduled pod" pod="default/job-train-imgclassfication-cuda-epoch-10"
I1030 05:16:35.020856       1 eventhandlers.go:206] "Update event for scheduled pod" pod="default/job-train-imgclassfication-cuda-epoch-10"
I1030 05:16:36.843091       1 scheduling_queue.go:1203] "[Bing]About to try and schedule pod" pod="default/job-train-imgclassfication17-cuda-epoch170"
I1030 05:16:36.843142       1 schedule_one.go:81] "Attempting to schedule pod" pod="default/job-train-imgclassfication17-cuda-epoch170"
I1030 05:16:37.043488       1 schedule_one.go:83] "sleep when attempting to schedule pod to increase job intervals..."
I1030 05:16:37.043818       1 schedule_one.go:875] "Unable to schedule pod; no fit; waiting" pod="default/job-train-imgclassfication17-cuda-epoch170" err="0/1 nodes are available: 1 Insufficient aliyun.com/gpu-mem. preemption: 0/1 nodes are available: 1 Insufficient aliyun.com/gpu-mem.."
I1030 05:16:37.043912       1 schedule_one.go:951] "Updating pod condition" pod="default/job-train-imgclassfication17-cuda-epoch170" conditionType=PodScheduled conditionStatus=False conditionReason="Unschedulable"
I1030 05:16:37.043941       1 schedule_one.go:63] "starting scheduling for next pod..."
I1030 05:16:37.244634       1 scheduling_queue.go:661] "[Bing]Pop called on the scheduling queue. current queue includes pods: " []="queue len:" %!s(int=0)="(MISSING)"
I1030 05:16:37.843398       1 scheduling_queue.go:1203] "[Bing]About to try and schedule pod" pod="default/job-train-imgclassfication19-cuda-epoch190"
I1030 05:16:37.843441       1 schedule_one.go:81] "Attempting to schedule pod" pod="default/job-train-imgclassfication19-cuda-epoch190"
I1030 05:16:38.043804       1 schedule_one.go:83] "sleep when attempting to schedule pod to increase job intervals..."
I1030 05:16:38.044207       1 schedule_one.go:875] "Unable to schedule pod; no fit; waiting" pod="default/job-train-imgclassfication19-cuda-epoch190" err="0/1 nodes are available: 1 Insufficient aliyun.com/gpu-mem. preemption: 0/1 nodes are available: 1 Insufficient aliyun.com/gpu-mem.."
I1030 05:16:38.044328       1 schedule_one.go:951] "Updating pod condition" pod="default/job-train-imgclassfication19-cuda-epoch190" conditionType=PodScheduled conditionStatus=False conditionReason="Unschedulable"
I1030 05:16:38.044381       1 schedule_one.go:63] "starting scheduling for next pod..."
I1030 05:16:38.245056       1 scheduling_queue.go:661] "[Bing]Pop called on the scheduling queue. current queue includes pods: " []="queue len:" %!s(int=0)="(MISSING)"
I1030 05:16:38.844489       1 scheduling_queue.go:1203] "[Bing]About to try and schedule pod" pod="default/job-train-imgclassfication20-cuda-epoch200"
I1030 05:16:38.844545       1 schedule_one.go:81] "Attempting to schedule pod" pod="default/job-train-imgclassfication20-cuda-epoch200"
I1030 05:16:39.044908       1 schedule_one.go:83] "sleep when attempting to schedule pod to increase job intervals..."
I1030 05:16:39.045334       1 schedule_one.go:875] "Unable to schedule pod; no fit; waiting" pod="default/job-train-imgclassfication20-cuda-epoch200" err="0/1 nodes are available: 1 Insufficient aliyun.com/gpu-mem. preemption: 0/1 nodes are available: 1 Insufficient aliyun.com/gpu-mem.."
I1030 05:16:39.045449       1 schedule_one.go:951] "Updating pod condition" pod="default/job-train-imgclassfication20-cuda-epoch200" conditionType=PodScheduled conditionStatus=False conditionReason="Unschedulable"
I1030 05:16:39.045501       1 schedule_one.go:63] "starting scheduling for next pod..."
I1030 05:16:39.245659       1 scheduling_queue.go:661] "[Bing]Pop called on the scheduling queue. current queue includes pods: " []="queue len:" %!s(int=0)="(MISSING)"
I1030 05:16:41.633955       1 httplog.go:132] "HTTP" verb="GET" URI="/healthz" latency="86.079µs" userAgent="kube-probe/1.27" audit-ID="" srcIP="127.0.0.1:35744" resp=200
I1030 05:16:51.627974       1 httplog.go:132] "HTTP" verb="GET" URI="/healthz" latency="69.097µs" userAgent="kube-probe/1.27" audit-ID="" srcIP="127.0.0.1:47690" resp=200
I1030 05:17:01.628860       1 httplog.go:132] "HTTP" verb="GET" URI="/healthz" latency="111.816µs" userAgent="kube-probe/1.27" audit-ID="" srcIP="127.0.0.1:49764" resp=200
I1030 05:17:04.151688       1 reflector.go:788] vendor/k8s.io/client-go/informers/factory.go:150: Watch close - *v1.PodDisruptionBudget total 8 items received
I1030 05:17:08.116038       1 eventhandlers.go:206] "Update event for scheduled pod" pod="default/dummy-highest"
I1030 05:17:08.151275       1 reflector.go:788] vendor/k8s.io/client-go/informers/factory.go:150: Watch close - *v1.CSIDriver total 11 items received
I1030 05:17:09.357743       1 eventhandlers.go:231] "Delete event for scheduled pod" pod="default/dummy-highest"
I1030 05:17:09.357924       1 scheduling_queue.go:1203] "[Bing]About to try and schedule pod" pod="default/job-train-imgclassfication17-cuda-epoch170"
I1030 05:17:09.357952       1 schedule_one.go:81] "Attempting to schedule pod" pod="default/job-train-imgclassfication17-cuda-epoch170"
I1030 05:17:09.558352       1 schedule_one.go:83] "sleep when attempting to schedule pod to increase job intervals..."
I1030 05:17:09.561182       1 schedule_one.go:63] "starting scheduling for next pod..."
I1030 05:17:09.687399       1 eventhandlers.go:161] "Delete event for unscheduled pod" pod="default/job-train-imgclassfication17-cuda-epoch170"
I1030 05:17:09.687467       1 eventhandlers.go:186] "Add event for scheduled pod" pod="default/job-train-imgclassfication17-cuda-epoch170"
I1030 05:17:09.688723       1 schedule_one.go:260] "Successfully bound pod to node" pod="default/job-train-imgclassfication17-cuda-epoch170" node="node2" evaluatedNodes=1 feasibleNodes=1
I1030 05:17:09.726566       1 eventhandlers.go:206] "Update event for scheduled pod" pod="default/job-train-imgclassfication17-cuda-epoch170"
I1030 05:17:09.761754       1 scheduling_queue.go:661] "[Bing]Pop called on the scheduling queue. current queue includes pods: " [%!s(*framework.QueuedPodInfo=&{0xc000346a80 {13927360878584573588 908712817135 0x38092e0} 8 {13927360205671620050 282035987245 0x38092e0} map[NodeResourcesFit:{}] false}) %!s(*framework.QueuedPodInfo=&{0xc0002f2a80 {13927360865425579371 896512466634 0x38092e0} 8 {13927360205549087692 281913454909 0x38092e0} map[NodeResourcesFit:{}] false}) %!s(*framework.QueuedPodInfo=&{0xc00035c7e0 {13927360877509700718 907711686073 0x38092e0} 9 {13927360205612739548 281977106744 0x38092e0} map[NodeResourcesFit:{}] false})]="queue len:" %!s(int=3)="(MISSING)"
I1030 05:17:09.761793       1 scheduling_queue.go:1203] "[Bing]About to try and schedule pod" pod="default/job-train-imgclassfication18-cuda-epoch180"
I1030 05:17:09.761812       1 schedule_one.go:81] "Attempting to schedule pod" pod="default/job-train-imgclassfication18-cuda-epoch180"
I1030 05:17:09.787343       1 eventhandlers.go:206] "Update event for scheduled pod" pod="default/job-train-imgclassfication17-cuda-epoch170"
I1030 05:17:09.962566       1 schedule_one.go:83] "sleep when attempting to schedule pod to increase job intervals..."
I1030 05:17:09.962940       1 schedule_one.go:875] "Unable to schedule pod; no fit; waiting" pod="default/job-train-imgclassfication18-cuda-epoch180" err="0/1 nodes are available: 1 Insufficient aliyun.com/gpu-mem. preemption: 0/1 nodes are available: 1 Insufficient aliyun.com/gpu-mem.."
I1030 05:17:09.963034       1 schedule_one.go:951] "Updating pod condition" pod="default/job-train-imgclassfication18-cuda-epoch180" conditionType=PodScheduled conditionStatus=False conditionReason="Unschedulable"
I1030 05:17:09.963062       1 schedule_one.go:63] "starting scheduling for next pod..."
I1030 05:17:10.163934       1 scheduling_queue.go:661] "[Bing]Pop called on the scheduling queue. current queue includes pods: " [%!s(*framework.QueuedPodInfo=&{0xc00035c7e0 {13927360877509700718 907711686073 0x38092e0} 9 {13927360205612739548 281977106744 0x38092e0} map[NodeResourcesFit:{}] false}) %!s(*framework.QueuedPodInfo=&{0xc000346a80 {13927360878584573588 908712817135 0x38092e0} 8 {13927360205671620050 282035987245 0x38092e0} map[NodeResourcesFit:{}] false})]="queue len:" %!s(int=2)="(MISSING)"
I1030 05:17:10.163974       1 scheduling_queue.go:1203] "[Bing]About to try and schedule pod" pod="default/job-train-imgclassfication19-cuda-epoch190"
I1030 05:17:10.163996       1 schedule_one.go:81] "Attempting to schedule pod" pod="default/job-train-imgclassfication19-cuda-epoch190"
I1030 05:17:10.364371       1 schedule_one.go:83] "sleep when attempting to schedule pod to increase job intervals..."
I1030 05:17:10.364650       1 schedule_one.go:875] "Unable to schedule pod; no fit; waiting" pod="default/job-train-imgclassfication19-cuda-epoch190" err="0/1 nodes are available: 1 Insufficient aliyun.com/gpu-mem. preemption: 0/1 nodes are available: 1 Insufficient aliyun.com/gpu-mem.."
I1030 05:17:10.364719       1 schedule_one.go:951] "Updating pod condition" pod="default/job-train-imgclassfication19-cuda-epoch190" conditionType=PodScheduled conditionStatus=False conditionReason="Unschedulable"
I1030 05:17:10.364743       1 schedule_one.go:63] "starting scheduling for next pod..."
I1030 05:17:10.565320       1 scheduling_queue.go:661] "[Bing]Pop called on the scheduling queue. current queue includes pods: " [%!s(*framework.QueuedPodInfo=&{0xc000346a80 {13927360878584573588 908712817135 0x38092e0} 8 {13927360205671620050 282035987245 0x38092e0} map[NodeResourcesFit:{}] false})]="queue len:" %!s(int=1)="(MISSING)"
I1030 05:17:10.565363       1 scheduling_queue.go:1203] "[Bing]About to try and schedule pod" pod="default/job-train-imgclassfication20-cuda-epoch200"
I1030 05:17:10.565386       1 schedule_one.go:81] "Attempting to schedule pod" pod="default/job-train-imgclassfication20-cuda-epoch200"
I1030 05:17:10.765901       1 schedule_one.go:83] "sleep when attempting to schedule pod to increase job intervals..."
I1030 05:17:10.766353       1 schedule_one.go:875] "Unable to schedule pod; no fit; waiting" pod="default/job-train-imgclassfication20-cuda-epoch200" err="0/1 nodes are available: 1 Insufficient aliyun.com/gpu-mem. preemption: 0/1 nodes are available: 1 Insufficient aliyun.com/gpu-mem.."
I1030 05:17:10.766471       1 schedule_one.go:951] "Updating pod condition" pod="default/job-train-imgclassfication20-cuda-epoch200" conditionType=PodScheduled conditionStatus=False conditionReason="Unschedulable"
I1030 05:17:10.766524       1 schedule_one.go:63] "starting scheduling for next pod..."
I1030 05:17:10.967181       1 scheduling_queue.go:661] "[Bing]Pop called on the scheduling queue. current queue includes pods: " []="queue len:" %!s(int=0)="(MISSING)"
I1030 05:17:11.127104       1 eventhandlers.go:206] "Update event for scheduled pod" pod="default/job-train-imgclassfication17-cuda-epoch170"
I1030 05:17:11.634194       1 httplog.go:132] "HTTP" verb="GET" URI="/healthz" latency="101.517µs" userAgent="kube-probe/1.27" audit-ID="" srcIP="127.0.0.1:60270" resp=200
I1030 05:17:16.154698       1 reflector.go:788] vendor/k8s.io/client-go/informers/factory.go:150: Watch close - *v1.Node total 7 items received
I1030 05:17:20.874668       1 scheduling_queue.go:1203] "[Bing]About to try and schedule pod" pod="default/job-train-imgclassfication18-cuda-epoch180"
I1030 05:17:20.874712       1 schedule_one.go:81] "Attempting to schedule pod" pod="default/job-train-imgclassfication18-cuda-epoch180"
I1030 05:17:21.074857       1 schedule_one.go:83] "sleep when attempting to schedule pod to increase job intervals..."
I1030 05:17:21.075176       1 schedule_one.go:875] "Unable to schedule pod; no fit; waiting" pod="default/job-train-imgclassfication18-cuda-epoch180" err="0/1 nodes are available: 1 Insufficient aliyun.com/gpu-mem. preemption: 0/1 nodes are available: 1 Insufficient aliyun.com/gpu-mem.."
I1030 05:17:21.075242       1 schedule_one.go:951] "Updating pod condition" pod="default/job-train-imgclassfication18-cuda-epoch180" conditionType=PodScheduled conditionStatus=False conditionReason="Unschedulable"
I1030 05:17:21.075265       1 schedule_one.go:63] "starting scheduling for next pod..."
I1030 05:17:21.276284       1 scheduling_queue.go:661] "[Bing]Pop called on the scheduling queue. current queue includes pods: " []="queue len:" %!s(int=0)="(MISSING)"
I1030 05:17:21.629518       1 httplog.go:132] "HTTP" verb="GET" URI="/healthz" latency="80.539µs" userAgent="kube-probe/1.27" audit-ID="" srcIP="127.0.0.1:49250" resp=200
I1030 05:17:23.159317       1 reflector.go:788] vendor/k8s.io/client-go/informers/factory.go:150: Watch close - *v1.Namespace total 8 items received
I1030 05:17:24.152653       1 reflector.go:788] vendor/k8s.io/client-go/informers/factory.go:150: Watch close - *v1.PersistentVolume total 7 items received
I1030 05:17:24.152744       1 reflector.go:788] vendor/k8s.io/client-go/informers/factory.go:150: Watch close - *v1.StorageClass total 8 items received
I1030 05:17:25.151593       1 reflector.go:788] vendor/k8s.io/client-go/informers/factory.go:150: Watch close - *v1.ReplicationController total 9 items received
I1030 05:17:31.628490       1 httplog.go:132] "HTTP" verb="GET" URI="/healthz" latency="81.963µs" userAgent="kube-probe/1.27" audit-ID="" srcIP="127.0.0.1:44384" resp=200
I1030 05:17:41.630389       1 httplog.go:132] "HTTP" verb="GET" URI="/healthz" latency="100.814µs" userAgent="kube-probe/1.27" audit-ID="" srcIP="127.0.0.1:41792" resp=200
I1030 05:17:51.630113       1 httplog.go:132] "HTTP" verb="GET" URI="/healthz" latency="87.667µs" userAgent="kube-probe/1.27" audit-ID="" srcIP="127.0.0.1:45120" resp=200
I1030 05:18:01.629198       1 httplog.go:132] "HTTP" verb="GET" URI="/healthz" latency="90.146µs" userAgent="kube-probe/1.27" audit-ID="" srcIP="127.0.0.1:47026" resp=200
I1030 05:18:11.628833       1 httplog.go:132] "HTTP" verb="GET" URI="/healthz" latency="74.454µs" userAgent="kube-probe/1.27" audit-ID="" srcIP="127.0.0.1:60140" resp=200
I1030 05:18:21.632954       1 httplog.go:132] "HTTP" verb="GET" URI="/healthz" latency="98.223µs" userAgent="kube-probe/1.27" audit-ID="" srcIP="127.0.0.1:58460" resp=200
I1030 05:18:22.328975       1 eventhandlers.go:206] "Update event for scheduled pod" pod="default/job-train-imgclassfication-cuda-epoch-5"
I1030 05:18:23.538327       1 eventhandlers.go:231] "Delete event for scheduled pod" pod="default/job-train-imgclassfication-cuda-epoch-5"
I1030 05:18:23.538497       1 scheduling_queue.go:1203] "[Bing]About to try and schedule pod" pod="default/job-train-imgclassfication18-cuda-epoch180"
I1030 05:18:23.538529       1 schedule_one.go:81] "Attempting to schedule pod" pod="default/job-train-imgclassfication18-cuda-epoch180"
I1030 05:18:23.739604       1 schedule_one.go:83] "sleep when attempting to schedule pod to increase job intervals..."
I1030 05:18:23.742679       1 schedule_one.go:63] "starting scheduling for next pod..."
I1030 05:18:23.871361       1 eventhandlers.go:161] "Delete event for unscheduled pod" pod="default/job-train-imgclassfication18-cuda-epoch180"
I1030 05:18:23.871400       1 eventhandlers.go:186] "Add event for scheduled pod" pod="default/job-train-imgclassfication18-cuda-epoch180"
I1030 05:18:23.874254       1 schedule_one.go:260] "Successfully bound pod to node" pod="default/job-train-imgclassfication18-cuda-epoch180" node="node2" evaluatedNodes=1 feasibleNodes=1
I1030 05:18:23.915810       1 eventhandlers.go:206] "Update event for scheduled pod" pod="default/job-train-imgclassfication18-cuda-epoch180"
I1030 05:18:23.942831       1 scheduling_queue.go:661] "[Bing]Pop called on the scheduling queue. current queue includes pods: " [%!s(*framework.QueuedPodInfo=&{0xc00019f880 {13927360912189860127 940032107101 0x38092e0} 10 {13927360205612739548 281977106744 0x38092e0} map[NodeResourcesFit:{}] false}) %!s(*framework.QueuedPodInfo=&{0xc00019ff80 {13927360912591587667 940433834676 0x38092e0} 9 {13927360205671620050 282035987245 0x38092e0} map[NodeResourcesFit:{}] false})]="queue len:" %!s(int=2)="(MISSING)"
I1030 05:18:23.942880       1 scheduling_queue.go:1203] "[Bing]About to try and schedule pod" pod="default/job-train-imgclassfication19-cuda-epoch190"
I1030 05:18:23.942907       1 schedule_one.go:81] "Attempting to schedule pod" pod="default/job-train-imgclassfication19-cuda-epoch190"
I1030 05:18:23.988735       1 eventhandlers.go:206] "Update event for scheduled pod" pod="default/job-train-imgclassfication18-cuda-epoch180"
I1030 05:18:24.142950       1 schedule_one.go:83] "sleep when attempting to schedule pod to increase job intervals..."
I1030 05:18:24.143273       1 schedule_one.go:875] "Unable to schedule pod; no fit; waiting" pod="default/job-train-imgclassfication19-cuda-epoch190" err="0/1 nodes are available: 1 Insufficient aliyun.com/gpu-mem. preemption: 0/1 nodes are available: 1 Insufficient aliyun.com/gpu-mem.."
I1030 05:18:24.143351       1 schedule_one.go:951] "Updating pod condition" pod="default/job-train-imgclassfication19-cuda-epoch190" conditionType=PodScheduled conditionStatus=False conditionReason="Unschedulable"
I1030 05:18:24.143387       1 schedule_one.go:63] "starting scheduling for next pod..."
I1030 05:18:24.343739       1 scheduling_queue.go:661] "[Bing]Pop called on the scheduling queue. current queue includes pods: " [%!s(*framework.QueuedPodInfo=&{0xc00019ff80 {13927360912591587667 940433834676 0x38092e0} 9 {13927360205671620050 282035987245 0x38092e0} map[NodeResourcesFit:{}] false})]="queue len:" %!s(int=1)="(MISSING)"
I1030 05:18:24.343769       1 scheduling_queue.go:1203] "[Bing]About to try and schedule pod" pod="default/job-train-imgclassfication20-cuda-epoch200"
I1030 05:18:24.343786       1 schedule_one.go:81] "Attempting to schedule pod" pod="default/job-train-imgclassfication20-cuda-epoch200"
I1030 05:18:24.544200       1 schedule_one.go:83] "sleep when attempting to schedule pod to increase job intervals..."
I1030 05:18:24.544829       1 schedule_one.go:875] "Unable to schedule pod; no fit; waiting" pod="default/job-train-imgclassfication20-cuda-epoch200" err="0/1 nodes are available: 1 Insufficient aliyun.com/gpu-mem. preemption: 0/1 nodes are available: 1 Insufficient aliyun.com/gpu-mem.."
I1030 05:18:24.544977       1 schedule_one.go:951] "Updating pod condition" pod="default/job-train-imgclassfication20-cuda-epoch200" conditionType=PodScheduled conditionStatus=False conditionReason="Unschedulable"
I1030 05:18:24.545041       1 schedule_one.go:63] "starting scheduling for next pod..."
I1030 05:18:24.745387       1 scheduling_queue.go:661] "[Bing]Pop called on the scheduling queue. current queue includes pods: " []="queue len:" %!s(int=0)="(MISSING)"
I1030 05:18:25.337478       1 eventhandlers.go:206] "Update event for scheduled pod" pod="default/job-train-imgclassfication18-cuda-epoch180"
I1030 05:18:31.634727       1 httplog.go:132] "HTTP" verb="GET" URI="/healthz" latency="104.012µs" userAgent="kube-probe/1.27" audit-ID="" srcIP="127.0.0.1:45958" resp=200
I1030 05:18:32.154946       1 reflector.go:788] vendor/k8s.io/client-go/informers/factory.go:150: Watch close - *v1.Pod total 139 items received
I1030 05:18:34.923509       1 scheduling_queue.go:1203] "[Bing]About to try and schedule pod" pod="default/job-train-imgclassfication19-cuda-epoch190"
I1030 05:18:34.923565       1 schedule_one.go:81] "Attempting to schedule pod" pod="default/job-train-imgclassfication19-cuda-epoch190"
I1030 05:18:35.123906       1 schedule_one.go:83] "sleep when attempting to schedule pod to increase job intervals..."
I1030 05:18:35.124279       1 schedule_one.go:875] "Unable to schedule pod; no fit; waiting" pod="default/job-train-imgclassfication19-cuda-epoch190" err="0/1 nodes are available: 1 Insufficient aliyun.com/gpu-mem. preemption: 0/1 nodes are available: 1 Insufficient aliyun.com/gpu-mem.."
I1030 05:18:35.124427       1 schedule_one.go:951] "Updating pod condition" pod="default/job-train-imgclassfication19-cuda-epoch190" conditionType=PodScheduled conditionStatus=False conditionReason="Unschedulable"
I1030 05:18:35.124471       1 schedule_one.go:63] "starting scheduling for next pod..."
I1030 05:18:35.325082       1 scheduling_queue.go:661] "[Bing]Pop called on the scheduling queue. current queue includes pods: " []="queue len:" %!s(int=0)="(MISSING)"
I1030 05:18:41.628849       1 httplog.go:132] "HTTP" verb="GET" URI="/healthz" latency="89.175µs" userAgent="kube-probe/1.27" audit-ID="" srcIP="127.0.0.1:42954" resp=200
I1030 05:18:51.635849       1 httplog.go:132] "HTTP" verb="GET" URI="/healthz" latency="111.063µs" userAgent="kube-probe/1.27" audit-ID="" srcIP="127.0.0.1:55614" resp=200
I1030 05:19:01.627060       1 httplog.go:132] "HTTP" verb="GET" URI="/healthz" latency="87.123µs" userAgent="kube-probe/1.27" audit-ID="" srcIP="127.0.0.1:43338" resp=200
I1030 05:19:11.628544       1 httplog.go:132] "HTTP" verb="GET" URI="/healthz" latency="123.365µs" userAgent="kube-probe/1.27" audit-ID="" srcIP="127.0.0.1:52264" resp=200
I1030 05:19:13.473824       1 eventhandlers.go:206] "Update event for scheduled pod" pod="default/job-train-imgclassfication4-cuda-epoch40"
I1030 05:19:14.714284       1 eventhandlers.go:231] "Delete event for scheduled pod" pod="default/job-train-imgclassfication4-cuda-epoch40"
I1030 05:19:14.714431       1 scheduling_queue.go:1203] "[Bing]About to try and schedule pod" pod="default/job-train-imgclassfication19-cuda-epoch190"
I1030 05:19:14.714450       1 schedule_one.go:81] "Attempting to schedule pod" pod="default/job-train-imgclassfication19-cuda-epoch190"
I1030 05:19:14.915300       1 schedule_one.go:83] "sleep when attempting to schedule pod to increase job intervals..."
I1030 05:19:14.919530       1 schedule_one.go:63] "starting scheduling for next pod..."
I1030 05:19:15.038444       1 eventhandlers.go:186] "Add event for scheduled pod" pod="default/job-train-imgclassfication19-cuda-epoch190"
I1030 05:19:15.038450       1 eventhandlers.go:161] "Delete event for unscheduled pod" pod="default/job-train-imgclassfication19-cuda-epoch190"
I1030 05:19:15.040008       1 schedule_one.go:260] "Successfully bound pod to node" pod="default/job-train-imgclassfication19-cuda-epoch190" node="node2" evaluatedNodes=1 feasibleNodes=1
I1030 05:19:15.092743       1 eventhandlers.go:206] "Update event for scheduled pod" pod="default/job-train-imgclassfication19-cuda-epoch190"
I1030 05:19:15.119676       1 scheduling_queue.go:661] "[Bing]Pop called on the scheduling queue. current queue includes pods: " [%!s(*framework.QueuedPodInfo=&{0xc000158690 {13927360991826976040 1014212328071 0x38092e0} 10 {13927360205671620050 282035987245 0x38092e0} map[NodeResourcesFit:{}] false})]="queue len:" %!s(int=1)="(MISSING)"
I1030 05:19:15.119730       1 scheduling_queue.go:1203] "[Bing]About to try and schedule pod" pod="default/job-train-imgclassfication20-cuda-epoch200"
I1030 05:19:15.119762       1 schedule_one.go:81] "Attempting to schedule pod" pod="default/job-train-imgclassfication20-cuda-epoch200"
I1030 05:19:15.161271       1 eventhandlers.go:206] "Update event for scheduled pod" pod="default/job-train-imgclassfication19-cuda-epoch190"
I1030 05:19:15.320670       1 schedule_one.go:83] "sleep when attempting to schedule pod to increase job intervals..."
I1030 05:19:15.321140       1 schedule_one.go:875] "Unable to schedule pod; no fit; waiting" pod="default/job-train-imgclassfication20-cuda-epoch200" err="0/1 nodes are available: 1 Insufficient aliyun.com/gpu-mem. preemption: 0/1 nodes are available: 1 Insufficient aliyun.com/gpu-mem.."
I1030 05:19:15.321256       1 schedule_one.go:951] "Updating pod condition" pod="default/job-train-imgclassfication20-cuda-epoch200" conditionType=PodScheduled conditionStatus=False conditionReason="Unschedulable"
I1030 05:19:15.321304       1 schedule_one.go:63] "starting scheduling for next pod..."
I1030 05:19:15.521779       1 scheduling_queue.go:661] "[Bing]Pop called on the scheduling queue. current queue includes pods: " []="queue len:" %!s(int=0)="(MISSING)"
I1030 05:19:16.490026       1 eventhandlers.go:206] "Update event for scheduled pod" pod="default/job-train-imgclassfication19-cuda-epoch190"
I1030 05:19:21.629799       1 httplog.go:132] "HTTP" verb="GET" URI="/healthz" latency="111.913µs" userAgent="kube-probe/1.27" audit-ID="" srcIP="127.0.0.1:44378" resp=200
I1030 05:19:25.954479       1 scheduling_queue.go:1203] "[Bing]About to try and schedule pod" pod="default/job-train-imgclassfication20-cuda-epoch200"
I1030 05:19:25.954528       1 schedule_one.go:81] "Attempting to schedule pod" pod="default/job-train-imgclassfication20-cuda-epoch200"
I1030 05:19:26.155514       1 schedule_one.go:83] "sleep when attempting to schedule pod to increase job intervals..."
I1030 05:19:26.155828       1 schedule_one.go:875] "Unable to schedule pod; no fit; waiting" pod="default/job-train-imgclassfication20-cuda-epoch200" err="0/1 nodes are available: 1 Insufficient aliyun.com/gpu-mem. preemption: 0/1 nodes are available: 1 Insufficient aliyun.com/gpu-mem.."
I1030 05:19:26.155897       1 schedule_one.go:951] "Updating pod condition" pod="default/job-train-imgclassfication20-cuda-epoch200" conditionType=PodScheduled conditionStatus=False conditionReason="Unschedulable"
I1030 05:19:26.155919       1 schedule_one.go:63] "starting scheduling for next pod..."
I1030 05:19:26.356324       1 scheduling_queue.go:661] "[Bing]Pop called on the scheduling queue. current queue includes pods: " []="queue len:" %!s(int=0)="(MISSING)"
I1030 05:19:31.631708       1 httplog.go:132] "HTTP" verb="GET" URI="/healthz" latency="86.193µs" userAgent="kube-probe/1.27" audit-ID="" srcIP="127.0.0.1:33454" resp=200
I1030 05:19:41.630136       1 httplog.go:132] "HTTP" verb="GET" URI="/healthz" latency="71.549µs" userAgent="kube-probe/1.27" audit-ID="" srcIP="127.0.0.1:47826" resp=200
I1030 05:19:51.632359       1 httplog.go:132] "HTTP" verb="GET" URI="/healthz" latency="105.72µs" userAgent="kube-probe/1.27" audit-ID="" srcIP="127.0.0.1:38984" resp=200
I1030 05:20:01.633750       1 httplog.go:132] "HTTP" verb="GET" URI="/healthz" latency="82.944µs" userAgent="kube-probe/1.27" audit-ID="" srcIP="127.0.0.1:33350" resp=200
I1030 05:20:02.629013       1 eventhandlers.go:206] "Update event for scheduled pod" pod="default/job-train-imgclassfication-cuda-epoch-10"
I1030 05:20:03.842704       1 eventhandlers.go:231] "Delete event for scheduled pod" pod="default/job-train-imgclassfication-cuda-epoch-10"
I1030 05:20:03.842890       1 scheduling_queue.go:1203] "[Bing]About to try and schedule pod" pod="default/job-train-imgclassfication20-cuda-epoch200"
I1030 05:20:03.842929       1 schedule_one.go:81] "Attempting to schedule pod" pod="default/job-train-imgclassfication20-cuda-epoch200"
I1030 05:20:04.043432       1 schedule_one.go:83] "sleep when attempting to schedule pod to increase job intervals..."
I1030 05:20:04.047492       1 schedule_one.go:63] "starting scheduling for next pod..."
I1030 05:20:04.174031       1 eventhandlers.go:161] "Delete event for unscheduled pod" pod="default/job-train-imgclassfication20-cuda-epoch200"
I1030 05:20:04.174049       1 eventhandlers.go:186] "Add event for scheduled pod" pod="default/job-train-imgclassfication20-cuda-epoch200"
I1030 05:20:04.176976       1 schedule_one.go:260] "Successfully bound pod to node" pod="default/job-train-imgclassfication20-cuda-epoch200" node="node2" evaluatedNodes=1 feasibleNodes=1
I1030 05:20:04.223453       1 eventhandlers.go:206] "Update event for scheduled pod" pod="default/job-train-imgclassfication20-cuda-epoch200"
I1030 05:20:04.248397       1 scheduling_queue.go:661] "[Bing]Pop called on the scheduling queue. current queue includes pods: " []="queue len:" %!s(int=0)="(MISSING)"
I1030 05:20:04.289770       1 eventhandlers.go:206] "Update event for scheduled pod" pod="default/job-train-imgclassfication20-cuda-epoch200"
I1030 05:20:05.636829       1 eventhandlers.go:206] "Update event for scheduled pod" pod="default/job-train-imgclassfication20-cuda-epoch200"
I1030 05:20:11.629726       1 httplog.go:132] "HTTP" verb="GET" URI="/healthz" latency="82.426µs" userAgent="kube-probe/1.27" audit-ID="" srcIP="127.0.0.1:35630" resp=200
I1030 05:20:21.629628       1 httplog.go:132] "HTTP" verb="GET" URI="/healthz" latency="91.42µs" userAgent="kube-probe/1.27" audit-ID="" srcIP="127.0.0.1:42096" resp=200
I1030 05:20:31.629176       1 httplog.go:132] "HTTP" verb="GET" URI="/healthz" latency="77.02µs" userAgent="kube-probe/1.27" audit-ID="" srcIP="127.0.0.1:39700" resp=200
I1030 05:20:41.628016       1 httplog.go:132] "HTTP" verb="GET" URI="/healthz" latency="88.289µs" userAgent="kube-probe/1.27" audit-ID="" srcIP="127.0.0.1:44410" resp=200
I1030 05:20:51.631655       1 httplog.go:132] "HTTP" verb="GET" URI="/healthz" latency="79.851µs" userAgent="kube-probe/1.27" audit-ID="" srcIP="127.0.0.1:41602" resp=200
I1030 05:21:01.628669       1 httplog.go:132] "HTTP" verb="GET" URI="/healthz" latency="90.743µs" userAgent="kube-probe/1.27" audit-ID="" srcIP="127.0.0.1:55424" resp=200
I1030 05:21:03.155958       1 reflector.go:788] vendor/k8s.io/client-go/informers/factory.go:150: Watch close - *v1.CSIStorageCapacity total 7 items received
I1030 05:21:11.629711       1 httplog.go:132] "HTTP" verb="GET" URI="/healthz" latency="86.171µs" userAgent="kube-probe/1.27" audit-ID="" srcIP="127.0.0.1:57672" resp=200
I1030 05:21:21.628084       1 httplog.go:132] "HTTP" verb="GET" URI="/healthz" latency="74.83µs" userAgent="kube-probe/1.27" audit-ID="" srcIP="127.0.0.1:42090" resp=200
I1030 05:21:25.153839       1 reflector.go:788] vendor/k8s.io/client-go/informers/factory.go:150: Watch close - *v1.StatefulSet total 7 items received
I1030 05:21:31.629617       1 httplog.go:132] "HTTP" verb="GET" URI="/healthz" latency="89.219µs" userAgent="kube-probe/1.27" audit-ID="" srcIP="127.0.0.1:53450" resp=200
I1030 05:21:41.628486       1 httplog.go:132] "HTTP" verb="GET" URI="/healthz" latency="72.209µs" userAgent="kube-probe/1.27" audit-ID="" srcIP="127.0.0.1:37212" resp=200
I1030 05:21:51.627920       1 httplog.go:132] "HTTP" verb="GET" URI="/healthz" latency="63.069µs" userAgent="kube-probe/1.27" audit-ID="" srcIP="127.0.0.1:47672" resp=200
I1030 05:22:01.629279       1 httplog.go:132] "HTTP" verb="GET" URI="/healthz" latency="85.56µs" userAgent="kube-probe/1.27" audit-ID="" srcIP="127.0.0.1:51682" resp=200
I1030 05:22:11.631713       1 httplog.go:132] "HTTP" verb="GET" URI="/healthz" latency="114.94µs" userAgent="kube-probe/1.27" audit-ID="" srcIP="127.0.0.1:51070" resp=200
I1030 05:22:21.631576       1 httplog.go:132] "HTTP" verb="GET" URI="/healthz" latency="87.934µs" userAgent="kube-probe/1.27" audit-ID="" srcIP="127.0.0.1:55208" resp=200
I1030 05:22:31.058015       1 eventhandlers.go:206] "Update event for scheduled pod" pod="default/job-train-imgclassfication5-cuda-epoch50"
I1030 05:22:31.632147       1 httplog.go:132] "HTTP" verb="GET" URI="/healthz" latency="97.333µs" userAgent="kube-probe/1.27" audit-ID="" srcIP="127.0.0.1:47970" resp=200
I1030 05:22:32.286826       1 eventhandlers.go:231] "Delete event for scheduled pod" pod="default/job-train-imgclassfication5-cuda-epoch50"
I1030 05:22:41.631756       1 httplog.go:132] "HTTP" verb="GET" URI="/healthz" latency="109.388µs" userAgent="kube-probe/1.27" audit-ID="" srcIP="127.0.0.1:46304" resp=200
I1030 05:22:44.154891       1 reflector.go:788] vendor/k8s.io/client-go/informers/factory.go:150: Watch close - *v1.StorageClass total 6 items received
I1030 05:22:51.628833       1 httplog.go:132] "HTTP" verb="GET" URI="/healthz" latency="71.405µs" userAgent="kube-probe/1.27" audit-ID="" srcIP="127.0.0.1:52292" resp=200
I1030 05:22:59.144383       1 eventhandlers.go:206] "Update event for scheduled pod" pod="default/job-train-imgclassfication-cuda-epoch-20"
I1030 05:23:00.380792       1 eventhandlers.go:231] "Delete event for scheduled pod" pod="default/job-train-imgclassfication-cuda-epoch-20"
I1030 05:23:01.629399       1 httplog.go:132] "HTTP" verb="GET" URI="/healthz" latency="102.723µs" userAgent="kube-probe/1.27" audit-ID="" srcIP="127.0.0.1:44412" resp=200
I1030 05:23:11.629904       1 httplog.go:132] "HTTP" verb="GET" URI="/healthz" latency="86.551µs" userAgent="kube-probe/1.27" audit-ID="" srcIP="127.0.0.1:32778" resp=200
I1030 05:23:14.155010       1 reflector.go:788] vendor/k8s.io/client-go/informers/factory.go:150: Watch close - *v1.CSINode total 9 items received
I1030 05:23:21.629422       1 httplog.go:132] "HTTP" verb="GET" URI="/healthz" latency="75.08µs" userAgent="kube-probe/1.27" audit-ID="" srcIP="127.0.0.1:56636" resp=200
I1030 05:23:28.154583       1 reflector.go:788] vendor/k8s.io/client-go/informers/factory.go:150: Watch close - *v1.Service total 11 items received
I1030 05:23:31.629880       1 httplog.go:132] "HTTP" verb="GET" URI="/healthz" latency="104.896µs" userAgent="kube-probe/1.27" audit-ID="" srcIP="127.0.0.1:57274" resp=200
I1030 05:23:41.629929       1 httplog.go:132] "HTTP" verb="GET" URI="/healthz" latency="89.434µs" userAgent="kube-probe/1.27" audit-ID="" srcIP="127.0.0.1:51928" resp=200
I1030 05:23:42.155147       1 reflector.go:788] vendor/k8s.io/client-go/informers/factory.go:150: Watch close - *v1.ReplicaSet total 10 items received
I1030 05:23:42.272166       1 eventhandlers.go:206] "Update event for scheduled pod" pod="default/job-train-online5-cuda-epoch40"
I1030 05:23:43.507712       1 eventhandlers.go:231] "Delete event for scheduled pod" pod="default/job-train-online5-cuda-epoch40"
I1030 05:23:51.633938       1 httplog.go:132] "HTTP" verb="GET" URI="/healthz" latency="75.088µs" userAgent="kube-probe/1.27" audit-ID="" srcIP="127.0.0.1:48288" resp=200
I1030 05:24:01.632791       1 httplog.go:132] "HTTP" verb="GET" URI="/healthz" latency="66.043µs" userAgent="kube-probe/1.27" audit-ID="" srcIP="127.0.0.1:51792" resp=200
I1030 05:24:11.631662       1 httplog.go:132] "HTTP" verb="GET" URI="/healthz" latency="83.085µs" userAgent="kube-probe/1.27" audit-ID="" srcIP="127.0.0.1:60136" resp=200
I1030 05:24:21.634055       1 httplog.go:132] "HTTP" verb="GET" URI="/healthz" latency="131.192µs" userAgent="kube-probe/1.27" audit-ID="" srcIP="127.0.0.1:56380" resp=200
I1030 05:24:23.154305       1 reflector.go:788] pkg/server/dynamiccertificates/configmap_cafile_content.go:206: Watch close - *v1.ConfigMap total 8 items received
I1030 05:24:31.631776       1 httplog.go:132] "HTTP" verb="GET" URI="/healthz" latency="67.426µs" userAgent="kube-probe/1.27" audit-ID="" srcIP="127.0.0.1:36296" resp=200
I1030 05:24:33.154818       1 reflector.go:788] vendor/k8s.io/client-go/informers/factory.go:150: Watch close - *v1.PersistentVolumeClaim total 9 items received
I1030 05:24:41.629055       1 httplog.go:132] "HTTP" verb="GET" URI="/healthz" latency="133.298µs" userAgent="kube-probe/1.27" audit-ID="" srcIP="127.0.0.1:41088" resp=200
I1030 05:24:48.161875       1 reflector.go:788] vendor/k8s.io/client-go/informers/factory.go:150: Watch close - *v1.Namespace total 8 items received
I1030 05:24:51.631414       1 httplog.go:132] "HTTP" verb="GET" URI="/healthz" latency="74.95µs" userAgent="kube-probe/1.27" audit-ID="" srcIP="127.0.0.1:47928" resp=200
I1030 05:24:54.154520       1 reflector.go:788] pkg/server/dynamiccertificates/configmap_cafile_content.go:206: Watch close - *v1.ConfigMap total 10 items received
I1030 05:25:01.628043       1 httplog.go:132] "HTTP" verb="GET" URI="/healthz" latency="70.534µs" userAgent="kube-probe/1.27" audit-ID="" srcIP="127.0.0.1:40926" resp=200
I1030 05:25:11.633147       1 httplog.go:132] "HTTP" verb="GET" URI="/healthz" latency="82.943µs" userAgent="kube-probe/1.27" audit-ID="" srcIP="127.0.0.1:51232" resp=200
I1030 05:25:20.562040       1 eventhandlers.go:206] "Update event for scheduled pod" pod="default/job-train-imgclassfication6-cuda-epoch60"
I1030 05:25:21.632223       1 httplog.go:132] "HTTP" verb="GET" URI="/healthz" latency="75.882µs" userAgent="kube-probe/1.27" audit-ID="" srcIP="127.0.0.1:37176" resp=200
I1030 05:25:21.796849       1 eventhandlers.go:231] "Delete event for scheduled pod" pod="default/job-train-imgclassfication6-cuda-epoch60"
I1030 05:25:31.633115       1 httplog.go:132] "HTTP" verb="GET" URI="/healthz" latency="102.164µs" userAgent="kube-probe/1.27" audit-ID="" srcIP="127.0.0.1:59702" resp=200
I1030 05:25:38.158095       1 reflector.go:788] pkg/authentication/request/headerrequest/requestheader_controller.go:172: Watch close - *v1.ConfigMap total 10 items received
I1030 05:25:41.630108       1 httplog.go:132] "HTTP" verb="GET" URI="/healthz" latency="80.884µs" userAgent="kube-probe/1.27" audit-ID="" srcIP="127.0.0.1:58300" resp=200
I1030 05:25:46.154541       1 reflector.go:788] vendor/k8s.io/client-go/informers/factory.go:150: Watch close - *v1.CSIDriver total 10 items received
I1030 05:25:51.629904       1 httplog.go:132] "HTTP" verb="GET" URI="/healthz" latency="101.746µs" userAgent="kube-probe/1.27" audit-ID="" srcIP="127.0.0.1:41950" resp=200
I1030 05:26:01.632157       1 httplog.go:132] "HTTP" verb="GET" URI="/healthz" latency="70.992µs" userAgent="kube-probe/1.27" audit-ID="" srcIP="127.0.0.1:32980" resp=200
I1030 05:26:10.154385       1 reflector.go:788] vendor/k8s.io/client-go/informers/factory.go:150: Watch close - *v1.ReplicationController total 10 items received
I1030 05:26:11.631968       1 httplog.go:132] "HTTP" verb="GET" URI="/healthz" latency="113.013µs" userAgent="kube-probe/1.27" audit-ID="" srcIP="127.0.0.1:51984" resp=200
I1030 05:26:12.153457       1 reflector.go:788] vendor/k8s.io/client-go/informers/factory.go:150: Watch close - *v1.PodDisruptionBudget total 10 items received
I1030 05:26:19.156961       1 reflector.go:788] vendor/k8s.io/client-go/informers/factory.go:150: Watch close - *v1.Pod total 30 items received
I1030 05:26:21.630404       1 httplog.go:132] "HTTP" verb="GET" URI="/healthz" latency="104.145µs" userAgent="kube-probe/1.27" audit-ID="" srcIP="127.0.0.1:51788" resp=200
I1030 05:26:31.631821       1 httplog.go:132] "HTTP" verb="GET" URI="/healthz" latency="108.61µs" userAgent="kube-probe/1.27" audit-ID="" srcIP="127.0.0.1:43160" resp=200
I1030 05:26:41.628546       1 httplog.go:132] "HTTP" verb="GET" URI="/healthz" latency="78.94µs" userAgent="kube-probe/1.27" audit-ID="" srcIP="127.0.0.1:44678" resp=200
I1030 05:26:51.632849       1 httplog.go:132] "HTTP" verb="GET" URI="/healthz" latency="76µs" userAgent="kube-probe/1.27" audit-ID="" srcIP="127.0.0.1:45556" resp=200
I1030 05:26:57.155020       1 reflector.go:788] vendor/k8s.io/client-go/informers/factory.go:150: Watch close - *v1.PersistentVolume total 10 items received
I1030 05:27:01.632851       1 httplog.go:132] "HTTP" verb="GET" URI="/healthz" latency="117.286µs" userAgent="kube-probe/1.27" audit-ID="" srcIP="127.0.0.1:36414" resp=200
I1030 05:27:03.157702       1 reflector.go:788] vendor/k8s.io/client-go/informers/factory.go:150: Watch close - *v1.Node total 12 items received
I1030 05:27:11.628384       1 httplog.go:132] "HTTP" verb="GET" URI="/healthz" latency="102.49µs" userAgent="kube-probe/1.27" audit-ID="" srcIP="127.0.0.1:57414" resp=200
I1030 05:27:21.632614       1 httplog.go:132] "HTTP" verb="GET" URI="/healthz" latency="97.344µs" userAgent="kube-probe/1.27" audit-ID="" srcIP="127.0.0.1:49816" resp=200
I1030 05:27:31.634481       1 httplog.go:132] "HTTP" verb="GET" URI="/healthz" latency="100.577µs" userAgent="kube-probe/1.27" audit-ID="" srcIP="127.0.0.1:50598" resp=200
I1030 05:27:41.629341       1 httplog.go:132] "HTTP" verb="GET" URI="/healthz" latency="114.154µs" userAgent="kube-probe/1.27" audit-ID="" srcIP="127.0.0.1:48286" resp=200
I1030 05:27:46.156873       1 reflector.go:788] vendor/k8s.io/client-go/informers/factory.go:150: Watch close - *v1.StatefulSet total 7 items received
I1030 05:27:51.629323       1 httplog.go:132] "HTTP" verb="GET" URI="/healthz" latency="117.302µs" userAgent="kube-probe/1.27" audit-ID="" srcIP="127.0.0.1:52814" resp=200
I1030 05:27:52.009295       1 eventhandlers.go:206] "Update event for scheduled pod" pod="default/job-train-imgclassfication7-cuda-epoch70"
I1030 05:27:53.203048       1 eventhandlers.go:231] "Delete event for scheduled pod" pod="default/job-train-imgclassfication7-cuda-epoch70"
I1030 05:28:00.158264       1 reflector.go:788] vendor/k8s.io/client-go/informers/factory.go:150: Watch close - *v1.CSIStorageCapacity total 8 items received
I1030 05:28:01.634160       1 httplog.go:132] "HTTP" verb="GET" URI="/healthz" latency="110.102µs" userAgent="kube-probe/1.27" audit-ID="" srcIP="127.0.0.1:57604" resp=200
I1030 05:28:11.634229       1 httplog.go:132] "HTTP" verb="GET" URI="/healthz" latency="77.788µs" userAgent="kube-probe/1.27" audit-ID="" srcIP="127.0.0.1:58532" resp=200
I1030 05:28:21.631359       1 httplog.go:132] "HTTP" verb="GET" URI="/healthz" latency="102.803µs" userAgent="kube-probe/1.27" audit-ID="" srcIP="127.0.0.1:59598" resp=200
I1030 05:28:31.632682       1 httplog.go:132] "HTTP" verb="GET" URI="/healthz" latency="95.225µs" userAgent="kube-probe/1.27" audit-ID="" srcIP="127.0.0.1:47776" resp=200
I1030 05:28:41.628197       1 httplog.go:132] "HTTP" verb="GET" URI="/healthz" latency="68.552µs" userAgent="kube-probe/1.27" audit-ID="" srcIP="127.0.0.1:37062" resp=200
I1030 05:28:51.632734       1 httplog.go:132] "HTTP" verb="GET" URI="/healthz" latency="73.866µs" userAgent="kube-probe/1.27" audit-ID="" srcIP="127.0.0.1:45090" resp=200
I1030 05:29:01.632865       1 httplog.go:132] "HTTP" verb="GET" URI="/healthz" latency="59.7µs" userAgent="kube-probe/1.27" audit-ID="" srcIP="127.0.0.1:38704" resp=200
I1030 05:29:11.632406       1 httplog.go:132] "HTTP" verb="GET" URI="/healthz" latency="157.362µs" userAgent="kube-probe/1.27" audit-ID="" srcIP="127.0.0.1:44914" resp=200
I1030 05:29:21.629815       1 httplog.go:132] "HTTP" verb="GET" URI="/healthz" latency="58.815µs" userAgent="kube-probe/1.27" audit-ID="" srcIP="127.0.0.1:36382" resp=200
I1030 05:29:31.629920       1 httplog.go:132] "HTTP" verb="GET" URI="/healthz" latency="103.754µs" userAgent="kube-probe/1.27" audit-ID="" srcIP="127.0.0.1:35520" resp=200
I1030 05:29:41.633438       1 httplog.go:132] "HTTP" verb="GET" URI="/healthz" latency="115.789µs" userAgent="kube-probe/1.27" audit-ID="" srcIP="127.0.0.1:37418" resp=200
I1030 05:29:45.156322       1 reflector.go:788] pkg/server/dynamiccertificates/configmap_cafile_content.go:206: Watch close - *v1.ConfigMap total 6 items received
I1030 05:29:45.157742       1 reflector.go:788] vendor/k8s.io/client-go/informers/factory.go:150: Watch close - *v1.ReplicaSet total 7 items received
I1030 05:29:51.632957       1 httplog.go:132] "HTTP" verb="GET" URI="/healthz" latency="107.214µs" userAgent="kube-probe/1.27" audit-ID="" srcIP="127.0.0.1:35504" resp=200
I1030 05:30:01.633614       1 httplog.go:132] "HTTP" verb="GET" URI="/healthz" latency="100.55µs" userAgent="kube-probe/1.27" audit-ID="" srcIP="127.0.0.1:45678" resp=200
I1030 05:30:11.634321       1 httplog.go:132] "HTTP" verb="GET" URI="/healthz" latency="105.145µs" userAgent="kube-probe/1.27" audit-ID="" srcIP="127.0.0.1:59552" resp=200
I1030 05:30:12.156713       1 reflector.go:788] pkg/server/dynamiccertificates/configmap_cafile_content.go:206: Watch close - *v1.ConfigMap total 6 items received
I1030 05:30:20.158279       1 reflector.go:788] vendor/k8s.io/client-go/informers/factory.go:150: Watch close - *v1.StorageClass total 9 items received
I1030 05:30:21.631496       1 httplog.go:132] "HTTP" verb="GET" URI="/healthz" latency="113.497µs" userAgent="kube-probe/1.27" audit-ID="" srcIP="127.0.0.1:39018" resp=200
I1030 05:30:31.631873       1 httplog.go:132] "HTTP" verb="GET" URI="/healthz" latency="70.73µs" userAgent="kube-probe/1.27" audit-ID="" srcIP="127.0.0.1:48458" resp=200
I1030 05:30:39.530197       1 eventhandlers.go:206] "Update event for scheduled pod" pod="default/job-train-imgclassfication8-cuda-epoch80"
I1030 05:30:40.796702       1 eventhandlers.go:231] "Delete event for scheduled pod" pod="default/job-train-imgclassfication8-cuda-epoch80"
I1030 05:30:41.631303       1 httplog.go:132] "HTTP" verb="GET" URI="/healthz" latency="112.934µs" userAgent="kube-probe/1.27" audit-ID="" srcIP="127.0.0.1:34468" resp=200
I1030 05:30:50.160126       1 reflector.go:788] pkg/authentication/request/headerrequest/requestheader_controller.go:172: Watch close - *v1.ConfigMap total 6 items received
I1030 05:30:51.631319       1 httplog.go:132] "HTTP" verb="GET" URI="/healthz" latency="118.611µs" userAgent="kube-probe/1.27" audit-ID="" srcIP="127.0.0.1:60808" resp=200
I1030 05:31:01.631830       1 httplog.go:132] "HTTP" verb="GET" URI="/healthz" latency="96.844µs" userAgent="kube-probe/1.27" audit-ID="" srcIP="127.0.0.1:52274" resp=200
I1030 05:31:11.164436       1 reflector.go:788] vendor/k8s.io/client-go/informers/factory.go:150: Watch close - *v1.Namespace total 7 items received
I1030 05:31:11.632007       1 httplog.go:132] "HTTP" verb="GET" URI="/healthz" latency="116.624µs" userAgent="kube-probe/1.27" audit-ID="" srcIP="127.0.0.1:48176" resp=200
I1030 05:31:21.632459       1 httplog.go:132] "HTTP" verb="GET" URI="/healthz" latency="160.585µs" userAgent="kube-probe/1.27" audit-ID="" srcIP="127.0.0.1:39450" resp=200
I1030 05:31:31.632011       1 httplog.go:132] "HTTP" verb="GET" URI="/healthz" latency="140.98µs" userAgent="kube-probe/1.27" audit-ID="" srcIP="127.0.0.1:44838" resp=200
I1030 05:31:41.632661       1 httplog.go:132] "HTTP" verb="GET" URI="/healthz" latency="143.636µs" userAgent="kube-probe/1.27" audit-ID="" srcIP="127.0.0.1:51162" resp=200
I1030 05:31:51.632834       1 httplog.go:132] "HTTP" verb="GET" URI="/healthz" latency="101.626µs" userAgent="kube-probe/1.27" audit-ID="" srcIP="127.0.0.1:60128" resp=200
I1030 05:31:53.156778       1 reflector.go:788] vendor/k8s.io/client-go/informers/factory.go:150: Watch close - *v1.PersistentVolumeClaim total 8 items received
I1030 05:32:01.631683       1 httplog.go:132] "HTTP" verb="GET" URI="/healthz" latency="99.729µs" userAgent="kube-probe/1.27" audit-ID="" srcIP="127.0.0.1:42954" resp=200
I1030 05:32:11.632098       1 httplog.go:132] "HTTP" verb="GET" URI="/healthz" latency="96.983µs" userAgent="kube-probe/1.27" audit-ID="" srcIP="127.0.0.1:55576" resp=200
I1030 05:32:21.628325       1 httplog.go:132] "HTTP" verb="GET" URI="/healthz" latency="72.123µs" userAgent="kube-probe/1.27" audit-ID="" srcIP="127.0.0.1:35416" resp=200
I1030 05:32:28.156837       1 reflector.go:788] vendor/k8s.io/client-go/informers/factory.go:150: Watch close - *v1.CSINode total 10 items received
I1030 05:32:31.632034       1 httplog.go:132] "HTTP" verb="GET" URI="/healthz" latency="104.866µs" userAgent="kube-probe/1.27" audit-ID="" srcIP="127.0.0.1:58164" resp=200
I1030 05:32:41.631669       1 httplog.go:132] "HTTP" verb="GET" URI="/healthz" latency="74.107µs" userAgent="kube-probe/1.27" audit-ID="" srcIP="127.0.0.1:57720" resp=200
I1030 05:32:45.158112       1 reflector.go:788] vendor/k8s.io/client-go/informers/factory.go:150: Watch close - *v1.Service total 11 items received
I1030 05:32:50.157806       1 reflector.go:788] vendor/k8s.io/client-go/informers/factory.go:150: Watch close - *v1.ReplicationController total 8 items received
I1030 05:32:51.159568       1 reflector.go:788] vendor/k8s.io/client-go/informers/factory.go:150: Watch close - *v1.Pod total 11 items received
I1030 05:32:51.631361       1 httplog.go:132] "HTTP" verb="GET" URI="/healthz" latency="76.769µs" userAgent="kube-probe/1.27" audit-ID="" srcIP="127.0.0.1:50128" resp=200
I1030 05:33:01.632898       1 httplog.go:132] "HTTP" verb="GET" URI="/healthz" latency="103.841µs" userAgent="kube-probe/1.27" audit-ID="" srcIP="127.0.0.1:45362" resp=200
I1030 05:33:11.631900       1 httplog.go:132] "HTTP" verb="GET" URI="/healthz" latency="60.439µs" userAgent="kube-probe/1.27" audit-ID="" srcIP="127.0.0.1:49718" resp=200
I1030 05:33:21.631984       1 httplog.go:132] "HTTP" verb="GET" URI="/healthz" latency="106.369µs" userAgent="kube-probe/1.27" audit-ID="" srcIP="127.0.0.1:38396" resp=200
I1030 05:33:31.628500       1 httplog.go:132] "HTTP" verb="GET" URI="/healthz" latency="61.318µs" userAgent="kube-probe/1.27" audit-ID="" srcIP="127.0.0.1:55178" resp=200
I1030 05:33:41.632743       1 httplog.go:132] "HTTP" verb="GET" URI="/healthz" latency="85.996µs" userAgent="kube-probe/1.27" audit-ID="" srcIP="127.0.0.1:36258" resp=200
I1030 05:33:51.630165       1 httplog.go:132] "HTTP" verb="GET" URI="/healthz" latency="64.475µs" userAgent="kube-probe/1.27" audit-ID="" srcIP="127.0.0.1:58690" resp=200
I1030 05:33:57.155225       1 reflector.go:788] vendor/k8s.io/client-go/informers/factory.go:150: Watch close - *v1.PodDisruptionBudget total 8 items received
I1030 05:34:01.632513       1 httplog.go:132] "HTTP" verb="GET" URI="/healthz" latency="98.406µs" userAgent="kube-probe/1.27" audit-ID="" srcIP="127.0.0.1:32940" resp=200
I1030 05:34:11.629411       1 httplog.go:132] "HTTP" verb="GET" URI="/healthz" latency="112.077µs" userAgent="kube-probe/1.27" audit-ID="" srcIP="127.0.0.1:51502" resp=200
I1030 05:34:21.628903       1 httplog.go:132] "HTTP" verb="GET" URI="/healthz" latency="108.123µs" userAgent="kube-probe/1.27" audit-ID="" srcIP="127.0.0.1:58232" resp=200
I1030 05:34:26.156826       1 reflector.go:788] vendor/k8s.io/client-go/informers/factory.go:150: Watch close - *v1.CSIDriver total 10 items received
I1030 05:34:31.632470       1 httplog.go:132] "HTTP" verb="GET" URI="/healthz" latency="106.324µs" userAgent="kube-probe/1.27" audit-ID="" srcIP="127.0.0.1:33690" resp=200
I1030 05:34:41.630291       1 httplog.go:132] "HTTP" verb="GET" URI="/healthz" latency="78.092µs" userAgent="kube-probe/1.27" audit-ID="" srcIP="127.0.0.1:55026" resp=200
I1030 05:34:51.629537       1 httplog.go:132] "HTTP" verb="GET" URI="/healthz" latency="121.706µs" userAgent="kube-probe/1.27" audit-ID="" srcIP="127.0.0.1:56634" resp=200
I1030 05:35:01.632250       1 httplog.go:132] "HTTP" verb="GET" URI="/healthz" latency="118.28µs" userAgent="kube-probe/1.27" audit-ID="" srcIP="127.0.0.1:54062" resp=200
I1030 05:35:11.632518       1 httplog.go:132] "HTTP" verb="GET" URI="/healthz" latency="136.378µs" userAgent="kube-probe/1.27" audit-ID="" srcIP="127.0.0.1:50790" resp=200
I1030 05:35:14.160235       1 reflector.go:788] vendor/k8s.io/client-go/informers/factory.go:150: Watch close - *v1.Node total 11 items received
I1030 05:35:21.632658       1 httplog.go:132] "HTTP" verb="GET" URI="/healthz" latency="109.591µs" userAgent="kube-probe/1.27" audit-ID="" srcIP="127.0.0.1:35314" resp=200
I1030 05:35:31.631112       1 httplog.go:132] "HTTP" verb="GET" URI="/healthz" latency="76.378µs" userAgent="kube-probe/1.27" audit-ID="" srcIP="127.0.0.1:39220" resp=200
I1030 05:35:41.629525       1 httplog.go:132] "HTTP" verb="GET" URI="/healthz" latency="103.223µs" userAgent="kube-probe/1.27" audit-ID="" srcIP="127.0.0.1:44056" resp=200
I1030 05:35:51.631476       1 httplog.go:132] "HTTP" verb="GET" URI="/healthz" latency="102.388µs" userAgent="kube-probe/1.27" audit-ID="" srcIP="127.0.0.1:41210" resp=200
I1030 05:36:01.632397       1 httplog.go:132] "HTTP" verb="GET" URI="/healthz" latency="82.244µs" userAgent="kube-probe/1.27" audit-ID="" srcIP="127.0.0.1:35396" resp=200
I1030 05:36:11.632990       1 httplog.go:132] "HTTP" verb="GET" URI="/healthz" latency="78.199µs" userAgent="kube-probe/1.27" audit-ID="" srcIP="127.0.0.1:46638" resp=200
I1030 05:36:21.630061       1 httplog.go:132] "HTTP" verb="GET" URI="/healthz" latency="75.652µs" userAgent="kube-probe/1.27" audit-ID="" srcIP="127.0.0.1:52652" resp=200
I1030 05:36:31.632456       1 httplog.go:132] "HTTP" verb="GET" URI="/healthz" latency="172.56µs" userAgent="kube-probe/1.27" audit-ID="" srcIP="127.0.0.1:39366" resp=200
I1030 05:36:41.632415       1 httplog.go:132] "HTTP" verb="GET" URI="/healthz" latency="131.333µs" userAgent="kube-probe/1.27" audit-ID="" srcIP="127.0.0.1:45530" resp=200
I1030 05:36:45.157402       1 reflector.go:788] vendor/k8s.io/client-go/informers/factory.go:150: Watch close - *v1.PersistentVolume total 10 items received
I1030 05:36:51.629898       1 httplog.go:132] "HTTP" verb="GET" URI="/healthz" latency="101.935µs" userAgent="kube-probe/1.27" audit-ID="" srcIP="127.0.0.1:52226" resp=200
I1030 05:37:01.632366       1 httplog.go:132] "HTTP" verb="GET" URI="/healthz" latency="92.544µs" userAgent="kube-probe/1.27" audit-ID="" srcIP="127.0.0.1:40364" resp=200
I1030 05:37:11.632162       1 httplog.go:132] "HTTP" verb="GET" URI="/healthz" latency="110.37µs" userAgent="kube-probe/1.27" audit-ID="" srcIP="127.0.0.1:36006" resp=200
I1030 05:37:15.159041       1 reflector.go:788] pkg/server/dynamiccertificates/configmap_cafile_content.go:206: Watch close - *v1.ConfigMap total 8 items received
I1030 05:37:21.628210       1 httplog.go:132] "HTTP" verb="GET" URI="/healthz" latency="101.298µs" userAgent="kube-probe/1.27" audit-ID="" srcIP="127.0.0.1:45150" resp=200
I1030 05:37:28.159908       1 reflector.go:788] vendor/k8s.io/client-go/informers/factory.go:150: Watch close - *v1.StatefulSet total 11 items received
I1030 05:37:28.159997       1 reflector.go:788] vendor/k8s.io/client-go/informers/factory.go:150: Watch close - *v1.CSIStorageCapacity total 11 items received
I1030 05:37:30.160450       1 reflector.go:788] vendor/k8s.io/client-go/informers/factory.go:150: Watch close - *v1.StorageClass total 9 items received
I1030 05:37:31.632044       1 httplog.go:132] "HTTP" verb="GET" URI="/healthz" latency="74.217µs" userAgent="kube-probe/1.27" audit-ID="" srcIP="127.0.0.1:60264" resp=200
I1030 05:37:41.631424       1 httplog.go:132] "HTTP" verb="GET" URI="/healthz" latency="113.652µs" userAgent="kube-probe/1.27" audit-ID="" srcIP="127.0.0.1:40236" resp=200
I1030 05:37:51.630280       1 httplog.go:132] "HTTP" verb="GET" URI="/healthz" latency="96.262µs" userAgent="kube-probe/1.27" audit-ID="" srcIP="127.0.0.1:47210" resp=200
I1030 05:37:58.159951       1 reflector.go:788] vendor/k8s.io/client-go/informers/factory.go:150: Watch close - *v1.ReplicationController total 7 items received
I1030 05:38:01.632886       1 httplog.go:132] "HTTP" verb="GET" URI="/healthz" latency="79.052µs" userAgent="kube-probe/1.27" audit-ID="" srcIP="127.0.0.1:44860" resp=200
I1030 05:38:11.631903       1 httplog.go:132] "HTTP" verb="GET" URI="/healthz" latency="109.198µs" userAgent="kube-probe/1.27" audit-ID="" srcIP="127.0.0.1:40594" resp=200
I1030 05:38:21.163281       1 reflector.go:788] pkg/authentication/request/headerrequest/requestheader_controller.go:172: Watch close - *v1.ConfigMap total 8 items received
I1030 05:38:21.631969       1 httplog.go:132] "HTTP" verb="GET" URI="/healthz" latency="127.91µs" userAgent="kube-probe/1.27" audit-ID="" srcIP="127.0.0.1:58240" resp=200
I1030 05:38:31.631545       1 httplog.go:132] "HTTP" verb="GET" URI="/healthz" latency="83.656µs" userAgent="kube-probe/1.27" audit-ID="" srcIP="127.0.0.1:40714" resp=200
I1030 05:38:41.628307       1 httplog.go:132] "HTTP" verb="GET" URI="/healthz" latency="84.069µs" userAgent="kube-probe/1.27" audit-ID="" srcIP="127.0.0.1:42718" resp=200
I1030 05:38:51.631349       1 httplog.go:132] "HTTP" verb="GET" URI="/healthz" latency="74.039µs" userAgent="kube-probe/1.27" audit-ID="" srcIP="127.0.0.1:45272" resp=200
I1030 05:39:00.088998       1 eventhandlers.go:206] "Update event for scheduled pod" pod="default/job-train-online-cuda-epoch6"
I1030 05:39:01.332210       1 eventhandlers.go:231] "Delete event for scheduled pod" pod="default/job-train-online-cuda-epoch6"
I1030 05:39:01.633566       1 httplog.go:132] "HTTP" verb="GET" URI="/healthz" latency="101.711µs" userAgent="kube-probe/1.27" audit-ID="" srcIP="127.0.0.1:59990" resp=200
I1030 05:39:11.632498       1 httplog.go:132] "HTTP" verb="GET" URI="/healthz" latency="122.466µs" userAgent="kube-probe/1.27" audit-ID="" srcIP="127.0.0.1:40332" resp=200
I1030 05:39:14.159929       1 reflector.go:788] pkg/server/dynamiccertificates/configmap_cafile_content.go:206: Watch close - *v1.ConfigMap total 9 items received
I1030 05:39:21.632838       1 httplog.go:132] "HTTP" verb="GET" URI="/healthz" latency="98.182µs" userAgent="kube-probe/1.27" audit-ID="" srcIP="127.0.0.1:40024" resp=200
I1030 05:39:25.160081       1 reflector.go:788] vendor/k8s.io/client-go/informers/factory.go:150: Watch close - *v1.CSINode total 8 items received
I1030 05:39:31.632158       1 httplog.go:132] "HTTP" verb="GET" URI="/healthz" latency="96.09µs" userAgent="kube-probe/1.27" audit-ID="" srcIP="127.0.0.1:40182" resp=200
I1030 05:39:34.159746       1 reflector.go:788] vendor/k8s.io/client-go/informers/factory.go:150: Watch close - *v1.ReplicaSet total 10 items received
I1030 05:39:41.631895       1 httplog.go:132] "HTTP" verb="GET" URI="/healthz" latency="58.149µs" userAgent="kube-probe/1.27" audit-ID="" srcIP="127.0.0.1:41770" resp=200
I1030 05:39:51.630613       1 httplog.go:132] "HTTP" verb="GET" URI="/healthz" latency="101.584µs" userAgent="kube-probe/1.27" audit-ID="" srcIP="127.0.0.1:46156" resp=200
I1030 05:39:57.166475       1 reflector.go:788] vendor/k8s.io/client-go/informers/factory.go:150: Watch close - *v1.Namespace total 9 items received
I1030 05:40:01.632854       1 httplog.go:132] "HTTP" verb="GET" URI="/healthz" latency="101.334µs" userAgent="kube-probe/1.27" audit-ID="" srcIP="127.0.0.1:57336" resp=200
I1030 05:40:11.632235       1 httplog.go:132] "HTTP" verb="GET" URI="/healthz" latency="115.872µs" userAgent="kube-probe/1.27" audit-ID="" srcIP="127.0.0.1:60822" resp=200
I1030 05:40:21.632355       1 httplog.go:132] "HTTP" verb="GET" URI="/healthz" latency="116.991µs" userAgent="kube-probe/1.27" audit-ID="" srcIP="127.0.0.1:42488" resp=200
I1030 05:40:31.631281       1 httplog.go:132] "HTTP" verb="GET" URI="/healthz" latency="109.084µs" userAgent="kube-probe/1.27" audit-ID="" srcIP="127.0.0.1:39760" resp=200
I1030 05:40:41.632499       1 httplog.go:132] "HTTP" verb="GET" URI="/healthz" latency="104.424µs" userAgent="kube-probe/1.27" audit-ID="" srcIP="127.0.0.1:54882" resp=200
I1030 05:40:43.158706       1 reflector.go:788] vendor/k8s.io/client-go/informers/factory.go:150: Watch close - *v1.PersistentVolumeClaim total 9 items received
I1030 05:40:51.632838       1 httplog.go:132] "HTTP" verb="GET" URI="/healthz" latency="109.251µs" userAgent="kube-probe/1.27" audit-ID="" srcIP="127.0.0.1:48538" resp=200
I1030 05:41:01.633156       1 httplog.go:132] "HTTP" verb="GET" URI="/healthz" latency="106.52µs" userAgent="kube-probe/1.27" audit-ID="" srcIP="127.0.0.1:50762" resp=200
I1030 05:41:08.158932       1 reflector.go:788] vendor/k8s.io/client-go/informers/factory.go:150: Watch close - *v1.CSIDriver total 8 items received
I1030 05:41:11.631577       1 httplog.go:132] "HTTP" verb="GET" URI="/healthz" latency="105.563µs" userAgent="kube-probe/1.27" audit-ID="" srcIP="127.0.0.1:43992" resp=200
I1030 05:41:15.162348       1 reflector.go:788] vendor/k8s.io/client-go/informers/factory.go:150: Watch close - *v1.Pod total 11 items received
I1030 05:41:21.633047       1 httplog.go:132] "HTTP" verb="GET" URI="/healthz" latency="101.644µs" userAgent="kube-probe/1.27" audit-ID="" srcIP="127.0.0.1:53274" resp=200
I1030 05:41:31.632120       1 httplog.go:132] "HTTP" verb="GET" URI="/healthz" latency="141.598µs" userAgent="kube-probe/1.27" audit-ID="" srcIP="127.0.0.1:39370" resp=200
I1030 05:41:41.632557       1 httplog.go:132] "HTTP" verb="GET" URI="/healthz" latency="104.306µs" userAgent="kube-probe/1.27" audit-ID="" srcIP="127.0.0.1:54110" resp=200
I1030 05:41:51.632015       1 httplog.go:132] "HTTP" verb="GET" URI="/healthz" latency="107.959µs" userAgent="kube-probe/1.27" audit-ID="" srcIP="127.0.0.1:38376" resp=200
I1030 05:42:01.632294       1 httplog.go:132] "HTTP" verb="GET" URI="/healthz" latency="133.362µs" userAgent="kube-probe/1.27" audit-ID="" srcIP="127.0.0.1:33122" resp=200
I1030 05:42:11.632525       1 httplog.go:132] "HTTP" verb="GET" URI="/healthz" latency="118.023µs" userAgent="kube-probe/1.27" audit-ID="" srcIP="127.0.0.1:45180" resp=200
I1030 05:42:21.632749       1 httplog.go:132] "HTTP" verb="GET" URI="/healthz" latency="105.639µs" userAgent="kube-probe/1.27" audit-ID="" srcIP="127.0.0.1:46332" resp=200
I1030 05:42:28.161155       1 reflector.go:788] vendor/k8s.io/client-go/informers/factory.go:150: Watch close - *v1.Service total 11 items received
I1030 05:42:31.630512       1 httplog.go:132] "HTTP" verb="GET" URI="/healthz" latency="101.728µs" userAgent="kube-probe/1.27" audit-ID="" srcIP="127.0.0.1:34466" resp=200
I1030 05:42:41.632151       1 httplog.go:132] "HTTP" verb="GET" URI="/healthz" latency="114.17µs" userAgent="kube-probe/1.27" audit-ID="" srcIP="127.0.0.1:50366" resp=200
I1030 05:42:51.633341       1 httplog.go:132] "HTTP" verb="GET" URI="/healthz" latency="96.865µs" userAgent="kube-probe/1.27" audit-ID="" srcIP="127.0.0.1:38250" resp=200
I1030 05:42:57.158033       1 reflector.go:788] vendor/k8s.io/client-go/informers/factory.go:150: Watch close - *v1.PodDisruptionBudget total 10 items received
I1030 05:43:01.628847       1 httplog.go:132] "HTTP" verb="GET" URI="/healthz" latency="99.956µs" userAgent="kube-probe/1.27" audit-ID="" srcIP="127.0.0.1:37528" resp=200
I1030 05:43:11.632076       1 httplog.go:132] "HTTP" verb="GET" URI="/healthz" latency="78.004µs" userAgent="kube-probe/1.27" audit-ID="" srcIP="127.0.0.1:37556" resp=200
I1030 05:43:14.161864       1 reflector.go:788] pkg/server/dynamiccertificates/configmap_cafile_content.go:206: Watch close - *v1.ConfigMap total 6 items received
I1030 05:43:21.631455       1 httplog.go:132] "HTTP" verb="GET" URI="/healthz" latency="99.038µs" userAgent="kube-probe/1.27" audit-ID="" srcIP="127.0.0.1:54000" resp=200
I1030 05:43:31.631247       1 httplog.go:132] "HTTP" verb="GET" URI="/healthz" latency="127.259µs" userAgent="kube-probe/1.27" audit-ID="" srcIP="127.0.0.1:46686" resp=200
I1030 05:43:41.632608       1 httplog.go:132] "HTTP" verb="GET" URI="/healthz" latency="115.533µs" userAgent="kube-probe/1.27" audit-ID="" srcIP="127.0.0.1:58194" resp=200
I1030 05:43:51.632423       1 httplog.go:132] "HTTP" verb="GET" URI="/healthz" latency="128.905µs" userAgent="kube-probe/1.27" audit-ID="" srcIP="127.0.0.1:43142" resp=200
I1030 05:44:01.166331       1 reflector.go:788] pkg/authentication/request/headerrequest/requestheader_controller.go:172: Watch close - *v1.ConfigMap total 6 items received
I1030 05:44:01.632059       1 httplog.go:132] "HTTP" verb="GET" URI="/healthz" latency="100.746µs" userAgent="kube-probe/1.27" audit-ID="" srcIP="127.0.0.1:56124" resp=200
I1030 05:44:11.632388       1 httplog.go:132] "HTTP" verb="GET" URI="/healthz" latency="121.532µs" userAgent="kube-probe/1.27" audit-ID="" srcIP="127.0.0.1:51988" resp=200
I1030 05:44:16.162703       1 reflector.go:788] vendor/k8s.io/client-go/informers/factory.go:150: Watch close - *v1.Node total 11 items received
I1030 05:44:20.162388       1 reflector.go:788] vendor/k8s.io/client-go/informers/factory.go:150: Watch close - *v1.StatefulSet total 7 items received
I1030 05:44:21.632339       1 httplog.go:132] "HTTP" verb="GET" URI="/healthz" latency="95.479µs" userAgent="kube-probe/1.27" audit-ID="" srcIP="127.0.0.1:59904" resp=200
I1030 05:44:31.632507       1 httplog.go:132] "HTTP" verb="GET" URI="/healthz" latency="84.162µs" userAgent="kube-probe/1.27" audit-ID="" srcIP="127.0.0.1:46646" resp=200
I1030 05:44:35.162132       1 reflector.go:788] vendor/k8s.io/client-go/informers/factory.go:150: Watch close - *v1.StorageClass total 9 items received
I1030 05:44:35.162860       1 reflector.go:788] vendor/k8s.io/client-go/informers/factory.go:150: Watch close - *v1.CSINode total 6 items received
I1030 05:44:41.629805       1 httplog.go:132] "HTTP" verb="GET" URI="/healthz" latency="96.761µs" userAgent="kube-probe/1.27" audit-ID="" srcIP="127.0.0.1:44558" resp=200
I1030 05:44:51.632628       1 httplog.go:132] "HTTP" verb="GET" URI="/healthz" latency="101.417µs" userAgent="kube-probe/1.27" audit-ID="" srcIP="127.0.0.1:58708" resp=200
I1030 05:44:55.161568       1 reflector.go:788] vendor/k8s.io/client-go/informers/factory.go:150: Watch close - *v1.ReplicationController total 8 items received
I1030 05:45:01.628264       1 httplog.go:132] "HTTP" verb="GET" URI="/healthz" latency="146.522µs" userAgent="kube-probe/1.27" audit-ID="" srcIP="127.0.0.1:44086" resp=200
I1030 05:45:02.162364       1 reflector.go:788] vendor/k8s.io/client-go/informers/factory.go:150: Watch close - *v1.CSIStorageCapacity total 9 items received
I1030 05:45:11.632216       1 httplog.go:132] "HTTP" verb="GET" URI="/healthz" latency="108.214µs" userAgent="kube-probe/1.27" audit-ID="" srcIP="127.0.0.1:58976" resp=200
I1030 05:45:21.632326       1 httplog.go:132] "HTTP" verb="GET" URI="/healthz" latency="78.562µs" userAgent="kube-probe/1.27" audit-ID="" srcIP="127.0.0.1:39906" resp=200
I1030 05:45:31.632233       1 httplog.go:132] "HTTP" verb="GET" URI="/healthz" latency="98.018µs" userAgent="kube-probe/1.27" audit-ID="" srcIP="127.0.0.1:56232" resp=200
I1030 05:45:41.631089       1 httplog.go:132] "HTTP" verb="GET" URI="/healthz" latency="98.601µs" userAgent="kube-probe/1.27" audit-ID="" srcIP="127.0.0.1:53876" resp=200
I1030 05:45:47.160210       1 reflector.go:788] vendor/k8s.io/client-go/informers/factory.go:150: Watch close - *v1.PersistentVolume total 9 items received
I1030 05:45:51.631502       1 httplog.go:132] "HTTP" verb="GET" URI="/healthz" latency="101.872µs" userAgent="kube-probe/1.27" audit-ID="" srcIP="127.0.0.1:59018" resp=200
I1030 05:46:01.631481       1 httplog.go:132] "HTTP" verb="GET" URI="/healthz" latency="61.419µs" userAgent="kube-probe/1.27" audit-ID="" srcIP="127.0.0.1:42768" resp=200
I1030 05:46:11.161700       1 reflector.go:788] vendor/k8s.io/client-go/informers/factory.go:150: Watch close - *v1.PersistentVolumeClaim total 6 items received
I1030 05:46:11.632220       1 httplog.go:132] "HTTP" verb="GET" URI="/healthz" latency="65.016µs" userAgent="kube-probe/1.27" audit-ID="" srcIP="127.0.0.1:49760" resp=200
I1030 05:46:21.632836       1 httplog.go:132] "HTTP" verb="GET" URI="/healthz" latency="101.288µs" userAgent="kube-probe/1.27" audit-ID="" srcIP="127.0.0.1:34124" resp=200
I1030 05:46:31.631642       1 httplog.go:132] "HTTP" verb="GET" URI="/healthz" latency="72.903µs" userAgent="kube-probe/1.27" audit-ID="" srcIP="127.0.0.1:43264" resp=200
I1030 05:46:33.161804       1 reflector.go:788] vendor/k8s.io/client-go/informers/factory.go:150: Watch close - *v1.CSIDriver total 7 items received
I1030 05:46:41.633001       1 httplog.go:132] "HTTP" verb="GET" URI="/healthz" latency="107.494µs" userAgent="kube-probe/1.27" audit-ID="" srcIP="127.0.0.1:42360" resp=200
I1030 05:46:51.632698       1 httplog.go:132] "HTTP" verb="GET" URI="/healthz" latency="64.481µs" userAgent="kube-probe/1.27" audit-ID="" srcIP="127.0.0.1:47198" resp=200
I1030 05:46:55.162470       1 reflector.go:788] vendor/k8s.io/client-go/informers/factory.go:150: Watch close - *v1.ReplicaSet total 9 items received
I1030 05:47:01.631398       1 httplog.go:132] "HTTP" verb="GET" URI="/healthz" latency="107.599µs" userAgent="kube-probe/1.27" audit-ID="" srcIP="127.0.0.1:54896" resp=200
I1030 05:47:11.630079       1 httplog.go:132] "HTTP" verb="GET" URI="/healthz" latency="102.996µs" userAgent="kube-probe/1.27" audit-ID="" srcIP="127.0.0.1:58146" resp=200
I1030 05:47:21.631852       1 httplog.go:132] "HTTP" verb="GET" URI="/healthz" latency="110.875µs" userAgent="kube-probe/1.27" audit-ID="" srcIP="127.0.0.1:35870" resp=200
I1030 05:47:25.163123       1 reflector.go:788] pkg/server/dynamiccertificates/configmap_cafile_content.go:206: Watch close - *v1.ConfigMap total 10 items received
I1030 05:47:31.632102       1 httplog.go:132] "HTTP" verb="GET" URI="/healthz" latency="118.328µs" userAgent="kube-probe/1.27" audit-ID="" srcIP="127.0.0.1:33132" resp=200
I1030 05:47:41.163677       1 reflector.go:788] vendor/k8s.io/client-go/informers/factory.go:150: Watch close - *v1.Service total 6 items received
I1030 05:47:41.630175       1 httplog.go:132] "HTTP" verb="GET" URI="/healthz" latency="113.07µs" userAgent="kube-probe/1.27" audit-ID="" srcIP="127.0.0.1:53546" resp=200
I1030 05:47:51.632391       1 httplog.go:132] "HTTP" verb="GET" URI="/healthz" latency="132.487µs" userAgent="kube-probe/1.27" audit-ID="" srcIP="127.0.0.1:48770" resp=200
I1030 05:48:01.632386       1 httplog.go:132] "HTTP" verb="GET" URI="/healthz" latency="85.864µs" userAgent="kube-probe/1.27" audit-ID="" srcIP="127.0.0.1:50510" resp=200
I1030 05:48:11.632993       1 httplog.go:132] "HTTP" verb="GET" URI="/healthz" latency="101.868µs" userAgent="kube-probe/1.27" audit-ID="" srcIP="127.0.0.1:44268" resp=200
I1030 05:48:13.164360       1 reflector.go:788] vendor/k8s.io/client-go/informers/factory.go:150: Watch close - *v1.Pod total 7 items received
I1030 05:48:21.631864       1 httplog.go:132] "HTTP" verb="GET" URI="/healthz" latency="105.4µs" userAgent="kube-probe/1.27" audit-ID="" srcIP="127.0.0.1:57256" resp=200
I1030 05:48:31.631742       1 httplog.go:132] "HTTP" verb="GET" URI="/healthz" latency="103.625µs" userAgent="kube-probe/1.27" audit-ID="" srcIP="127.0.0.1:55818" resp=200
I1030 05:48:41.633595       1 httplog.go:132] "HTTP" verb="GET" URI="/healthz" latency="107.965µs" userAgent="kube-probe/1.27" audit-ID="" srcIP="127.0.0.1:41282" resp=200
I1030 05:48:51.629446       1 httplog.go:132] "HTTP" verb="GET" URI="/healthz" latency="111.317µs" userAgent="kube-probe/1.27" audit-ID="" srcIP="127.0.0.1:35886" resp=200
I1030 05:49:01.633204       1 httplog.go:132] "HTTP" verb="GET" URI="/healthz" latency="102.388µs" userAgent="kube-probe/1.27" audit-ID="" srcIP="127.0.0.1:58720" resp=200
I1030 05:49:11.630515       1 httplog.go:132] "HTTP" verb="GET" URI="/healthz" latency="78.626µs" userAgent="kube-probe/1.27" audit-ID="" srcIP="127.0.0.1:35142" resp=200
I1030 05:49:21.632453       1 httplog.go:132] "HTTP" verb="GET" URI="/healthz" latency="98.986µs" userAgent="kube-probe/1.27" audit-ID="" srcIP="127.0.0.1:45096" resp=200
I1030 05:49:31.629319       1 httplog.go:132] "HTTP" verb="GET" URI="/healthz" latency="100.244µs" userAgent="kube-probe/1.27" audit-ID="" srcIP="127.0.0.1:47000" resp=200
I1030 05:49:41.628946       1 httplog.go:132] "HTTP" verb="GET" URI="/healthz" latency="108.814µs" userAgent="kube-probe/1.27" audit-ID="" srcIP="127.0.0.1:50928" resp=200
I1030 05:49:51.632434       1 httplog.go:132] "HTTP" verb="GET" URI="/healthz" latency="148.987µs" userAgent="kube-probe/1.27" audit-ID="" srcIP="127.0.0.1:47192" resp=200
I1030 05:49:56.169035       1 reflector.go:788] vendor/k8s.io/client-go/informers/factory.go:150: Watch close - *v1.Namespace total 11 items received
I1030 05:50:01.633429       1 httplog.go:132] "HTTP" verb="GET" URI="/healthz" latency="118.616µs" userAgent="kube-probe/1.27" audit-ID="" srcIP="127.0.0.1:36134" resp=200
I1030 05:50:10.165298       1 reflector.go:788] vendor/k8s.io/client-go/informers/factory.go:150: Watch close - *v1.CSINode total 7 items received
I1030 05:50:11.632277       1 httplog.go:132] "HTTP" verb="GET" URI="/healthz" latency="99.336µs" userAgent="kube-probe/1.27" audit-ID="" srcIP="127.0.0.1:37028" resp=200
I1030 05:50:21.632722       1 httplog.go:132] "HTTP" verb="GET" URI="/healthz" latency="104.126µs" userAgent="kube-probe/1.27" audit-ID="" srcIP="127.0.0.1:47952" resp=200
I1030 05:50:31.631785       1 httplog.go:132] "HTTP" verb="GET" URI="/healthz" latency="101.889µs" userAgent="kube-probe/1.27" audit-ID="" srcIP="127.0.0.1:54776" resp=200
I1030 05:50:41.633275       1 httplog.go:132] "HTTP" verb="GET" URI="/healthz" latency="100.259µs" userAgent="kube-probe/1.27" audit-ID="" srcIP="127.0.0.1:54522" resp=200
I1030 05:50:51.630939       1 httplog.go:132] "HTTP" verb="GET" URI="/healthz" latency="106.045µs" userAgent="kube-probe/1.27" audit-ID="" srcIP="127.0.0.1:45336" resp=200
I1030 05:50:53.162148       1 reflector.go:788] vendor/k8s.io/client-go/informers/factory.go:150: Watch close - *v1.PersistentVolume total 6 items received
I1030 05:51:01.629547       1 httplog.go:132] "HTTP" verb="GET" URI="/healthz" latency="94.96µs" userAgent="kube-probe/1.27" audit-ID="" srcIP="127.0.0.1:47662" resp=200
I1030 05:51:11.631964       1 httplog.go:132] "HTTP" verb="GET" URI="/healthz" latency="109.792µs" userAgent="kube-probe/1.27" audit-ID="" srcIP="127.0.0.1:45766" resp=200
I1030 05:51:21.632560       1 httplog.go:132] "HTTP" verb="GET" URI="/healthz" latency="83.14µs" userAgent="kube-probe/1.27" audit-ID="" srcIP="127.0.0.1:37174" resp=200
I1030 05:51:31.632089       1 httplog.go:132] "HTTP" verb="GET" URI="/healthz" latency="99.151µs" userAgent="kube-probe/1.27" audit-ID="" srcIP="127.0.0.1:49528" resp=200
I1030 05:51:41.629120       1 httplog.go:132] "HTTP" verb="GET" URI="/healthz" latency="106.622µs" userAgent="kube-probe/1.27" audit-ID="" srcIP="127.0.0.1:41102" resp=200
I1030 05:51:51.629084       1 httplog.go:132] "HTTP" verb="GET" URI="/healthz" latency="95.467µs" userAgent="kube-probe/1.27" audit-ID="" srcIP="127.0.0.1:39514" resp=200
I1030 05:51:52.160685       1 reflector.go:788] vendor/k8s.io/client-go/informers/factory.go:150: Watch close - *v1.PodDisruptionBudget total 10 items received
I1030 05:52:01.635617       1 httplog.go:132] "HTTP" verb="GET" URI="/healthz" latency="106.566µs" userAgent="kube-probe/1.27" audit-ID="" srcIP="127.0.0.1:55868" resp=200
I1030 05:52:11.632583       1 httplog.go:132] "HTTP" verb="GET" URI="/healthz" latency="96.085µs" userAgent="kube-probe/1.27" audit-ID="" srcIP="127.0.0.1:54072" resp=200
I1030 05:52:21.632169       1 httplog.go:132] "HTTP" verb="GET" URI="/healthz" latency="78.128µs" userAgent="kube-probe/1.27" audit-ID="" srcIP="127.0.0.1:44558" resp=200
I1030 05:52:31.633515       1 httplog.go:132] "HTTP" verb="GET" URI="/healthz" latency="114.162µs" userAgent="kube-probe/1.27" audit-ID="" srcIP="127.0.0.1:44378" resp=200
I1030 05:52:41.631996       1 httplog.go:132] "HTTP" verb="GET" URI="/healthz" latency="108.128µs" userAgent="kube-probe/1.27" audit-ID="" srcIP="127.0.0.1:54930" resp=200
I1030 05:52:45.164483       1 reflector.go:788] pkg/server/dynamiccertificates/configmap_cafile_content.go:206: Watch close - *v1.ConfigMap total 10 items received
I1030 05:52:51.632016       1 httplog.go:132] "HTTP" verb="GET" URI="/healthz" latency="104.119µs" userAgent="kube-probe/1.27" audit-ID="" srcIP="127.0.0.1:46436" resp=200
I1030 05:52:54.165000       1 reflector.go:788] vendor/k8s.io/client-go/informers/factory.go:150: Watch close - *v1.StatefulSet total 10 items received
I1030 05:53:01.632925       1 httplog.go:132] "HTTP" verb="GET" URI="/healthz" latency="96.944µs" userAgent="kube-probe/1.27" audit-ID="" srcIP="127.0.0.1:34710" resp=200
I1030 05:53:02.164955       1 reflector.go:788] vendor/k8s.io/client-go/informers/factory.go:150: Watch close - *v1.Node total 10 items received
I1030 05:53:03.163966       1 reflector.go:788] vendor/k8s.io/client-go/informers/factory.go:150: Watch close - *v1.CSIDriver total 8 items received
I1030 05:53:11.632448       1 httplog.go:132] "HTTP" verb="GET" URI="/healthz" latency="141.955µs" userAgent="kube-probe/1.27" audit-ID="" srcIP="127.0.0.1:60896" resp=200
I1030 05:53:21.632411       1 httplog.go:132] "HTTP" verb="GET" URI="/healthz" latency="118.334µs" userAgent="kube-probe/1.27" audit-ID="" srcIP="127.0.0.1:55408" resp=200
I1030 05:53:31.632500       1 httplog.go:132] "HTTP" verb="GET" URI="/healthz" latency="85.176µs" userAgent="kube-probe/1.27" audit-ID="" srcIP="127.0.0.1:45734" resp=200
I1030 05:53:41.169490       1 reflector.go:788] pkg/authentication/request/headerrequest/requestheader_controller.go:172: Watch close - *v1.ConfigMap total 10 items received
I1030 05:53:41.632214       1 httplog.go:132] "HTTP" verb="GET" URI="/healthz" latency="97.626µs" userAgent="kube-probe/1.27" audit-ID="" srcIP="127.0.0.1:54476" resp=200
I1030 05:53:51.632428       1 httplog.go:132] "HTTP" verb="GET" URI="/healthz" latency="118.851µs" userAgent="kube-probe/1.27" audit-ID="" srcIP="127.0.0.1:50666" resp=200
I1030 05:54:01.629216       1 httplog.go:132] "HTTP" verb="GET" URI="/healthz" latency="92.273µs" userAgent="kube-probe/1.27" audit-ID="" srcIP="127.0.0.1:59576" resp=200
I1030 05:54:10.164482       1 reflector.go:788] vendor/k8s.io/client-go/informers/factory.go:150: Watch close - *v1.CSIStorageCapacity total 10 items received
I1030 05:54:11.629615       1 httplog.go:132] "HTTP" verb="GET" URI="/healthz" latency="99.972µs" userAgent="kube-probe/1.27" audit-ID="" srcIP="127.0.0.1:55330" resp=200
I1030 05:54:16.164992       1 reflector.go:788] vendor/k8s.io/client-go/informers/factory.go:150: Watch close - *v1.ReplicationController total 11 items received
I1030 05:54:19.164444       1 reflector.go:788] vendor/k8s.io/client-go/informers/factory.go:150: Watch close - *v1.PersistentVolumeClaim total 9 items received
I1030 05:54:21.632503       1 httplog.go:132] "HTTP" verb="GET" URI="/healthz" latency="103.525µs" userAgent="kube-probe/1.27" audit-ID="" srcIP="127.0.0.1:43492" resp=200
I1030 05:54:22.164567       1 reflector.go:788] vendor/k8s.io/client-go/informers/factory.go:150: Watch close - *v1.StorageClass total 11 items received
I1030 05:54:23.166239       1 reflector.go:788] vendor/k8s.io/client-go/informers/factory.go:150: Watch close - *v1.Service total 8 items received
I1030 05:54:31.634817       1 httplog.go:132] "HTTP" verb="GET" URI="/healthz" latency="124.698µs" userAgent="kube-probe/1.27" audit-ID="" srcIP="127.0.0.1:59884" resp=200
I1030 05:54:41.165756       1 reflector.go:788] vendor/k8s.io/client-go/informers/factory.go:150: Watch close - *v1.ReplicaSet total 9 items received
I1030 05:54:41.630062       1 httplog.go:132] "HTTP" verb="GET" URI="/healthz" latency="61.602µs" userAgent="kube-probe/1.27" audit-ID="" srcIP="127.0.0.1:53024" resp=200
I1030 05:54:51.628959       1 httplog.go:132] "HTTP" verb="GET" URI="/healthz" latency="76.458µs" userAgent="kube-probe/1.27" audit-ID="" srcIP="127.0.0.1:50212" resp=200
I1030 05:55:01.632069       1 httplog.go:132] "HTTP" verb="GET" URI="/healthz" latency="63.541µs" userAgent="kube-probe/1.27" audit-ID="" srcIP="127.0.0.1:48352" resp=200
I1030 05:55:10.166230       1 reflector.go:788] pkg/server/dynamiccertificates/configmap_cafile_content.go:206: Watch close - *v1.ConfigMap total 9 items received
I1030 05:55:11.628556       1 httplog.go:132] "HTTP" verb="GET" URI="/healthz" latency="144.327µs" userAgent="kube-probe/1.27" audit-ID="" srcIP="127.0.0.1:57250" resp=200
I1030 05:55:21.632558       1 httplog.go:132] "HTTP" verb="GET" URI="/healthz" latency="101.99µs" userAgent="kube-probe/1.27" audit-ID="" srcIP="127.0.0.1:41366" resp=200
I1030 05:55:31.633269       1 httplog.go:132] "HTTP" verb="GET" URI="/healthz" latency="104.045µs" userAgent="kube-probe/1.27" audit-ID="" srcIP="127.0.0.1:44638" resp=200
I1030 05:55:41.630949       1 httplog.go:132] "HTTP" verb="GET" URI="/healthz" latency="109.509µs" userAgent="kube-probe/1.27" audit-ID="" srcIP="127.0.0.1:35986" resp=200
I1030 05:55:51.629127       1 httplog.go:132] "HTTP" verb="GET" URI="/healthz" latency="92.413µs" userAgent="kube-probe/1.27" audit-ID="" srcIP="127.0.0.1:44986" resp=200
I1030 05:55:55.168527       1 reflector.go:788] vendor/k8s.io/client-go/informers/factory.go:150: Watch close - *v1.CSINode total 6 items received
I1030 05:56:01.632760       1 httplog.go:132] "HTTP" verb="GET" URI="/healthz" latency="76.929µs" userAgent="kube-probe/1.27" audit-ID="" srcIP="127.0.0.1:43766" resp=200
I1030 05:56:11.633054       1 httplog.go:132] "HTTP" verb="GET" URI="/healthz" latency="108.078µs" userAgent="kube-probe/1.27" audit-ID="" srcIP="127.0.0.1:44884" resp=200
I1030 05:56:18.167129       1 reflector.go:788] vendor/k8s.io/client-go/informers/factory.go:150: Watch close - *v1.Pod total 9 items received
I1030 05:56:21.629619       1 httplog.go:132] "HTTP" verb="GET" URI="/healthz" latency="87.543µs" userAgent="kube-probe/1.27" audit-ID="" srcIP="127.0.0.1:58364" resp=200
I1030 05:56:31.632205       1 httplog.go:132] "HTTP" verb="GET" URI="/healthz" latency="108.042µs" userAgent="kube-probe/1.27" audit-ID="" srcIP="127.0.0.1:36662" resp=200
I1030 05:56:41.632071       1 httplog.go:132] "HTTP" verb="GET" URI="/healthz" latency="97.572µs" userAgent="kube-probe/1.27" audit-ID="" srcIP="127.0.0.1:45262" resp=200
I1030 05:56:50.407900       1 eventhandlers.go:206] "Update event for scheduled pod" pod="default/job-train-imgclassfication16-cuda-epoch160"
I1030 05:56:51.630866       1 httplog.go:132] "HTTP" verb="GET" URI="/healthz" latency="93.526µs" userAgent="kube-probe/1.27" audit-ID="" srcIP="127.0.0.1:40700" resp=200
I1030 05:56:51.644587       1 eventhandlers.go:231] "Delete event for scheduled pod" pod="default/job-train-imgclassfication16-cuda-epoch160"
I1030 05:57:01.631915       1 httplog.go:132] "HTTP" verb="GET" URI="/healthz" latency="109.112µs" userAgent="kube-probe/1.27" audit-ID="" srcIP="127.0.0.1:58932" resp=200
I1030 05:57:11.164724       1 reflector.go:788] vendor/k8s.io/client-go/informers/factory.go:150: Watch close - *v1.PersistentVolume total 7 items received
I1030 05:57:11.630998       1 httplog.go:132] "HTTP" verb="GET" URI="/healthz" latency="104.556µs" userAgent="kube-probe/1.27" audit-ID="" srcIP="127.0.0.1:44304" resp=200
I1030 05:57:21.632127       1 httplog.go:132] "HTTP" verb="GET" URI="/healthz" latency="97.3µs" userAgent="kube-probe/1.27" audit-ID="" srcIP="127.0.0.1:39914" resp=200
I1030 05:57:27.171545       1 reflector.go:788] vendor/k8s.io/client-go/informers/factory.go:150: Watch close - *v1.Namespace total 8 items received
I1030 05:57:31.632584       1 httplog.go:132] "HTTP" verb="GET" URI="/healthz" latency="108.722µs" userAgent="kube-probe/1.27" audit-ID="" srcIP="127.0.0.1:54256" resp=200
I1030 05:57:41.632794       1 httplog.go:132] "HTTP" verb="GET" URI="/healthz" latency="124.137µs" userAgent="kube-probe/1.27" audit-ID="" srcIP="127.0.0.1:60552" resp=200
I1030 05:57:46.167360       1 reflector.go:788] pkg/server/dynamiccertificates/configmap_cafile_content.go:206: Watch close - *v1.ConfigMap total 5 items received
I1030 05:57:51.629617       1 httplog.go:132] "HTTP" verb="GET" URI="/healthz" latency="104.283µs" userAgent="kube-probe/1.27" audit-ID="" srcIP="127.0.0.1:49290" resp=200
I1030 05:58:01.630021       1 httplog.go:132] "HTTP" verb="GET" URI="/healthz" latency="99.958µs" userAgent="kube-probe/1.27" audit-ID="" srcIP="127.0.0.1:41666" resp=200
I1030 05:58:06.167322       1 reflector.go:788] vendor/k8s.io/client-go/informers/factory.go:150: Watch close - *v1.StatefulSet total 6 items received
I1030 05:58:11.629036       1 httplog.go:132] "HTTP" verb="GET" URI="/healthz" latency="103.183µs" userAgent="kube-probe/1.27" audit-ID="" srcIP="127.0.0.1:49264" resp=200
I1030 05:58:21.632022       1 httplog.go:132] "HTTP" verb="GET" URI="/healthz" latency="126.922µs" userAgent="kube-probe/1.27" audit-ID="" srcIP="127.0.0.1:52692" resp=200
I1030 05:58:31.632808       1 httplog.go:132] "HTTP" verb="GET" URI="/healthz" latency="99.089µs" userAgent="kube-probe/1.27" audit-ID="" srcIP="127.0.0.1:41708" resp=200
I1030 05:58:41.632400       1 httplog.go:132] "HTTP" verb="GET" URI="/healthz" latency="118.937µs" userAgent="kube-probe/1.27" audit-ID="" srcIP="127.0.0.1:50458" resp=200
I1030 05:58:51.629805       1 httplog.go:132] "HTTP" verb="GET" URI="/healthz" latency="103.065µs" userAgent="kube-probe/1.27" audit-ID="" srcIP="127.0.0.1:55034" resp=200
I1030 05:59:01.628949       1 httplog.go:132] "HTTP" verb="GET" URI="/healthz" latency="99.073µs" userAgent="kube-probe/1.27" audit-ID="" srcIP="127.0.0.1:60298" resp=200
I1030 05:59:11.632940       1 httplog.go:132] "HTTP" verb="GET" URI="/healthz" latency="68.651µs" userAgent="kube-probe/1.27" audit-ID="" srcIP="127.0.0.1:54354" resp=200
I1030 05:59:21.631802       1 httplog.go:132] "HTTP" verb="GET" URI="/healthz" latency="107.236µs" userAgent="kube-probe/1.27" audit-ID="" srcIP="127.0.0.1:50376" resp=200
I1030 05:59:31.632274       1 httplog.go:132] "HTTP" verb="GET" URI="/healthz" latency="102.352µs" userAgent="kube-probe/1.27" audit-ID="" srcIP="127.0.0.1:33926" resp=200
I1030 05:59:33.166597       1 reflector.go:788] vendor/k8s.io/client-go/informers/factory.go:150: Watch close - *v1.CSIDriver total 8 items received
I1030 05:59:41.632520       1 httplog.go:132] "HTTP" verb="GET" URI="/healthz" latency="97.199µs" userAgent="kube-probe/1.27" audit-ID="" srcIP="127.0.0.1:47928" resp=200
I1030 05:59:44.959289       1 eventhandlers.go:206] "Update event for scheduled pod" pod="default/job-train-imgclassfication17-cuda-epoch170"
I1030 05:59:46.206461       1 eventhandlers.go:231] "Delete event for scheduled pod" pod="default/job-train-imgclassfication17-cuda-epoch170"
I1030 05:59:51.630159       1 httplog.go:132] "HTTP" verb="GET" URI="/healthz" latency="81.446µs" userAgent="kube-probe/1.27" audit-ID="" srcIP="127.0.0.1:45406" resp=200
I1030 05:59:55.167742       1 reflector.go:788] vendor/k8s.io/client-go/informers/factory.go:150: Watch close - *v1.Node total 9 items received
I1030 06:00:01.632640       1 httplog.go:132] "HTTP" verb="GET" URI="/healthz" latency="114.277µs" userAgent="kube-probe/1.27" audit-ID="" srcIP="127.0.0.1:44378" resp=200
I1030 06:00:11.628869       1 httplog.go:132] "HTTP" verb="GET" URI="/healthz" latency="65.084µs" userAgent="kube-probe/1.27" audit-ID="" srcIP="127.0.0.1:45730" resp=200
I1030 06:00:21.633055       1 httplog.go:132] "HTTP" verb="GET" URI="/healthz" latency="120.463µs" userAgent="kube-probe/1.27" audit-ID="" srcIP="127.0.0.1:56276" resp=200
I1030 06:00:31.631683       1 httplog.go:132] "HTTP" verb="GET" URI="/healthz" latency="91.898µs" userAgent="kube-probe/1.27" audit-ID="" srcIP="127.0.0.1:46232" resp=200
I1030 06:00:41.632587       1 httplog.go:132] "HTTP" verb="GET" URI="/healthz" latency="106.188µs" userAgent="kube-probe/1.27" audit-ID="" srcIP="127.0.0.1:33748" resp=200
I1030 06:00:48.168383       1 reflector.go:788] vendor/k8s.io/client-go/informers/factory.go:150: Watch close - *v1.ReplicationController total 8 items received
I1030 06:00:51.632133       1 httplog.go:132] "HTTP" verb="GET" URI="/healthz" latency="136.067µs" userAgent="kube-probe/1.27" audit-ID="" srcIP="127.0.0.1:39228" resp=200
I1030 06:01:01.632054       1 httplog.go:132] "HTTP" verb="GET" URI="/healthz" latency="90.116µs" userAgent="kube-probe/1.27" audit-ID="" srcIP="127.0.0.1:52794" resp=200
I1030 06:01:11.632735       1 httplog.go:132] "HTTP" verb="GET" URI="/healthz" latency="115.891µs" userAgent="kube-probe/1.27" audit-ID="" srcIP="127.0.0.1:54006" resp=200
I1030 06:01:16.168858       1 reflector.go:788] pkg/server/dynamiccertificates/configmap_cafile_content.go:206: Watch close - *v1.ConfigMap total 7 items received
I1030 06:01:21.632190       1 httplog.go:132] "HTTP" verb="GET" URI="/healthz" latency="93.871µs" userAgent="kube-probe/1.27" audit-ID="" srcIP="127.0.0.1:50246" resp=200
I1030 06:01:22.163251       1 reflector.go:788] vendor/k8s.io/client-go/informers/factory.go:150: Watch close - *v1.PodDisruptionBudget total 10 items received
I1030 06:01:31.632768       1 httplog.go:132] "HTTP" verb="GET" URI="/healthz" latency="93.6µs" userAgent="kube-probe/1.27" audit-ID="" srcIP="127.0.0.1:39364" resp=200
I1030 06:01:41.632717       1 httplog.go:132] "HTTP" verb="GET" URI="/healthz" latency="97.087µs" userAgent="kube-probe/1.27" audit-ID="" srcIP="127.0.0.1:56200" resp=200
I1030 06:01:51.632580       1 httplog.go:132] "HTTP" verb="GET" URI="/healthz" latency="96.993µs" userAgent="kube-probe/1.27" audit-ID="" srcIP="127.0.0.1:60202" resp=200
I1030 06:01:58.167437       1 reflector.go:788] vendor/k8s.io/client-go/informers/factory.go:150: Watch close - *v1.StorageClass total 9 items received
I1030 06:02:01.633590       1 httplog.go:132] "HTTP" verb="GET" URI="/healthz" latency="119.227µs" userAgent="kube-probe/1.27" audit-ID="" srcIP="127.0.0.1:51746" resp=200
I1030 06:02:07.168329       1 reflector.go:788] vendor/k8s.io/client-go/informers/factory.go:150: Watch close - *v1.ReplicaSet total 9 items received
I1030 06:02:08.169382       1 reflector.go:788] vendor/k8s.io/client-go/informers/factory.go:150: Watch close - *v1.Service total 9 items received
I1030 06:02:11.631053       1 httplog.go:132] "HTTP" verb="GET" URI="/healthz" latency="104.202µs" userAgent="kube-probe/1.27" audit-ID="" srcIP="127.0.0.1:55644" resp=200
I1030 06:02:21.632326       1 httplog.go:132] "HTTP" verb="GET" URI="/healthz" latency="94.372µs" userAgent="kube-probe/1.27" audit-ID="" srcIP="127.0.0.1:55166" resp=200
I1030 06:02:31.632849       1 httplog.go:132] "HTTP" verb="GET" URI="/healthz" latency="106.638µs" userAgent="kube-probe/1.27" audit-ID="" srcIP="127.0.0.1:59156" resp=200
I1030 06:02:39.167467       1 reflector.go:788] vendor/k8s.io/client-go/informers/factory.go:150: Watch close - *v1.CSIStorageCapacity total 9 items received
I1030 06:02:41.631986       1 httplog.go:132] "HTTP" verb="GET" URI="/healthz" latency="97.933µs" userAgent="kube-probe/1.27" audit-ID="" srcIP="127.0.0.1:59314" resp=200
I1030 06:02:43.170322       1 reflector.go:788] vendor/k8s.io/client-go/informers/factory.go:150: Watch close - *v1.Pod total 11 items received
I1030 06:02:48.167503       1 reflector.go:788] vendor/k8s.io/client-go/informers/factory.go:150: Watch close - *v1.PersistentVolume total 6 items received
I1030 06:02:50.172726       1 reflector.go:788] pkg/authentication/request/headerrequest/requestheader_controller.go:172: Watch close - *v1.ConfigMap total 10 items received
I1030 06:02:51.632481       1 httplog.go:132] "HTTP" verb="GET" URI="/healthz" latency="111.013µs" userAgent="kube-probe/1.27" audit-ID="" srcIP="127.0.0.1:50048" resp=200
I1030 06:03:01.632781       1 httplog.go:132] "HTTP" verb="GET" URI="/healthz" latency="68.96µs" userAgent="kube-probe/1.27" audit-ID="" srcIP="127.0.0.1:44240" resp=200
I1030 06:03:11.632874       1 httplog.go:132] "HTTP" verb="GET" URI="/healthz" latency="108.984µs" userAgent="kube-probe/1.27" audit-ID="" srcIP="127.0.0.1:49738" resp=200
I1030 06:03:15.620157       1 eventhandlers.go:206] "Update event for scheduled pod" pod="default/job-train-imgclassfication18-cuda-epoch180"
I1030 06:03:16.859394       1 eventhandlers.go:231] "Delete event for scheduled pod" pod="default/job-train-imgclassfication18-cuda-epoch180"
I1030 06:03:21.632132       1 httplog.go:132] "HTTP" verb="GET" URI="/healthz" latency="94.353µs" userAgent="kube-probe/1.27" audit-ID="" srcIP="127.0.0.1:39574" resp=200
I1030 06:03:31.631466       1 httplog.go:132] "HTTP" verb="GET" URI="/healthz" latency="94.087µs" userAgent="kube-probe/1.27" audit-ID="" srcIP="127.0.0.1:41974" resp=200
I1030 06:03:41.633135       1 httplog.go:132] "HTTP" verb="GET" URI="/healthz" latency="94.368µs" userAgent="kube-probe/1.27" audit-ID="" srcIP="127.0.0.1:48548" resp=200
I1030 06:03:51.632779       1 httplog.go:132] "HTTP" verb="GET" URI="/healthz" latency="134.383µs" userAgent="kube-probe/1.27" audit-ID="" srcIP="127.0.0.1:41058" resp=200
I1030 06:03:52.167139       1 reflector.go:788] vendor/k8s.io/client-go/informers/factory.go:150: Watch close - *v1.PersistentVolumeClaim total 10 items received
I1030 06:04:01.631527       1 httplog.go:132] "HTTP" verb="GET" URI="/healthz" latency="109.225µs" userAgent="kube-probe/1.27" audit-ID="" srcIP="127.0.0.1:46488" resp=200
I1030 06:04:11.632734       1 httplog.go:132] "HTTP" verb="GET" URI="/healthz" latency="114.878µs" userAgent="kube-probe/1.27" audit-ID="" srcIP="127.0.0.1:41894" resp=200
I1030 06:04:21.632231       1 httplog.go:132] "HTTP" verb="GET" URI="/healthz" latency="106.686µs" userAgent="kube-probe/1.27" audit-ID="" srcIP="127.0.0.1:54656" resp=200
I1030 06:04:31.632778       1 httplog.go:132] "HTTP" verb="GET" URI="/healthz" latency="100.48µs" userAgent="kube-probe/1.27" audit-ID="" srcIP="127.0.0.1:50478" resp=200
I1030 06:04:34.171194       1 reflector.go:788] vendor/k8s.io/client-go/informers/factory.go:150: Watch close - *v1.CSINode total 10 items received
I1030 06:04:41.632028       1 httplog.go:132] "HTTP" verb="GET" URI="/healthz" latency="105.84µs" userAgent="kube-probe/1.27" audit-ID="" srcIP="127.0.0.1:59708" resp=200
I1030 06:04:51.631622       1 httplog.go:132] "HTTP" verb="GET" URI="/healthz" latency="97.609µs" userAgent="kube-probe/1.27" audit-ID="" srcIP="127.0.0.1:52150" resp=200
I1030 06:05:01.632037       1 httplog.go:132] "HTTP" verb="GET" URI="/healthz" latency="102.409µs" userAgent="kube-probe/1.27" audit-ID="" srcIP="127.0.0.1:57290" resp=200
I1030 06:05:11.632535       1 httplog.go:132] "HTTP" verb="GET" URI="/healthz" latency="104.515µs" userAgent="kube-probe/1.27" audit-ID="" srcIP="127.0.0.1:46186" resp=200
I1030 06:05:21.629023       1 httplog.go:132] "HTTP" verb="GET" URI="/healthz" latency="103.67µs" userAgent="kube-probe/1.27" audit-ID="" srcIP="127.0.0.1:42976" resp=200
I1030 06:05:31.631963       1 httplog.go:132] "HTTP" verb="GET" URI="/healthz" latency="74.936µs" userAgent="kube-probe/1.27" audit-ID="" srcIP="127.0.0.1:40024" resp=200
I1030 06:05:37.174018       1 reflector.go:788] vendor/k8s.io/client-go/informers/factory.go:150: Watch close - *v1.Namespace total 9 items received
I1030 06:05:41.632422       1 httplog.go:132] "HTTP" verb="GET" URI="/healthz" latency="142.47µs" userAgent="kube-probe/1.27" audit-ID="" srcIP="127.0.0.1:33884" resp=200
I1030 06:05:51.632471       1 httplog.go:132] "HTTP" verb="GET" URI="/healthz" latency="106.016µs" userAgent="kube-probe/1.27" audit-ID="" srcIP="127.0.0.1:40246" resp=200
I1030 06:06:01.632729       1 httplog.go:132] "HTTP" verb="GET" URI="/healthz" latency="119.962µs" userAgent="kube-probe/1.27" audit-ID="" srcIP="127.0.0.1:40438" resp=200
I1030 06:06:03.170377       1 reflector.go:788] vendor/k8s.io/client-go/informers/factory.go:150: Watch close - *v1.Node total 8 items received
I1030 06:06:11.632113       1 httplog.go:132] "HTTP" verb="GET" URI="/healthz" latency="97.942µs" userAgent="kube-probe/1.27" audit-ID="" srcIP="127.0.0.1:51860" resp=200
I1030 06:06:21.632165       1 httplog.go:132] "HTTP" verb="GET" URI="/healthz" latency="106.761µs" userAgent="kube-probe/1.27" audit-ID="" srcIP="127.0.0.1:47250" resp=200
I1030 06:06:22.201934       1 eventhandlers.go:206] "Update event for scheduled pod" pod="default/job-train-imgclassfication19-cuda-epoch190"
I1030 06:06:23.439295       1 eventhandlers.go:231] "Delete event for scheduled pod" pod="default/job-train-imgclassfication19-cuda-epoch190"
I1030 06:06:31.632513       1 httplog.go:132] "HTTP" verb="GET" URI="/healthz" latency="104.931µs" userAgent="kube-probe/1.27" audit-ID="" srcIP="127.0.0.1:36074" resp=200
I1030 06:06:39.170384       1 reflector.go:788] vendor/k8s.io/client-go/informers/factory.go:150: Watch close - *v1.StatefulSet total 10 items received
I1030 06:06:41.632036       1 httplog.go:132] "HTTP" verb="GET" URI="/healthz" latency="107.353µs" userAgent="kube-probe/1.27" audit-ID="" srcIP="127.0.0.1:34720" resp=200
I1030 06:06:43.170972       1 reflector.go:788] pkg/server/dynamiccertificates/configmap_cafile_content.go:206: Watch close - *v1.ConfigMap total 6 items received
I1030 06:06:48.165779       1 reflector.go:788] vendor/k8s.io/client-go/informers/factory.go:150: Watch close - *v1.PodDisruptionBudget total 6 items received
I1030 06:06:51.632197       1 httplog.go:132] "HTTP" verb="GET" URI="/healthz" latency="98.034µs" userAgent="kube-probe/1.27" audit-ID="" srcIP="127.0.0.1:41058" resp=200
I1030 06:07:01.632009       1 httplog.go:132] "HTTP" verb="GET" URI="/healthz" latency="87.818µs" userAgent="kube-probe/1.27" audit-ID="" srcIP="127.0.0.1:49994" resp=200
I1030 06:07:11.631492       1 httplog.go:132] "HTTP" verb="GET" URI="/healthz" latency="104.462µs" userAgent="kube-probe/1.27" audit-ID="" srcIP="127.0.0.1:51906" resp=200
I1030 06:07:21.631530       1 httplog.go:132] "HTTP" verb="GET" URI="/healthz" latency="108.475µs" userAgent="kube-probe/1.27" audit-ID="" srcIP="127.0.0.1:45110" resp=200
I1030 06:07:31.632682       1 httplog.go:132] "HTTP" verb="GET" URI="/healthz" latency="97.244µs" userAgent="kube-probe/1.27" audit-ID="" srcIP="127.0.0.1:39862" resp=200
I1030 06:07:41.631468       1 httplog.go:132] "HTTP" verb="GET" URI="/healthz" latency="97.917µs" userAgent="kube-probe/1.27" audit-ID="" srcIP="127.0.0.1:37014" resp=200
I1030 06:07:44.170359       1 reflector.go:788] pkg/server/dynamiccertificates/configmap_cafile_content.go:206: Watch close - *v1.ConfigMap total 10 items received
I1030 06:07:51.632381       1 httplog.go:132] "HTTP" verb="GET" URI="/healthz" latency="108.321µs" userAgent="kube-probe/1.27" audit-ID="" srcIP="127.0.0.1:41906" resp=200
I1030 06:08:01.633012       1 httplog.go:132] "HTTP" verb="GET" URI="/healthz" latency="110.232µs" userAgent="kube-probe/1.27" audit-ID="" srcIP="127.0.0.1:55096" resp=200
I1030 06:08:10.173604       1 reflector.go:788] vendor/k8s.io/client-go/informers/factory.go:150: Watch close - *v1.Pod total 10 items received
I1030 06:08:11.632686       1 httplog.go:132] "HTTP" verb="GET" URI="/healthz" latency="94.25µs" userAgent="kube-probe/1.27" audit-ID="" srcIP="127.0.0.1:45378" resp=200
I1030 06:08:21.632074       1 httplog.go:132] "HTTP" verb="GET" URI="/healthz" latency="107.064µs" userAgent="kube-probe/1.27" audit-ID="" srcIP="127.0.0.1:56178" resp=200
I1030 06:08:27.170619       1 reflector.go:788] vendor/k8s.io/client-go/informers/factory.go:150: Watch close - *v1.ReplicationController total 8 items received
I1030 06:08:28.176187       1 reflector.go:788] pkg/authentication/request/headerrequest/requestheader_controller.go:172: Watch close - *v1.ConfigMap total 6 items received
I1030 06:08:31.632263       1 httplog.go:132] "HTTP" verb="GET" URI="/healthz" latency="104.611µs" userAgent="kube-probe/1.27" audit-ID="" srcIP="127.0.0.1:41948" resp=200
I1030 06:08:41.631679       1 httplog.go:132] "HTTP" verb="GET" URI="/healthz" latency="93.883µs" userAgent="kube-probe/1.27" audit-ID="" srcIP="127.0.0.1:38862" resp=200
I1030 06:08:51.632691       1 httplog.go:132] "HTTP" verb="GET" URI="/healthz" latency="98.094µs" userAgent="kube-probe/1.27" audit-ID="" srcIP="127.0.0.1:42234" resp=200
I1030 06:09:01.632542       1 httplog.go:132] "HTTP" verb="GET" URI="/healthz" latency="87.604µs" userAgent="kube-probe/1.27" audit-ID="" srcIP="127.0.0.1:35608" resp=200
I1030 06:09:11.632225       1 httplog.go:132] "HTTP" verb="GET" URI="/healthz" latency="94.603µs" userAgent="kube-probe/1.27" audit-ID="" srcIP="127.0.0.1:33042" resp=200
I1030 06:09:14.734484       1 eventhandlers.go:206] "Update event for scheduled pod" pod="default/job-train-imgclassfication20-cuda-epoch200"
I1030 06:09:15.999230       1 eventhandlers.go:231] "Delete event for scheduled pod" pod="default/job-train-imgclassfication20-cuda-epoch200"
I1030 06:09:20.169232       1 reflector.go:788] vendor/k8s.io/client-go/informers/factory.go:150: Watch close - *v1.CSIDriver total 11 items received
I1030 06:09:21.633675       1 httplog.go:132] "HTTP" verb="GET" URI="/healthz" latency="138.084µs" userAgent="kube-probe/1.27" audit-ID="" srcIP="127.0.0.1:37024" resp=200
I1030 06:09:23.171817       1 reflector.go:788] vendor/k8s.io/client-go/informers/factory.go:150: Watch close - *v1.Service total 9 items received
I1030 06:09:27.170793       1 reflector.go:788] vendor/k8s.io/client-go/informers/factory.go:150: Watch close - *v1.PersistentVolume total 7 items received
I1030 06:09:31.633179       1 httplog.go:132] "HTTP" verb="GET" URI="/healthz" latency="171.21µs" userAgent="kube-probe/1.27" audit-ID="" srcIP="127.0.0.1:47050" resp=200
I1030 06:09:40.169277       1 reflector.go:788] vendor/k8s.io/client-go/informers/factory.go:150: Watch close - *v1.StorageClass total 8 items received
I1030 06:09:41.632284       1 httplog.go:132] "HTTP" verb="GET" URI="/healthz" latency="138.849µs" userAgent="kube-probe/1.27" audit-ID="" srcIP="127.0.0.1:59366" resp=200
I1030 06:09:51.632880       1 httplog.go:132] "HTTP" verb="GET" URI="/healthz" latency="155.887µs" userAgent="kube-probe/1.27" audit-ID="" srcIP="127.0.0.1:59156" resp=200
I1030 06:10:01.633722       1 httplog.go:132] "HTTP" verb="GET" URI="/healthz" latency="139.643µs" userAgent="kube-probe/1.27" audit-ID="" srcIP="127.0.0.1:41376" resp=200
I1030 06:10:09.174808       1 reflector.go:788] vendor/k8s.io/client-go/informers/factory.go:150: Watch close - *v1.CSINode total 7 items received
I1030 06:10:11.632885       1 httplog.go:132] "HTTP" verb="GET" URI="/healthz" latency="136.438µs" userAgent="kube-probe/1.27" audit-ID="" srcIP="127.0.0.1:43348" resp=200
I1030 06:10:21.633359       1 httplog.go:132] "HTTP" verb="GET" URI="/healthz" latency="128.399µs" userAgent="kube-probe/1.27" audit-ID="" srcIP="127.0.0.1:58580" resp=200
I1030 06:10:30.170960       1 reflector.go:788] vendor/k8s.io/client-go/informers/factory.go:150: Watch close - *v1.ReplicaSet total 10 items received
I1030 06:10:31.633229       1 httplog.go:132] "HTTP" verb="GET" URI="/healthz" latency="129.834µs" userAgent="kube-probe/1.27" audit-ID="" srcIP="127.0.0.1:53072" resp=200
I1030 06:10:41.631942       1 httplog.go:132] "HTTP" verb="GET" URI="/healthz" latency="111.533µs" userAgent="kube-probe/1.27" audit-ID="" srcIP="127.0.0.1:52980" resp=200
I1030 06:10:51.633299       1 httplog.go:132] "HTTP" verb="GET" URI="/healthz" latency="137.69µs" userAgent="kube-probe/1.27" audit-ID="" srcIP="127.0.0.1:50348" resp=200
I1030 06:10:58.169845       1 reflector.go:788] vendor/k8s.io/client-go/informers/factory.go:150: Watch close - *v1.CSIStorageCapacity total 10 items received
I1030 06:11:01.633344       1 httplog.go:132] "HTTP" verb="GET" URI="/healthz" latency="150.215µs" userAgent="kube-probe/1.27" audit-ID="" srcIP="127.0.0.1:42350" resp=200
I1030 06:11:11.633220       1 httplog.go:132] "HTTP" verb="GET" URI="/healthz" latency="132.422µs" userAgent="kube-probe/1.27" audit-ID="" srcIP="127.0.0.1:54898" resp=200
I1030 06:11:21.633345       1 httplog.go:132] "HTTP" verb="GET" URI="/healthz" latency="134.631µs" userAgent="kube-probe/1.27" audit-ID="" srcIP="127.0.0.1:59244" resp=200
I1030 06:11:31.633012       1 httplog.go:132] "HTTP" verb="GET" URI="/healthz" latency="137.001µs" userAgent="kube-probe/1.27" audit-ID="" srcIP="127.0.0.1:48124" resp=200
I1030 06:11:41.633290       1 httplog.go:132] "HTTP" verb="GET" URI="/healthz" latency="128.631µs" userAgent="kube-probe/1.27" audit-ID="" srcIP="127.0.0.1:35894" resp=200
I1030 06:11:51.633154       1 httplog.go:132] "HTTP" verb="GET" URI="/healthz" latency="122.434µs" userAgent="kube-probe/1.27" audit-ID="" srcIP="127.0.0.1:59514" resp=200
I1030 06:11:52.168953       1 reflector.go:788] vendor/k8s.io/client-go/informers/factory.go:150: Watch close - *v1.PersistentVolumeClaim total 8 items received
I1030 06:12:01.631781       1 httplog.go:132] "HTTP" verb="GET" URI="/healthz" latency="114.251µs" userAgent="kube-probe/1.27" audit-ID="" srcIP="127.0.0.1:57888" resp=200
I1030 06:12:08.177238       1 reflector.go:788] vendor/k8s.io/client-go/informers/factory.go:150: Watch close - *v1.Namespace total 7 items received
I1030 06:12:11.633343       1 httplog.go:132] "HTTP" verb="GET" URI="/healthz" latency="117.248µs" userAgent="kube-probe/1.27" audit-ID="" srcIP="127.0.0.1:43158" resp=200
I1030 06:12:14.173260       1 reflector.go:788] vendor/k8s.io/client-go/informers/factory.go:150: Watch close - *v1.StatefulSet total 7 items received
I1030 06:12:21.633358       1 httplog.go:132] "HTTP" verb="GET" URI="/healthz" latency="129.914µs" userAgent="kube-probe/1.27" audit-ID="" srcIP="127.0.0.1:42826" resp=200
I1030 06:12:31.633361       1 httplog.go:132] "HTTP" verb="GET" URI="/healthz" latency="140.523µs" userAgent="kube-probe/1.27" audit-ID="" srcIP="127.0.0.1:33186" resp=200
I1030 06:12:41.631982       1 httplog.go:132] "HTTP" verb="GET" URI="/healthz" latency="120.97µs" userAgent="kube-probe/1.27" audit-ID="" srcIP="127.0.0.1:54114" resp=200
I1030 06:12:51.632805       1 httplog.go:132] "HTTP" verb="GET" URI="/healthz" latency="131.449µs" userAgent="kube-probe/1.27" audit-ID="" srcIP="127.0.0.1:50454" resp=200
I1030 06:13:01.633238       1 httplog.go:132] "HTTP" verb="GET" URI="/healthz" latency="117.223µs" userAgent="kube-probe/1.27" audit-ID="" srcIP="127.0.0.1:46832" resp=200
I1030 06:13:07.172892       1 reflector.go:788] vendor/k8s.io/client-go/informers/factory.go:150: Watch close - *v1.Node total 9 items received
I1030 06:13:11.632328       1 httplog.go:132] "HTTP" verb="GET" URI="/healthz" latency="127.469µs" userAgent="kube-probe/1.27" audit-ID="" srcIP="127.0.0.1:57148" resp=200
I1030 06:13:21.632013       1 httplog.go:132] "HTTP" verb="GET" URI="/healthz" latency="128.493µs" userAgent="kube-probe/1.27" audit-ID="" srcIP="127.0.0.1:44042" resp=200
I1030 06:13:31.632949       1 httplog.go:132] "HTTP" verb="GET" URI="/healthz" latency="135.129µs" userAgent="kube-probe/1.27" audit-ID="" srcIP="127.0.0.1:33132" resp=200
I1030 06:13:41.631858       1 httplog.go:132] "HTTP" verb="GET" URI="/healthz" latency="134.725µs" userAgent="kube-probe/1.27" audit-ID="" srcIP="127.0.0.1:55670" resp=200
I1030 06:13:51.632941       1 httplog.go:132] "HTTP" verb="GET" URI="/healthz" latency="140.235µs" userAgent="kube-probe/1.27" audit-ID="" srcIP="127.0.0.1:47676" resp=200
I1030 06:14:01.633167       1 httplog.go:132] "HTTP" verb="GET" URI="/healthz" latency="118.176µs" userAgent="kube-probe/1.27" audit-ID="" srcIP="127.0.0.1:39772" resp=200
I1030 06:14:11.632179       1 httplog.go:132] "HTTP" verb="GET" URI="/healthz" latency="147.605µs" userAgent="kube-probe/1.27" audit-ID="" srcIP="127.0.0.1:48682" resp=200
I1030 06:14:21.632929       1 httplog.go:132] "HTTP" verb="GET" URI="/healthz" latency="118.977µs" userAgent="kube-probe/1.27" audit-ID="" srcIP="127.0.0.1:60784" resp=200
I1030 06:14:31.632221       1 httplog.go:132] "HTTP" verb="GET" URI="/healthz" latency="116.359µs" userAgent="kube-probe/1.27" audit-ID="" srcIP="127.0.0.1:35472" resp=200
I1030 06:14:41.632368       1 httplog.go:132] "HTTP" verb="GET" URI="/healthz" latency="144.58µs" userAgent="kube-probe/1.27" audit-ID="" srcIP="127.0.0.1:37904" resp=200
I1030 06:14:51.632184       1 httplog.go:132] "HTTP" verb="GET" URI="/healthz" latency="139.878µs" userAgent="kube-probe/1.27" audit-ID="" srcIP="127.0.0.1:58700" resp=200
I1030 06:14:55.173397       1 reflector.go:788] pkg/server/dynamiccertificates/configmap_cafile_content.go:206: Watch close - *v1.ConfigMap total 9 items received
I1030 06:15:01.632240       1 httplog.go:132] "HTTP" verb="GET" URI="/healthz" latency="117.285µs" userAgent="kube-probe/1.27" audit-ID="" srcIP="127.0.0.1:46160" resp=200
I1030 06:15:11.632894       1 httplog.go:132] "HTTP" verb="GET" URI="/healthz" latency="139.889µs" userAgent="kube-probe/1.27" audit-ID="" srcIP="127.0.0.1:38400" resp=200
I1030 06:15:21.632169       1 httplog.go:132] "HTTP" verb="GET" URI="/healthz" latency="138.951µs" userAgent="kube-probe/1.27" audit-ID="" srcIP="127.0.0.1:39516" resp=200
I1030 06:15:31.632270       1 httplog.go:132] "HTTP" verb="GET" URI="/healthz" latency="119.083µs" userAgent="kube-probe/1.27" audit-ID="" srcIP="127.0.0.1:45090" resp=200
I1030 06:15:40.179561       1 reflector.go:788] pkg/authentication/request/headerrequest/requestheader_controller.go:172: Watch close - *v1.ConfigMap total 8 items received
I1030 06:15:41.631813       1 httplog.go:132] "HTTP" verb="GET" URI="/healthz" latency="137.413µs" userAgent="kube-probe/1.27" audit-ID="" srcIP="127.0.0.1:36914" resp=200
I1030 06:15:44.173489       1 reflector.go:788] vendor/k8s.io/client-go/informers/factory.go:150: Watch close - *v1.ReplicationController total 8 items received
I1030 06:15:51.172862       1 reflector.go:788] vendor/k8s.io/client-go/informers/factory.go:150: Watch close - *v1.StorageClass total 8 items received
I1030 06:15:51.632513       1 httplog.go:132] "HTTP" verb="GET" URI="/healthz" latency="117.09µs" userAgent="kube-probe/1.27" audit-ID="" srcIP="127.0.0.1:59644" resp=200
I1030 06:16:01.632598       1 httplog.go:132] "HTTP" verb="GET" URI="/healthz" latency="113.404µs" userAgent="kube-probe/1.27" audit-ID="" srcIP="127.0.0.1:35264" resp=200
I1030 06:16:10.174069       1 reflector.go:788] pkg/server/dynamiccertificates/configmap_cafile_content.go:206: Watch close - *v1.ConfigMap total 9 items received
I1030 06:16:11.632486       1 httplog.go:132] "HTTP" verb="GET" URI="/healthz" latency="197.908µs" userAgent="kube-probe/1.27" audit-ID="" srcIP="127.0.0.1:54940" resp=200
I1030 06:16:21.168590       1 reflector.go:788] vendor/k8s.io/client-go/informers/factory.go:150: Watch close - *v1.PodDisruptionBudget total 10 items received
I1030 06:16:21.631862       1 httplog.go:132] "HTTP" verb="GET" URI="/healthz" latency="134.138µs" userAgent="kube-probe/1.27" audit-ID="" srcIP="127.0.0.1:43588" resp=200
I1030 06:16:31.631779       1 httplog.go:132] "HTTP" verb="GET" URI="/healthz" latency="117.815µs" userAgent="kube-probe/1.27" audit-ID="" srcIP="127.0.0.1:33100" resp=200
I1030 06:16:41.632578       1 httplog.go:132] "HTTP" verb="GET" URI="/healthz" latency="131.735µs" userAgent="kube-probe/1.27" audit-ID="" srcIP="127.0.0.1:48580" resp=200
I1030 06:16:51.633223       1 httplog.go:132] "HTTP" verb="GET" URI="/healthz" latency="121.649µs" userAgent="kube-probe/1.27" audit-ID="" srcIP="127.0.0.1:33664" resp=200
I1030 06:17:01.632625       1 httplog.go:132] "HTTP" verb="GET" URI="/healthz" latency="115.191µs" userAgent="kube-probe/1.27" audit-ID="" srcIP="127.0.0.1:38078" resp=200
I1030 06:17:05.177210       1 reflector.go:788] vendor/k8s.io/client-go/informers/factory.go:150: Watch close - *v1.Pod total 11 items received
I1030 06:17:11.633265       1 httplog.go:132] "HTTP" verb="GET" URI="/healthz" latency="131.808µs" userAgent="kube-probe/1.27" audit-ID="" srcIP="127.0.0.1:51968" resp=200
I1030 06:17:21.633763       1 httplog.go:132] "HTTP" verb="GET" URI="/healthz" latency="143.348µs" userAgent="kube-probe/1.27" audit-ID="" srcIP="127.0.0.1:44532" resp=200
I1030 06:17:31.632809       1 httplog.go:132] "HTTP" verb="GET" URI="/healthz" latency="123.781µs" userAgent="kube-probe/1.27" audit-ID="" srcIP="127.0.0.1:42226" resp=200
I1030 06:17:36.173048       1 reflector.go:788] vendor/k8s.io/client-go/informers/factory.go:150: Watch close - *v1.CSIStorageCapacity total 7 items received
I1030 06:17:41.632211       1 httplog.go:132] "HTTP" verb="GET" URI="/healthz" latency="120.845µs" userAgent="kube-probe/1.27" audit-ID="" srcIP="127.0.0.1:52006" resp=200
I1030 06:17:51.174724       1 reflector.go:788] vendor/k8s.io/client-go/informers/factory.go:150: Watch close - *v1.PersistentVolume total 10 items received
I1030 06:17:51.632114       1 httplog.go:132] "HTTP" verb="GET" URI="/healthz" latency="118.087µs" userAgent="kube-probe/1.27" audit-ID="" srcIP="127.0.0.1:60690" resp=200
I1030 06:18:01.632347       1 httplog.go:132] "HTTP" verb="GET" URI="/healthz" latency="137.742µs" userAgent="kube-probe/1.27" audit-ID="" srcIP="127.0.0.1:41046" resp=200
I1030 06:18:02.175936       1 reflector.go:788] vendor/k8s.io/client-go/informers/factory.go:150: Watch close - *v1.StatefulSet total 7 items received
I1030 06:18:03.177109       1 reflector.go:788] vendor/k8s.io/client-go/informers/factory.go:150: Watch close - *v1.CSINode total 8 items received
I1030 06:18:08.172999       1 reflector.go:788] vendor/k8s.io/client-go/informers/factory.go:150: Watch close - *v1.PersistentVolumeClaim total 7 items received
I1030 06:18:11.632923       1 httplog.go:132] "HTTP" verb="GET" URI="/healthz" latency="140.263µs" userAgent="kube-probe/1.27" audit-ID="" srcIP="127.0.0.1:39570" resp=200
I1030 06:18:21.632737       1 httplog.go:132] "HTTP" verb="GET" URI="/healthz" latency="139.232µs" userAgent="kube-probe/1.27" audit-ID="" srcIP="127.0.0.1:34764" resp=200
I1030 06:18:27.172289       1 reflector.go:788] vendor/k8s.io/client-go/informers/factory.go:150: Watch close - *v1.CSIDriver total 11 items received
I1030 06:18:31.632191       1 httplog.go:132] "HTTP" verb="GET" URI="/healthz" latency="117.85µs" userAgent="kube-probe/1.27" audit-ID="" srcIP="127.0.0.1:59118" resp=200
I1030 06:18:41.633338       1 httplog.go:132] "HTTP" verb="GET" URI="/healthz" latency="114.786µs" userAgent="kube-probe/1.27" audit-ID="" srcIP="127.0.0.1:35172" resp=200
I1030 06:18:51.632272       1 httplog.go:132] "HTTP" verb="GET" URI="/healthz" latency="120.796µs" userAgent="kube-probe/1.27" audit-ID="" srcIP="127.0.0.1:60566" resp=200
I1030 06:19:01.632107       1 httplog.go:132] "HTTP" verb="GET" URI="/healthz" latency="134.07µs" userAgent="kube-probe/1.27" audit-ID="" srcIP="127.0.0.1:56716" resp=200
I1030 06:19:11.633104       1 httplog.go:132] "HTTP" verb="GET" URI="/healthz" latency="116.253µs" userAgent="kube-probe/1.27" audit-ID="" srcIP="127.0.0.1:58536" resp=200
I1030 06:19:15.174962       1 reflector.go:788] vendor/k8s.io/client-go/informers/factory.go:150: Watch close - *v1.Service total 11 items received
I1030 06:19:21.633321       1 httplog.go:132] "HTTP" verb="GET" URI="/healthz" latency="125.754µs" userAgent="kube-probe/1.27" audit-ID="" srcIP="127.0.0.1:56576" resp=200
I1030 06:19:31.631775       1 httplog.go:132] "HTTP" verb="GET" URI="/healthz" latency="127.889µs" userAgent="kube-probe/1.27" audit-ID="" srcIP="127.0.0.1:32840" resp=200
I1030 06:19:41.632245       1 httplog.go:132] "HTTP" verb="GET" URI="/healthz" latency="106.255µs" userAgent="kube-probe/1.27" audit-ID="" srcIP="127.0.0.1:37886" resp=200
I1030 06:19:48.173999       1 reflector.go:788] vendor/k8s.io/client-go/informers/factory.go:150: Watch close - *v1.ReplicaSet total 11 items received
I1030 06:19:51.632716       1 httplog.go:132] "HTTP" verb="GET" URI="/healthz" latency="110.149µs" userAgent="kube-probe/1.27" audit-ID="" srcIP="127.0.0.1:42222" resp=200
I1030 06:20:01.632929       1 httplog.go:132] "HTTP" verb="GET" URI="/healthz" latency="109.121µs" userAgent="kube-probe/1.27" audit-ID="" srcIP="127.0.0.1:57348" resp=200
I1030 06:20:11.632028       1 httplog.go:132] "HTTP" verb="GET" URI="/healthz" latency="85.125µs" userAgent="kube-probe/1.27" audit-ID="" srcIP="127.0.0.1:56012" resp=200
I1030 06:20:21.633675       1 httplog.go:132] "HTTP" verb="GET" URI="/healthz" latency="133.562µs" userAgent="kube-probe/1.27" audit-ID="" srcIP="127.0.0.1:46632" resp=200
I1030 06:20:31.632799       1 httplog.go:132] "HTTP" verb="GET" URI="/healthz" latency="112.135µs" userAgent="kube-probe/1.27" audit-ID="" srcIP="127.0.0.1:37296" resp=200
I1030 06:20:41.631857       1 httplog.go:132] "HTTP" verb="GET" URI="/healthz" latency="115.912µs" userAgent="kube-probe/1.27" audit-ID="" srcIP="127.0.0.1:53598" resp=200
I1030 06:20:51.632928       1 httplog.go:132] "HTTP" verb="GET" URI="/healthz" latency="137.759µs" userAgent="kube-probe/1.27" audit-ID="" srcIP="127.0.0.1:54002" resp=200
I1030 06:21:01.631879       1 httplog.go:132] "HTTP" verb="GET" URI="/healthz" latency="125.437µs" userAgent="kube-probe/1.27" audit-ID="" srcIP="127.0.0.1:44392" resp=200
I1030 06:21:11.631820       1 httplog.go:132] "HTTP" verb="GET" URI="/healthz" latency="118.34µs" userAgent="kube-probe/1.27" audit-ID="" srcIP="127.0.0.1:52514" resp=200
I1030 06:21:21.633076       1 httplog.go:132] "HTTP" verb="GET" URI="/healthz" latency="140.048µs" userAgent="kube-probe/1.27" audit-ID="" srcIP="127.0.0.1:41082" resp=200
I1030 06:21:31.632888       1 httplog.go:132] "HTTP" verb="GET" URI="/healthz" latency="120.216µs" userAgent="kube-probe/1.27" audit-ID="" srcIP="127.0.0.1:41988" resp=200
I1030 06:21:36.180725       1 reflector.go:788] vendor/k8s.io/client-go/informers/factory.go:150: Watch close - *v1.Namespace total 10 items received
I1030 06:21:41.631615       1 httplog.go:132] "HTTP" verb="GET" URI="/healthz" latency="129.911µs" userAgent="kube-probe/1.27" audit-ID="" srcIP="127.0.0.1:32996" resp=200
I1030 06:21:51.631641       1 httplog.go:132] "HTTP" verb="GET" URI="/healthz" latency="115.72µs" userAgent="kube-probe/1.27" audit-ID="" srcIP="127.0.0.1:42968" resp=200
I1030 06:22:01.633207       1 httplog.go:132] "HTTP" verb="GET" URI="/healthz" latency="115.43µs" userAgent="kube-probe/1.27" audit-ID="" srcIP="127.0.0.1:51200" resp=200
I1030 06:22:02.175700       1 reflector.go:788] vendor/k8s.io/client-go/informers/factory.go:150: Watch close - *v1.Node total 11 items received
I1030 06:22:02.175754       1 reflector.go:788] vendor/k8s.io/client-go/informers/factory.go:150: Watch close - *v1.StorageClass total 8 items received
I1030 06:22:11.631871       1 httplog.go:132] "HTTP" verb="GET" URI="/healthz" latency="114.876µs" userAgent="kube-probe/1.27" audit-ID="" srcIP="127.0.0.1:50880" resp=200
I1030 06:22:21.632843       1 httplog.go:132] "HTTP" verb="GET" URI="/healthz" latency="163.01µs" userAgent="kube-probe/1.27" audit-ID="" srcIP="127.0.0.1:34302" resp=200
I1030 06:22:31.631540       1 httplog.go:132] "HTTP" verb="GET" URI="/healthz" latency="131.761µs" userAgent="kube-probe/1.27" audit-ID="" srcIP="127.0.0.1:32870" resp=200
I1030 06:22:39.177114       1 reflector.go:788] vendor/k8s.io/client-go/informers/factory.go:150: Watch close - *v1.ReplicationController total 8 items received
I1030 06:22:41.633202       1 httplog.go:132] "HTTP" verb="GET" URI="/healthz" latency="115.756µs" userAgent="kube-probe/1.27" audit-ID="" srcIP="127.0.0.1:55018" resp=200
I1030 06:22:50.176982       1 reflector.go:788] pkg/server/dynamiccertificates/configmap_cafile_content.go:206: Watch close - *v1.ConfigMap total 8 items received
I1030 06:22:51.632040       1 httplog.go:132] "HTTP" verb="GET" URI="/healthz" latency="127.849µs" userAgent="kube-probe/1.27" audit-ID="" srcIP="127.0.0.1:52598" resp=200
I1030 06:23:01.632793       1 httplog.go:132] "HTTP" verb="GET" URI="/healthz" latency="111.703µs" userAgent="kube-probe/1.27" audit-ID="" srcIP="127.0.0.1:42052" resp=200
I1030 06:23:08.179738       1 reflector.go:788] vendor/k8s.io/client-go/informers/factory.go:150: Watch close - *v1.CSINode total 7 items received
I1030 06:23:11.633366       1 httplog.go:132] "HTTP" verb="GET" URI="/healthz" latency="110.966µs" userAgent="kube-probe/1.27" audit-ID="" srcIP="127.0.0.1:57474" resp=200
I1030 06:23:21.633211       1 httplog.go:132] "HTTP" verb="GET" URI="/healthz" latency="112.374µs" userAgent="kube-probe/1.27" audit-ID="" srcIP="127.0.0.1:59142" resp=200
I1030 06:23:31.633121       1 httplog.go:132] "HTTP" verb="GET" URI="/healthz" latency="125.731µs" userAgent="kube-probe/1.27" audit-ID="" srcIP="127.0.0.1:54328" resp=200
I1030 06:23:32.180107       1 reflector.go:788] vendor/k8s.io/client-go/informers/factory.go:150: Watch close - *v1.Pod total 7 items received
I1030 06:23:41.633193       1 httplog.go:132] "HTTP" verb="GET" URI="/healthz" latency="133.478µs" userAgent="kube-probe/1.27" audit-ID="" srcIP="127.0.0.1:33168" resp=200
I1030 06:23:51.632328       1 httplog.go:132] "HTTP" verb="GET" URI="/healthz" latency="103.484µs" userAgent="kube-probe/1.27" audit-ID="" srcIP="127.0.0.1:59176" resp=200
I1030 06:24:01.633222       1 httplog.go:132] "HTTP" verb="GET" URI="/healthz" latency="130.896µs" userAgent="kube-probe/1.27" audit-ID="" srcIP="127.0.0.1:51748" resp=200
I1030 06:24:11.633176       1 httplog.go:132] "HTTP" verb="GET" URI="/healthz" latency="131.234µs" userAgent="kube-probe/1.27" audit-ID="" srcIP="127.0.0.1:33920" resp=200
I1030 06:24:18.171386       1 reflector.go:788] vendor/k8s.io/client-go/informers/factory.go:150: Watch close - *v1.PodDisruptionBudget total 9 items received
I1030 06:24:21.633250       1 httplog.go:132] "HTTP" verb="GET" URI="/healthz" latency="122.525µs" userAgent="kube-probe/1.27" audit-ID="" srcIP="127.0.0.1:37304" resp=200
I1030 06:24:31.633292       1 httplog.go:132] "HTTP" verb="GET" URI="/healthz" latency="123.353µs" userAgent="kube-probe/1.27" audit-ID="" srcIP="127.0.0.1:48370" resp=200
I1030 06:24:41.633354       1 httplog.go:132] "HTTP" verb="GET" URI="/healthz" latency="120.767µs" userAgent="kube-probe/1.27" audit-ID="" srcIP="127.0.0.1:39934" resp=200
I1030 06:24:45.178507       1 reflector.go:788] pkg/server/dynamiccertificates/configmap_cafile_content.go:206: Watch close - *v1.ConfigMap total 9 items received
I1030 06:24:51.631750       1 httplog.go:132] "HTTP" verb="GET" URI="/healthz" latency="135.727µs" userAgent="kube-probe/1.27" audit-ID="" srcIP="127.0.0.1:34338" resp=200
I1030 06:24:53.183256       1 reflector.go:788] pkg/authentication/request/headerrequest/requestheader_controller.go:172: Watch close - *v1.ConfigMap total 10 items received
I1030 06:25:01.632290       1 httplog.go:132] "HTTP" verb="GET" URI="/healthz" latency="130.855µs" userAgent="kube-probe/1.27" audit-ID="" srcIP="127.0.0.1:59898" resp=200
I1030 06:25:11.631755       1 httplog.go:132] "HTTP" verb="GET" URI="/healthz" latency="117.862µs" userAgent="kube-probe/1.27" audit-ID="" srcIP="127.0.0.1:50018" resp=200
I1030 06:25:16.178872       1 reflector.go:788] vendor/k8s.io/client-go/informers/factory.go:150: Watch close - *v1.StatefulSet total 9 items received
I1030 06:25:21.632125       1 httplog.go:132] "HTTP" verb="GET" URI="/healthz" latency="143.861µs" userAgent="kube-probe/1.27" audit-ID="" srcIP="127.0.0.1:48238" resp=200
I1030 06:25:31.631877       1 httplog.go:132] "HTTP" verb="GET" URI="/healthz" latency="117.995µs" userAgent="kube-probe/1.27" audit-ID="" srcIP="127.0.0.1:49776" resp=200
I1030 06:25:41.633437       1 httplog.go:132] "HTTP" verb="GET" URI="/healthz" latency="118.07µs" userAgent="kube-probe/1.27" audit-ID="" srcIP="127.0.0.1:52928" resp=200
I1030 06:25:51.633351       1 httplog.go:132] "HTTP" verb="GET" URI="/healthz" latency="166.629µs" userAgent="kube-probe/1.27" audit-ID="" srcIP="127.0.0.1:42388" resp=200
I1030 06:26:01.633282       1 httplog.go:132] "HTTP" verb="GET" URI="/healthz" latency="123.407µs" userAgent="kube-probe/1.27" audit-ID="" srcIP="127.0.0.1:40370" resp=200
I1030 06:26:03.178629       1 reflector.go:788] vendor/k8s.io/client-go/informers/factory.go:150: Watch close - *v1.PersistentVolume total 9 items received
I1030 06:26:11.633243       1 httplog.go:132] "HTTP" verb="GET" URI="/healthz" latency="128.397µs" userAgent="kube-probe/1.27" audit-ID="" srcIP="127.0.0.1:35208" resp=200
I1030 06:26:21.632700       1 httplog.go:132] "HTTP" verb="GET" URI="/healthz" latency="133.914µs" userAgent="kube-probe/1.27" audit-ID="" srcIP="127.0.0.1:56092" resp=200
I1030 06:26:31.632465       1 httplog.go:132] "HTTP" verb="GET" URI="/healthz" latency="153.754µs" userAgent="kube-probe/1.27" audit-ID="" srcIP="127.0.0.1:49088" resp=200
I1030 06:26:41.632587       1 httplog.go:132] "HTTP" verb="GET" URI="/healthz" latency="138.259µs" userAgent="kube-probe/1.27" audit-ID="" srcIP="127.0.0.1:35630" resp=200
I1030 06:26:51.632461       1 httplog.go:132] "HTTP" verb="GET" URI="/healthz" latency="132.642µs" userAgent="kube-probe/1.27" audit-ID="" srcIP="127.0.0.1:52384" resp=200
I1030 06:27:01.631891       1 httplog.go:132] "HTTP" verb="GET" URI="/healthz" latency="110.819µs" userAgent="kube-probe/1.27" audit-ID="" srcIP="127.0.0.1:46026" resp=200
I1030 06:27:07.178517       1 reflector.go:788] vendor/k8s.io/client-go/informers/factory.go:150: Watch close - *v1.Node total 7 items received
I1030 06:27:11.632033       1 httplog.go:132] "HTTP" verb="GET" URI="/healthz" latency="124.485µs" userAgent="kube-probe/1.27" audit-ID="" srcIP="127.0.0.1:44154" resp=200
I1030 06:27:16.175484       1 reflector.go:788] vendor/k8s.io/client-go/informers/factory.go:150: Watch close - *v1.CSIStorageCapacity total 10 items received
I1030 06:27:16.177358       1 reflector.go:788] vendor/k8s.io/client-go/informers/factory.go:150: Watch close - *v1.Service total 9 items received
I1030 06:27:21.631899       1 httplog.go:132] "HTTP" verb="GET" URI="/healthz" latency="118.33µs" userAgent="kube-probe/1.27" audit-ID="" srcIP="127.0.0.1:34448" resp=200
I1030 06:27:22.175127       1 reflector.go:788] vendor/k8s.io/client-go/informers/factory.go:150: Watch close - *v1.CSIDriver total 9 items received
I1030 06:27:31.633176       1 httplog.go:132] "HTTP" verb="GET" URI="/healthz" latency="126.101µs" userAgent="kube-probe/1.27" audit-ID="" srcIP="127.0.0.1:50496" resp=200
I1030 06:27:41.632825       1 httplog.go:132] "HTTP" verb="GET" URI="/healthz" latency="131.678µs" userAgent="kube-probe/1.27" audit-ID="" srcIP="127.0.0.1:56410" resp=200
I1030 06:27:51.632030       1 httplog.go:132] "HTTP" verb="GET" URI="/healthz" latency="118.212µs" userAgent="kube-probe/1.27" audit-ID="" srcIP="127.0.0.1:47294" resp=200
I1030 06:27:55.176549       1 reflector.go:788] vendor/k8s.io/client-go/informers/factory.go:150: Watch close - *v1.PersistentVolumeClaim total 10 items received
I1030 06:28:01.633335       1 httplog.go:132] "HTTP" verb="GET" URI="/healthz" latency="124.711µs" userAgent="kube-probe/1.27" audit-ID="" srcIP="127.0.0.1:44426" resp=200
I1030 06:28:11.632260       1 httplog.go:132] "HTTP" verb="GET" URI="/healthz" latency="122.784µs" userAgent="kube-probe/1.27" audit-ID="" srcIP="127.0.0.1:58636" resp=200
I1030 06:28:21.632511       1 httplog.go:132] "HTTP" verb="GET" URI="/healthz" latency="131.246µs" userAgent="kube-probe/1.27" audit-ID="" srcIP="127.0.0.1:34384" resp=200
I1030 06:28:31.633235       1 httplog.go:132] "HTTP" verb="GET" URI="/healthz" latency="139.488µs" userAgent="kube-probe/1.27" audit-ID="" srcIP="127.0.0.1:51920" resp=200
I1030 06:28:41.632410       1 httplog.go:132] "HTTP" verb="GET" URI="/healthz" latency="145.008µs" userAgent="kube-probe/1.27" audit-ID="" srcIP="127.0.0.1:42298" resp=200
I1030 06:28:51.632503       1 httplog.go:132] "HTTP" verb="GET" URI="/healthz" latency="171.171µs" userAgent="kube-probe/1.27" audit-ID="" srcIP="127.0.0.1:47784" resp=200
I1030 06:29:01.632574       1 httplog.go:132] "HTTP" verb="GET" URI="/healthz" latency="113.52µs" userAgent="kube-probe/1.27" audit-ID="" srcIP="127.0.0.1:42802" resp=200
I1030 06:29:03.177414       1 reflector.go:788] vendor/k8s.io/client-go/informers/factory.go:150: Watch close - *v1.ReplicaSet total 11 items received
I1030 06:29:05.179834       1 reflector.go:788] pkg/server/dynamiccertificates/configmap_cafile_content.go:206: Watch close - *v1.ConfigMap total 7 items received
I1030 06:29:11.631929       1 httplog.go:132] "HTTP" verb="GET" URI="/healthz" latency="146.262µs" userAgent="kube-probe/1.27" audit-ID="" srcIP="127.0.0.1:57870" resp=200
I1030 06:29:21.632245       1 httplog.go:132] "HTTP" verb="GET" URI="/healthz" latency="121.217µs" userAgent="kube-probe/1.27" audit-ID="" srcIP="127.0.0.1:46784" resp=200
I1030 06:29:31.633162       1 httplog.go:132] "HTTP" verb="GET" URI="/healthz" latency="114.837µs" userAgent="kube-probe/1.27" audit-ID="" srcIP="127.0.0.1:57590" resp=200
I1030 06:29:41.632329       1 httplog.go:132] "HTTP" verb="GET" URI="/healthz" latency="140.25µs" userAgent="kube-probe/1.27" audit-ID="" srcIP="127.0.0.1:52004" resp=200
I1030 06:29:51.633329       1 httplog.go:132] "HTTP" verb="GET" URI="/healthz" latency="129.029µs" userAgent="kube-probe/1.27" audit-ID="" srcIP="127.0.0.1:35940" resp=200
I1030 06:30:01.631822       1 httplog.go:132] "HTTP" verb="GET" URI="/healthz" latency="127.342µs" userAgent="kube-probe/1.27" audit-ID="" srcIP="127.0.0.1:52194" resp=200
I1030 06:30:11.633398       1 httplog.go:132] "HTTP" verb="GET" URI="/healthz" latency="134.405µs" userAgent="kube-probe/1.27" audit-ID="" srcIP="127.0.0.1:60542" resp=200
I1030 06:30:21.633262       1 httplog.go:132] "HTTP" verb="GET" URI="/healthz" latency="136.516µs" userAgent="kube-probe/1.27" audit-ID="" srcIP="127.0.0.1:54028" resp=200
I1030 06:30:30.181636       1 reflector.go:788] vendor/k8s.io/client-go/informers/factory.go:150: Watch close - *v1.StatefulSet total 6 items received
I1030 06:30:31.632211       1 httplog.go:132] "HTTP" verb="GET" URI="/healthz" latency="107.664µs" userAgent="kube-probe/1.27" audit-ID="" srcIP="127.0.0.1:46562" resp=200
I1030 06:30:32.183397       1 reflector.go:788] vendor/k8s.io/client-go/informers/factory.go:150: Watch close - *v1.Namespace total 9 items received
I1030 06:30:41.633388       1 httplog.go:132] "HTTP" verb="GET" URI="/healthz" latency="121.132µs" userAgent="kube-probe/1.27" audit-ID="" srcIP="127.0.0.1:44342" resp=200
I1030 06:30:49.178682       1 reflector.go:788] vendor/k8s.io/client-go/informers/factory.go:150: Watch close - *v1.StorageClass total 9 items received
I1030 06:30:49.179804       1 reflector.go:788] vendor/k8s.io/client-go/informers/factory.go:150: Watch close - *v1.ReplicationController total 10 items received
I1030 06:30:51.633089       1 httplog.go:132] "HTTP" verb="GET" URI="/healthz" latency="119.966µs" userAgent="kube-probe/1.27" audit-ID="" srcIP="127.0.0.1:60282" resp=200
I1030 06:31:01.633278       1 httplog.go:132] "HTTP" verb="GET" URI="/healthz" latency="123.337µs" userAgent="kube-probe/1.27" audit-ID="" srcIP="127.0.0.1:55076" resp=200
I1030 06:31:11.633415       1 httplog.go:132] "HTTP" verb="GET" URI="/healthz" latency="121.783µs" userAgent="kube-probe/1.27" audit-ID="" srcIP="127.0.0.1:36768" resp=200
I1030 06:31:12.183497       1 reflector.go:788] vendor/k8s.io/client-go/informers/factory.go:150: Watch close - *v1.CSINode total 9 items received
I1030 06:31:13.184269       1 reflector.go:788] vendor/k8s.io/client-go/informers/factory.go:150: Watch close - *v1.Pod total 8 items received
I1030 06:31:21.632076       1 httplog.go:132] "HTTP" verb="GET" URI="/healthz" latency="113.555µs" userAgent="kube-probe/1.27" audit-ID="" srcIP="127.0.0.1:49208" resp=200
I1030 06:31:31.631775       1 httplog.go:132] "HTTP" verb="GET" URI="/healthz" latency="136.21µs" userAgent="kube-probe/1.27" audit-ID="" srcIP="127.0.0.1:36948" resp=200
I1030 06:31:41.633371       1 httplog.go:132] "HTTP" verb="GET" URI="/healthz" latency="131.367µs" userAgent="kube-probe/1.27" audit-ID="" srcIP="127.0.0.1:50040" resp=200
I1030 06:31:51.633421       1 httplog.go:132] "HTTP" verb="GET" URI="/healthz" latency="123.391µs" userAgent="kube-probe/1.27" audit-ID="" srcIP="127.0.0.1:60746" resp=200
I1030 06:32:01.631988       1 httplog.go:132] "HTTP" verb="GET" URI="/healthz" latency="127.88µs" userAgent="kube-probe/1.27" audit-ID="" srcIP="127.0.0.1:55476" resp=200
I1030 06:32:11.632023       1 httplog.go:132] "HTTP" verb="GET" URI="/healthz" latency="110.337µs" userAgent="kube-probe/1.27" audit-ID="" srcIP="127.0.0.1:53594" resp=200
I1030 06:32:21.632632       1 httplog.go:132] "HTTP" verb="GET" URI="/healthz" latency="112.515µs" userAgent="kube-probe/1.27" audit-ID="" srcIP="127.0.0.1:55378" resp=200
I1030 06:32:31.633310       1 httplog.go:132] "HTTP" verb="GET" URI="/healthz" latency="120.224µs" userAgent="kube-probe/1.27" audit-ID="" srcIP="127.0.0.1:42696" resp=200
I1030 06:32:41.633185       1 httplog.go:132] "HTTP" verb="GET" URI="/healthz" latency="143.325µs" userAgent="kube-probe/1.27" audit-ID="" srcIP="127.0.0.1:57114" resp=200
I1030 06:32:51.632346       1 httplog.go:132] "HTTP" verb="GET" URI="/healthz" latency="120.61µs" userAgent="kube-probe/1.27" audit-ID="" srcIP="127.0.0.1:51370" resp=200
I1030 06:33:01.631767       1 httplog.go:132] "HTTP" verb="GET" URI="/healthz" latency="136.123µs" userAgent="kube-probe/1.27" audit-ID="" srcIP="127.0.0.1:46628" resp=200
I1030 06:33:11.632774       1 httplog.go:132] "HTTP" verb="GET" URI="/healthz" latency="149.268µs" userAgent="kube-probe/1.27" audit-ID="" srcIP="127.0.0.1:58154" resp=200
I1030 06:33:18.174045       1 reflector.go:788] vendor/k8s.io/client-go/informers/factory.go:150: Watch close - *v1.PodDisruptionBudget total 9 items received
I1030 06:33:21.632364       1 httplog.go:132] "HTTP" verb="GET" URI="/healthz" latency="140.134µs" userAgent="kube-probe/1.27" audit-ID="" srcIP="127.0.0.1:46222" resp=200
I1030 06:33:31.633091       1 httplog.go:132] "HTTP" verb="GET" URI="/healthz" latency="113.638µs" userAgent="kube-probe/1.27" audit-ID="" srcIP="127.0.0.1:39988" resp=200
I1030 06:33:35.182348       1 reflector.go:788] vendor/k8s.io/client-go/informers/factory.go:150: Watch close - *v1.Node total 8 items received
I1030 06:33:41.632368       1 httplog.go:132] "HTTP" verb="GET" URI="/healthz" latency="139.004µs" userAgent="kube-probe/1.27" audit-ID="" srcIP="127.0.0.1:50510" resp=200
I1030 06:33:49.181220       1 reflector.go:788] pkg/server/dynamiccertificates/configmap_cafile_content.go:206: Watch close - *v1.ConfigMap total 10 items received
I1030 06:33:51.633225       1 httplog.go:132] "HTTP" verb="GET" URI="/healthz" latency="147.276µs" userAgent="kube-probe/1.27" audit-ID="" srcIP="127.0.0.1:40444" resp=200
I1030 06:34:01.633368       1 httplog.go:132] "HTTP" verb="GET" URI="/healthz" latency="115.554µs" userAgent="kube-probe/1.27" audit-ID="" srcIP="127.0.0.1:35218" resp=200
I1030 06:34:11.632295       1 httplog.go:132] "HTTP" verb="GET" URI="/healthz" latency="113.552µs" userAgent="kube-probe/1.27" audit-ID="" srcIP="127.0.0.1:34194" resp=200
I1030 06:34:21.633641       1 httplog.go:132] "HTTP" verb="GET" URI="/healthz" latency="119.945µs" userAgent="kube-probe/1.27" audit-ID="" srcIP="127.0.0.1:47626" resp=200
I1030 06:34:31.186993       1 reflector.go:788] pkg/authentication/request/headerrequest/requestheader_controller.go:172: Watch close - *v1.ConfigMap total 10 items received
I1030 06:34:31.632894       1 httplog.go:132] "HTTP" verb="GET" URI="/healthz" latency="104.391µs" userAgent="kube-probe/1.27" audit-ID="" srcIP="127.0.0.1:45056" resp=200
I1030 06:34:36.181735       1 reflector.go:788] vendor/k8s.io/client-go/informers/factory.go:150: Watch close - *v1.PersistentVolume total 9 items received
I1030 06:34:41.634580       1 httplog.go:132] "HTTP" verb="GET" URI="/healthz" latency="119.972µs" userAgent="kube-probe/1.27" audit-ID="" srcIP="127.0.0.1:53474" resp=200
I1030 06:34:51.633352       1 httplog.go:132] "HTTP" verb="GET" URI="/healthz" latency="127.99µs" userAgent="kube-probe/1.27" audit-ID="" srcIP="127.0.0.1:42578" resp=200
I1030 06:35:01.633012       1 httplog.go:132] "HTTP" verb="GET" URI="/healthz" latency="120.974µs" userAgent="kube-probe/1.27" audit-ID="" srcIP="127.0.0.1:34380" resp=200
I1030 06:35:09.178615       1 reflector.go:788] vendor/k8s.io/client-go/informers/factory.go:150: Watch close - *v1.CSIDriver total 9 items received
I1030 06:35:11.632002       1 httplog.go:132] "HTTP" verb="GET" URI="/healthz" latency="127.083µs" userAgent="kube-probe/1.27" audit-ID="" srcIP="127.0.0.1:53882" resp=200
I1030 06:35:21.631989       1 httplog.go:132] "HTTP" verb="GET" URI="/healthz" latency="118.039µs" userAgent="kube-probe/1.27" audit-ID="" srcIP="127.0.0.1:52470" resp=200
I1030 06:35:31.633609       1 httplog.go:132] "HTTP" verb="GET" URI="/healthz" latency="134.661µs" userAgent="kube-probe/1.27" audit-ID="" srcIP="127.0.0.1:51156" resp=200
I1030 06:35:41.632813       1 httplog.go:132] "HTTP" verb="GET" URI="/healthz" latency="141.429µs" userAgent="kube-probe/1.27" audit-ID="" srcIP="127.0.0.1:52346" resp=200
I1030 06:35:51.631761       1 httplog.go:132] "HTTP" verb="GET" URI="/healthz" latency="137.264µs" userAgent="kube-probe/1.27" audit-ID="" srcIP="127.0.0.1:44120" resp=200
I1030 06:36:01.632037       1 httplog.go:132] "HTTP" verb="GET" URI="/healthz" latency="114.722µs" userAgent="kube-probe/1.27" audit-ID="" srcIP="127.0.0.1:39510" resp=200
I1030 06:36:08.181208       1 reflector.go:788] vendor/k8s.io/client-go/informers/factory.go:150: Watch close - *v1.ReplicaSet total 8 items received
I1030 06:36:11.633067       1 httplog.go:132] "HTTP" verb="GET" URI="/healthz" latency="121.372µs" userAgent="kube-probe/1.27" audit-ID="" srcIP="127.0.0.1:34126" resp=200
I1030 06:36:15.186223       1 reflector.go:788] vendor/k8s.io/client-go/informers/factory.go:150: Watch close - *v1.CSINode total 6 items received
I1030 06:36:21.632550       1 httplog.go:132] "HTTP" verb="GET" URI="/healthz" latency="145.42µs" userAgent="kube-probe/1.27" audit-ID="" srcIP="127.0.0.1:52894" resp=200
I1030 06:36:30.177985       1 reflector.go:788] vendor/k8s.io/client-go/informers/factory.go:150: Watch close - *v1.CSIStorageCapacity total 11 items received
I1030 06:36:31.632494       1 httplog.go:132] "HTTP" verb="GET" URI="/healthz" latency="166.398µs" userAgent="kube-probe/1.27" audit-ID="" srcIP="127.0.0.1:35040" resp=200
I1030 06:36:41.632326       1 httplog.go:132] "HTTP" verb="GET" URI="/healthz" latency="139.871µs" userAgent="kube-probe/1.27" audit-ID="" srcIP="127.0.0.1:35516" resp=200
I1030 06:36:42.188111       1 reflector.go:788] vendor/k8s.io/client-go/informers/factory.go:150: Watch close - *v1.Pod total 6 items received
I1030 06:36:51.631862       1 httplog.go:132] "HTTP" verb="GET" URI="/healthz" latency="117.333µs" userAgent="kube-probe/1.27" audit-ID="" srcIP="127.0.0.1:47886" resp=200
I1030 06:36:59.183557       1 reflector.go:788] pkg/server/dynamiccertificates/configmap_cafile_content.go:206: Watch close - *v1.ConfigMap total 8 items received
I1030 06:37:01.633364       1 httplog.go:132] "HTTP" verb="GET" URI="/healthz" latency="145.775µs" userAgent="kube-probe/1.27" audit-ID="" srcIP="127.0.0.1:37934" resp=200
I1030 06:37:09.179913       1 reflector.go:788] vendor/k8s.io/client-go/informers/factory.go:150: Watch close - *v1.Service total 11 items received
I1030 06:37:11.632439       1 httplog.go:132] "HTTP" verb="GET" URI="/healthz" latency="199.939µs" userAgent="kube-probe/1.27" audit-ID="" srcIP="127.0.0.1:49414" resp=200
I1030 06:37:16.179165       1 reflector.go:788] vendor/k8s.io/client-go/informers/factory.go:150: Watch close - *v1.PersistentVolumeClaim total 10 items received
I1030 06:37:21.632535       1 httplog.go:132] "HTTP" verb="GET" URI="/healthz" latency="118.406µs" userAgent="kube-probe/1.27" audit-ID="" srcIP="127.0.0.1:52636" resp=200
I1030 06:37:31.631980       1 httplog.go:132] "HTTP" verb="GET" URI="/healthz" latency="130.657µs" userAgent="kube-probe/1.27" audit-ID="" srcIP="127.0.0.1:55646" resp=200
I1030 06:37:35.183138       1 reflector.go:788] vendor/k8s.io/client-go/informers/factory.go:150: Watch close - *v1.ReplicationController total 8 items received
I1030 06:37:39.184355       1 reflector.go:788] vendor/k8s.io/client-go/informers/factory.go:150: Watch close - *v1.StatefulSet total 9 items received
I1030 06:37:41.632466       1 httplog.go:132] "HTTP" verb="GET" URI="/healthz" latency="131.794µs" userAgent="kube-probe/1.27" audit-ID="" srcIP="127.0.0.1:57298" resp=200
I1030 06:37:51.633125       1 httplog.go:132] "HTTP" verb="GET" URI="/healthz" latency="107.642µs" userAgent="kube-probe/1.27" audit-ID="" srcIP="127.0.0.1:44624" resp=200
I1030 06:38:01.633188       1 httplog.go:132] "HTTP" verb="GET" URI="/healthz" latency="121.597µs" userAgent="kube-probe/1.27" audit-ID="" srcIP="127.0.0.1:34650" resp=200
I1030 06:38:11.634009       1 httplog.go:132] "HTTP" verb="GET" URI="/healthz" latency="136.545µs" userAgent="kube-probe/1.27" audit-ID="" srcIP="127.0.0.1:37940" resp=200
I1030 06:38:21.631975       1 httplog.go:132] "HTTP" verb="GET" URI="/healthz" latency="135.117µs" userAgent="kube-probe/1.27" audit-ID="" srcIP="127.0.0.1:58858" resp=200
I1030 06:38:24.181481       1 reflector.go:788] vendor/k8s.io/client-go/informers/factory.go:150: Watch close - *v1.StorageClass total 8 items received
I1030 06:38:31.632240       1 httplog.go:132] "HTTP" verb="GET" URI="/healthz" latency="117.962µs" userAgent="kube-probe/1.27" audit-ID="" srcIP="127.0.0.1:36722" resp=200
I1030 06:38:41.632178       1 httplog.go:132] "HTTP" verb="GET" URI="/healthz" latency="114.507µs" userAgent="kube-probe/1.27" audit-ID="" srcIP="127.0.0.1:39378" resp=200
I1030 06:38:42.186474       1 reflector.go:788] vendor/k8s.io/client-go/informers/factory.go:150: Watch close - *v1.Namespace total 9 items received
I1030 06:38:51.632796       1 httplog.go:132] "HTTP" verb="GET" URI="/healthz" latency="139.525µs" userAgent="kube-probe/1.27" audit-ID="" srcIP="127.0.0.1:51510" resp=200
I1030 06:39:01.633388       1 httplog.go:132] "HTTP" verb="GET" URI="/healthz" latency="140.849µs" userAgent="kube-probe/1.27" audit-ID="" srcIP="127.0.0.1:34234" resp=200
I1030 06:39:11.632204       1 httplog.go:132] "HTTP" verb="GET" URI="/healthz" latency="116.731µs" userAgent="kube-probe/1.27" audit-ID="" srcIP="127.0.0.1:34026" resp=200
I1030 06:39:21.631630       1 httplog.go:132] "HTTP" verb="GET" URI="/healthz" latency="120.691µs" userAgent="kube-probe/1.27" audit-ID="" srcIP="127.0.0.1:60402" resp=200
I1030 06:39:31.633318       1 httplog.go:132] "HTTP" verb="GET" URI="/healthz" latency="121.14µs" userAgent="kube-probe/1.27" audit-ID="" srcIP="127.0.0.1:43248" resp=200
I1030 06:39:32.184799       1 reflector.go:788] vendor/k8s.io/client-go/informers/factory.go:150: Watch close - *v1.Node total 8 items received
I1030 06:39:41.632559       1 httplog.go:132] "HTTP" verb="GET" URI="/healthz" latency="117.351µs" userAgent="kube-probe/1.27" audit-ID="" srcIP="127.0.0.1:40762" resp=200
I1030 06:39:51.632640       1 httplog.go:132] "HTTP" verb="GET" URI="/healthz" latency="152.156µs" userAgent="kube-probe/1.27" audit-ID="" srcIP="127.0.0.1:53738" resp=200
I1030 06:39:54.183968       1 reflector.go:788] pkg/server/dynamiccertificates/configmap_cafile_content.go:206: Watch close - *v1.ConfigMap total 7 items received
I1030 06:40:01.632504       1 httplog.go:132] "HTTP" verb="GET" URI="/healthz" latency="208.685µs" userAgent="kube-probe/1.27" audit-ID="" srcIP="127.0.0.1:45454" resp=200
I1030 06:40:11.632887       1 httplog.go:132] "HTTP" verb="GET" URI="/healthz" latency="118.381µs" userAgent="kube-probe/1.27" audit-ID="" srcIP="127.0.0.1:39838" resp=200
I1030 06:40:21.633308       1 httplog.go:132] "HTTP" verb="GET" URI="/healthz" latency="120.476µs" userAgent="kube-probe/1.27" audit-ID="" srcIP="127.0.0.1:54266" resp=200
I1030 06:40:31.633440       1 httplog.go:132] "HTTP" verb="GET" URI="/healthz" latency="138.87µs" userAgent="kube-probe/1.27" audit-ID="" srcIP="127.0.0.1:57398" resp=200
I1030 06:40:41.633117       1 httplog.go:132] "HTTP" verb="GET" URI="/healthz" latency="145.237µs" userAgent="kube-probe/1.27" audit-ID="" srcIP="127.0.0.1:34302" resp=200
I1030 06:40:46.176710       1 reflector.go:788] vendor/k8s.io/client-go/informers/factory.go:150: Watch close - *v1.PodDisruptionBudget total 9 items received
I1030 06:40:51.631637       1 httplog.go:132] "HTTP" verb="GET" URI="/healthz" latency="113.536µs" userAgent="kube-probe/1.27" audit-ID="" srcIP="127.0.0.1:56836" resp=200
I1030 06:41:01.631606       1 httplog.go:132] "HTTP" verb="GET" URI="/healthz" latency="115.662µs" userAgent="kube-probe/1.27" audit-ID="" srcIP="127.0.0.1:51048" resp=200
I1030 06:41:11.632941       1 httplog.go:132] "HTTP" verb="GET" URI="/healthz" latency="129.33µs" userAgent="kube-probe/1.27" audit-ID="" srcIP="127.0.0.1:45244" resp=200
I1030 06:41:21.632460       1 httplog.go:132] "HTTP" verb="GET" URI="/healthz" latency="124.495µs" userAgent="kube-probe/1.27" audit-ID="" srcIP="127.0.0.1:54838" resp=200
I1030 06:41:31.631925       1 httplog.go:132] "HTTP" verb="GET" URI="/healthz" latency="129.522µs" userAgent="kube-probe/1.27" audit-ID="" srcIP="127.0.0.1:43900" resp=200
I1030 06:41:41.631645       1 httplog.go:132] "HTTP" verb="GET" URI="/healthz" latency="131.416µs" userAgent="kube-probe/1.27" audit-ID="" srcIP="127.0.0.1:56860" resp=200
I1030 06:41:51.633353       1 httplog.go:132] "HTTP" verb="GET" URI="/healthz" latency="105.919µs" userAgent="kube-probe/1.27" audit-ID="" srcIP="127.0.0.1:46906" resp=200
I1030 06:42:01.633027       1 httplog.go:132] "HTTP" verb="GET" URI="/healthz" latency="126.058µs" userAgent="kube-probe/1.27" audit-ID="" srcIP="127.0.0.1:44016" resp=200
I1030 06:42:11.632515       1 httplog.go:132] "HTTP" verb="GET" URI="/healthz" latency="126.089µs" userAgent="kube-probe/1.27" audit-ID="" srcIP="127.0.0.1:41400" resp=200
I1030 06:42:21.632805       1 httplog.go:132] "HTTP" verb="GET" URI="/healthz" latency="129.752µs" userAgent="kube-probe/1.27" audit-ID="" srcIP="127.0.0.1:49506" resp=200
I1030 06:42:25.181181       1 reflector.go:788] vendor/k8s.io/client-go/informers/factory.go:150: Watch close - *v1.CSIStorageCapacity total 7 items received
I1030 06:42:31.632031       1 httplog.go:132] "HTTP" verb="GET" URI="/healthz" latency="136.743µs" userAgent="kube-probe/1.27" audit-ID="" srcIP="127.0.0.1:36178" resp=200
I1030 06:42:41.632914       1 httplog.go:132] "HTTP" verb="GET" URI="/healthz" latency="133.877µs" userAgent="kube-probe/1.27" audit-ID="" srcIP="127.0.0.1:51152" resp=200
I1030 06:42:51.633512       1 httplog.go:132] "HTTP" verb="GET" URI="/healthz" latency="125.641µs" userAgent="kube-probe/1.27" audit-ID="" srcIP="127.0.0.1:42006" resp=200
I1030 06:43:01.633247       1 httplog.go:132] "HTTP" verb="GET" URI="/healthz" latency="124.676µs" userAgent="kube-probe/1.27" audit-ID="" srcIP="127.0.0.1:36052" resp=200
I1030 06:43:11.631730       1 httplog.go:132] "HTTP" verb="GET" URI="/healthz" latency="117.415µs" userAgent="kube-probe/1.27" audit-ID="" srcIP="127.0.0.1:45456" resp=200
I1030 06:43:18.185222       1 reflector.go:788] vendor/k8s.io/client-go/informers/factory.go:150: Watch close - *v1.PersistentVolume total 9 items received
I1030 06:43:21.631520       1 httplog.go:132] "HTTP" verb="GET" URI="/healthz" latency="118.036µs" userAgent="kube-probe/1.27" audit-ID="" srcIP="127.0.0.1:34778" resp=200
I1030 06:43:31.632502       1 httplog.go:132] "HTTP" verb="GET" URI="/healthz" latency="116.256µs" userAgent="kube-probe/1.27" audit-ID="" srcIP="127.0.0.1:53152" resp=200
I1030 06:43:41.632660       1 httplog.go:132] "HTTP" verb="GET" URI="/healthz" latency="140.599µs" userAgent="kube-probe/1.27" audit-ID="" srcIP="127.0.0.1:47478" resp=200
I1030 06:43:50.181414       1 reflector.go:788] vendor/k8s.io/client-go/informers/factory.go:150: Watch close - *v1.CSIDriver total 9 items received
I1030 06:43:51.632503       1 httplog.go:132] "HTTP" verb="GET" URI="/healthz" latency="130.994µs" userAgent="kube-probe/1.27" audit-ID="" srcIP="127.0.0.1:43476" resp=200
I1030 06:44:01.633241       1 httplog.go:132] "HTTP" verb="GET" URI="/healthz" latency="124.684µs" userAgent="kube-probe/1.27" audit-ID="" srcIP="127.0.0.1:42922" resp=200
I1030 06:44:11.632846       1 httplog.go:132] "HTTP" verb="GET" URI="/healthz" latency="123.646µs" userAgent="kube-probe/1.27" audit-ID="" srcIP="127.0.0.1:40736" resp=200
I1030 06:44:16.182881       1 reflector.go:788] vendor/k8s.io/client-go/informers/factory.go:150: Watch close - *v1.PersistentVolumeClaim total 7 items received
I1030 06:44:18.185050       1 reflector.go:788] vendor/k8s.io/client-go/informers/factory.go:150: Watch close - *v1.ReplicaSet total 9 items received
I1030 06:44:21.183905       1 reflector.go:788] vendor/k8s.io/client-go/informers/factory.go:150: Watch close - *v1.StorageClass total 7 items received
I1030 06:44:21.632219       1 httplog.go:132] "HTTP" verb="GET" URI="/healthz" latency="115.608µs" userAgent="kube-probe/1.27" audit-ID="" srcIP="127.0.0.1:60354" resp=200
I1030 06:44:28.190823       1 reflector.go:788] pkg/authentication/request/headerrequest/requestheader_controller.go:172: Watch close - *v1.ConfigMap total 11 items received
I1030 06:44:29.190597       1 reflector.go:788] vendor/k8s.io/client-go/informers/factory.go:150: Watch close - *v1.Pod total 8 items received
I1030 06:44:31.632614       1 httplog.go:132] "HTTP" verb="GET" URI="/healthz" latency="136.783µs" userAgent="kube-probe/1.27" audit-ID="" srcIP="127.0.0.1:52808" resp=200
I1030 06:44:41.632216       1 httplog.go:132] "HTTP" verb="GET" URI="/healthz" latency="134.142µs" userAgent="kube-probe/1.27" audit-ID="" srcIP="127.0.0.1:50688" resp=200
I1030 06:44:51.633135       1 httplog.go:132] "HTTP" verb="GET" URI="/healthz" latency="117.238µs" userAgent="kube-probe/1.27" audit-ID="" srcIP="127.0.0.1:38020" resp=200
I1030 06:44:54.188897       1 reflector.go:788] vendor/k8s.io/client-go/informers/factory.go:150: Watch close - *v1.Namespace total 7 items received
I1030 06:45:01.631792       1 httplog.go:132] "HTTP" verb="GET" URI="/healthz" latency="112.258µs" userAgent="kube-probe/1.27" audit-ID="" srcIP="127.0.0.1:43874" resp=200
I1030 06:45:06.186865       1 reflector.go:788] vendor/k8s.io/client-go/informers/factory.go:150: Watch close - *v1.ReplicationController total 9 items received
I1030 06:45:11.633134       1 httplog.go:132] "HTTP" verb="GET" URI="/healthz" latency="110.368µs" userAgent="kube-probe/1.27" audit-ID="" srcIP="127.0.0.1:39462" resp=200
I1030 06:45:21.632452       1 httplog.go:132] "HTTP" verb="GET" URI="/healthz" latency="126.625µs" userAgent="kube-probe/1.27" audit-ID="" srcIP="127.0.0.1:56210" resp=200
I1030 06:45:31.187259       1 reflector.go:788] pkg/server/dynamiccertificates/configmap_cafile_content.go:206: Watch close - *v1.ConfigMap total 9 items received
I1030 06:45:31.633054       1 httplog.go:132] "HTTP" verb="GET" URI="/healthz" latency="110.241µs" userAgent="kube-probe/1.27" audit-ID="" srcIP="127.0.0.1:40502" resp=200
I1030 06:45:41.631797       1 httplog.go:132] "HTTP" verb="GET" URI="/healthz" latency="115.153µs" userAgent="kube-probe/1.27" audit-ID="" srcIP="127.0.0.1:34210" resp=200
I1030 06:45:51.633059       1 httplog.go:132] "HTTP" verb="GET" URI="/healthz" latency="145.266µs" userAgent="kube-probe/1.27" audit-ID="" srcIP="127.0.0.1:53014" resp=200
I1030 06:46:00.190163       1 reflector.go:788] vendor/k8s.io/client-go/informers/factory.go:150: Watch close - *v1.CSINode total 11 items received
I1030 06:46:01.633185       1 httplog.go:132] "HTTP" verb="GET" URI="/healthz" latency="139.606µs" userAgent="kube-probe/1.27" audit-ID="" srcIP="127.0.0.1:50936" resp=200
I1030 06:46:09.186962       1 reflector.go:788] vendor/k8s.io/client-go/informers/factory.go:150: Watch close - *v1.StatefulSet total 9 items received
I1030 06:46:11.632282       1 httplog.go:132] "HTTP" verb="GET" URI="/healthz" latency="131.314µs" userAgent="kube-probe/1.27" audit-ID="" srcIP="127.0.0.1:40996" resp=200
I1030 06:46:21.187220       1 reflector.go:788] pkg/server/dynamiccertificates/configmap_cafile_content.go:206: Watch close - *v1.ConfigMap total 7 items received
I1030 06:46:21.632959       1 httplog.go:132] "HTTP" verb="GET" URI="/healthz" latency="123.538µs" userAgent="kube-probe/1.27" audit-ID="" srcIP="127.0.0.1:47986" resp=200
I1030 06:46:31.633239       1 httplog.go:132] "HTTP" verb="GET" URI="/healthz" latency="129.266µs" userAgent="kube-probe/1.27" audit-ID="" srcIP="127.0.0.1:41854" resp=200
I1030 06:46:41.632198       1 httplog.go:132] "HTTP" verb="GET" URI="/healthz" latency="134.073µs" userAgent="kube-probe/1.27" audit-ID="" srcIP="127.0.0.1:57100" resp=200
I1030 06:46:51.633455       1 httplog.go:132] "HTTP" verb="GET" URI="/healthz" latency="118.445µs" userAgent="kube-probe/1.27" audit-ID="" srcIP="127.0.0.1:47224" resp=200
I1030 06:47:01.633129       1 httplog.go:132] "HTTP" verb="GET" URI="/healthz" latency="137.84µs" userAgent="kube-probe/1.27" audit-ID="" srcIP="127.0.0.1:59250" resp=200
I1030 06:47:02.182745       1 reflector.go:788] vendor/k8s.io/client-go/informers/factory.go:150: Watch close - *v1.Service total 10 items received
I1030 06:47:11.632456       1 httplog.go:132] "HTTP" verb="GET" URI="/healthz" latency="131.327µs" userAgent="kube-probe/1.27" audit-ID="" srcIP="127.0.0.1:40040" resp=200
I1030 06:47:21.632152       1 httplog.go:132] "HTTP" verb="GET" URI="/healthz" latency="113.471µs" userAgent="kube-probe/1.27" audit-ID="" srcIP="127.0.0.1:46846" resp=200
I1030 06:47:31.631856       1 httplog.go:132] "HTTP" verb="GET" URI="/healthz" latency="133.058µs" userAgent="kube-probe/1.27" audit-ID="" srcIP="127.0.0.1:54350" resp=200
I1030 06:47:41.631718       1 httplog.go:132] "HTTP" verb="GET" URI="/healthz" latency="131.715µs" userAgent="kube-probe/1.27" audit-ID="" srcIP="127.0.0.1:37408" resp=200
I1030 06:47:51.632261       1 httplog.go:132] "HTTP" verb="GET" URI="/healthz" latency="109.722µs" userAgent="kube-probe/1.27" audit-ID="" srcIP="127.0.0.1:55654" resp=200
I1030 06:48:01.632241       1 httplog.go:132] "HTTP" verb="GET" URI="/healthz" latency="131.328µs" userAgent="kube-probe/1.27" audit-ID="" srcIP="127.0.0.1:36094" resp=200
I1030 06:48:11.183879       1 reflector.go:788] vendor/k8s.io/client-go/informers/factory.go:150: Watch close - *v1.CSIStorageCapacity total 7 items received
I1030 06:48:11.632233       1 httplog.go:132] "HTTP" verb="GET" URI="/healthz" latency="112.253µs" userAgent="kube-probe/1.27" audit-ID="" srcIP="127.0.0.1:46474" resp=200
I1030 06:48:21.633060       1 httplog.go:132] "HTTP" verb="GET" URI="/healthz" latency="110.347µs" userAgent="kube-probe/1.27" audit-ID="" srcIP="127.0.0.1:41118" resp=200
I1030 06:48:29.180072       1 reflector.go:788] vendor/k8s.io/client-go/informers/factory.go:150: Watch close - *v1.PodDisruptionBudget total 8 items received
I1030 06:48:31.632661       1 httplog.go:132] "HTTP" verb="GET" URI="/healthz" latency="110.226µs" userAgent="kube-probe/1.27" audit-ID="" srcIP="127.0.0.1:41130" resp=200
I1030 06:48:41.630775       1 httplog.go:132] "HTTP" verb="GET" URI="/healthz" latency="121.92µs" userAgent="kube-probe/1.27" audit-ID="" srcIP="127.0.0.1:39484" resp=200
I1030 06:48:51.631811       1 httplog.go:132] "HTTP" verb="GET" URI="/healthz" latency="104.973µs" userAgent="kube-probe/1.27" audit-ID="" srcIP="127.0.0.1:42336" resp=200
I1030 06:49:00.188404       1 reflector.go:788] vendor/k8s.io/client-go/informers/factory.go:150: Watch close - *v1.Node total 11 items received
I1030 06:49:01.632749       1 httplog.go:132] "HTTP" verb="GET" URI="/healthz" latency="129.429µs" userAgent="kube-probe/1.27" audit-ID="" srcIP="127.0.0.1:36848" resp=200
I1030 06:49:11.633212       1 httplog.go:132] "HTTP" verb="GET" URI="/healthz" latency="138.545µs" userAgent="kube-probe/1.27" audit-ID="" srcIP="127.0.0.1:56080" resp=200
I1030 06:49:21.632732       1 httplog.go:132] "HTTP" verb="GET" URI="/healthz" latency="134.479µs" userAgent="kube-probe/1.27" audit-ID="" srcIP="127.0.0.1:50896" resp=200
I1030 06:49:31.632178       1 httplog.go:132] "HTTP" verb="GET" URI="/healthz" latency="147.964µs" userAgent="kube-probe/1.27" audit-ID="" srcIP="127.0.0.1:41216" resp=200
I1030 06:49:41.633405       1 httplog.go:132] "HTTP" verb="GET" URI="/healthz" latency="128.78µs" userAgent="kube-probe/1.27" audit-ID="" srcIP="127.0.0.1:49854" resp=200
I1030 06:49:51.633433       1 httplog.go:132] "HTTP" verb="GET" URI="/healthz" latency="130.767µs" userAgent="kube-probe/1.27" audit-ID="" srcIP="127.0.0.1:40178" resp=200
I1030 06:50:01.631789       1 httplog.go:132] "HTTP" verb="GET" URI="/healthz" latency="146.126µs" userAgent="kube-probe/1.27" audit-ID="" srcIP="127.0.0.1:48146" resp=200
I1030 06:50:05.186622       1 reflector.go:788] vendor/k8s.io/client-go/informers/factory.go:150: Watch close - *v1.StorageClass total 6 items received
I1030 06:50:11.631632       1 httplog.go:132] "HTTP" verb="GET" URI="/healthz" latency="114.008µs" userAgent="kube-probe/1.27" audit-ID="" srcIP="127.0.0.1:34370" resp=200
I1030 06:50:21.632841       1 httplog.go:132] "HTTP" verb="GET" URI="/healthz" latency="135.177µs" userAgent="kube-probe/1.27" audit-ID="" srcIP="127.0.0.1:53104" resp=200
I1030 06:50:31.632181       1 httplog.go:132] "HTTP" verb="GET" URI="/healthz" latency="111.089µs" userAgent="kube-probe/1.27" audit-ID="" srcIP="127.0.0.1:44280" resp=200
I1030 06:50:32.188418       1 reflector.go:788] vendor/k8s.io/client-go/informers/factory.go:150: Watch close - *v1.ReplicaSet total 7 items received
I1030 06:50:41.633414       1 httplog.go:132] "HTTP" verb="GET" URI="/healthz" latency="119.084µs" userAgent="kube-probe/1.27" audit-ID="" srcIP="127.0.0.1:33454" resp=200
I1030 06:50:51.632276       1 httplog.go:132] "HTTP" verb="GET" URI="/healthz" latency="135.784µs" userAgent="kube-probe/1.27" audit-ID="" srcIP="127.0.0.1:35998" resp=200
I1030 06:51:01.633956       1 httplog.go:132] "HTTP" verb="GET" URI="/healthz" latency="104.135µs" userAgent="kube-probe/1.27" audit-ID="" srcIP="127.0.0.1:56054" resp=200
I1030 06:51:11.183998       1 reflector.go:788] vendor/k8s.io/client-go/informers/factory.go:150: Watch close - *v1.CSIDriver total 9 items received
I1030 06:51:11.632838       1 httplog.go:132] "HTTP" verb="GET" URI="/healthz" latency="138.025µs" userAgent="kube-probe/1.27" audit-ID="" srcIP="127.0.0.1:37502" resp=200
I1030 06:51:14.194486       1 reflector.go:788] vendor/k8s.io/client-go/informers/factory.go:150: Watch close - *v1.Pod total 7 items received
I1030 06:51:20.190474       1 reflector.go:788] vendor/k8s.io/client-go/informers/factory.go:150: Watch close - *v1.ReplicationController total 8 items received
I1030 06:51:21.633231       1 httplog.go:132] "HTTP" verb="GET" URI="/healthz" latency="135.328µs" userAgent="kube-probe/1.27" audit-ID="" srcIP="127.0.0.1:46804" resp=200
I1030 06:51:22.189914       1 reflector.go:788] pkg/server/dynamiccertificates/configmap_cafile_content.go:206: Watch close - *v1.ConfigMap total 6 items received
I1030 06:51:31.631755       1 httplog.go:132] "HTTP" verb="GET" URI="/healthz" latency="128.231µs" userAgent="kube-probe/1.27" audit-ID="" srcIP="127.0.0.1:51206" resp=200
I1030 06:51:41.633203       1 httplog.go:132] "HTTP" verb="GET" URI="/healthz" latency="124.968µs" userAgent="kube-probe/1.27" audit-ID="" srcIP="127.0.0.1:42206" resp=200
I1030 06:51:51.632770       1 httplog.go:132] "HTTP" verb="GET" URI="/healthz" latency="125.112µs" userAgent="kube-probe/1.27" audit-ID="" srcIP="127.0.0.1:34148" resp=200
I1030 06:51:55.190639       1 reflector.go:788] vendor/k8s.io/client-go/informers/factory.go:150: Watch close - *v1.StatefulSet total 7 items received
I1030 06:52:01.632093       1 httplog.go:132] "HTTP" verb="GET" URI="/healthz" latency="132.668µs" userAgent="kube-probe/1.27" audit-ID="" srcIP="127.0.0.1:60994" resp=200
I1030 06:52:11.185803       1 reflector.go:788] vendor/k8s.io/client-go/informers/factory.go:150: Watch close - *v1.PersistentVolumeClaim total 8 items received
I1030 06:52:11.633012       1 httplog.go:132] "HTTP" verb="GET" URI="/healthz" latency="112.216µs" userAgent="kube-probe/1.27" audit-ID="" srcIP="127.0.0.1:45618" resp=200
I1030 06:52:21.631561       1 httplog.go:132] "HTTP" verb="GET" URI="/healthz" latency="102.741µs" userAgent="kube-probe/1.27" audit-ID="" srcIP="127.0.0.1:43818" resp=200
I1030 06:52:31.633198       1 httplog.go:132] "HTTP" verb="GET" URI="/healthz" latency="123.42µs" userAgent="kube-probe/1.27" audit-ID="" srcIP="127.0.0.1:47170" resp=200
I1030 06:52:32.190019       1 reflector.go:788] pkg/server/dynamiccertificates/configmap_cafile_content.go:206: Watch close - *v1.ConfigMap total 7 items received
I1030 06:52:41.633087       1 httplog.go:132] "HTTP" verb="GET" URI="/healthz" latency="117.628µs" userAgent="kube-probe/1.27" audit-ID="" srcIP="127.0.0.1:43690" resp=200
I1030 06:52:51.632091       1 httplog.go:132] "HTTP" verb="GET" URI="/healthz" latency="132.646µs" userAgent="kube-probe/1.27" audit-ID="" srcIP="127.0.0.1:50942" resp=200
I1030 06:53:01.636116       1 httplog.go:132] "HTTP" verb="GET" URI="/healthz" latency="122.272µs" userAgent="kube-probe/1.27" audit-ID="" srcIP="127.0.0.1:43860" resp=200
I1030 06:53:06.192335       1 reflector.go:788] vendor/k8s.io/client-go/informers/factory.go:150: Watch close - *v1.Namespace total 9 items received
I1030 06:53:10.187745       1 reflector.go:788] vendor/k8s.io/client-go/informers/factory.go:150: Watch close - *v1.PersistentVolume total 10 items received
I1030 06:53:11.631691       1 httplog.go:132] "HTTP" verb="GET" URI="/healthz" latency="118.068µs" userAgent="kube-probe/1.27" audit-ID="" srcIP="127.0.0.1:60400" resp=200
I1030 06:53:15.194701       1 reflector.go:788] pkg/authentication/request/headerrequest/requestheader_controller.go:172: Watch close - *v1.ConfigMap total 9 items received
I1030 06:53:20.193263       1 reflector.go:788] vendor/k8s.io/client-go/informers/factory.go:150: Watch close - *v1.CSINode total 8 items received
I1030 06:53:21.633117       1 httplog.go:132] "HTTP" verb="GET" URI="/healthz" latency="131.026µs" userAgent="kube-probe/1.27" audit-ID="" srcIP="127.0.0.1:53456" resp=200
I1030 06:53:22.185731       1 reflector.go:788] vendor/k8s.io/client-go/informers/factory.go:150: Watch close - *v1.Service total 7 items received
I1030 06:53:31.633616       1 httplog.go:132] "HTTP" verb="GET" URI="/healthz" latency="139.128µs" userAgent="kube-probe/1.27" audit-ID="" srcIP="127.0.0.1:54170" resp=200
I1030 06:53:41.632403       1 httplog.go:132] "HTTP" verb="GET" URI="/healthz" latency="156.026µs" userAgent="kube-probe/1.27" audit-ID="" srcIP="127.0.0.1:58648" resp=200
I1030 06:53:51.633290       1 httplog.go:132] "HTTP" verb="GET" URI="/healthz" latency="121.855µs" userAgent="kube-probe/1.27" audit-ID="" srcIP="127.0.0.1:52112" resp=200
I1030 06:54:01.632947       1 httplog.go:132] "HTTP" verb="GET" URI="/healthz" latency="122.447µs" userAgent="kube-probe/1.27" audit-ID="" srcIP="127.0.0.1:41706" resp=200
I1030 06:54:11.632944       1 httplog.go:132] "HTTP" verb="GET" URI="/healthz" latency="117.02µs" userAgent="kube-probe/1.27" audit-ID="" srcIP="127.0.0.1:38994" resp=200
I1030 06:54:21.633275       1 httplog.go:132] "HTTP" verb="GET" URI="/healthz" latency="113.436µs" userAgent="kube-probe/1.27" audit-ID="" srcIP="127.0.0.1:33528" resp=200
I1030 06:54:31.633019       1 httplog.go:132] "HTTP" verb="GET" URI="/healthz" latency="128.307µs" userAgent="kube-probe/1.27" audit-ID="" srcIP="127.0.0.1:47444" resp=200
I1030 06:54:41.631940       1 httplog.go:132] "HTTP" verb="GET" URI="/healthz" latency="173.024µs" userAgent="kube-probe/1.27" audit-ID="" srcIP="127.0.0.1:59926" resp=200
I1030 06:54:51.633224       1 httplog.go:132] "HTTP" verb="GET" URI="/healthz" latency="116.439µs" userAgent="kube-probe/1.27" audit-ID="" srcIP="127.0.0.1:55414" resp=200
I1030 06:54:55.191761       1 reflector.go:788] vendor/k8s.io/client-go/informers/factory.go:150: Watch close - *v1.Node total 8 items received
I1030 06:55:01.632068       1 httplog.go:132] "HTTP" verb="GET" URI="/healthz" latency="113.472µs" userAgent="kube-probe/1.27" audit-ID="" srcIP="127.0.0.1:33014" resp=200
I1030 06:55:11.632032       1 httplog.go:132] "HTTP" verb="GET" URI="/healthz" latency="110.167µs" userAgent="kube-probe/1.27" audit-ID="" srcIP="127.0.0.1:39048" resp=200
I1030 06:55:21.632898       1 httplog.go:132] "HTTP" verb="GET" URI="/healthz" latency="117.778µs" userAgent="kube-probe/1.27" audit-ID="" srcIP="127.0.0.1:40694" resp=200
I1030 06:55:31.631702       1 httplog.go:132] "HTTP" verb="GET" URI="/healthz" latency="107.029µs" userAgent="kube-probe/1.27" audit-ID="" srcIP="127.0.0.1:42442" resp=200
I1030 06:55:41.632328       1 httplog.go:132] "HTTP" verb="GET" URI="/healthz" latency="125.492µs" userAgent="kube-probe/1.27" audit-ID="" srcIP="127.0.0.1:54640" resp=200
I1030 06:55:49.186574       1 reflector.go:788] vendor/k8s.io/client-go/informers/factory.go:150: Watch close - *v1.CSIStorageCapacity total 9 items received
I1030 06:55:51.633414       1 httplog.go:132] "HTTP" verb="GET" URI="/healthz" latency="145.869µs" userAgent="kube-probe/1.27" audit-ID="" srcIP="127.0.0.1:55922" resp=200
I1030 06:55:52.182886       1 reflector.go:788] vendor/k8s.io/client-go/informers/factory.go:150: Watch close - *v1.PodDisruptionBudget total 8 items received
I1030 06:56:01.632156       1 httplog.go:132] "HTTP" verb="GET" URI="/healthz" latency="116.597µs" userAgent="kube-probe/1.27" audit-ID="" srcIP="127.0.0.1:48590" resp=200
